Workbook

Sheet Parameters
A1: USDA RURAL DEVELOPMENT — CENTRALIZED TRAINING BUDGET (Nov 29 – Dec 1, 2026)
A2: Adjust the yellow cells. Daily, Options, Historical and Thresholds sheets recompute automatically. No internet pricing is pulled; quotes are a 2026-10-24 snapshot.
A4: Parameter | B4: Value | C4: Allowed range / note | D4: Unit
A5: Approved budget ceiling (incl. reserve) | B5: 53000 | C5: 0 – 100,000 (incl. reserve) | D5: USD
A6: Airfare adjustment factor | B6: 1 | C6: 0.5 – 2.0; stress scenario = factor × 1.20
A7: Contingency reserve rate | B7: 0.05 | C7: 0 – 20% of base subtotal
A8: Nov 29 breakfast provided by government? | B8: No | C8: Yes/No — 'Yes' adds NO new purchase
A9: Attendee count (headcount) | B9: =INDEX(Candidate_Model!C:C,Decision!B12) -> 24 | C9: Automatically selected conditional headcount; no claim of business necessity.
A10: Lodging nights | B10: =MAX(0,B14-B13) -> 4 | C10: Automatically recalculated from arrival / departure; no fixed 4-night assumption | D10: nights
A11: Internal lodging-tax rate (budget est.) | B11: 0.12 | C11: 12% of reimbursable lodging — planning only
A12: Registration fee per person | B12: 180 | C12: Incl. lunches Nov 29/30 & Dec 1 | D12: USD
A13: Arrival date | B13: 46354 | C13: Day before training; must fully attend
A14: Departure date | B14: 46358 | C14: Day after training
A15: Training dates (fixed) | B15: 2026-11-29 → 2026-12-01 | C15: Catered dates unchanged
A18: Key regulatory basis:
A19: Use actual room quote, never truncate over-cap quote to reimbursement cap. Internal 12% tax is a task assumption.
A20: FTR301-11.17/.18/.101: hotel complimentary meals do not reduce M&IE; government meals do; travel days 75%, then full meal deductions, minimum incidentals.
A21: Tea/coffee/fruit refreshments do not reduce M&IE. Registration already purchases the three training lunches: no second procurement charge.
A22: Government meals reduce traveler M&IE; net traveler M&IE AND agency catering estimates are both included in this budget.
A23: RD2036-A, 07/19/2024, sec2036.74: compare sites and verify approval requirements; see Sources and approval_register.csv.
A24: • Over-cap hotels are NOT compliant recommendations without written actual-expense authorization (301-11.300/.301); none is held.
A30: SNAPSHOT: Word, CSV, PPT and approval PDF are static. Change parameters -> recalculate, recheck quote validity and re-export all four. Blank unknowns are NOT zero-cost quotes.
A34: Quote applicability | B34: =IF(AND(B13=DATE(2026,11,28),B14=DATE(2026,12,2)),"DATED SNAPSHOT; inventory unheld","STALE: RE-QUOTE; computed costs are old-price estimates") -> DATED SNAPSHOT; inventory unheld
A35: Priority city for Daily detail | B35: =INDEX(Candidate_Model!B:B,Decision!B12) -> Boston
A36: Full attendance / period coverage | B36: =IF(AND(B13<=DATE(2026,11,28),B14>=DATE(2026,12,2),B14>B13,B14-B13<=365),"VALID DATE STRUCTURE","NOT VERIFIED FOR FULL TRAINING OR OUTSIDE DAILY GRID") -> VALID DATE STRUCTURE

Sheet CityData
A1: EXISTING QUOTE ANCHORS, corrected against real screenshots; single-seat/room planning only, not approved or held
A2: City | B2: Dest airport | C2: Flight RT /person, origin in airline/source field | D2: Flight airline | E2: Hotel (budgeted) | F2: Hotel nightly (excl tax) | G2: Displayed score normalized /10 (source scale in HotelQuality) | H2: Review count visible in retained capture | I2: Breakfast incl? | J2: FY27 cap Nov night | K2: FY27 cap Dec1 night | L2: MIE (FY27)
A3: Boston | B3: BOS | C3: 311 | D3: See Google Flights screenshot, DCA | E3: DoubleTree by Hilton Boston Bayside | F3: 108 | G3: 8.6 | H3: 449 | I3: Unknown | J3: 213 | K3: 213 | L3: 92
A4: Chicago | B4: ORD | C4: 270 | D4: See Google Flights screenshot, DCA | E4: Embassy Suites by Hilton Chicago O’Hare Rosemont | F4: 158 | G4: 8.2 | H4: 3418 | I4: Agoda158: free breakfast shown; single occupancy UNVERIFIED | J4: 232 | K4: 148 | L4: 92
A5: Denver | B5: DEN | C5: 578 | D5: See Google Flights screenshot, IAD | E5: Home2 Suites by Hilton Denver Downtown Convention Center | F5: 109 | G5: 9 | H5: 94 | I5: Yes | J5: 170 | K5: 170 | L5: 92
A6: Phoenix | B6: PHX | C6: 499 | D6: See Google Flights screenshot, IAD | E6: Hampton Inn & Suites Phoenix North/Happy Valley | F6: 150 | G6: 9.4 | H6: 116 | I6: Yes | J6: 165 | K6: 165 | L6: 86
A7: Seattle | B7: SEA | C7: 590 | D7: See Google Flights screenshot, IAD | E7: Country Inn & Suites by Radisson Seattle-Tacoma International Airport | F7: 101 | G7: 8.6 | H7: 2018 | I7: Booking101: free breakfast shown; 2 guests, single occupancy UNVERIFIED | J7: 188 | K7: 188 | L7: 92
A9: Meal planning rates (GSA FY2027 M&IE components, internal catering estimate):
A10: City | B10: Breakfast $ | C10: Lunch $ | D10: Dinner $
A11: Boston | B11: 23 | C11: 26 | D11: 38
A12: Chicago | B12: 23 | C12: 26 | D12: 38
A13: Denver | B13: 23 | C13: 26 | D13: 38
A14: Phoenix | B14: 22 | C14: 23 | D14: 36
A15: Seattle | B15: 23 | C15: 26 | D15: 38
A17: Personal ground planning allowances: HQ comparison base, road travel for early flights; not claimed home addresses/receipts. Venue transfer still unquoted.
A18: City | B18: Airport↔hotel RT $ | C18: Home↔DCA RT $
A19: Boston | B19: 40 | C19: 80
A20: Chicago | B20: 40 | C20: 80
A21: Denver | B21: 60 | C21: 160
A22: Phoenix | B22: 50 | C22: 160
A23: Seattle | B23: 60 | C23: 160
A25: Shared/fixed & light-refreshment planning inputs (to be quoted — see Sources):
A26: Venue quote not provided: use independent Unknowns inputs, never a shared fictitious supplier price. | B26: 0
A27: Venue days | B27: 3
A28: Light refreshments per person/day (301-74.7) | B28: 15
A29: Refreshment days | B29: 3

Sheet Daily
A1: DAILY PARTIAL COST DETAIL — priority for evidence completion, not approved recommendation
A2: Recommended city: | B2: =Parameters!B35 -> Boston | C2: (change to Boston/Chicago/Denver/Phoenix/Seattle — pulls that city's anchor data)
A4: Per-person building blocks
A5: Round-trip airfare (× airfare factor) | B5: =INDEX(Candidate_Model!D:D,Decision!B12)*FFAC -> 311
A6: Lodging — room only (nightly × nights) | B6: =INDEX(Candidate_Model!E:E,Decision!B12)*NIGHTS -> 432
A7: Lodging tax (internal est.) | B7: =B6*TAXRATE -> 51.84
A8: Registration fee (incl. 3 lunches) | B8: =REGFEE -> 180
A9: Agency dinners (Nov 28 & Dec 1) | B9: =2*INDEX(CityData!$D$11:$D$15,MATCH(Daily!$B$2,CityData!$A$11:$A$15,0)) -> 76
A10: Agency lunch (Dec 2 travel-home day) | B10: =INDEX(CityData!$C$11:$C$15,MATCH(Daily!$B$2,CityData!$A$11:$A$15,0)) -> 26
A11: Extra hotel breakfast: NOT a verified rate; enter Unknowns if required | B11: 0
A12: Government-breakfast toggle changes net MIE below, not new procurement | B12: 0
A13: Light refreshments (coffee/fruit/water) | B13: =REFRPP*REFRDAYS -> 45
A14: Ground transport (airport↔hotel + home↔DCA) | B14: =INDEX(Candidate_Model!F:F,Decision!B12) -> 120
A15: PER-PERSON SUBTOTAL | B15: =SUM(B5:B14)+B31 -> 1475.84
A17: Shared / fixed costs (per event)
A18: Additional unknown cost scenario for selected city/headcount | B18: =SUM(INDEX(Candidate_Model!I:I,Decision!B12)) -> 0
A19: FIXED SUBTOTAL | B19: =B18 -> 0
A21: EVENT TOTALS (at chosen headcount)
A22: Headcount (param) | B22: =HEADCOUNT -> 24
A23: Variable total (per-person × headcount) | B23: =B15*HEADCOUNT -> 35420.16
A24: Base subtotal (variable + fixed) | B24: =B23+B19 -> 35420.16
A25: Contingency reserve | B25: =B24*RESRATE -> 1771.008
A26: GRAND TOTAL (base + reserve) | B26: =B24+B25 -> 37191.168
A27: Budget ceiling | B27: =CEILING -> 53000
A28: Within budget? | B28: =IF(B26<=CEILING,"YES — within ceiling","NO — exceeds ceiling") -> YES — within ceiling
A29: Headroom for unquoted/TBD base costs | B29: =CEILING/(1+RESRATE)-B24 -> 15056.03
A31: Net traveler MIE /person (included in B15 and event budget) | B31: =SUM(INDEX(MIE_Daily!$B$2:$AO$367,0,5+8*(MATCH(B2,CityData!A3:A7,0)-1))) -> 234
A33: All displayed totals are partial estimates with unresolved U, not complete approved costs.
A34: Selected combination ID (qualified first, otherwise evidence priority) | B34: =INDEX(Candidate_Model!A:A,Decision!B12) -> P01
A35: Date | B35: Net traveler MIE/person | C35: Lodging+tax/person | D35: Headcount | E35: MIE group | F35: Lodging group | G35: Note
A36: =MIE_Daily!A2 -> 46354 | B36: =INDEX(MIE_Daily!$B$2:$AO$367,ROW()-35,5+8*(MATCH($B$2,CityData!$A$3:$A$7,0)-1)) -> 31 | C36: =IF(AND(A36<>"",A36<Parameters!$B$14),INDEX(Candidate_Model!E:E,Decision!B12)*(1+TAXRATE),0) -> 120.96 | D36: =HEADCOUNT -> 24 | E36: =B36*D36 -> 744 | F36: =C36*D36 -> 2903.04 | G36: Government meals on fixed calendar dates; hotel breakfast/refreshments not deducted.
A37: =MIE_Daily!A3 -> 46355 | B37: =INDEX(MIE_Daily!$B$2:$AO$367,ROW()-35,5+8*(MATCH($B$2,CityData!$A$3:$A$7,0)-1)) -> 66 | C37: =IF(AND(A37<>"",A37<Parameters!$B$14),INDEX(Candidate_Model!E:E,Decision!B12)*(1+TAXRATE),0) -> 120.96 | D37: =HEADCOUNT -> 24 | E37: =B37*D37 -> 1584 | F37: =C37*D37 -> 2903.04 | G37: Government meals on fixed calendar dates; hotel breakfast/refreshments not deducted.
A38: =MIE_Daily!A4 -> 46356 | B38: =INDEX(MIE_Daily!$B$2:$AO$367,ROW()-35,5+8*(MATCH($B$2,CityData!$A$3:$A$7,0)-1)) -> 66 | C38: =IF(AND(A38<>"",A38<Parameters!$B$14),INDEX(Candidate_Model!E:E,Decision!B12)*(1+TAXRATE),0) -> 120.96 | D38: =HEADCOUNT -> 24 | E38: =B38*D38 -> 1584 | F38: =C38*D38 -> 2903.04 | G38: Government meals on fixed calendar dates; hotel breakfast/refreshments not deducted.
A39: =MIE_Daily!A5 -> 46357 | B39: =INDEX(MIE_Daily!$B$2:$AO$367,ROW()-35,5+8*(MATCH($B$2,CityData!$A$3:$A$7,0)-1)) -> 28 | C39: =IF(AND(A39<>"",A39<Parameters!$B$14),INDEX(Candidate_Model!E:E,Decision!B12)*(1+TAXRATE),0) -> 120.96 | D39: =HEADCOUNT -> 24 | E39: =B39*D39 -> 672 | F39: =C39*D39 -> 2903.04 | G39: Government meals on fixed calendar dates; hotel breakfast/refreshments not deducted.
A40: =MIE_Daily!A6 -> 46358 | B40: =INDEX(MIE_Daily!$B$2:$AO$367,ROW()-35,5+8*(MATCH($B$2,CityData!$A$3:$A$7,0)-1)) -> 43 | C40: =IF(AND(A40<>"",A40<Parameters!$B$14),INDEX(Candidate_Model!E:E,Decision!B12)*(1+TAXRATE),0) -> 0 | D40: =HEADCOUNT -> 24 | E40: =B40*D40 -> 1032 | F40: =C40*D40 -> 0 | G40: Government meals on fixed calendar dates; hotel breakfast/refreshments not deducted.
A41: =MIE_Daily!A7 | B41: =INDEX(MIE_Daily!$B$2:$AO$367,ROW()-35,5+8*(MATCH($B$2,CityData!$A$3:$A$7,0)-1)) -> 0 | C41: =IF(AND(A41<>"",A41<Parameters!$B$14),INDEX(Candidate_Model!E:E,Decision!B12)*(1+TAXRATE),0) -> 0 | D41: =HEADCOUNT -> 24 | E41: =B41*D41 -> 0 | F41: =C41*D41 -> 0 | G41: Government meals on fixed calendar dates; hotel breakfast/refreshments not deducted.
A42: =MIE_Daily!A8 | B42: =INDEX(MIE_Daily!$B$2:$AO$367,ROW()-35,5+8*(MATCH($B$2,CityData!$A$3:$A$7,0)-1)) -> 0 | C42: =IF(AND(A42<>"",A42<Parameters!$B$14),INDEX(Candidate_Model!E:E,Decision!B12)*(1+TAXRATE),0) -> 0 | D42: =HEADCOUNT -> 24 | E42: =B42*D42 -> 0 | F42: =C42*D42 -> 0 | G42: Government meals on fixed calendar dates; hotel breakfast/refreshments not deducted.
A43: =MIE_Daily!A9 | B43: =INDEX(MIE_Daily!$B$2:$AO$367,ROW()-35,5+8*(MATCH($B$2,CityData!$A$3:$A$7,0)-1)) -> 0 | C43: =IF(AND(A43<>"",A43<Parameters!$B$14),INDEX(Candidate_Model!E:E,Decision!B12)*(1+TAXRATE),0) -> 0 | D43: =HEADCOUNT -> 24 | E43: =B43*D43 -> 0 | F43: =C43*D43 -> 0 | G43: Government meals on fixed calendar dates; hotel breakfast/refreshments not deducted.
A44: =MIE_Daily!A10 | B44: =INDEX(MIE_Daily!$B$2:$AO$367,ROW()-35,5+8*(MATCH($B$2,CityData!$A$3:$A$7,0)-1)) -> 0 | C44: =IF(AND(A44<>"",A44<Parameters!$B$14),INDEX(Candidate_Model!E:E,Decision!B12)*(1+TAXRATE),0) -> 0 | D44: =HEADCOUNT -> 24 | E44: =B44*D44 -> 0 | F44: =C44*D44 -> 0 | G44: Government meals on fixed calendar dates; hotel breakfast/refreshments not deducted.
A45: =MIE_Daily!A11 | B45: =INDEX(MIE_Daily!$B$2:$AO$367,ROW()-35,5+8*(MATCH($B$2,CityData!$A$3:$A$7,0)-1)) -> 0 | C45: =IF(AND(A45<>"",A45<Parameters!$B$14),INDEX(Candidate_Model!E:E,Decision!B12)*(1+TAXRATE),0) -> 0 | D45: =HEADCOUNT -> 24 | E45: =B45*D45 -> 0 | F45: =C45*D45 -> 0 | G45: Government meals on fixed calendar dates; hotel breakfast/refreshments not deducted.
...

Sheet Options
A1: OPTIONS COMPARISON — 5 candidate cities × 18/24 attendees (base & +20% airfare stress)
A2: Per-person & event totals built from the same formulas as Daily. 'Stress' applies airfare ×1.20 on top of the airfare factor. Decision rule: fit ceiling → more people → lower total-with-reserve → alphabetical.
A4: City | B4: Head-count | C4: Airfare RT×fac | D4: Lodging+tax / person (dynamic nights) | E4: Reg | F4: Agency meals+bkfst | G4: Refresh. | H4: Ground | I4: Per-person | J4: Variable ×N | K4: Entered additional unquoted base U | L4: Partial/scenario base K+entered U | M4: Reserve | N4: Partial/scenario total incl reserve | O4: Net traveler MIE /person | P4: Known/estimated K excluding U | Q4: Entered U scenario | R4: Lodging compliant | S4: Dated quote applies | T4: Qualified feasible | U4: Conditional cost feasible | V4: Qualified rank | W4: Conditional rank | X4: Airfare total A | Y4: Max additional U @base | Z4: Max additional U @+20% | AA4: Stress total | AB4: Cost scope / unresolved
A5: Boston | B5: 24 | C5: =INDEX(CityData!$C:$C,MATCH(A5,CityData!$A:$A,0))*FFAC -> 311 | D5: =SUM(MIE_Daily!G2:G367) -> 483.84 | E5: =REGFEE -> 180 | F5: =INDEX(CityData!$D$11:$D$15,MATCH(A5,CityData!$A$11:$A$15,0))*(IF(AND(Parameters!$B$13<=DATE(2026,11,28),Parameters!$B$14>=DATE(2026,11,28)),1,0)+IF(AND(Parameters!$B$13<=DATE(2026,12,1),Parameters!$B$14>=DATE(2026,12,1)),1,0))+INDEX(CityData!$C$11:$C$15,MATCH(A5,CityData!$A$11:$A$15,0))*IF(AND(Parameters!$B$13<=DATE(2026,12,2),Parameters!$B$14>=DATE(2026,12,2)),1,0) -> 102 | G5: =REFRPP*REFRDAYS -> 45 | H5: =INDEX(CityData!$B$19:$B$23,MATCH(A5,CityData!$A$19:$A$23,0))+INDEX(CityData!$C$19:$C$23,MATCH(A5,CityData!$A$19:$A$23,0)) -> 120 | I5: =SUM(C5:H5)+O5 -> 1475.84 | J5: =I5*B5 -> 35420.16 | K5: =SUM(Unknowns!B2,Unknowns!G2)+B5*(NIGHTS*SUM(Unknowns!C2)+SUM(Unknowns!D2:F2)) -> 0 | L5: =J5+K5 -> 35420.16 | M5: =L5*RESRATE -> 1771.008 | N5: =L5+M5 -> 37191.168 | O5: =SUM(MIE_Daily!F2:F367) -> 234 | P5: =J5 -> 35420.16 | Q5: =K5 -> 0 | R5: =MIN(MIE_Daily!I2:I367) -> 1 | S5: =IF(AND(Parameters!$B$13=DATE(2026,11,28),Parameters!$B$14=DATE(2026,12,2)),1,0) -> 1 | T5: =IF(AND(R5=1,S5=1,Unknowns!H2=1,Unknowns!I2=1,N5<=CEILING,Parameters!$B$36="VALID DATE STRUCTURE"),1,0) -> 0 | U5: =IF(AND(R5=1,S5=1,N5<=CEILING,Parameters!$B$36="VALID DATE STRUCTURE"),1,0) -> 1 | V5: =IF(T5=0,99999,1+SUMPRODUCT($T$5:$T$14,--($B$5:$B$14>B5))+SUMPRODUCT($T$5:$T$14,--($B$5:$B$14=B5),--($N$5:$N$14<N5))+SUMPRODUCT($T$5:$T$14,--($B$5:$B$14=B5),--($N$5:$N$14=N5),--($A$5:$A$14<A5))) -> 99999 | W5: =IF(U5=0,99999,1+SUMPRODUCT($U$5:$U$14,--($B$5:$B$14>B5))+SUMPRODUCT($U$5:$U$14,--($B$5:$B$14=B5),--($N$5:$N$14<N5))+SUMPRODUCT($U$5:$U$14,--($B$5:$B$14=B5),--($N$5:$N$14=N5),--($A$5:$A$14<A5))) -> 1 | X5: =C5*B5 -> 7464 | Y5: =CEILING/(1+RESRATE)-P5 -> 15056.03 | Z5: =Y5-0.2*X5 -> 13563.23 | AA5: =(L5+0.2*X5)*(1+RESRATE) -> 38758.608 | AB5: Partial at entered U only; U_Boston,24 remains independently unknown; no qualified recommendation. Group inventory, occupancy, breakfast, fees, venue/local transfers pending as applicable.
A6: Boston | B6: 18 | C6: =INDEX(CityData!$C:$C,MATCH(A6,CityData!$A:$A,0))*FFAC -> 311 | D6: =SUM(MIE_Daily!G2:G367) -> 483.84 | E6: =REGFEE -> 180 | F6: =INDEX(CityData!$D$11:$D$15,MATCH(A6,CityData!$A$11:$A$15,0))*(IF(AND(Parameters!$B$13<=DATE(2026,11,28),Parameters!$B$14>=DATE(2026,11,28)),1,0)+IF(AND(Parameters!$B$13<=DATE(2026,12,1),Parameters!$B$14>=DATE(2026,12,1)),1,0))+INDEX(CityData!$C$11:$C$15,MATCH(A6,CityData!$A$11:$A$15,0))*IF(AND(Parameters!$B$13<=DATE(2026,12,2),Parameters!$B$14>=DATE(2026,12,2)),1,0) -> 102 | G6: =REFRPP*REFRDAYS -> 45 | H6: =INDEX(CityData!$B$19:$B$23,MATCH(A6,CityData!$A$19:$A$23,0))+INDEX(CityData!$C$19:$C$23,MATCH(A6,CityData!$A$19:$A$23,0)) -> 120 | I6: =SUM(C6:H6)+O6 -> 1475.84 | J6: =I6*B6 -> 26565.12 | K6: =SUM(Unknowns!B2,Unknowns!G2)+B6*(NIGHTS*SUM(Unknowns!C2)+SUM(Unknowns!D2:F2)) -> 0 | L6: =J6+K6 -> 26565.12 | M6: =L6*RESRATE -> 1328.256 | N6: =L6+M6 -> 27893.376 | O6: =SUM(MIE_Daily!F2:F367) -> 234 | P6: =J6 -> 26565.12 | Q6: =K6 -> 0 | R6: =MIN(MIE_Daily!I2:I367) -> 1 | S6: =IF(AND(Parameters!$B$13=DATE(2026,11,28),Parameters!$B$14=DATE(2026,12,2)),1,0) -> 1 | T6: =IF(AND(R6=1,S6=1,Unknowns!H2=1,Unknowns!I2=1,N6<=CEILING,Parameters!$B$36="VALID DATE STRUCTURE"),1,0) -> 0 | U6: =IF(AND(R6=1,S6=1,N6<=CEILING,Parameters!$B$36="VALID DATE STRUCTURE"),1,0) -> 1 | V6: =IF(T6=0,99999,1+SUMPRODUCT($T$5:$T$14,--($B$5:$B$14>B6))+SUMPRODUCT($T$5:$T$14,--($B$5:$B$14=B6),--($N$5:$N$14<N6))+SUMPRODUCT($T$5:$T$14,--($B$5:$B$14=B6),--($N$5:$N$14=N6),--($A$5:$A$14<A6))) -> 99999 | W6: =IF(U6=0,99999,1+SUMPRODUCT($U$5:$U$14,--($B$5:$B$14>B6))+SUMPRODUCT($U$5:$U$14,--($B$5:$B$14=B6),--($N$5:$N$14<N6))+SUMPRODUCT($U$5:$U$14,--($B$5:$B$14=B6),--($N$5:$N$14=N6),--($A$5:$A$14<A6))) -> 5 | X6: =C6*B6 -> 5598 | Y6: =CEILING/(1+RESRATE)-P6 -> 23911.07 | Z6: =Y6-0.2*X6 -> 22791.47 | AA6: =(L6+0.2*X6)*(1+RESRATE) -> 29068.956 | AB6: Partial at entered U only; U_Boston,18 remains independently unknown; no qualified recommendation. Group inventory, occupancy, breakfast, fees, venue/local transfers pending as applicable.
A7: Chicago | B7: 24 | C7: =INDEX(CityData!$C:$C,MATCH(A7,CityData!$A:$A,0))*FFAC -> 270 | D7: =SUM(MIE_Daily!O2:O367) -> 707.84 | E7: =REGFEE -> 180 | F7: =INDEX(CityData!$D$11:$D$15,MATCH(A7,CityData!$A$11:$A$15,0))*(IF(AND(Parameters!$B$13<=DATE(2026,11,28),Parameters!$B$14>=DATE(2026,11,28)),1,0)+IF(AND(Parameters!$B$13<=DATE(2026,12,1),Parameters!$B$14>=DATE(2026,12,1)),1,0))+INDEX(CityData!$C$11:$C$15,MATCH(A7,CityData!$A$11:$A$15,0))*IF(AND(Parameters!$B$13<=DATE(2026,12,2),Parameters!$B$14>=DATE(2026,12,2)),1,0) -> 102 | G7: =REFRPP*REFRDAYS -> 45 | H7: =INDEX(CityData!$B$19:$B$23,MATCH(A7,CityData!$A$19:$A$23,0))+INDEX(CityData!$C$19:$C$23,MATCH(A7,CityData!$A$19:$A$23,0)) -> 120 | I7: =SUM(C7:H7)+O7 -> 1658.84 | J7: =I7*B7 -> 39812.16 | K7: =SUM(Unknowns!B3,Unknowns!G3)+B7*(NIGHTS*SUM(Unknowns!C3)+SUM(Unknowns!D3:F3)) -> 0 | L7: =J7+K7 -> 39812.16 | M7: =L7*RESRATE -> 1990.608 | N7: =L7+M7 -> 41802.768 | O7: =SUM(MIE_Daily!N2:N367) -> 234 | P7: =J7 -> 39812.16 | Q7: =K7 -> 0 | R7: =MIN(MIE_Daily!Q2:Q367) -> 0 | S7: =IF(AND(Parameters!$B$13=DATE(2026,11,28),Parameters!$B$14=DATE(2026,12,2)),1,0) -> 1 | T7: =IF(AND(R7=1,S7=1,Unknowns!H3=1,Unknowns!I3=1,N7<=CEILING,Parameters!$B$36="VALID DATE STRUCTURE"),1,0) -> 0 | U7: =IF(AND(R7=1,S7=1,N7<=CEILING,Parameters!$B$36="VALID DATE STRUCTURE"),1,0) -> 0 | V7: =IF(T7=0,99999,1+SUMPRODUCT($T$5:$T$14,--($B$5:$B$14>B7))+SUMPRODUCT($T$5:$T$14,--($B$5:$B$14=B7),--($N$5:$N$14<N7))+SUMPRODUCT($T$5:$T$14,--($B$5:$B$14=B7),--($N$5:$N$14=N7),--($A$5:$A$14<A7))) -> 99999 | W7: =IF(U7=0,99999,1+SUMPRODUCT($U$5:$U$14,--($B$5:$B$14>B7))+SUMPRODUCT($U$5:$U$14,--($B$5:$B$14=B7),--($N$5:$N$14<N7))+SUMPRODUCT($U$5:$U$14,--($B$5:$B$14=B7),--($N$5:$N$14=N7),--($A$5:$A$14<A7))) -> 99999 | X7: =C7*B7 -> 6480 | Y7: =CEILING/(1+RESRATE)-P7 -> 10664.03 | Z7: =Y7-0.2*X7 -> 9368.0305 | AA7: =(L7+0.2*X7)*(1+RESRATE) -> 43163.568 | AB7: Partial at entered U only; U_Chicago,24 remains independently unknown; no qualified recommendation. Group inventory, occupancy, breakfast, fees, venue/local transfers pending as applicable.
A8: Chicago | B8: 18 | C8: =INDEX(CityData!$C:$C,MATCH(A8,CityData!$A:$A,0))*FFAC -> 270 | D8: =SUM(MIE_Daily!O2:O367) -> 707.84 | E8: =REGFEE -> 180 | F8: =INDEX(CityData!$D$11:$D$15,MATCH(A8,CityData!$A$11:$A$15,0))*(IF(AND(Parameters!$B$13<=DATE(2026,11,28),Parameters!$B$14>=DATE(2026,11,28)),1,0)+IF(AND(Parameters!$B$13<=DATE(2026,12,1),Parameters!$B$14>=DATE(2026,12,1)),1,0))+INDEX(CityData!$C$11:$C$15,MATCH(A8,CityData!$A$11:$A$15,0))*IF(AND(Parameters!$B$13<=DATE(2026,12,2),Parameters!$B$14>=DATE(2026,12,2)),1,0) -> 102 | G8: =REFRPP*REFRDAYS -> 45 | H8: =INDEX(CityData!$B$19:$B$23,MATCH(A8,CityData!$A$19:$A$23,0))+INDEX(CityData!$C$19:$C$23,MATCH(A8,CityData!$A$19:$A$23,0)) -> 120 | I8: =SUM(C8:H8)+O8 -> 1658.84 | J8: =I8*B8 -> 29859.12 | K8: =SUM(Unknowns!B3,Unknowns!G3)+B8*(NIGHTS*SUM(Unknowns!C3)+SUM(Unknowns!D3:F3)) -> 0 | L8: =J8+K8 -> 29859.12 | M8: =L8*RESRATE -> 1492.956 | N8: =L8+M8 -> 31352.076 | O8: =SUM(MIE_Daily!N2:N367) -> 234 | P8: =J8 -> 29859.12 | Q8: =K8 -> 0 | R8: =MIN(MIE_Daily!Q2:Q367) -> 0 | S8: =IF(AND(Parameters!$B$13=DATE(2026,11,28),Parameters!$B$14=DATE(2026,12,2)),1,0) -> 1 | T8: =IF(AND(R8=1,S8=1,Unknowns!H3=1,Unknowns!I3=1,N8<=CEILING,Parameters!$B$36="VALID DATE STRUCTURE"),1,0) -> 0 | U8: =IF(AND(R8=1,S8=1,N8<=CEILING,Parameters!$B$36="VALID DATE STRUCTURE"),1,0) -> 0 | V8: =IF(T8=0,99999,1+SUMPRODUCT($T$5:$T$14,--($B$5:$B$14>B8))+SUMPRODUCT($T$5:$T$14,--($B$5:$B$14=B8),--($N$5:$N$14<N8))+SUMPRODUCT($T$5:$T$14,--($B$5:$B$14=B8),--($N$5:$N$14=N8),--($A$5:$A$14<A8))) -> 99999 | W8: =IF(U8=0,99999,1+SUMPRODUCT($U$5:$U$14,--($B$5:$B$14>B8))+SUMPRODUCT($U$5:$U$14,--($B$5:$B$14=B8),--($N$5:$N$14<N8))+SUMPRODUCT($U$5:$U$14,--($B$5:$B$14=B8),--($N$5:$N$14=N8),--($A$5:$A$14<A8))) -> 99999 | X8: =C8*B8 -> 4860 | Y8: =CEILING/(1+RESRATE)-P8 -> 20617.07 | Z8: =Y8-0.2*X8 -> 19645.07 | AA8: =(L8+0.2*X8)*(1+RESRATE) -> 32372.676 | AB8: Partial at entered U only; U_Chicago,18 remains independently unknown; no qualified recommendation. Group inventory, occupancy, breakfast, fees, venue/local transfers pending as applicable.
A9: Denver | B9: 24 | C9: =INDEX(CityData!$C:$C,MATCH(A9,CityData!$A:$A,0))*FFAC -> 578 | D9: =SUM(MIE_Daily!W2:W367) -> 488.32 | E9: =REGFEE -> 180 | F9: =INDEX(CityData!$D$11:$D$15,MATCH(A9,CityData!$A$11:$A$15,0))*(IF(AND(Parameters!$B$13<=DATE(2026,11,28),Parameters!$B$14>=DATE(2026,11,28)),1,0)+IF(AND(Parameters!$B$13<=DATE(2026,12,1),Parameters!$B$14>=DATE(2026,12,1)),1,0))+INDEX(CityData!$C$11:$C$15,MATCH(A9,CityData!$A$11:$A$15,0))*IF(AND(Parameters!$B$13<=DATE(2026,12,2),Parameters!$B$14>=DATE(2026,12,2)),1,0) -> 102 | G9: =REFRPP*REFRDAYS -> 45 | H9: =INDEX(CityData!$B$19:$B$23,MATCH(A9,CityData!$A$19:$A$23,0))+INDEX(CityData!$C$19:$C$23,MATCH(A9,CityData!$A$19:$A$23,0)) -> 220 | I9: =SUM(C9:H9)+O9 -> 1847.32 | J9: =I9*B9 -> 44335.68 | K9: =SUM(Unknowns!B4,Unknowns!G4)+B9*(NIGHTS*SUM(Unknowns!C4)+SUM(Unknowns!D4:F4)) -> 0 | L9: =J9+K9 -> 44335.68 | M9: =L9*RESRATE -> 2216.784 | N9: =L9+M9 -> 46552.464 | O9: =SUM(MIE_Daily!V2:V367) -> 234 | P9: =J9 -> 44335.68 | Q9: =K9 -> 0 | R9: =MIN(MIE_Daily!Y2:Y367) -> 1 | S9: =IF(AND(Parameters!$B$13=DATE(2026,11,28),Parameters!$B$14=DATE(2026,12,2)),1,0) -> 1 | T9: =IF(AND(R9=1,S9=1,Unknowns!H4=1,Unknowns!I4=1,N9<=CEILING,Parameters!$B$36="VALID DATE STRUCTURE"),1,0) -> 0 | U9: =IF(AND(R9=1,S9=1,N9<=CEILING,Parameters!$B$36="VALID DATE STRUCTURE"),1,0) -> 1 | V9: =IF(T9=0,99999,1+SUMPRODUCT($T$5:$T$14,--($B$5:$B$14>B9))+SUMPRODUCT($T$5:$T$14,--($B$5:$B$14=B9),--($N$5:$N$14<N9))+SUMPRODUCT($T$5:$T$14,--($B$5:$B$14=B9),--($N$5:$N$14=N9),--($A$5:$A$14<A9))) -> 99999 | W9: =IF(U9=0,99999,1+SUMPRODUCT($U$5:$U$14,--($B$5:$B$14>B9))+SUMPRODUCT($U$5:$U$14,--($B$5:$B$14=B9),--($N$5:$N$14<N9))+SUMPRODUCT($U$5:$U$14,--($B$5:$B$14=B9),--($N$5:$N$14=N9),--($A$5:$A$14<A9))) -> 3 | X9: =C9*B9 -> 13872 | Y9: =CEILING/(1+RESRATE)-P9 -> 6140.5105 | Z9: =Y9-0.2*X9 -> 3366.1105 | AA9: =(L9+0.2*X9)*(1+RESRATE) -> 49465.584 | AB9: Partial at entered U only; U_Denver,24 remains independently unknown; no qualified recommendation. Group inventory, occupancy, breakfast, fees, venue/local transfers pending as applicable.
A10: Denver | B10: 18 | C10: =INDEX(CityData!$C:$C,MATCH(A10,CityData!$A:$A,0))*FFAC -> 578 | D10: =SUM(MIE_Daily!W2:W367) -> 488.32 | E10: =REGFEE -> 180 | F10: =INDEX(CityData!$D$11:$D$15,MATCH(A10,CityData!$A$11:$A$15,0))*(IF(AND(Parameters!$B$13<=DATE(2026,11,28),Parameters!$B$14>=DATE(2026,11,28)),1,0)+IF(AND(Parameters!$B$13<=DATE(2026,12,1),Parameters!$B$14>=DATE(2026,12,1)),1,0))+INDEX(CityData!$C$11:$C$15,MATCH(A10,CityData!$A$11:$A$15,0))*IF(AND(Parameters!$B$13<=DATE(2026,12,2),Parameters!$B$14>=DATE(2026,12,2)),1,0) -> 102 | G10: =REFRPP*REFRDAYS -> 45 | H10: =INDEX(CityData!$B$19:$B$23,MATCH(A10,CityData!$A$19:$A$23,0))+INDEX(CityData!$C$19:$C$23,MATCH(A10,CityData!$A$19:$A$23,0)) -> 220 | I10: =SUM(C10:H10)+O10 -> 1847.32 | J10: =I10*B10 -> 33251.76 | K10: =SUM(Unknowns!B4,Unknowns!G4)+B10*(NIGHTS*SUM(Unknowns!C4)+SUM(Unknowns!D4:F4)) -> 0 | L10: =J10+K10 -> 33251.76 | M10: =L10*RESRATE -> 1662.588 | N10: =L10+M10 -> 34914.348 | O10: =SUM(MIE_Daily!V2:V367) -> 234 | P10: =J10 -> 33251.76 | Q10: =K10 -> 0 | R10: =MIN(MIE_Daily!Y2:Y367) -> 1 | S10: =IF(AND(Parameters!$B$13=DATE(2026,11,28),Parameters!$B$14=DATE(2026,12,2)),1,0) -> 1 | T10: =IF(AND(R10=1,S10=1,Unknowns!H4=1,Unknowns!I4=1,N10<=CEILING,Parameters!$B$36="VALID DATE STRUCTURE"),1,0) -> 0 | U10: =IF(AND(R10=1,S10=1,N10<=CEILING,Parameters!$B$36="VALID DATE STRUCTURE"),1,0) -> 1 | V10: =IF(T10=0,99999,1+SUMPRODUCT($T$5:$T$14,--($B$5:$B$14>B10))+SUMPRODUCT($T$5:$T$14,--($B$5:$B$14=B10),--($N$5:$N$14<N10))+SUMPRODUCT($T$5:$T$14,--($B$5:$B$14=B10),--($N$5:$N$14=N10),--($A$5:$A$14<A10))) -> 99999 | W10: =IF(U10=0,99999,1+SUMPRODUCT($U$5:$U$14,--($B$5:$B$14>B10))+SUMPRODUCT($U$5:$U$14,--($B$5:$B$14=B10),--($N$5:$N$14<N10))+SUMPRODUCT($U$5:$U$14,--($B$5:$B$14=B10),--($N$5:$N$14=N10),--($A$5:$A$14<A10))) -> 7 | X10: =C10*B10 -> 10404 | Y10: =CEILING/(1+RESRATE)-P10 -> 17224.43 | Z10: =Y10-0.2*X10 -> 15143.63 | AA10: =(L10+0.2*X10)*(1+RESRATE) -> 37099.188 | AB10: Partial at entered U only; U_Denver,18 remains independently unknown; no qualified recommendation. Group inventory, occupancy, breakfast, fees, venue/local transfers pending as applicable.
A11: Phoenix | B11: 24 | C11: =INDEX(CityData!$C:$C,MATCH(A11,CityData!$A:$A,0))*FFAC -> 499 | D11: =SUM(MIE_Daily!AE2:AE367) -> 672 | E11: =REGFEE -> 180 | F11: =INDEX(CityData!$D$11:$D$15,MATCH(A11,CityData!$A$11:$A$15,0))*(IF(AND(Parameters!$B$13<=DATE(2026,11,28),Parameters!$B$14>=DATE(2026,11,28)),1,0)+IF(AND(Parameters!$B$13<=DATE(2026,12,1),Parameters!$B$14>=DATE(2026,12,1)),1,0))+INDEX(CityData!$C$11:$C$15,MATCH(A11,CityData!$A$11:$A$15,0))*IF(AND(Parameters!$B$13<=DATE(2026,12,2),Parameters!$B$14>=DATE(2026,12,2)),1,0) -> 95 | G11: =REFRPP*REFRDAYS -> 45 | H11: =INDEX(CityData!$B$19:$B$23,MATCH(A11,CityData!$A$19:$A$23,0))+INDEX(CityData!$C$19:$C$23,MATCH(A11,CityData!$A$19:$A$23,0)) -> 210 | I11: =SUM(C11:H11)+O11 -> 1924 | J11: =I11*B11 -> 46176 | K11: =SUM(Unknowns!B5,Unknowns!G5)+B11*(NIGHTS*SUM(Unknowns!C5)+SUM(Unknowns!D5:F5)) -> 0 | L11: =J11+K11 -> 46176 | M11: =L11*RESRATE -> 2308.8 | N11: =L11+M11 -> 48484.8 | O11: =SUM(MIE_Daily!AD2:AD367) -> 223 | P11: =J11 -> 46176 | Q11: =K11 -> 0 | R11: =MIN(MIE_Daily!AG2:AG367) -> 1 | S11: =IF(AND(Parameters!$B$13=DATE(2026,11,28),Parameters!$B$14=DATE(2026,12,2)),1,0) -> 1 | T11: =IF(AND(R11=1,S11=1,Unknowns!H5=1,Unknowns!I5=1,N11<=CEILING,Parameters!$B$36="VALID DATE STRUCTURE"),1,0) -> 0 | U11: =IF(AND(R11=1,S11=1,N11<=CEILING,Parameters!$B$36="VALID DATE STRUCTURE"),1,0) -> 1 | V11: =IF(T11=0,99999,1+SUMPRODUCT($T$5:$T$14,--($B$5:$B$14>B11))+SUMPRODUCT($T$5:$T$14,--($B$5:$B$14=B11),--($N$5:$N$14<N11))+SUMPRODUCT($T$5:$T$14,--($B$5:$B$14=B11),--($N$5:$N$14=N11),--($A$5:$A$14<A11))) -> 99999 | W11: =IF(U11=0,99999,1+SUMPRODUCT($U$5:$U$14,--($B$5:$B$14>B11))+SUMPRODUCT($U$5:$U$14,--($B$5:$B$14=B11),--($N$5:$N$14<N11))+SUMPRODUCT($U$5:$U$14,--($B$5:$B$14=B11),--($N$5:$N$14=N11),--($A$5:$A$14<A11))) -> 4 | X11: =C11*B11 -> 11976 | Y11: =CEILING/(1+RESRATE)-P11 -> 4300.1905 | Z11: =Y11-0.2*X11 -> 1904.9905 | AA11: =(L11+0.2*X11)*(1+RESRATE) -> 50999.76 | AB11: Partial at entered U only; U_Phoenix,24 remains independently unknown; no qualified recommendation. Group inventory, occupancy, breakfast, fees, venue/local transfers pending as applicable.
A12: Phoenix | B12: 18 | C12: =INDEX(CityData!$C:$C,MATCH(A12,CityData!$A:$A,0))*FFAC -> 499 | D12: =SUM(MIE_Daily!AE2:AE367) -> 672 | E12: =REGFEE -> 180 | F12: =INDEX(CityData!$D$11:$D$15,MATCH(A12,CityData!$A$11:$A$15,0))*(IF(AND(Parameters!$B$13<=DATE(2026,11,28),Parameters!$B$14>=DATE(2026,11,28)),1,0)+IF(AND(Parameters!$B$13<=DATE(2026,12,1),Parameters!$B$14>=DATE(2026,12,1)),1,0))+INDEX(CityData!$C$11:$C$15,MATCH(A12,CityData!$A$11:$A$15,0))*IF(AND(Parameters!$B$13<=DATE(2026,12,2),Parameters!$B$14>=DATE(2026,12,2)),1,0) -> 95 | G12: =REFRPP*REFRDAYS -> 45 | H12: =INDEX(CityData!$B$19:$B$23,MATCH(A12,CityData!$A$19:$A$23,0))+INDEX(CityData!$C$19:$C$23,MATCH(A12,CityData!$A$19:$A$23,0)) -> 210 | I12: =SUM(C12:H12)+O12 -> 1924 | J12: =I12*B12 -> 34632 | K12: =SUM(Unknowns!B5,Unknowns!G5)+B12*(NIGHTS*SUM(Unknowns!C5)+SUM(Unknowns!D5:F5)) -> 0 | L12: =J12+K12 -> 34632 | M12: =L12*RESRATE -> 1731.6 | N12: =L12+M12 -> 36363.6 | O12: =SUM(MIE_Daily!AD2:AD367) -> 223 | P12: =J12 -> 34632 | Q12: =K12 -> 0 | R12: =MIN(MIE_Daily!AG2:AG367) -> 1 | S12: =IF(AND(Parameters!$B$13=DATE(2026,11,28),Parameters!$B$14=DATE(2026,12,2)),1,0) -> 1 | T12: =IF(AND(R12=1,S12=1,Unknowns!H5=1,Unknowns!I5=1,N12<=CEILING,Parameters!$B$36="VALID DATE STRUCTURE"),1,0) -> 0 | U12: =IF(AND(R12=1,S12=1,N12<=CEILING,Parameters!$B$36="VALID DATE STRUCTURE"),1,0) -> 1 | V12: =IF(T12=0,99999,1+SUMPRODUCT($T$5:$T$14,--($B$5:$B$14>B12))+SUMPRODUCT($T$5:$T$14,--($B$5:$B$14=B12),--($N$5:$N$14<N12))+SUMPRODUCT($T$5:$T$14,--($B$5:$B$14=B12),--($N$5:$N$14=N12),--($A$5:$A$14<A12))) -> 99999 | W12: =IF(U12=0,99999,1+SUMPRODUCT($U$5:$U$14,--($B$5:$B$14>B12))+SUMPRODUCT($U$5:$U$14,--($B$5:$B$14=B12),--($N$5:$N$14<N12))+SUMPRODUCT($U$5:$U$14,--($B$5:$B$14=B12),--($N$5:$N$14=N12),--($A$5:$A$14<A12))) -> 8 | X12: =C12*B12 -> 8982 | Y12: =CEILING/(1+RESRATE)-P12 -> 15844.19 | Z12: =Y12-0.2*X12 -> 14047.79 | AA12: =(L12+0.2*X12)*(1+RESRATE) -> 38249.82 | AB12: Partial at entered U only; U_Phoenix,18 remains independently unknown; no qualified recommendation. Group inventory, occupancy, breakfast, fees, venue/local transfers pending as applicable.
A13: Seattle | B13: 24 | C13: =INDEX(CityData!$C:$C,MATCH(A13,CityData!$A:$A,0))*FFAC -> 590 | D13: =SUM(MIE_Daily!AM2:AM367) -> 452.48 | E13: =REGFEE -> 180 | F13: =INDEX(CityData!$D$11:$D$15,MATCH(A13,CityData!$A$11:$A$15,0))*(IF(AND(Parameters!$B$13<=DATE(2026,11,28),Parameters!$B$14>=DATE(2026,11,28)),1,0)+IF(AND(Parameters!$B$13<=DATE(2026,12,1),Parameters!$B$14>=DATE(2026,12,1)),1,0))+INDEX(CityData!$C$11:$C$15,MATCH(A13,CityData!$A$11:$A$15,0))*IF(AND(Parameters!$B$13<=DATE(2026,12,2),Parameters!$B$14>=DATE(2026,12,2)),1,0) -> 102 | G13: =REFRPP*REFRDAYS -> 45 | H13: =INDEX(CityData!$B$19:$B$23,MATCH(A13,CityData!$A$19:$A$23,0))+INDEX(CityData!$C$19:$C$23,MATCH(A13,CityData!$A$19:$A$23,0)) -> 220 | I13: =SUM(C13:H13)+O13 -> 1823.48 | J13: =I13*B13 -> 43763.52 | K13: =SUM(Unknowns!B6,Unknowns!G6)+B13*(NIGHTS*SUM(Unknowns!C6)+SUM(Unknowns!D6:F6)) -> 0 | L13: =J13+K13 -> 43763.52 | M13: =L13*RESRATE -> 2188.176 | N13: =L13+M13 -> 45951.696 | O13: =SUM(MIE_Daily!AL2:AL367) -> 234 | P13: =J13 -> 43763.52 | Q13: =K13 -> 0 | R13: =MIN(MIE_Daily!AO2:AO367) -> 1 | S13: =IF(AND(Parameters!$B$13=DATE(2026,11,28),Parameters!$B$14=DATE(2026,12,2)),1,0) -> 1 | T13: =IF(AND(R13=1,S13=1,Unknowns!H6=1,Unknowns!I6=1,N13<=CEILING,Parameters!$B$36="VALID DATE STRUCTURE"),1,0) -> 0 | U13: =IF(AND(R13=1,S13=1,N13<=CEILING,Parameters!$B$36="VALID DATE STRUCTURE"),1,0) -> 1 | V13: =IF(T13=0,99999,1+SUMPRODUCT($T$5:$T$14,--($B$5:$B$14>B13))+SUMPRODUCT($T$5:$T$14,--($B$5:$B$14=B13),--($N$5:$N$14<N13))+SUMPRODUCT($T$5:$T$14,--($B$5:$B$14=B13),--($N$5:$N$14=N13),--($A$5:$A$14<A13))) -> 99999 | W13: =IF(U13=0,99999,1+SUMPRODUCT($U$5:$U$14,--($B$5:$B$14>B13))+SUMPRODUCT($U$5:$U$14,--($B$5:$B$14=B13),--($N$5:$N$14<N13))+SUMPRODUCT($U$5:$U$14,--($B$5:$B$14=B13),--($N$5:$N$14=N13),--($A$5:$A$14<A13))) -> 2 | X13: =C13*B13 -> 14160 | Y13: =CEILING/(1+RESRATE)-P13 -> 6712.6705 | Z13: =Y13-0.2*X13 -> 3880.6705 | AA13: =(L13+0.2*X13)*(1+RESRATE) -> 48925.296 | AB13: Partial at entered U only; U_Seattle,24 remains independently unknown; no qualified recommendation. Group inventory, occupancy, breakfast, fees, venue/local transfers pending as applicable.
A14: Seattle | B14: 18 | C14: =INDEX(CityData!$C:$C,MATCH(A14,CityData!$A:$A,0))*FFAC -> 590 | D14: =SUM(MIE_Daily!AM2:AM367) -> 452.48 | E14: =REGFEE -> 180 | F14: =INDEX(CityData!$D$11:$D$15,MATCH(A14,CityData!$A$11:$A$15,0))*(IF(AND(Parameters!$B$13<=DATE(2026,11,28),Parameters!$B$14>=DATE(2026,11,28)),1,0)+IF(AND(Parameters!$B$13<=DATE(2026,12,1),Parameters!$B$14>=DATE(2026,12,1)),1,0))+INDEX(CityData!$C$11:$C$15,MATCH(A14,CityData!$A$11:$A$15,0))*IF(AND(Parameters!$B$13<=DATE(2026,12,2),Parameters!$B$14>=DATE(2026,12,2)),1,0) -> 102 | G14: =REFRPP*REFRDAYS -> 45 | H14: =INDEX(CityData!$B$19:$B$23,MATCH(A14,CityData!$A$19:$A$23,0))+INDEX(CityData!$C$19:$C$23,MATCH(A14,CityData!$A$19:$A$23,0)) -> 220 | I14: =SUM(C14:H14)+O14 -> 1823.48 | J14: =I14*B14 -> 32822.64 | K14: =SUM(Unknowns!B6,Unknowns!G6)+B14*(NIGHTS*SUM(Unknowns!C6)+SUM(Unknowns!D6:F6)) -> 0 | L14: =J14+K14 -> 32822.64 | M14: =L14*RESRATE -> 1641.132 | N14: =L14+M14 -> 34463.772 | O14: =SUM(MIE_Daily!AL2:AL367) -> 234 | P14: =J14 -> 32822.64 | Q14: =K14 -> 0 | R14: =MIN(MIE_Daily!AO2:AO367) -> 1 | S14: =IF(AND(Parameters!$B$13=DATE(2026,11,28),Parameters!$B$14=DATE(2026,12,2)),1,0) -> 1 | T14: =IF(AND(R14=1,S14=1,Unknowns!H6=1,Unknowns!I6=1,N14<=CEILING,Parameters!$B$36="VALID DATE STRUCTURE"),1,0) -> 0 | U14: =IF(AND(R14=1,S14=1,N14<=CEILING,Parameters!$B$36="VALID DATE STRUCTURE"),1,0) -> 1 | V14: =IF(T14=0,99999,1+SUMPRODUCT($T$5:$T$14,--($B$5:$B$14>B14))+SUMPRODUCT($T$5:$T$14,--($B$5:$B$14=B14),--($N$5:$N$14<N14))+SUMPRODUCT($T$5:$T$14,--($B$5:$B$14=B14),--($N$5:$N$14=N14),--($A$5:$A$14<A14))) -> 99999 | W14: =IF(U14=0,99999,1+SUMPRODUCT($U$5:$U$14,--($B$5:$B$14>B14))+SUMPRODUCT($U$5:$U$14,--($B$5:$B$14=B14),--($N$5:$N$14<N14))+SUMPRODUCT($U$5:$U$14,--($B$5:$B$14=B14),--($N$5:$N$14=N14),--($A$5:$A$14<A14))) -> 6 | X14: =C14*B14 -> 10620 | Y14: =CEILING/(1+RESRATE)-P14 -> 17653.55 | Z14: =Y14-0.2*X14 -> 15529.55 | AA14: =(L14+0.2*X14)*(1+RESRATE) -> 36693.972 | AB14: Partial at entered U only; U_Seattle,18 remains independently unknown; no qualified recommendation. Group inventory, occupancy, breakfast, fees, venue/local transfers pending as applicable.
A17: STRESS: airfare × 1.20 (on top of airfare factor)
A18: City | B18: Headcount | C18: Per-person (stress) | D18: Base (stress) | E18: TOTAL (stress) | F18: Within ceiling?
A19: Boston | B19: 24 | C19: =I5+C5*0.2 -> 1538.04 | D19: =(I5+C5*0.2)*B5+K5 -> 36912.96 | E19: =AA5 -> 38758.608 | F19: =IF(E19<=CEILING,"YES","NO") -> YES
A20: Boston | B20: 18 | C20: =I6+C6*0.2 -> 1538.04 | D20: =(I6+C6*0.2)*B6+K6 -> 27684.72 | E20: =AA6 -> 29068.956 | F20: =IF(E20<=CEILING,"YES","NO") -> YES
A21: Chicago | B21: 24 | C21: =I7+C7*0.2 -> 1712.84 | D21: =(I7+C7*0.2)*B7+K7 -> 41108.16 | E21: =AA7 -> 43163.568 | F21: =IF(E21<=CEILING,"YES","NO") -> YES
A22: Chicago | B22: 18 | C22: =I8+C8*0.2 -> 1712.84 | D22: =(I8+C8*0.2)*B8+K8 -> 30831.12 | E22: =AA8 -> 32372.676 | F22: =IF(E22<=CEILING,"YES","NO") -> YES
A23: Denver | B23: 24 | C23: =I9+C9*0.2 -> 1962.92 | D23: =(I9+C9*0.2)*B9+K9 -> 47110.08 | E23: =AA9 -> 49465.584 | F23: =IF(E23<=CEILING,"YES","NO") -> YES
A24: Denver | B24: 18 | C24: =I10+C10*0.2 -> 1962.92 | D24: =(I10+C10*0.2)*B10+K10 -> 35332.56 | E24: =AA10 -> 37099.188 | F24: =IF(E24<=CEILING,"YES","NO") -> YES
A25: Phoenix | B25: 24 | C25: =I11+C11*0.2 -> 2023.8 | D25: =(I11+C11*0.2)*B11+K11 -> 48571.2 | E25: =AA11 -> 50999.76 | F25: =IF(E25<=CEILING,"YES","NO") -> YES
A26: Phoenix | B26: 18 | C26: =I12+C12*0.2 -> 2023.8 | D26: =(I12+C12*0.2)*B12+K12 -> 36428.4 | E26: =AA12 -> 38249.82 | F26: =IF(E26<=CEILING,"YES","NO") -> YES
A27: Seattle | B27: 24 | C27: =I13+C13*0.2 -> 1941.48 | D27: =(I13+C13*0.2)*B13+K13 -> 46595.52 | E27: =AA13 -> 48925.296 | F27: =IF(E27<=CEILING,"YES","NO") -> YES
A28: Seattle | B28: 18 | C28: =I14+C14*0.2 -> 1941.48 | D28: =(I14+C14*0.2)*B14+K14 -> 34946.64 | E28: =AA14 -> 36693.972 | F28: =IF(E28<=CEILING,"YES","NO") -> YES

Sheet Historical
A1: HISTORICAL PER-DIEM CROSS-CHECK — FY2025 / FY2026 / FY2027 (same month/day, same market rates)
A2: Historical reference only (not actual past quotes, not for this reimbursement). Shows how each FY's lodging cap and M&IE would affect lodging compliance and the per-diem comparison, holding headcount, dates and market quotes constant.
A4: City | B4: Market room/night (held) | C4: FY | D4: Lodging cap — Nov night | E4: Lodging cap — Dec 1 night | F4: M&IE | G4: 4-night cap sum | H4: Compliant each night? | I4: Room 4n vs cap sum | J4: Notes
A5: Boston | B5: 108 | C5: FY2025 | D5: 209 | E5: 209 | F5: 92 | G5: =3*D5+E5 -> 836 | H5: =IF(AND(B5<=D5,B5<=E5),"YES","NO: OVER CAP, NOT BOOKABLE WITHOUT AUTHORIZATION") -> YES | I5: =4*B5 -> 432
A6: Boston | B6: 108 | C6: FY2026 | D6: 209 | E6: 209 | F6: 92 | G6: =3*D6+E6 -> 836 | H6: =IF(AND(B6<=D6,B6<=E6),"YES","NO: OVER CAP, NOT BOOKABLE WITHOUT AUTHORIZATION") -> YES | I6: =4*B6 -> 432
A7: Boston | B7: 108 | C7: FY2027 | D7: 213 | E7: 213 | F7: 92 | G7: =3*D7+E7 -> 852 | H7: =IF(AND(B7<=D7,B7<=E7),"YES","NO: OVER CAP, NOT BOOKABLE WITHOUT AUTHORIZATION") -> YES | I7: =4*B7 -> 432
A8: Chicago | B8: =CityData!F4 -> 158 | C8: FY2025 | D8: 223 | E8: 142 | F8: 92 | G8: =3*D8+E8 -> 811 | H8: =IF(AND(B8<=D8,B8<=E8),"YES","NO: OVER CAP, NOT BOOKABLE WITHOUT AUTHORIZATION") -> NO: OVER CAP, NOT BOOKABLE WITHOUT AUTHORIZATION | I8: =4*B8 -> 632 | J8: Dec-1 cap < $145 → NON-compliant this FY (FY27 only compliant)
A9: Chicago | B9: =CityData!F4 -> 158 | C9: FY2026 | D9: 223 | E9: 142 | F9: 92 | G9: =3*D9+E9 -> 811 | H9: =IF(AND(B9<=D9,B9<=E9),"YES","NO: OVER CAP, NOT BOOKABLE WITHOUT AUTHORIZATION") -> NO: OVER CAP, NOT BOOKABLE WITHOUT AUTHORIZATION | I9: =4*B9 -> 632 | J9: Dec-1 cap < $145 → NON-compliant this FY (FY27 only compliant)
A10: Chicago | B10: =CityData!F4 -> 158 | C10: FY2027 | D10: 232 | E10: 148 | F10: 92 | G10: =3*D10+E10 -> 844 | H10: =IF(AND(B10<=D10,B10<=E10),"YES","NO: OVER CAP, NOT BOOKABLE WITHOUT AUTHORIZATION") -> NO: OVER CAP, NOT BOOKABLE WITHOUT AUTHORIZATION | I10: =4*B10 -> 632
A11: Denver | B11: 109 | C11: FY2025 | D11: 165 | E11: 165 | F11: 92 | G11: =3*D11+E11 -> 660 | H11: =IF(AND(B11<=D11,B11<=E11),"YES","NO: OVER CAP, NOT BOOKABLE WITHOUT AUTHORIZATION") -> YES | I11: =4*B11 -> 436
A12: Denver | B12: 109 | C12: FY2026 | D12: 165 | E12: 165 | F12: 92 | G12: =3*D12+E12 -> 660 | H12: =IF(AND(B12<=D12,B12<=E12),"YES","NO: OVER CAP, NOT BOOKABLE WITHOUT AUTHORIZATION") -> YES | I12: =4*B12 -> 436
A13: Denver | B13: 109 | C13: FY2027 | D13: 170 | E13: 170 | F13: 92 | G13: =3*D13+E13 -> 680 | H13: =IF(AND(B13<=D13,B13<=E13),"YES","NO: OVER CAP, NOT BOOKABLE WITHOUT AUTHORIZATION") -> YES | I13: =4*B13 -> 436
A14: Phoenix | B14: 150 | C14: FY2025 | D14: 160 | E14: 160 | F14: 86 | G14: =3*D14+E14 -> 640 | H14: =IF(AND(B14<=D14,B14<=E14),"YES","NO: OVER CAP, NOT BOOKABLE WITHOUT AUTHORIZATION") -> YES | I14: =4*B14 -> 600 | J14: Rate $150 ≤ cap but little headroom
A15: Phoenix | B15: 150 | C15: FY2026 | D15: 160 | E15: 160 | F15: 86 | G15: =3*D15+E15 -> 640 | H15: =IF(AND(B15<=D15,B15<=E15),"YES","NO: OVER CAP, NOT BOOKABLE WITHOUT AUTHORIZATION") -> YES | I15: =4*B15 -> 600 | J15: Rate $150 ≤ cap but little headroom
A16: Phoenix | B16: 150 | C16: FY2027 | D16: 165 | E16: 165 | F16: 86 | G16: =3*D16+E16 -> 660 | H16: =IF(AND(B16<=D16,B16<=E16),"YES","NO: OVER CAP, NOT BOOKABLE WITHOUT AUTHORIZATION") -> YES | I16: =4*B16 -> 600 | J16: Rate $150 ≤ cap but little headroom
A17: Seattle | B17: 101 | C17: FY2025 | D17: 188 | E17: 188 | F17: 92 | G17: =3*D17+E17 -> 752 | H17: =IF(AND(B17<=D17,B17<=E17),"YES","NO: OVER CAP, NOT BOOKABLE WITHOUT AUTHORIZATION") -> YES | I17: =4*B17 -> 404
A18: Seattle | B18: 101 | C18: FY2026 | D18: 188 | E18: 188 | F18: 92 | G18: =3*D18+E18 -> 752 | H18: =IF(AND(B18<=D18,B18<=E18),"YES","NO: OVER CAP, NOT BOOKABLE WITHOUT AUTHORIZATION") -> YES | I18: =4*B18 -> 404
A19: Seattle | B19: 101 | C19: FY2027 | D19: 188 | E19: 188 | F19: 92 | G19: =3*D19+E19 -> 752 | H19: =IF(AND(B19<=D19,B19<=E19),"YES","NO: OVER CAP, NOT BOOKABLE WITHOUT AUTHORIZATION") -> YES | I19: =4*B19 -> 404
A21: Impact summary:
A22: • Lodging caps rose modestly FY25→FY27 (Boston +4, Chicago +9/+6, Denver +5, Phoenix +5, Seattle flat). M&IE unchanged.
A23: Chicago158 exceeds Dec1 FY27 cap148 and historical cap142; it cannot be used as a compliant recommendation.
A24: Billabook101 is archived without breakfast binding. Agoda158 and Booking159 explicitly show breakfast but exceed cap.
A25: Historical_Impact quantifies both previous FYs × both headcounts × all5cities. Same observed market quotes, not actual historical offers.
A26: • FY2027 is the applicable year (travel Nov 29–Dec 1 2026 = FY27, eff. Oct 1 2026). FY25/26 shown for historical contrast only.

Sheet Thresholds
A1: THRESHOLDS, STRESS & SEGMENTED ACTIONS
A2: Decision metrics for airfare increases (0–20%) and unquoted-cost movements. Recomputes from Options/Daily.
A4: Metric | B4: Value | C4: Basis / condition
A5: Qualified recommendation | B5: =Decision!B2 -> NO QUALIFIED RECOMMENDATION | C5: No qualified recommendation until admission and exact quote conditions verified.
A6: Priority estimate (not approval) | B6: =Decision!B3&" / "&Decision!B4 -> Boston / 24 | C6: Conditional ranking at entered U; U values not confirmed zero.
A7: Priority partial total | B7: =Decision!B6 -> 37191.168 | C7: All5cities and both headcounts in Options.
A8: Priority candidate maximum additional base U | B8: =INDEX(Candidate_Model!U:U,MATCH(Decision!B11,Candidate_Model!A:A,0)) -> 15056.03 | C8: Budget/(1+reserve)-known/estimated K, not reserve-inclusive budget remainder.
A9: Priority Umax +20% | B9: =INDEX(Candidate_Model!V:V,MATCH(Decision!B11,Candidate_Model!A:A,0)) -> 13563.23 | C9: Pressure on currently adjusted airfare.
A10: Next candidate maximum additional base U | B10: =INDEX(Candidate_Model!U2:U45,MATCH(2,Candidate_Model!T2:T45,0)) -> 13928.03 | C10: Most competitive conditional backup among primary anchors.
A11: Next candidate Umax +20% | B11: =INDEX(Candidate_Model!V2:V45,MATCH(2,Candidate_Model!T2:T45,0)) -> 12209.63 | C11: Same basis.
A12: Chicago-Boston equal-U intersection p | B12: =IF(Options!X7=Options!X5,IF(Options!P5=Options!P7,"ALL p TIE: alphabetical Boston","PARALLEL: no finite crossing"),(Options!P5-Options!P7)/(Options!X7-Options!X5)) -> 4.4634146 | C12: Diagnostic arithmetic for the EXCLUDED Chicago158 quote only; not an eligible switch. Current selection and bounds: Candidate_Model / Boundary_All. No authorized above-cap exception.
A13: General optimum region | B13: See Boundary_Checks all10 candidates | C13: Cost_i=(1+reserve)*(K_i+p*A_i+U_i). Region for selected same-size i: U_i-U_j <= K_j-K_i+p*(A_j-A_i) for EVERY eligible j; strict inequality if j alphabetically earlier.
A14: Keep Chicago24 | B14: Uchi<=Umaxchi(p), all same-size inequalities hold | C14: All dates, price compliance and quality/quote admission must also hold. Any unresolved cheaper combination remains a competitor, not removed.
A15: Keep current evidence priority | B15: Apply ALL eligible competitor inequalities in Boundary_All; never include archived101 or over-cap158/159. | C15: Boston remains breakfast/quality/occupancy pending; this is partial-cost evidence priority, not a qualified recommendation.
A16: Drop to18 | B16: ALL admitted24 totals>budget or unavailable; at least one admitted18 total<=budget | C16: Recalculate per-person and fixed/unknown components separately; no proportional scaling of event total.
A17: Neither size executable | B17: No admitted budget-feasible18 or24, or admission evidence absent | C17: Currently admission evidence absent: no qualified recommendation. Evidence priority may still be given without claiming approval.
A18: Negative Umax test @budget30000 | B18: =30000/(1+RESRATE)-Options!P7 -> -11240.731 | C18: Negative means known/estimated K already exceeds budget; never truncate to zero.
A19: Negative Umax stress @30000 | B19: =30000/(1+RESRATE)-Options!P7-0.2*Options!X7 -> -12536.731 | C19: Recompute after any parameter change.
A20: Historical effect | B20: See Historical_Impact 20 units | C20: Same quotes and MIE tiers -> numerical zero delta; caps and candidate eligibility evaluated separately.
A21: Quote applicability | B21: =Parameters!B34 -> DATED SNAPSHOT; inventory unheld | C21: Old-price recalculation on changed dates is not a new quote.
A23: Unknown-difference switch p* (Chicago24 vs Boston24) | B23: =IF(Options!X5=Options!X7,IF(Options!Q7-Options!Q5=Options!P5-Options!P7,"ALL p TIE: alphabetical Boston","PARALLEL: no finite crossing"),((Options!Q7-Options!Q5)-(Options!P5-Options!P7))/(Options!X5-Options!X7)) -> 4.4634146 | C23: Diagnostic arithmetic for the EXCLUDED Chicago158 quote only; not an eligible switch. Current selection and bounds: Candidate_Model / Boundary_All. No authorized above-cap exception.
A24: 18-person switching condition | B24: =Options!P6-Options!P8 -> -3294 | C24: Diagnostic arithmetic for the EXCLUDED Chicago158 quote only; not an eligible switch. Current selection and bounds: Candidate_Model / Boundary_All. No authorized above-cap exception.
A25: Direction of crossing | B25: Chicago airfare slope6480 < Boston7464 | C25: Diagnostic arithmetic for the EXCLUDED Chicago158 quote only; not an eligible switch. Current selection and bounds: Candidate_Model / Boundary_All. No authorized above-cap exception.
A26: Additional captured joint alternatives | B26: Joint_Alternatives: 15 component alternatives ×2headcounts | C26: All44 combinations enter Candidate_Model/Decision; archived101 and above-cap158/159 excluded. Boundary_All contains current priority comparisons.
A27: Conditional no-crossing proof with all recorded alternatives | B27: For EVERY same-headcount primary/alternative j require Uchi-Uj <= (Kj-Kchi)+p*(Aj-Achi) | C27: Use Boundary_All recomputed from current44 combinations. Boundaries are conditional on independent unknowns; excluded quotes do not enter the feasible minimum.

Sheet Itinerary
A1: RETAINED ITINERARY STRUCTURE — Boston priority for evidence completion; no qualified recommendation
A2: Boston P01: DCA-BOS Nov28, trainingNov29-Dec1, returnDec2, four nights. Primary dated flight311, backupA19 flight358. Exact booking, breakfast, occupancy and quality remain pending. Chicago158/159 above-cap excluded.
A4: Item | B4: Detail | C4: Date | D4: Connects to
A5: Outbound flight | B5: DCA → BOS, dated Google Flights Delta311, Nov28 06:00–07:38; verify before ticketing | C5: 2026-11-28 | D5: Arrive BOS afternoon → hotel check-in same day
A6: Hotel check-in | B6: DoubleTree by Hilton Boston Bayside — displayed108; breakfast condition unresolved | C6: 2026-11-28 | D6: Airport-hotel ground allowance included; check actual shuttle and venue address
A7: Training Day 1 | B7: Full day (lunch via registration) | C7: 2026-11-29 | D7: On-site; breakfast at hotel
A8: Training Day 2 | B8: Full day (lunch via registration) | C8: 2026-11-30 | D8: On-site
A9: Training Day 3 | B9: Full day (lunch via registration) | C9: 2026-12-01 | D9: Agency dinner Dec 1 evening
A10: Return flight | B10: BOS → DCA, Dec2 Delta14:29–16:20 (P01). A19 uses alternative AA358; exact meal/transfer timings remain to verify. | C10: 2026-12-02 | D10: Checkout Dec 2 → BOS airport → DCA
A11: Agency catered | B11: Dinner Nov 28, Dinner Dec 1, Lunch Dec 2 | C11: various | D11: Budgeted in Daily/Options
A13: Execution conditions (venue/date/capacity not yet verified):
A14: • Meeting venue address & 24-seat capacity for Nov 29–Dec 1 NOT yet confirmed — list as execution condition (see Register).
A15: • Hotel room block of 24 single rooms at quoted rate NOT confirmed; single-occupancy quote used as whole-group estimate only.
A16: • Flight fares are per-person public quotes (single seat); group inventory at same fare not guaranteed.
A17: Fare class, baggage, refund terms, group seats and room inventory are unheld and must be rechecked.

Sheet Sources
A1: SOURCES, QUERY TIMES & APPLICABILITY
A3: # | B3: Item | C3: Source / platform | D3: URL | E3: Queried (UTC) | F3: Applicable dates / notes
A4: 1 | B4: Flights DCA↔ORD (Chicago) $270 AA nonstop | C4: ITA Matrix (Google) | D4: https://matrix.itasoftware.com | E4: 2026-10-24 | F4: RT Nov 28–Dec 2 2026, 1 adult; public fare, basic econ possible
A5: 2 | B5: Flights DCA↔BOS (Boston) $358 AA nonstop | C5: ITA Matrix (Google) | D5: https://matrix.itasoftware.com | E5: 2026-10-24 | F5: RT Nov 28–Dec 2 2026, 1 adult
A6: 3 | B6: Flights DCA↔PHX (Phoenix) $581 AA nonstop | C6: ITA Matrix (Google) | D6: https://matrix.itasoftware.com | E6: 2026-10-24 | F6: RT Nov 28–Dec 2 2026, 1 adult
A7: 4 | B7: Flights DCA↔DEN (Denver) $741 Frontier / $940 United | C7: ITA Matrix (Google) | D7: https://matrix.itasoftware.com | E7: 2026-10-24 | F7: RT; Frontier basic; United more flexible
A8: 5 | B8: Flights DCA↔SEA (Seattle) $977 nonstop / $982 1-stop | C8: ITA Matrix (Google) | D8: https://matrix.itasoftware.com | E8: 2026-10-24 | F8: RT Nov 28–Dec 2 2026, 1 adult
A9: 6 | B9: Boston hotel — DoubleTree Hilton Boston Bayside $108/n, 8.6/10 (449 rev), breakfast | C9: Trip.com (US) | D9: https://us.trip.com/hotels/list?cityId=26848 | E9: 2026-10-24 | F9: 4 nights, 1 room/1 adult; total $501 incl taxes&fees
A10: 7 | B10: Boston alt — Hilton Boston Park Plaza $205/n, 8.8 (170), breakfast | C10: Trip.com (US) | D10: https://us.trip.com/hotels/list?cityId=26848 | E10: 2026-10-24 | F10: Central; ≤$213 FY27 cap
A11: 8 | B11: Chicago hotel — Warwick Allerton $145/n, 8.6 (399) | C11: Trip.com (US) | D11: https://us.trip.com/hotels/list?cityId=549 | E11: 2026-10-24 | F11: ≤ $148 Dec-1 FY27 cap; total $668 incl tax
A12: 9 | B12: Denver hotel — Home2 Suites Hilton Downtown $109/n, 9.0 (94), breakfast | C12: Trip.com (US) | D12: https://us.trip.com/hotels/list?cityId=20099 | E12: 2026-10-24 | F12: ≤$170 cap
A13: 10 | B13: Phoenix hotel — Hampton Inn & Suites $150/n, 9.4 (116), breakfast | C13: Trip.com (US) | D13: https://us.trip.com/hotels/list?cityId=25938 | E13: 2026-10-24 | F13: ≤$165 cap (thin margin)
A14: 11 | B14: DISCARDED: Seattle103 hotel identity not supported by original screenshot | C14: Trip.com (US) | D14: https://us.trip.com/hotels/list?cityId=511 | E14: 2026-10-24 | F14: Not used; replaced by Country Inn101 dated Google Hotels evidence. Breakfast/occupancy conditions still pending.
A15: 12 | B15: FY2027 per-diem (lodging & M&IE) | C15: GSA / input file | D15: FY2027_PerDiemRates_Validated090126.xlsx | E15: file (read) | F15: Eff. Oct 1 2026 — APPLICABLE year
... A21: 18 | B21: FX note | C21: N/A — all prices captured in USD | D21: ITA Matrix & us.trip.com default USD | E21: 2026-10-24 | F21: No currency conversion applied
A23: Price scope: original market quotes kept as snapshots. Internal12% lodging tax replaces tax planning basis; other mandatory fees not disclosed remain unresolved. No full verified recommendation.
A27: SRC-EXPERT | B27: Corrected flight/room anchors | C27: Original dated model captures, not new quotes | D27: See PPT flight and hotel pages | E27: 2026-10-24 | F27: Qwen real flight captures supplement Claude. Old Seattle103 identity abandoned. Single-room2guests quotes not verified single occupancy.
A28: RD-2036A | B28: Applicable agency instruction | C28: USDA RD official | D28: https://www.rd.usda.gov/media/file/download/2036a.pdf | E28: 2026-10-24 | F28: Effective07/19/24 sec2036.74(a,b): sites/mission/necessity/remote/procurement. Agency cost>20k OCFO advance approval. Old templateOCFO7k/OIG20k/HR933 not automatically current.
A29: MIE-CURRENT | B29: Current CONUS breakdown applicability | C29: GSA official | D29: https://www.gsa.gov/travel/plan-a-trip/per-diem-rates/mie-breakdowns | E29: 2026-10-24 | F29: 92=23/26/38/5;86=22/23/36/5, matches supplied categories; hotel complimentary meals do not reduce MIE.
A30: AIRPORT | B30: Connection routes and published fare range | C30: WMATA official | D30: https://www.wmata.com/rider-guide/airport-and-rail/ | E30: 2026-10-24 | F30: Metro2.25–6.75 one-way published; our early-flight ROAD allowances80/160/200RT are internal assumptions, not this page taxi tariffs.
A31: SCOPE | B31: Unquoted costs and qualifications | C31: Unknowns sheet | D31: Internal estimation, not supplier quote | E31: 2026-10-24 | F31: Independent Ucity,n; default blanks not zero facts. Catering and refresh already estimated, delta inputs adjust them; no registration-lunch double charge.
A32: GROUND-ROAD | B32: Official road taxi information vs internal allowance | C32: MWAA / WMATC / BWI | D32: https://www.flyreagan.com/parking-transportation/taxi-service ; https://www.wmatc.gov/order/new/taxicabfares/WashingtonFlyerTaxi.pdf ; https://bwiairport.com/to-from-bwi/transportation/taxis/ | E32: 2026-10-24 | F32: Published metered/airport fare basis checked.80/160/200RT are disclosed internal planning allowances; traffic, waiting, fuel and personal route details remain unknown.
A33: QUOTE-CORRECTION | B33: Chicago/Seattle offer conditions | C33: Original unmodified Google Hotels screenshots | D33: PPT original image11 and image21 | E33: 2026-10-24 | F33: CHI Billabook101 unbound breakfast archived; Agoda158/Booking159 breakfast shown over cap. SEA Booking101 breakfast shown but2guests; single occupancy unresolved.

Sheet Rates
A1: Key | B1: FY | C1: City | D1: Month | E1: Lodging cap | F1: MIE | G1: Original file | H1: Sheet | I1: Row/location
A2: 2025|Phoenix|1 | B2: 2025 | C2: Phoenix | D2: 1 | E2: 160 | F2: 86 | G2: FY2025_PerDiemMasterRatesFile.xlsx | H2: Master | I2: 18 / Phoenix / Scottsdale
A3: 2025|Phoenix|2 | B3: 2025 | C3: Phoenix | D3: 2 | E3: 229 | F3: 86 | G3: FY2025_PerDiemMasterRatesFile.xlsx | H3: Master | I3: 19 / Phoenix / Scottsdale
A4: 2025|Phoenix|3 | B4: 2025 | C4: Phoenix | D4: 3 | E4: 229 | F4: 86 | G4: FY2025_PerDiemMasterRatesFile.xlsx | H4: Master | I4: 19 / Phoenix / Scottsdale
A5: 2025|Phoenix|4 | B5: 2025 | C5: Phoenix | D5: 4 | E5: 161 | F5: 86 | G5: FY2025_PerDiemMasterRatesFile.xlsx | H5: Master | I5: 20 / Phoenix / Scottsdale
A6: 2025|Phoenix|5 | B6: 2025 | C6: Phoenix | D6: 5 | E6: 161 | F6: 86 | G6: FY2025_PerDiemMasterRatesFile.xlsx | H6: Master | I6: 20 / Phoenix / Scottsdale
A7: 2025|Phoenix|6 | B7: 2025 | C7: Phoenix | D7: 6 | E7: 113 | F7: 86 | G7: FY2025_PerDiemMasterRatesFile.xlsx | H7: Master | I7: 21 / Phoenix / Scottsdale
A8: 2025|Phoenix|7 | B8: 2025 | C8: Phoenix | D8: 7 | E8: 113 | F8: 86 | G8: FY2025_PerDiemMasterRatesFile.xlsx | H8: Master | I8: 21 / Phoenix / Scottsdale
A9: 2025|Phoenix|8 | B9: 2025 | C9: Phoenix | D9: 8 | E9: 113 | F9: 86 | G9: FY2025_PerDiemMasterRatesFile.xlsx | H9: Master | I9: 21 / Phoenix / Scottsdale
A10: 2025|Phoenix|9 | B10: 2025 | C10: Phoenix | D10: 9 | E10: 160 | F10: 86 | G10: FY2025_PerDiemMasterRatesFile.xlsx | H10: Master | I10: 22 / Phoenix / Scottsdale
A11: 2025|Phoenix|10 | B11: 2025 | C11: Phoenix | D11: 10 | E11: 160 | F11: 86 | G11: FY2025_PerDiemMasterRatesFile.xlsx | H11: Master | I11: 18 / Phoenix / Scottsdale
A12: 2025|Phoenix|11 | B12: 2025 | C12: Phoenix | D12: 11 | E12: 160 | F12: 86 | G12: FY2025_PerDiemMasterRatesFile.xlsx | H12: Master | I12: 18 / Phoenix / Scottsdale
A13: 2025|Phoenix|12 | B13: 2025 | C13: Phoenix | D13: 12 | E13: 160 | F13: 86 | G13: FY2025_PerDiemMasterRatesFile.xlsx | H13: Master | I13: 18 / Phoenix / Scottsdale
... A181: 2027|Seattle|12 | B181: 2027 | C181: Seattle | D181: 12 | E181: 188 | F181: 92 | G181: FY2027_PerDiemRates_Validated090126.xlsx | H181: Sheet1 | I181: 627 / Seattle

Sheet MIE_Components
A1: MIE total | B1: Breakfast | C1: Lunch | D1: Dinner | E1: Incidental | F1: Basis
A2: 68 | B2: 16 | C2: 19 | D2: 28 | E2: 5 | F2: Supplied FY2025 breakdown, checked against GSA current CONUS breakdown; not OCONUS
A3: 74 | B3: 18 | C3: 20 | D3: 31 | E3: 5 | F3: Supplied FY2025 breakdown, checked against GSA current CONUS breakdown; not OCONUS
A4: 80 | B4: 20 | C4: 22 | D4: 33 | E4: 5 | F4: Supplied FY2025 breakdown, checked against GSA current CONUS breakdown; not OCONUS
A5: 86 | B5: 22 | C5: 23 | D5: 36 | E5: 5 | F5: Supplied FY2025 breakdown, checked against GSA current CONUS breakdown; not OCONUS
A6: 92 | B6: 23 | C6: 26 | D6: 38 | E6: 5 | F6: Supplied FY2025 breakdown, checked against GSA current CONUS breakdown; not OCONUS

Sheet Unknowns
A1: City | B1: Venue fixed/event USD | C1: Breakfast extra USD/person/night | D1: Venue ground USD/person/trip | E1: Catering adjustment USD/person | F1: Refreshment adjustment USD/person | G1: Other fixed USD | H1: Quality admission (0/1) | I1: Quote/conditions complete (0/1) | J1: Status / billing basis
A2: Boston | H2: 0 | I2: 0 | J2: Blank=unquoted. Independent city inputs; catering/refresh entries adjust existing planning allowances, not duplicate purchases. 1 flags only after evidence, not current facts.
A3: Chicago | H3: 0 | I3: 0 | J3: Blank=unquoted. Independent city inputs; catering/refresh entries adjust existing planning allowances, not duplicate purchases. 1 flags only after evidence, not current facts.
A4: Denver | H4: 0 | I4: 0 | J4: Blank=unquoted. Independent city inputs; catering/refresh entries adjust existing planning allowances, not duplicate purchases. 1 flags only after evidence, not current facts.
A5: Phoenix | H5: 0 | I5: 0 | J5: Blank=unquoted. Independent city inputs; catering/refresh entries adjust existing planning allowances, not duplicate purchases. 1 flags only after evidence, not current facts.
A6: Seattle | H6: 0 | I6: 0 | J6: Blank=unquoted. Independent city inputs; catering/refresh entries adjust existing planning allowances, not duplicate purchases. 1 flags only after evidence, not current facts.

Sheet MIE_Daily
A1: Date | B1: Boston MIE rate | C1: Boston Breakfast | D1: Boston Lunch | E1: Boston Dinner | F1: Boston Net MIE | G1: Boston Room+12% tax | H1: Boston Room cap | I1: Boston Night compliant | J1: Chicago MIE rate | K1: Chicago Breakfast | L1: Chicago Lunch | M1: Chicago Dinner | N1: Chicago Net MIE | O1: Chicago Room+12% tax | P1: Chicago Room cap | Q1: Chicago Night compliant | R1: Denver MIE rate | S1: Denver Breakfast | T1: Denver Lunch | U1: Denver Dinner | V1: Denver Net MIE | W1: Denver Room+12% tax | X1: Denver Room cap | Y1: Denver Night compliant | Z1: Phoenix MIE rate | AA1: Phoenix Breakfast | AB1: Phoenix Lunch | AC1: Phoenix Dinner | AD1: Phoenix Net MIE | AE1: Phoenix Room+12% tax | AF1: Phoenix Room cap | AG1: Phoenix Night compliant | AH1: Seattle MIE rate | AI1: Seattle Breakfast | AJ1: Seattle Lunch | AK1: Seattle Dinner | AL1: Seattle Net MIE | AM1: Seattle Room+12% tax | AN1: Seattle Room cap | AO1: Seattle Night compliant
