Workbook

Sheet ControlPanel
A1: Credit Review Control Panel
A2: Blue cells are editable model inputs. Static Word/CSV snapshots reflect only default inputs and unchanged source amounts.
A4: Input | B4: Value | C4: Rule / status
A5: Start period | B5: 20240630 | C5: Existing YYYYMMDD quarter; must precede end
A6: End period | B6: 20250630 | C6: Existing YYYYMMDD quarter; must follow start
A7: Review slots | B7: 8 | C7: Integer 3–12
A9: Model valid | B9: =AND(COUNTIF(RawFinancials!$W$5:$W$750,$B$5)>0,COUNTIF(RawFinancials!$W$5:$W$750,$B$6)>0,$B$5<$B$6,ISNUMBER($B$7),$B$7=INT($B$7),$B$7>=3,$B$7<=12,COUNTIFS(BankQuarter!$D$5:$D$750,$B$6,BankQuarter!$R$5:$R$750,TRUE())>=$B$7,COUNTIFS(BankQuarter!$D$5:$D$750,$B$6,BankQuarter!$E$5:$E$750,"VT",BankQuarter!$R$5:$R$750,TRUE())>0,COUNTIFS(BankQuarter!$D$5:$D$750,$B$6,BankQuarter!$E$5:$E$750,"NH",BankQuarter!$R$5:$R$750,TRUE())>0,COUNTIFS(BankQuarter!$D$5:$D$750,$B$6,BankQuarter!$E$5:$E$750,"ME",BankQuarter!$R$5:$R$750,TRUE())>0) -> TRUE | C9: FALSE clears all priority outputs
A10: Raw amounts unchanged | B10: =COUNTIF(BankQuarter!$T$5:$T$750,TRUE())=0 -> TRUE | C10: Exact comparison for ASSET, P9ASSET, NAASSET; blank differs from 0
A11: Static snapshot current | B11: =AND($B$5=20240630,$B$6=20250630,$B$7=8,$B$10) -> TRUE | C11: TRUE only for default inputs and unchanged raw amounts
A13: Interpretation
A14: If MODEL VALID is FALSE, correct the period/order/slot inputs or ensure the end period has enough valid banks and at least one valid bank in each state. Priority names and count are automatically cleared. Parameter or raw-amount changes do not update the static memo or follow-up CSV; re-export them. Amount corrections are an internal verified-copy scenario and do not assert the public source was wrong.

Sheet RawFinancials
A1: Raw Financials — Editable Local Copy
A2: 746 source records in original order. Only ASSET, P9ASSET and NAASSET are unlocked; blanks remain distinct from numeric zero.
A4: source_row | B4: ASSET | C4: CERT | D4: DEP | E4: ELNATRY | F4: EQ | G4: EQV | H4: ID | I4: LNATRESR | J4: LNCI | K4: LNCON | L4: LNLSGR | M4: LNLSNET | N4: LNRE | O4: NAASSET | P4: NAMEFULL | Q4: NCLNLSR | R4: NIMY | S4: NTLNLS | T4: P3ASSET | U4: P9ASSET | V4: RBCRWAJ | W4: REPDTE | X4: ROA | Y4: ROE | Z4: STALP
A5: 2 | B5: 3688993 | C5: 11971 | D5: 3055632 | E5: 0.08 | F5: 461681 | G5: 12.515095582995142 | H5: 11971_20220331 | I5: 0.8726555144377637 | J5: 201303 | K5: 7873 | L5: 2657406 | M5: 2634216 | N5: 2317079 | O5: 9213 | P5: BAR HARBOR BANK & TRUST | Q5: 0.3784141376966862 | R5: 3.006742138500755 | S5: -95 | T5: 4642 | U5: 843 | V5: 13.678961 | W5: 20220331 | X5: 1.1162343 | Y5: 8.77 | Z5: ME
A6: 3 | B6: 964163 | C6: 12874 | D6: 854194 | E6: 0 | F6: 97916 | G6: 10.155544238889068 | H6: 12874_20220331 | I6: 1.0653480801084996 | J6: 138143 | K6: 5249 | L6: 732906 | M6: 725098 | N6: 577596 | O6: 1069 | P6: KATAHDIN TRUST COMPANY | Q6: 0.14585772254559248 | R6: 3.4019504411499137 | S6: -5 | T6: 374 | U6: 0 | V6: 15.601603 | W6: 20220331 | X6: 0.83149732 | Y6: 7.95 | Z6: ME
A7: 4 | B7: 1784835 | C7: 13063 | D7: 1619076 | E7: 0 | F7: 148181 | G7: 8.302224015105038 | H7: 13063_20220331 | I7: 1.2180099706634604 | J7: 55361 | K7: 837 | L7: 1223389 | M7: 1208488 | N7: 1160807 | O7: 408 | P7: KENNEBUNK SAVINGS BANK | Q7: 0.13111120011705188 | R7: 3.2711147741028457 | S7: -5 | T7: 3 | U7: 1196 | V7: 0 | W7: 20220331 | X7: 0.48237313 | Y7: 5.56 | Z7: ME
A8: 5 | B8: 869402 | C8: 14134 | D8: 737795 | E8: 0.1 | F8: 101808 | G8: 11.710117989146562 | H8: 14134_20220331 | I8: 1.4014366486247207 | J8: 27870 | K8: 26813 | L8: 596388 | M8: 588030 | N8: 516229 | O8: 8014 | P8: PASSUMPSIC SAVINGS BANK | Q8: 1.3437560782577784 | R8: 2.742437977347796 | S8: 19 | T8: 4990 | U8: 0 | V8: 17.570983 | W8: 20220331 | X8: -0.38729339 | Y8: -3.23 | Z8: VT
A9: 6 | B9: 222692 | C9: 14136 | D9: 199279 | E9: 0.08 | F9: 18834 | G9: 8.457421011980673 | H9: 14136_20220331 | I9: 1.1501745063903168 | J9: 12518 | K9: 11422 | L9: 121199 | M9: 119805 | N9: 96809 | O9: 174 | P9: WELLS RIVER SAVINGS BANK | Q9: 0.6707976138416983 | R9: 3.4223699758291275 | S9: 7 | T9: 803 | U9: 639 | V9: 17.27622 | W9: 20220331 | X9: 0.19954922 | Y9: 2.14 | Z9: VT
A10: 7 | B10: 1414510 | C10: 14140 | D10: 1199427 | E10: 0 | F10: 123854 | G10: 8.75596496313211 | H10: 14140_20220331 | I10: 1.1077738349896176 | J10: 82518 | K10: 1318 | L10: 957867 | M10: 947256 | N10: 866005 | O10: 5589 | P10: NORTHFIELD SAVINGS BANK | Q10: 0.58348392835331 | R10: 2.9698131336094122 | S10: 9 | T10: 785 | U10: 0 | V10: 0 | W10: 20220331 | X10: 0.66212632 | Y10: 7.07 | Z10: VT
A11: 8 | B11: 1232701 | C11: 14158 | D11: 1137254 | E11: 0 | F11: 85105 | G11: 6.9039450767055435 | H11: 14158_20220331 | I11: 1.0031734264943204 | J11: 44549 | K11: 2157 | L11: 830963 | M11: 822627 | N11: 698008 | O11: 4405 | P11: UNION BANK | Q11: 0.5576662258127016 | R11: 3.185373520467468 | S11: 0 | T11: 1620 | U11: 229 | V11: 14.788126 | W11: 20220331 | X11: 0.88329132 | Y11: 11.64 | Z11: VT
A12: 9 | B12: 384095 | C12: 14168 | D12: 345364 | E12: 0 | F12: 34244 | G12: 8.915502675119438 | H12: 14168_20220331 | I12: 1.5327875284455024 | J12: 9537 | K12: 8111 | L12: 191155 | M12: 188225 | N12: 161619 | O12: 1188 | P12: PEOPLES TRUST COMPANY OF ST. ALBANS | Q12: 0.6214851821819989 | R12: 2.4184590804383865 | S12: 34 | T12: 187 | U12: 0 | V12: 19.824643 | W12: 20220331 | X12: 0.13578832 | Y12: 1.45 | Z12: VT
A13: 10 | B13: 1221074 | C13: 14240 | D13: 1020645 | E13: 0 | F13: 102113 | G13: 8.36255624147267 | H13: 14240_20220331 | I13: 1.1483381231280392 | J13: 29648 | K13: 17990 | L13: 824670 | M13: 815200 | N13: 705835 | O13: 2204 | P13: NORTHWAY BANK | Q13: 0.26725841851892274 | R13: 2.8194207261510216 | S13: -4 | T13: 1936 | U13: 0 | V13: 15.106992 | W13: 20220331 | X13: 0.069811881 | Y13: 0.79 | Z13: NH
A14: 11 | B14: 836644 | C14: 17115 | D14: 738943 | E14: -0.08 | F14: 83239 | G14: 9.949154000984887 | H14: 17115_20220331 | I14: 1.1671320266694696 | J14: 43003 | K14: 3606 | L14: 656481 | M14: 648819 | N14: 608827 | O14: 164 | P14: PARTNERS BANK OF NEW ENGLAND | Q14: 0.02498168263818755 | R14: 3.5126361724170407 | S14: 240 | T14: 62 | U14: 0 | V14: 15.606469 | W14: 20220331 | X14: 1.1149693 | Y14: 11.05 | Z14: ME
A15: 12 | B15: 1291920 | C15: 17180 | D15: 1121172 | E15: 0.06 | F15: 126979 | G15: 9.828704563750078 | H15: 17180_20220331 | I15: 0.9861620605817762 | J15: 44797 | K15: 141431 | L15: 1143017 | M15: 1131745 | N15: 937482 | O15: 5753 | P15: MEREDITH VILLAGE SAVINGS BANK | Q15: 0.5033170985208444 | R15: 3.569993155239652 | S15: 36 | T15: 1540 | U15: 0 | V15: 16.056943 | W15: 20220331 | X15: 0.80278929 | Y15: 8.11 | Z15: NH
A16: 13 | B16: 352255 | C16: 17443 | D16: 302135 | E16: 0.06 | F16: 42822 | G16: 12.15653432882429 | H16: 17443_20220331 | I16: 0.858419069393285 | J16: 0 | K16: 1909 | L16: 188952 | M16: 187330 | N16: 186037 | O16: 842 | P16: PISCATAQUA SAVINGS BANK | Q16: 0.44561581777382614 | R16: 2.012217920234347 | S16: 0 | T16: 2524 | U16: 0 | V16: 0 | W16: 20220331 | X16: 0.61925341 | Y16: 4.79 | Z16: NH
... A750: 747 | B750: 87770 | C750: 6280 | D750: 77256 | E750: 0.09 | F750: 9949 | G750: 11.335308191865103 | H750: 6280_20250630 | I750: 1.2995896032831737 | J750: 3899 | K750: 1311 | L750: 73100 | M750: 72150 | N750: 64947 | O750: 1455 | P750: THE FIRST NATIONAL BANK OF ORWELL | Q750: 1.990424076607387 | R750: 4.539434075857917 | S750: 0 | T750: 592 | U750: 0 | V750: 0 | W750: 20250630 | X750: 1.3665403 | Y750: 12.13 | Z750: VT

Sheet _RawBaseline
A1: source_row | B1: ASSET | C1: CERT | D1: DEP | E1: ELNATRY | F1: EQ | G1: EQV | H1: ID | I1: LNATRESR | J1: LNCI | K1: LNCON | L1: LNLSGR | M1: LNLSNET | N1: LNRE | O1: NAASSET | P1: NAMEFULL | Q1: NCLNLSR | R1: NIMY | S1: NTLNLS | T1: P3ASSET | U1: P9ASSET | V1: RBCRWAJ | W1: REPDTE | X1: ROA | Y1: ROE | Z1: STALP
A2: 2 | B2: 3688993 | C2: 11971 | D2: 3055632 | E2: 0.08 | F2: 461681 | G2: 12.515095582995142 | H2: 11971_20220331 | I2: 0.8726555144377637 | J2: 201303 | K2: 7873 | L2: 2657406 | M2: 2634216 | N2: 2317079 | O2: 9213 | P2: BAR HARBOR BANK & TRUST | Q2: 0.3784141376966862 | R2: 3.006742138500755 | S2: -95 | T2: 4642 | U2: 843 | V2: 13.678961 | W2: 20220331 | X2: 1.1162343 | Y2: 8.77 | Z2: ME
A3: 3 | B3: 964163 | C3: 12874 | D3: 854194 | E3: 0 | F3: 97916 | G3: 10.155544238889068 | H3: 12874_20220331 | I3: 1.0653480801084996 | J3: 138143 | K3: 5249 | L3: 732906 | M3: 725098 | N3: 577596 | O3: 1069 | P3: KATAHDIN TRUST COMPANY | Q3: 0.14585772254559248 | R3: 3.4019504411499137 | S3: -5 | T3: 374 | U3: 0 | V3: 15.601603 | W3: 20220331 | X3: 0.83149732 | Y3: 7.95 | Z3: ME
A4: 4 | B4: 1784835 | C4: 13063 | D4: 1619076 | E4: 0 | F4: 148181 | G4: 8.302224015105038 | H4: 13063_20220331 | I4: 1.2180099706634604 | J4: 55361 | K4: 837 | L4: 1223389 | M4: 1208488 | N4: 1160807 | O4: 408 | P4: KENNEBUNK SAVINGS BANK | Q4: 0.13111120011705188 | R4: 3.2711147741028457 | S4: -5 | T4: 3 | U4: 1196 | V4: 0 | W4: 20220331 | X4: 0.48237313 | Y4: 5.56 | Z4: ME
A5: 5 | B5: 869402 | C5: 14134 | D5: 737795 | E5: 0.1 | F5: 101808 | G5: 11.710117989146562 | H5: 14134_20220331 | I5: 1.4014366486247207 | J5: 27870 | K5: 26813 | L5: 596388 | M5: 588030 | N5: 516229 | O5: 8014 | P5: PASSUMPSIC SAVINGS BANK | Q5: 1.3437560782577784 | R5: 2.742437977347796 | S5: 19 | T5: 4990 | U5: 0 | V5: 17.570983 | W5: 20220331 | X5: -0.38729339 | Y5: -3.23 | Z5: VT
A6: 6 | B6: 222692 | C6: 14136 | D6: 199279 | E6: 0.08 | F6: 18834 | G6: 8.457421011980673 | H6: 14136_20220331 | I6: 1.1501745063903168 | J6: 12518 | K6: 11422 | L6: 121199 | M6: 119805 | N6: 96809 | O6: 174 | P6: WELLS RIVER SAVINGS BANK | Q6: 0.6707976138416983 | R6: 3.4223699758291275 | S6: 7 | T6: 803 | U6: 639 | V6: 17.27622 | W6: 20220331 | X6: 0.19954922 | Y6: 2.14 | Z6: VT
A7: 7 | B7: 1414510 | C7: 14140 | D7: 1199427 | E7: 0 | F7: 123854 | G7: 8.75596496313211 | H7: 14140_20220331 | I7: 1.1077738349896176 | J7: 82518 | K7: 1318 | L7: 957867 | M7: 947256 | N7: 866005 | O7: 5589 | P7: NORTHFIELD SAVINGS BANK | Q7: 0.58348392835331 | R7: 2.9698131336094122 | S7: 9 | T7: 785 | U7: 0 | V7: 0 | W7: 20220331 | X7: 0.66212632 | Y7: 7.07 | Z7: VT
A8: 8 | B8: 1232701 | C8: 14158 | D8: 1137254 | E8: 0 | F8: 85105 | G8: 6.9039450767055435 | H8: 14158_20220331 | I8: 1.0031734264943204 | J8: 44549 | K8: 2157 | L8: 830963 | M8: 822627 | N8: 698008 | O8: 4405 | P8: UNION BANK | Q8: 0.5576662258127016 | R8: 3.185373520467468 | S8: 0 | T8: 1620 | U8: 229 | V8: 14.788126 | W8: 20220331 | X8: 0.88329132 | Y8: 11.64 | Z8: VT
A9: 9 | B9: 384095 | C9: 14168 | D9: 345364 | E9: 0 | F9: 34244 | G9: 8.915502675119438 | H9: 14168_20220331 | I9: 1.5327875284455024 | J9: 9537 | K9: 8111 | L9: 191155 | M9: 188225 | N9: 161619 | O9: 1188 | P9: PEOPLES TRUST COMPANY OF ST. ALBANS | Q9: 0.6214851821819989 | R9: 2.4184590804383865 | S9: 34 | T9: 187 | U9: 0 | V9: 19.824643 | W9: 20220331 | X9: 0.13578832 | Y9: 1.45 | Z9: VT
A10: 10 | B10: 1221074 | C10: 14240 | D10: 1020645 | E10: 0 | F10: 102113 | G10: 8.36255624147267 | H10: 14240_20220331 | I10: 1.1483381231280392 | J10: 29648 | K10: 17990 | L10: 824670 | M10: 815200 | N10: 705835 | O10: 2204 | P10: NORTHWAY BANK | Q10: 0.26725841851892274 | R10: 2.8194207261510216 | S10: -4 | T10: 1936 | U10: 0 | V10: 15.106992 | W10: 20220331 | X10: 0.069811881 | Y10: 0.79 | Z10: NH
A11: 11 | B11: 836644 | C11: 17115 | D11: 738943 | E11: -0.08 | F11: 83239 | G11: 9.949154000984887 | H11: 17115_20220331 | I11: 1.1671320266694696 | J11: 43003 | K11: 3606 | L11: 656481 | M11: 648819 | N11: 608827 | O11: 164 | P11: PARTNERS BANK OF NEW ENGLAND | Q11: 0.02498168263818755 | R11: 3.5126361724170407 | S11: 240 | T11: 62 | U11: 0 | V11: 15.606469 | W11: 20220331 | X11: 1.1149693 | Y11: 11.05 | Z11: ME
A12: 12 | B12: 1291920 | C12: 17180 | D12: 1121172 | E12: 0.06 | F12: 126979 | G12: 9.828704563750078 | H12: 17180_20220331 | I12: 0.9861620605817762 | J12: 44797 | K12: 141431 | L12: 1143017 | M12: 1131745 | N12: 937482 | O12: 5753 | P12: MEREDITH VILLAGE SAVINGS BANK | Q12: 0.5033170985208444 | R12: 3.569993155239652 | S12: 36 | T12: 1540 | U12: 0 | V12: 16.056943 | W12: 20220331 | X12: 0.80278929 | Y12: 8.11 | Z12: NH
A13: 13 | B13: 352255 | C13: 17443 | D13: 302135 | E13: 0.06 | F13: 42822 | G13: 12.15653432882429 | H13: 17443_20220331 | I13: 0.858419069393285 | J13: 0 | K13: 1909 | L13: 188952 | M13: 187330 | N13: 186037 | O13: 842 | P13: PISCATAQUA SAVINGS BANK | Q13: 0.44561581777382614 | R13: 2.012217920234347 | S13: 0 | T13: 2524 | U13: 0 | V13: 0 | W13: 20220331 | X13: 0.61925341 | Y13: 4.79 | Z13: NH
... A747: 747 | B747: 87770 | C747: 6280 | D747: 77256 | E747: 0.09 | F747: 9949 | G747: 11.335308191865103 | H747: 6280_20250630 | I747: 1.2995896032831737 | J747: 3899 | K747: 1311 | L747: 73100 | M747: 72150 | N747: 64947 | O747: 1455 | P747: THE FIRST NATIONAL BANK OF ORWELL | Q747: 1.990424076607387 | R747: 4.539434075857917 | S747: 0 | T747: 592 | U747: 0 | V747: 0 | W747: 20250630 | X747: 1.3665403 | Y747: 12.13 | Z747: VT

Sheet InstitutionSnapshot
A1: Institution Snapshot
A2: Later snapshot joined by CERT only; ACTIVE is shown for context and is not used to remove or backfill historical financial records.
A4: CERT | B4: NAME | C4: ACTIVE | D4: REPDTE | E4: DATEUPDT | F4: STALP | G4: Matched financial CERT?
A5: 10 | B5: Northeast Bank of Sanford | C5: 0 | E5: 10/04/1990 | F5: ME | G5: =COUNTIF(BankQuarter!$B$5:$B$750,A5)>0 -> FALSE
A6: 10022 | B6: BankEast National Bank | C6: 0 | E6: 10/04/1990 | F6: NH | G6: =COUNTIF(BankQuarter!$B$5:$B$750,A6)>0 -> FALSE
A7: 10029 | B7: The Island Pond National Bank | C7: 0 | E7: 10/05/1995 | F7: VT | G7: =COUNTIF(BankQuarter!$B$5:$B$750,A7)>0 -> FALSE
A8: 11369 | B8: Aroostook Trust Company | C8: 0 | D8: 09/30/1986 | E8: 10/05/1995 | F8: ME | G8: =COUNTIF(BankQuarter!$B$5:$B$750,A8)>0 -> FALSE
A9: 11372 | B9: Casco Bank & Trust Company | C9: 0 | E9: 10/04/1990 | F9: ME | G9: =COUNTIF(BankQuarter!$B$5:$B$750,A9)>0 -> FALSE
A10: 11485 | B10: North Country Bank | C10: 0 | D10: 03/31/1986 | E10: 10/04/1990 | F10: NH | G10: =COUNTIF(BankQuarter!$B$5:$B$750,A10)>0 -> FALSE
A11: 11486 | B11: Nashua Trust Company | C11: 0 | D11: 06/30/1991 | E11: 08/24/1994 | F11: NH | G11: =COUNTIF(BankQuarter!$B$5:$B$750,A11)>0 -> FALSE
A12: 11970 | B12: Keybank National Association | C12: 0 | D12: 03/31/1997 | E12: 07/21/1997 | F12: ME | G12: =COUNTIF(BankQuarter!$B$5:$B$750,A12)>0 -> FALSE
A13: 11971 | B13: Bar Harbor Bank & Trust | C13: 1 | D13: 06/30/2026 | E13: 09/16/2025 | F13: ME | G13: =COUNTIF(BankQuarter!$B$5:$B$750,A13)>0 -> TRUE
A14: 12003 | B14: Eastport Savings Bank | C14: 0 | E14: 09/14/1995 | F14: ME | G14: =COUNTIF(BankQuarter!$B$5:$B$750,A14)>0 -> FALSE
A15: 12254 | B15: North Conway Bank | C15: 0 | D15: 06/30/1995 | E15: 08/03/1995 | F15: NH | G15: =COUNTIF(BankQuarter!$B$5:$B$750,A15)>0 -> FALSE
A16: 12725 | B16: Livermore Falls Trust Company | C16: 0 | D16: 12/31/1998 | E16: 02/26/1999 | F16: ME | G16: =COUNTIF(BankQuarter!$B$5:$B$750,A16)>0 -> FALSE
A17: 12873 | B17: Pepperell Bank & Trust | C17: 0 | D17: 06/30/2007 | E17: 09/12/2007 | F17: ME | G17: =COUNTIF(BankQuarter!$B$5:$B$750,A17)>0 -> FALSE
A18: 12874 | B18: Katahdin Trust Company | C18: 1 | D18: 06/30/2026 | E18: 11/18/2024 | F18: ME | G18: =COUNTIF(BankQuarter!$B$5:$B$750,A18)>0 -> TRUE
A19: 12878 | B19: 1st Consumers Savings Bank | C19: 0 | E19: 09/11/1995 | F19: ME | G19: =COUNTIF(BankQuarter!$B$5:$B$750,A19)>0 -> FALSE
A20: 13063 | B20: Kennebunk Savings Bank | C20: 1 | D20: 06/30/2026 | E20: 11/18/2024 | F20: ME | G20: =COUNTIF(BankQuarter!$B$5:$B$750,A20)>0 -> TRUE
A21: 13064 | B21: Heritage Savings Bank | C21: 0 | E21: 09/14/1995 | F21: ME | G21: =COUNTIF(BankQuarter!$B$5:$B$750,A21)>0 -> FALSE
A22: 13174 | B22: Federal Trust Company | C22: 0 | D22: 06/30/1984 | E22: 10/04/1990 | F22: ME | G22: =COUNTIF(BankQuarter!$B$5:$B$750,A22)>0 -> FALSE
A23: 13175 | B23: Key Bank of Eastern Maine | C23: 0 | D23: 09/30/1988 | E23: 10/04/1990 | F23: ME | G23: =COUNTIF(BankQuarter!$B$5:$B$750,A23)>0 -> FALSE
A24: 13176 | B24: Northeast Bank of Lincoln | C24: 0 | E24: 05/05/1999 | F24: ME | G24: =COUNTIF(BankQuarter!$B$5:$B$750,A24)>0 -> FALSE
A25: 13288 | B25: South Paris Savings Bank | C25: 0 | E25: 09/20/1995 | F25: ME | G25: =COUNTIF(BankQuarter!$B$5:$B$750,A25)>0 -> FALSE
A26: 13422 | B26: Montpelier National Bank | C26: 0 | E26: 09/12/1997 | F26: VT | G26: =COUNTIF(BankQuarter!$B$5:$B$750,A26)>0 -> FALSE
A27: 13848 | B27: The Enosburg Falls National Bank | C27: 0 | E27: 08/20/1992 | F27: VT | G27: =COUNTIF(BankQuarter!$B$5:$B$750,A27)>0 -> FALSE
A28: 14127 | B28: KeyBank National Association | C28: 0 | D28: 03/31/1997 | E28: 07/21/1997 | F28: VT | G28: =COUNTIF(BankQuarter!$B$5:$B$750,A28)>0 -> FALSE
A29: 14132 | B29: Marble Bank | C29: 0 | D29: 12/31/1995 | E29: 03/15/1996 | F29: VT | G29: =COUNTIF(BankQuarter!$B$5:$B$750,A29)>0 -> FALSE
A30: 14133 | B30: Rutland Savings Bank | C30: 0 | E30: 09/11/1995 | F30: VT | G30: =COUNTIF(BankQuarter!$B$5:$B$750,A30)>0 -> FALSE
A31: 14134 | B31: Passumpsic Savings Bank | C31: 1 | D31: 06/30/2026 | E31: 11/18/2024 | F31: VT | G31: =COUNTIF(BankQuarter!$B$5:$B$750,A31)>0 -> TRUE
A32: 14136 | B32: Wells River Savings Bank | C32: 1 | D32: 06/30/2026 | E32: 11/18/2024 | F32: VT | G32: =COUNTIF(BankQuarter!$B$5:$B$750,A32)>0 -> TRUE
A33: 14140 | B33: Northfield Savings Bank | C33: 1 | D33: 06/30/2026 | E33: 11/18/2024 | F33: VT | G33: =COUNTIF(BankQuarter!$B$5:$B$750,A33)>0 -> TRUE
A34: 14142 | B34: Barre Trust Company | C34: 0 | E34: 06/09/1995 | F34: VT | G34: =COUNTIF(BankQuarter!$B$5:$B$750,A34)>0 -> FALSE
A35: 14143 | B35: Granite Savings Bank and Trust Company | C35: 0 | D35: 03/31/2000 | E35: 08/07/2000 | F35: VT | G35: =COUNTIF(BankQuarter!$B$5:$B$750,A35)>0 -> FALSE
A36: 14146 | B36: Bellows Falls Trust Company | C36: 0 | D36: 03/31/1993 | E36: 05/26/1993 | F36: VT | G36: =COUNTIF(BankQuarter!$B$5:$B$750,A36)>0 -> FALSE
A37: 14147 | B37: First Vermont Bank , National Association | C37: 0 | D37: 12/31/2001 | E37: 01/28/2002 | F37: VT | G37: =COUNTIF(BankQuarter!$B$5:$B$750,A37)>0 -> FALSE
A38: 14149 | B38: Chittenden Trust Company | C38: 0 | D38: 12/31/2008 | E38: 02/19/2009 | F38: VT | G38: =COUNTIF(BankQuarter!$B$5:$B$750,A38)>0 -> FALSE
A39: 14152 | B39: Hardwick Trust Company | C39: 0 | E39: 05/05/1999 | F39: VT | G39: =COUNTIF(BankQuarter!$B$5:$B$750,A39)>0 -> FALSE
A40: 14153 | B40: Lamoille County Bank | C40: 0 | E40: 10/05/1995 | F40: VT | G40: =COUNTIF(BankQuarter!$B$5:$B$750,A40)>0 -> FALSE
A41: 14154 | B41: Sterling Trust Company | C41: 0 | D41: 03/31/1985 | E41: 08/20/1992 | F41: VT | G41: =COUNTIF(BankQuarter!$B$5:$B$750,A41)>0 -> FALSE
...

Sheet BankQuarter
A1: Bank-Quarter Calculation Table
A2: Formula-driven from RawFinancials. Proxy = 100 × (P9ASSET + NAASSET) / ASSET; invalid rows remain excluded, never coerced to zero.
A4: source_row | B4: CERT | C4: Bank name | D4: REPDTE | E4: State | F4: ASSET ($000) | G4: P9ASSET ($000) | H4: NAASSET ($000) | I4: Proxy numerator ($000) | J4: DEP ($000) | K4: EQ ($000) | L4: LNLSGR ($000) | M4: LNRE ($000) | N4: ROA raw % | O4: RBCRWAJ raw % | P4: RE loans / gross loans % | Q4: Equity / assets % | R4: Proxy valid? | S4: Proxy % | T4: Amount revised? | U4: End proxy for start row % | V4: End state for start row | W4: Has valid start? | X4: Has valid end? | Y4: Start state for end row | Z4: State rank at end | AA4: Remaining rank at end | AB4: Endpoint row? | AC4: Key
A5: =RawFinancials!A5 -> 2 | B5: =RawFinancials!C5 -> 11971 | C5: =RawFinancials!P5 -> BAR HARBOR BANK & TRUST | D5: =RawFinancials!W5 -> 20220331 | E5: =RawFinancials!Z5 -> ME | F5: =RawFinancials!B5 -> 3688993 | G5: =RawFinancials!U5 -> 843 | H5: =RawFinancials!O5 -> 9213 | I5: =IF(AND(ISNUMBER(G5),ISNUMBER(H5)),G5+H5,"") -> 10056 | J5: =RawFinancials!D5 -> 3055632 | K5: =RawFinancials!F5 -> 461681 | L5: =RawFinancials!L5 -> 2657406 | M5: =RawFinancials!N5 -> 2317079 | N5: =RawFinancials!X5 -> 1.1162343 | O5: =RawFinancials!V5 -> 13.678961 | P5: =IF(AND(ISNUMBER(L5),L5<>0,ISNUMBER(M5)),100*M5/L5,"") -> 87.193263 | Q5: =IF(AND(ISNUMBER(F5),F5<>0,ISNUMBER(K5)),100*K5/F5,"") -> 12.515096 | R5: =AND(ISNUMBER(F5),F5>0,ISNUMBER(G5),G5>=0,ISNUMBER(H5),H5>=0) -> TRUE | S5: =IF(R5,100*I5/F5,"") -> 0.27259472 | T5: =NOT(AND(OR(AND(ISBLANK(RawFinancials!B5),ISBLANK(_RawBaseline!B2)),AND(ISNUMBER(RawFinancials!B5),ISNUMBER(_RawBaseline!B2),RawFinancials!B5=_RawBaseline!B2)),OR(AND(ISBLANK(RawFinancials!U5),ISBLANK(_RawBaseline!U2)),AND(ISNUMBER(RawFinancials!U5),ISNUMBER(_RawBaseline!U2),RawFinancials!U5=_RawBaseline!U2)),OR(AND(ISBLANK(RawFinancials!O5),ISBLANK(_RawBaseline!O2)),AND(ISNUMBER(RawFinancials!O5),ISNUMBER(_RawBaseline!O2),RawFinancials!O5=_RawBaseline!O2)))) -> FALSE | U5: =IF(AND(D5=WF_START_PERIOD,R5,COUNTIFS($B$5:$B$750,B5,$D$5:$D$750,WF_END_PERIOD,$R$5:$R$750,TRUE())>0),SUMIFS($S$5:$S$750,$B$5:$B$750,B5,$D$5:$D$750,WF_END_PERIOD,$R$5:$R$750,TRUE()),0) -> 0 | V5: =IF(AND(D5=WF_START_PERIOD,COUNTIFS($B$5:$B$750,B5,$D$5:$D$750,WF_END_PERIOD)>0),INDEX($E$5:$E$750,MATCH(B5&"|"&WF_END_PERIOD,$AC$5:$AC$750,0)),"") | W5: =COUNTIFS($B$5:$B$750,B5,$D$5:$D$750,WF_START_PERIOD,$R$5:$R$750,TRUE())>0 -> TRUE | X5: =COUNTIFS($B$5:$B$750,B5,$D$5:$D$750,WF_END_PERIOD,$R$5:$R$750,TRUE())>0 -> TRUE | Y5: =IF(AND(D5=WF_END_PERIOD,COUNTIFS($B$5:$B$750,B5,$D$5:$D$750,WF_START_PERIOD)>0),INDEX($E$5:$E$750,MATCH(B5&"|"&WF_START_PERIOD,$AC$5:$AC$750,0)),"") | Z5: =IF(AND(D5=WF_END_PERIOD,R5),1+COUNTIFS($D$5:$D$750,WF_END_PERIOD,$E$5:$E$750,E5,$R$5:$R$750,TRUE(),$S$5:$S$750,">"&S5)+COUNTIFS($D$5:$D$750,WF_END_PERIOD,$E$5:$E$750,E5,$R$5:$R$750,TRUE(),$S$5:$S$750,S5,$B$5:$B$750,"<"&B5),"") | AA5: =IF(AND(D5=WF_END_PERIOD,R5,Z5<>1),1+COUNTIFS($D$5:$D$750,WF_END_PERIOD,$R$5:$R$750,TRUE(),$Z$5:$Z$750,"<>1",$S$5:$S$750,">"&S5)+COUNTIFS($D$5:$D$750,WF_END_PERIOD,$R$5:$R$750,TRUE(),$Z$5:$Z$750,"<>1",$S$5:$S$750,S5,$B$5:$B$750,"<"&B5),"") | AB5: =OR(D5=WF_START_PERIOD,D5=WF_END_PERIOD) -> FALSE | AC5: =B5&"|"&D5 -> 11971|20220331
A6: =RawFinancials!A6 -> 3 | B6: =RawFinancials!C6 -> 12874 | C6: =RawFinancials!P6 -> KATAHDIN TRUST COMPANY | D6: =RawFinancials!W6 -> 20220331 | E6: =RawFinancials!Z6 -> ME | F6: =RawFinancials!B6 -> 964163 | G6: =RawFinancials!U6 -> 0 | H6: =RawFinancials!O6 -> 1069 | I6: =IF(AND(ISNUMBER(G6),ISNUMBER(H6)),G6+H6,"") -> 1069 | J6: =RawFinancials!D6 -> 854194 | K6: =RawFinancials!F6 -> 97916 | L6: =RawFinancials!L6 -> 732906 | M6: =RawFinancials!N6 -> 577596 | N6: =RawFinancials!X6 -> 0.83149732 | O6: =RawFinancials!V6 -> 15.601603 | P6: =IF(AND(ISNUMBER(L6),L6<>0,ISNUMBER(M6)),100*M6/L6,"") -> 78.809015 | Q6: =IF(AND(ISNUMBER(F6),F6<>0,ISNUMBER(K6)),100*K6/F6,"") -> 10.155544 | R6: =AND(ISNUMBER(F6),F6>0,ISNUMBER(G6),G6>=0,ISNUMBER(H6),H6>=0) -> TRUE | S6: =IF(R6,100*I6/F6,"") -> 0.11087337 | T6: =NOT(AND(OR(AND(ISBLANK(RawFinancials!B6),ISBLANK(_RawBaseline!B3)),AND(ISNUMBER(RawFinancials!B6),ISNUMBER(_RawBaseline!B3),RawFinancials!B6=_RawBaseline!B3)),OR(AND(ISBLANK(RawFinancials!U6),ISBLANK(_RawBaseline!U3)),AND(ISNUMBER(RawFinancials!U6),ISNUMBER(_RawBaseline!U3),RawFinancials!U6=_RawBaseline!U3)),OR(AND(ISBLANK(RawFinancials!O6),ISBLANK(_RawBaseline!O3)),AND(ISNUMBER(RawFinancials!O6),ISNUMBER(_RawBaseline!O3),RawFinancials!O6=_RawBaseline!O3)))) -> FALSE | U6: =IF(AND(D6=WF_START_PERIOD,R6,COUNTIFS($B$5:$B$750,B6,$D$5:$D$750,WF_END_PERIOD,$R$5:$R$750,TRUE())>0),SUMIFS($S$5:$S$750,$B$5:$B$750,B6,$D$5:$D$750,WF_END_PERIOD,$R$5:$R$750,TRUE()),0) -> 0 | V6: =IF(AND(D6=WF_START_PERIOD,COUNTIFS($B$5:$B$750,B6,$D$5:$D$750,WF_END_PERIOD)>0),INDEX($E$5:$E$750,MATCH(B6&"|"&WF_END_PERIOD,$AC$5:$AC$750,0)),"") | W6: =COUNTIFS($B$5:$B$750,B6,$D$5:$D$750,WF_START_PERIOD,$R$5:$R$750,TRUE())>0 -> TRUE | X6: =COUNTIFS($B$5:$B$750,B6,$D$5:$D$750,WF_END_PERIOD,$R$5:$R$750,TRUE())>0 -> TRUE | Y6: =IF(AND(D6=WF_END_PERIOD,COUNTIFS($B$5:$B$750,B6,$D$5:$D$750,WF_START_PERIOD)>0),INDEX($E$5:$E$750,MATCH(B6&"|"&WF_START_PERIOD,$AC$5:$AC$750,0)),"") | Z6: =IF(AND(D6=WF_END_PERIOD,R6),1+COUNTIFS($D$5:$D$750,WF_END_PERIOD,$E$5:$E$750,E6,$R$5:$R$750,TRUE(),$S$5:$S$750,">"&S6)+COUNTIFS($D$5:$D$750,WF_END_PERIOD,$E$5:$E$750,E6,$R$5:$R$750,TRUE(),$S$5:$S$750,S6,$B$5:$B$750,"<"&B6),"") | AA6: =IF(AND(D6=WF_END_PERIOD,R6,Z6<>1),1+COUNTIFS($D$5:$D$750,WF_END_PERIOD,$R$5:$R$750,TRUE(),$Z$5:$Z$750,"<>1",$S$5:$S$750,">"&S6)+COUNTIFS($D$5:$D$750,WF_END_PERIOD,$R$5:$R$750,TRUE(),$Z$5:$Z$750,"<>1",$S$5:$S$750,S6,$B$5:$B$750,"<"&B6),"") | AB6: =OR(D6=WF_START_PERIOD,D6=WF_END_PERIOD) -> FALSE | AC6: =B6&"|"&D6 -> 12874|20220331
A7: =RawFinancials!A7 -> 4 | B7: =RawFinancials!C7 -> 13063 | C7: =RawFinancials!P7 -> KENNEBUNK SAVINGS BANK | D7: =RawFinancials!W7 -> 20220331 | E7: =RawFinancials!Z7 -> ME | F7: =RawFinancials!B7 -> 1784835 | G7: =RawFinancials!U7 -> 1196 | H7: =RawFinancials!O7 -> 408 | I7: =IF(AND(ISNUMBER(G7),ISNUMBER(H7)),G7+H7,"") -> 1604 | J7: =RawFinancials!D7 -> 1619076 | K7: =RawFinancials!F7 -> 148181 | L7: =RawFinancials!L7 -> 1223389 | M7: =RawFinancials!N7 -> 1160807 | N7: =RawFinancials!X7 -> 0.48237313 | O7: =RawFinancials!V7 -> 0 | P7: =IF(AND(ISNUMBER(L7),L7<>0,ISNUMBER(M7)),100*M7/L7,"") -> 94.884538 | Q7: =IF(AND(ISNUMBER(F7),F7<>0,ISNUMBER(K7)),100*K7/F7,"") -> 8.302224 | R7: =AND(ISNUMBER(F7),F7>0,ISNUMBER(G7),G7>=0,ISNUMBER(H7),H7>=0) -> TRUE | S7: =IF(R7,100*I7/F7,"") -> 0.089868251 | T7: =NOT(AND(OR(AND(ISBLANK(RawFinancials!B7),ISBLANK(_RawBaseline!B4)),AND(ISNUMBER(RawFinancials!B7),ISNUMBER(_RawBaseline!B4),RawFinancials!B7=_RawBaseline!B4)),OR(AND(ISBLANK(RawFinancials!U7),ISBLANK(_RawBaseline!U4)),AND(ISNUMBER(RawFinancials!U7),ISNUMBER(_RawBaseline!U4),RawFinancials!U7=_RawBaseline!U4)),OR(AND(ISBLANK(RawFinancials!O7),ISBLANK(_RawBaseline!O4)),AND(ISNUMBER(RawFinancials!O7),ISNUMBER(_RawBaseline!O4),RawFinancials!O7=_RawBaseline!O4)))) -> FALSE | U7: =IF(AND(D7=WF_START_PERIOD,R7,COUNTIFS($B$5:$B$750,B7,$D$5:$D$750,WF_END_PERIOD,$R$5:$R$750,TRUE())>0),SUMIFS($S$5:$S$750,$B$5:$B$750,B7,$D$5:$D$750,WF_END_PERIOD,$R$5:$R$750,TRUE()),0) -> 0 | V7: =IF(AND(D7=WF_START_PERIOD,COUNTIFS($B$5:$B$750,B7,$D$5:$D$750,WF_END_PERIOD)>0),INDEX($E$5:$E$750,MATCH(B7&"|"&WF_END_PERIOD,$AC$5:$AC$750,0)),"") | W7: =COUNTIFS($B$5:$B$750,B7,$D$5:$D$750,WF_START_PERIOD,$R$5:$R$750,TRUE())>0 -> TRUE | X7: =COUNTIFS($B$5:$B$750,B7,$D$5:$D$750,WF_END_PERIOD,$R$5:$R$750,TRUE())>0 -> TRUE | Y7: =IF(AND(D7=WF_END_PERIOD,COUNTIFS($B$5:$B$750,B7,$D$5:$D$750,WF_START_PERIOD)>0),INDEX($E$5:$E$750,MATCH(B7&"|"&WF_START_PERIOD,$AC$5:$AC$750,0)),"") | Z7: =IF(AND(D7=WF_END_PERIOD,R7),1+COUNTIFS($D$5:$D$750,WF_END_PERIOD,$E$5:$E$750,E7,$R$5:$R$750,TRUE(),$S$5:$S$750,">"&S7)+COUNTIFS($D$5:$D$750,WF_END_PERIOD,$E$5:$E$750,E7,$R$5:$R$750,TRUE(),$S$5:$S$750,S7,$B$5:$B$750,"<"&B7),"") | AA7: =IF(AND(D7=WF_END_PERIOD,R7,Z7<>1),1+COUNTIFS($D$5:$D$750,WF_END_PERIOD,$R$5:$R$750,TRUE(),$Z$5:$Z$750,"<>1",$S$5:$S$750,">"&S7)+COUNTIFS($D$5:$D$750,WF_END_PERIOD,$R$5:$R$750,TRUE(),$Z$5:$Z$750,"<>1",$S$5:$S$750,S7,$B$5:$B$750,"<"&B7),"") | AB7: =OR(D7=WF_START_PERIOD,D7=WF_END_PERIOD) -> FALSE | AC7: =B7&"|"&D7 -> 13063|20220331
A8: =RawFinancials!A8 -> 5 | B8: =RawFinancials!C8 -> 14134 | C8: =RawFinancials!P8 -> PASSUMPSIC SAVINGS BANK | D8: =RawFinancials!W8 -> 20220331 | E8: =RawFinancials!Z8 -> VT | F8: =RawFinancials!B8 -> 869402 | G8: =RawFinancials!U8 -> 0 | H8: =RawFinancials!O8 -> 8014 | I8: =IF(AND(ISNUMBER(G8),ISNUMBER(H8)),G8+H8,"") -> 8014 | J8: =RawFinancials!D8 -> 737795 | K8: =RawFinancials!F8 -> 101808 | L8: =RawFinancials!L8 -> 596388 | M8: =RawFinancials!N8 -> 516229 | N8: =RawFinancials!X8 -> -0.38729339 | O8: =RawFinancials!V8 -> 17.570983 | P8: =IF(AND(ISNUMBER(L8),L8<>0,ISNUMBER(M8)),100*M8/L8,"") -> 86.559253 | Q8: =IF(AND(ISNUMBER(F8),F8<>0,ISNUMBER(K8)),100*K8/F8,"") -> 11.710118 | R8: =AND(ISNUMBER(F8),F8>0,ISNUMBER(G8),G8>=0,ISNUMBER(H8),H8>=0) -> TRUE | S8: =IF(R8,100*I8/F8,"") -> 0.92178302 | T8: =NOT(AND(OR(AND(ISBLANK(RawFinancials!B8),ISBLANK(_RawBaseline!B5)),AND(ISNUMBER(RawFinancials!B8),ISNUMBER(_RawBaseline!B5),RawFinancials!B8=_RawBaseline!B5)),OR(AND(ISBLANK(RawFinancials!U8),ISBLANK(_RawBaseline!U5)),AND(ISNUMBER(RawFinancials!U8),ISNUMBER(_RawBaseline!U5),RawFinancials!U8=_RawBaseline!U5)),OR(AND(ISBLANK(RawFinancials!O8),ISBLANK(_RawBaseline!O5)),AND(ISNUMBER(RawFinancials!O8),ISNUMBER(_RawBaseline!O5),RawFinancials!O8=_RawBaseline!O5)))) -> FALSE | U8: =IF(AND(D8=WF_START_PERIOD,R8,COUNTIFS($B$5:$B$750,B8,$D$5:$D$750,WF_END_PERIOD,$R$5:$R$750,TRUE())>0),SUMIFS($S$5:$S$750,$B$5:$B$750,B8,$D$5:$D$750,WF_END_PERIOD,$R$5:$R$750,TRUE()),0) -> 0 | V8: =IF(AND(D8=WF_START_PERIOD,COUNTIFS($B$5:$B$750,B8,$D$5:$D$750,WF_END_PERIOD)>0),INDEX($E$5:$E$750,MATCH(B8&"|"&WF_END_PERIOD,$AC$5:$AC$750,0)),"") | W8: =COUNTIFS($B$5:$B$750,B8,$D$5:$D$750,WF_START_PERIOD,$R$5:$R$750,TRUE())>0 -> TRUE | X8: =COUNTIFS($B$5:$B$750,B8,$D$5:$D$750,WF_END_PERIOD,$R$5:$R$750,TRUE())>0 -> TRUE | Y8: =IF(AND(D8=WF_END_PERIOD,COUNTIFS($B$5:$B$750,B8,$D$5:$D$750,WF_START_PERIOD)>0),INDEX($E$5:$E$750,MATCH(B8&"|"&WF_START_PERIOD,$AC$5:$AC$750,0)),"") | Z8: =IF(AND(D8=WF_END_PERIOD,R8),1+COUNTIFS($D$5:$D$750,WF_END_PERIOD,$E$5:$E$750,E8,$R$5:$R$750,TRUE(),$S$5:$S$750,">"&S8)+COUNTIFS($D$5:$D$750,WF_END_PERIOD,$E$5:$E$750,E8,$R$5:$R$750,TRUE(),$S$5:$S$750,S8,$B$5:$B$750,"<"&B8),"") | AA8: =IF(AND(D8=WF_END_PERIOD,R8,Z8<>1),1+COUNTIFS($D$5:$D$750,WF_END_PERIOD,$R$5:$R$750,TRUE(),$Z$5:$Z$750,"<>1",$S$5:$S$750,">"&S8)+COUNTIFS($D$5:$D$750,WF_END_PERIOD,$R$5:$R$750,TRUE(),$Z$5:$Z$750,"<>1",$S$5:$S$750,S8,$B$5:$B$750,"<"&B8),"") | AB8: =OR(D8=WF_START_PERIOD,D8=WF_END_PERIOD) -> FALSE | AC8: =B8&"|"&D8 -> 14134|20220331
A9: =RawFinancials!A9 -> 6 | B9: =RawFinancials!C9 -> 14136 | C9: =RawFinancials!P9 -> WELLS RIVER SAVINGS BANK | D9: =RawFinancials!W9 -> 20220331 | E9: =RawFinancials!Z9 -> VT | F9: =RawFinancials!B9 -> 222692 | G9: =RawFinancials!U9 -> 639 | H9: =RawFinancials!O9 -> 174 | I9: =IF(AND(ISNUMBER(G9),ISNUMBER(H9)),G9+H9,"") -> 813 | J9: =RawFinancials!D9 -> 199279 | K9: =RawFinancials!F9 -> 18834 | L9: =RawFinancials!L9 -> 121199 | M9: =RawFinancials!N9 -> 96809 | N9: =RawFinancials!X9 -> 0.19954922 | O9: =RawFinancials!V9 -> 17.27622 | P9: =IF(AND(ISNUMBER(L9),L9<>0,ISNUMBER(M9)),100*M9/L9,"") -> 79.876072 | Q9: =IF(AND(ISNUMBER(F9),F9<>0,ISNUMBER(K9)),100*K9/F9,"") -> 8.457421 | R9: =AND(ISNUMBER(F9),F9>0,ISNUMBER(G9),G9>=0,ISNUMBER(H9),H9>=0) -> TRUE | S9: =IF(R9,100*I9/F9,"") -> 0.36507822 | T9: =NOT(AND(OR(AND(ISBLANK(RawFinancials!B9),ISBLANK(_RawBaseline!B6)),AND(ISNUMBER(RawFinancials!B9),ISNUMBER(_RawBaseline!B6),RawFinancials!B9=_RawBaseline!B6)),OR(AND(ISBLANK(RawFinancials!U9),ISBLANK(_RawBaseline!U6)),AND(ISNUMBER(RawFinancials!U9),ISNUMBER(_RawBaseline!U6),RawFinancials!U9=_RawBaseline!U6)),OR(AND(ISBLANK(RawFinancials!O9),ISBLANK(_RawBaseline!O6)),AND(ISNUMBER(RawFinancials!O9),ISNUMBER(_RawBaseline!O6),RawFinancials!O9=_RawBaseline!O6)))) -> FALSE | U9: =IF(AND(D9=WF_START_PERIOD,R9,COUNTIFS($B$5:$B$750,B9,$D$5:$D$750,WF_END_PERIOD,$R$5:$R$750,TRUE())>0),SUMIFS($S$5:$S$750,$B$5:$B$750,B9,$D$5:$D$750,WF_END_PERIOD,$R$5:$R$750,TRUE()),0) -> 0 | V9: =IF(AND(D9=WF_START_PERIOD,COUNTIFS($B$5:$B$750,B9,$D$5:$D$750,WF_END_PERIOD)>0),INDEX($E$5:$E$750,MATCH(B9&"|"&WF_END_PERIOD,$AC$5:$AC$750,0)),"") | W9: =COUNTIFS($B$5:$B$750,B9,$D$5:$D$750,WF_START_PERIOD,$R$5:$R$750,TRUE())>0 -> TRUE | X9: =COUNTIFS($B$5:$B$750,B9,$D$5:$D$750,WF_END_PERIOD,$R$5:$R$750,TRUE())>0 -> TRUE | Y9: =IF(AND(D9=WF_END_PERIOD,COUNTIFS($B$5:$B$750,B9,$D$5:$D$750,WF_START_PERIOD)>0),INDEX($E$5:$E$750,MATCH(B9&"|"&WF_START_PERIOD,$AC$5:$AC$750,0)),"") | Z9: =IF(AND(D9=WF_END_PERIOD,R9),1+COUNTIFS($D$5:$D$750,WF_END_PERIOD,$E$5:$E$750,E9,$R$5:$R$750,TRUE(),$S$5:$S$750,">"&S9)+COUNTIFS($D$5:$D$750,WF_END_PERIOD,$E$5:$E$750,E9,$R$5:$R$750,TRUE(),$S$5:$S$750,S9,$B$5:$B$750,"<"&B9),"") | AA9: =IF(AND(D9=WF_END_PERIOD,R9,Z9<>1),1+COUNTIFS($D$5:$D$750,WF_END_PERIOD,$R$5:$R$750,TRUE(),$Z$5:$Z$750,"<>1",$S$5:$S$750,">"&S9)+COUNTIFS($D$5:$D$750,WF_END_PERIOD,$R$5:$R$750,TRUE(),$Z$5:$Z$750,"<>1",$S$5:$S$750,S9,$B$5:$B$750,"<"&B9),"") | AB9: =OR(D9=WF_START_PERIOD,D9=WF_END_PERIOD) -> FALSE | AC9: =B9&"|"&D9 -> 14136|20220331
A10: =RawFinancials!A10 -> 7 | B10: =RawFinancials!C10 -> 14140 | C10: =RawFinancials!P10 -> NORTHFIELD SAVINGS BANK | D10: =RawFinancials!W10 -> 20220331 | E10: =RawFinancials!Z10 -> VT | F10: =RawFinancials!B10 -> 1414510 | G10: =RawFinancials!U10 -> 0 | H10: =RawFinancials!O10 -> 5589 | I10: =IF(AND(ISNUMBER(G10),ISNUMBER(H10)),G10+H10,"") -> 5589 | J10: =RawFinancials!D10 -> 1199427 | K10: =RawFinancials!F10 -> 123854 | L10: =RawFinancials!L10 -> 957867 | M10: =RawFinancials!N10 -> 866005 | N10: =RawFinancials!X10 -> 0.66212632 | O10: =RawFinancials!V10 -> 0 | P10: =IF(AND(ISNUMBER(L10),L10<>0,ISNUMBER(M10)),100*M10/L10,"") -> 90.409733 | Q10: =IF(AND(ISNUMBER(F10),F10<>0,ISNUMBER(K10)),100*K10/F10,"") -> 8.755965 | R10: =AND(ISNUMBER(F10),F10>0,ISNUMBER(G10),G10>=0,ISNUMBER(H10),H10>=0) -> TRUE | S10: =IF(R10,100*I10/F10,"") -> 0.39511916 | T10: =NOT(AND(OR(AND(ISBLANK(RawFinancials!B10),ISBLANK(_RawBaseline!B7)),AND(ISNUMBER(RawFinancials!B10),ISNUMBER(_RawBaseline!B7),RawFinancials!B10=_RawBaseline!B7)),OR(AND(ISBLANK(RawFinancials!U10),ISBLANK(_RawBaseline!U7)),AND(ISNUMBER(RawFinancials!U10),ISNUMBER(_RawBaseline!U7),RawFinancials!U10=_RawBaseline!U7)),OR(AND(ISBLANK(RawFinancials!O10),ISBLANK(_RawBaseline!O7)),AND(ISNUMBER(RawFinancials!O10),ISNUMBER(_RawBaseline!O7),RawFinancials!O10=_RawBaseline!O7)))) -> FALSE | U10: =IF(AND(D10=WF_START_PERIOD,R10,COUNTIFS($B$5:$B$750,B10,$D$5:$D$750,WF_END_PERIOD,$R$5:$R$750,TRUE())>0),SUMIFS($S$5:$S$750,$B$5:$B$750,B10,$D$5:$D$750,WF_END_PERIOD,$R$5:$R$750,TRUE()),0) -> 0 | V10: =IF(AND(D10=WF_START_PERIOD,COUNTIFS($B$5:$B$750,B10,$D$5:$D$750,WF_END_PERIOD)>0),INDEX($E$5:$E$750,MATCH(B10&"|"&WF_END_PERIOD,$AC$5:$AC$750,0)),"") | W10: =COUNTIFS($B$5:$B$750,B10,$D$5:$D$750,WF_START_PERIOD,$R$5:$R$750,TRUE())>0 -> TRUE | X10: =COUNTIFS($B$5:$B$750,B10,$D$5:$D$750,WF_END_PERIOD,$R$5:$R$750,TRUE())>0 -> TRUE | Y10: =IF(AND(D10=WF_END_PERIOD,COUNTIFS($B$5:$B$750,B10,$D$5:$D$750,WF_START_PERIOD)>0),INDEX($E$5:$E$750,MATCH(B10&"|"&WF_START_PERIOD,$AC$5:$AC$750,0)),"") | Z10: =IF(AND(D10=WF_END_PERIOD,R10),1+COUNTIFS($D$5:$D$750,WF_END_PERIOD,$E$5:$E$750,E10,$R$5:$R$750,TRUE(),$S$5:$S$750,">"&S10)+COUNTIFS($D$5:$D$750,WF_END_PERIOD,$E$5:$E$750,E10,$R$5:$R$750,TRUE(),$S$5:$S$750,S10,$B$5:$B$750,"<"&B10),"") | AA10: =IF(AND(D10=WF_END_PERIOD,R10,Z10<>1),1+COUNTIFS($D$5:$D$750,WF_END_PERIOD,$R$5:$R$750,TRUE(),$Z$5:$Z$750,"<>1",$S$5:$S$750,">"&S10)+COUNTIFS($D$5:$D$750,WF_END_PERIOD,$R$5:$R$750,TRUE(),$Z$5:$Z$750,"<>1",$S$5:$S$750,S10,$B$5:$B$750,"<"&B10),"") | AB10: =OR(D10=WF_START_PERIOD,D10=WF_END_PERIOD) -> FALSE | AC10: =B10&"|"&D10 -> 14140|20220331
A11: =RawFinancials!A11 -> 8 | B11: =RawFinancials!C11 -> 14158 | C11: =RawFinancials!P11 -> UNION BANK | D11: =RawFinancials!W11 -> 20220331 | E11: =RawFinancials!Z11 -> VT | F11: =RawFinancials!B11 -> 1232701 | G11: =RawFinancials!U11 -> 229 | H11: =RawFinancials!O11 -> 4405 | I11: =IF(AND(ISNUMBER(G11),ISNUMBER(H11)),G11+H11,"") -> 4634 | J11: =RawFinancials!D11 -> 1137254 | K11: =RawFinancials!F11 -> 85105 | L11: =RawFinancials!L11 -> 830963 | M11: =RawFinancials!N11 -> 698008 | N11: =RawFinancials!X11 -> 0.88329132 | O11: =RawFinancials!V11 -> 14.788126 | P11: =IF(AND(ISNUMBER(L11),L11<>0,ISNUMBER(M11)),100*M11/L11,"") -> 83.999889 | Q11: =IF(AND(ISNUMBER(F11),F11<>0,ISNUMBER(K11)),100*K11/F11,"") -> 6.9039451 | R11: =AND(ISNUMBER(F11),F11>0,ISNUMBER(G11),G11>=0,ISNUMBER(H11),H11>=0) -> TRUE | S11: =IF(R11,100*I11/F11,"") -> 0.37592247 | T11: =NOT(AND(OR(AND(ISBLANK(RawFinancials!B11),ISBLANK(_RawBaseline!B8)),AND(ISNUMBER(RawFinancials!B11),ISNUMBER(_RawBaseline!B8),RawFinancials!B11=_RawBaseline!B8)),OR(AND(ISBLANK(RawFinancials!U11),ISBLANK(_RawBaseline!U8)),AND(ISNUMBER(RawFinancials!U11),ISNUMBER(_RawBaseline!U8),RawFinancials!U11=_RawBaseline!U8)),OR(AND(ISBLANK(RawFinancials!O11),ISBLANK(_RawBaseline!O8)),AND(ISNUMBER(RawFinancials!O11),ISNUMBER(_RawBaseline!O8),RawFinancials!O11=_RawBaseline!O8)))) -> FALSE | U11: =IF(AND(D11=WF_START_PERIOD,R11,COUNTIFS($B$5:$B$750,B11,$D$5:$D$750,WF_END_PERIOD,$R$5:$R$750,TRUE())>0),SUMIFS($S$5:$S$750,$B$5:$B$750,B11,$D$5:$D$750,WF_END_PERIOD,$R$5:$R$750,TRUE()),0) -> 0 | V11: =IF(AND(D11=WF_START_PERIOD,COUNTIFS($B$5:$B$750,B11,$D$5:$D$750,WF_END_PERIOD)>0),INDEX($E$5:$E$750,MATCH(B11&"|"&WF_END_PERIOD,$AC$5:$AC$750,0)),"") | W11: =COUNTIFS($B$5:$B$750,B11,$D$5:$D$750,WF_START_PERIOD,$R$5:$R$750,TRUE())>0 -> TRUE | X11: =COUNTIFS($B$5:$B$750,B11,$D$5:$D$750,WF_END_PERIOD,$R$5:$R$750,TRUE())>0 -> TRUE | Y11: =IF(AND(D11=WF_END_PERIOD,COUNTIFS($B$5:$B$750,B11,$D$5:$D$750,WF_START_PERIOD)>0),INDEX($E$5:$E$750,MATCH(B11&"|"&WF_START_PERIOD,$AC$5:$AC$750,0)),"") | Z11: =IF(AND(D11=WF_END_PERIOD,R11),1+COUNTIFS($D$5:$D$750,WF_END_PERIOD,$E$5:$E$750,E11,$R$5:$R$750,TRUE(),$S$5:$S$750,">"&S11)+COUNTIFS($D$5:$D$750,WF_END_PERIOD,$E$5:$E$750,E11,$R$5:$R$750,TRUE(),$S$5:$S$750,S11,$B$5:$B$750,"<"&B11),"") | AA11: =IF(AND(D11=WF_END_PERIOD,R11,Z11<>1),1+COUNTIFS($D$5:$D$750,WF_END_PERIOD,$R$5:$R$750,TRUE(),$Z$5:$Z$750,"<>1",$S$5:$S$750,">"&S11)+COUNTIFS($D$5:$D$750,WF_END_PERIOD,$R$5:$R$750,TRUE(),$Z$5:$Z$750,"<>1",$S$5:$S$750,S11,$B$5:$B$750,"<"&B11),"") | AB11: =OR(D11=WF_START_PERIOD,D11=WF_END_PERIOD) -> FALSE | AC11: =B11&"|"&D11 -> 14158|20220331
A12: =RawFinancials!A12 -> 9 | B12: =RawFinancials!C12 -> 14168 | C12: =RawFinancials!P12 -> PEOPLES TRUST COMPANY OF ST. ALBANS | D12: =RawFinancials!W12 -> 20220331 | E12: =RawFinancials!Z12 -> VT | F12: =RawFinancials!B12 -> 384095 | G12: =RawFinancials!U12 -> 0 | H12: =RawFinancials!O12 -> 1188 | I12: =IF(AND(ISNUMBER(G12),ISNUMBER(H12)),G12+H12,"") -> 1188 | J12: =RawFinancials!D12 -> 345364 | K12: =RawFinancials!F12 -> 34244 | L12: =RawFinancials!L12 -> 191155 | M12: =RawFinancials!N12 -> 161619 | N12: =RawFinancials!X12 -> 0.13578832 | O12: =RawFinancials!V12 -> 19.824643 | P12: =IF(AND(ISNUMBER(L12),L12<>0,ISNUMBER(M12)),100*M12/L12,"") -> 84.548665 | Q12: =IF(AND(ISNUMBER(F12),F12<>0,ISNUMBER(K12)),100*K12/F12,"") -> 8.9155027 | R12: =AND(ISNUMBER(F12),F12>0,ISNUMBER(G12),G12>=0,ISNUMBER(H12),H12>=0) -> TRUE | S12: =IF(R12,100*I12/F12,"") -> 0.30929848 | T12: =NOT(AND(OR(AND(ISBLANK(RawFinancials!B12),ISBLANK(_RawBaseline!B9)),AND(ISNUMBER(RawFinancials!B12),ISNUMBER(_RawBaseline!B9),RawFinancials!B12=_RawBaseline!B9)),OR(AND(ISBLANK(RawFinancials!U12),ISBLANK(_RawBaseline!U9)),AND(ISNUMBER(RawFinancials!U12),ISNUMBER(_RawBaseline!U9),RawFinancials!U12=_RawBaseline!U9)),OR(AND(ISBLANK(RawFinancials!O12),ISBLANK(_RawBaseline!O9)),AND(ISNUMBER(RawFinancials!O12),ISNUMBER(_RawBaseline!O9),RawFinancials!O12=_RawBaseline!O9)))) -> FALSE | U12: =IF(AND(D12=WF_START_PERIOD,R12,COUNTIFS($B$5:$B$750,B12,$D$5:$D$750,WF_END_PERIOD,$R$5:$R$750,TRUE())>0),SUMIFS($S$5:$S$750,$B$5:$B$750,B12,$D$5:$D$750,WF_END_PERIOD,$R$5:$R$750,TRUE()),0) -> 0 | V12: =IF(AND(D12=WF_START_PERIOD,COUNTIFS($B$5:$B$750,B12,$D$5:$D$750,WF_END_PERIOD)>0),INDEX($E$5:$E$750,MATCH(B12&"|"&WF_END_PERIOD,$AC$5:$AC$750,0)),"") | W12: =COUNTIFS($B$5:$B$750,B12,$D$5:$D$750,WF_START_PERIOD,$R$5:$R$750,TRUE())>0 -> TRUE | X12: =COUNTIFS($B$5:$B$750,B12,$D$5:$D$750,WF_END_PERIOD,$R$5:$R$750,TRUE())>0 -> TRUE | Y12: =IF(AND(D12=WF_END_PERIOD,COUNTIFS($B$5:$B$750,B12,$D$5:$D$750,WF_START_PERIOD)>0),INDEX($E$5:$E$750,MATCH(B12&"|"&WF_START_PERIOD,$AC$5:$AC$750,0)),"") | Z12: =IF(AND(D12=WF_END_PERIOD,R12),1+COUNTIFS($D$5:$D$750,WF_END_PERIOD,$E$5:$E$750,E12,$R$5:$R$750,TRUE(),$S$5:$S$750,">"&S12)+COUNTIFS($D$5:$D$750,WF_END_PERIOD,$E$5:$E$750,E12,$R$5:$R$750,TRUE(),$S$5:$S$750,S12,$B$5:$B$750,"<"&B12),"") | AA12: =IF(AND(D12=WF_END_PERIOD,R12,Z12<>1),1+COUNTIFS($D$5:$D$750,WF_END_PERIOD,$R$5:$R$750,TRUE(),$Z$5:$Z$750,"<>1",$S$5:$S$750,">"&S12)+COUNTIFS($D$5:$D$750,WF_END_PERIOD,$R$5:$R$750,TRUE(),$Z$5:$Z$750,"<>1",$S$5:$S$750,S12,$B$5:$B$750,"<"&B12),"") | AB12: =OR(D12=WF_START_PERIOD,D12=WF_END_PERIOD) -> FALSE | AC12: =B12&"|"&D12 -> 14168|20220331
A13: =RawFinancials!A13 -> 10 | B13: =RawFinancials!C13 -> 14240 | C13: =RawFinancials!P13 -> NORTHWAY BANK | D13: =RawFinancials!W13 -> 20220331 | E13: =RawFinancials!Z13 -> NH | F13: =RawFinancials!B13 -> 1221074 | G13: =RawFinancials!U13 -> 0 | H13: =RawFinancials!O13 -> 2204 | I13: =IF(AND(ISNUMBER(G13),ISNUMBER(H13)),G13+H13,"") -> 2204 | J13: =RawFinancials!D13 -> 1020645 | K13: =RawFinancials!F13 -> 102113 | L13: =RawFinancials!L13 -> 824670 | M13: =RawFinancials!N13 -> 705835 | N13: =RawFinancials!X13 -> 0.069811881 | O13: =RawFinancials!V13 -> 15.106992 | P13: =IF(AND(ISNUMBER(L13),L13<>0,ISNUMBER(M13)),100*M13/L13,"") -> 85.589994 | Q13: =IF(AND(ISNUMBER(F13),F13<>0,ISNUMBER(K13)),100*K13/F13,"") -> 8.3625562 | R13: =AND(ISNUMBER(F13),F13>0,ISNUMBER(G13),G13>=0,ISNUMBER(H13),H13>=0) -> TRUE | S13: =IF(R13,100*I13/F13,"") -> 0.18049684 | T13: =NOT(AND(OR(AND(ISBLANK(RawFinancials!B13),ISBLANK(_RawBaseline!B10)),AND(ISNUMBER(RawFinancials!B13),ISNUMBER(_RawBaseline!B10),RawFinancials!B13=_RawBaseline!B10)),OR(AND(ISBLANK(RawFinancials!U13),ISBLANK(_RawBaseline!U10)),AND(ISNUMBER(RawFinancials!U13),ISNUMBER(_RawBaseline!U10),RawFinancials!U13=_RawBaseline!U10)),OR(AND(ISBLANK(RawFinancials!O13),ISBLANK(_RawBaseline!O10)),AND(ISNUMBER(RawFinancials!O13),ISNUMBER(_RawBaseline!O10),RawFinancials!O13=_RawBaseline!O10)))) -> FALSE | U13: =IF(AND(D13=WF_START_PERIOD,R13,COUNTIFS($B$5:$B$750,B13,$D$5:$D$750,WF_END_PERIOD,$R$5:$R$750,TRUE())>0),SUMIFS($S$5:$S$750,$B$5:$B$750,B13,$D$5:$D$750,WF_END_PERIOD,$R$5:$R$750,TRUE()),0) -> 0 | V13: =IF(AND(D13=WF_START_PERIOD,COUNTIFS($B$5:$B$750,B13,$D$5:$D$750,WF_END_PERIOD)>0),INDEX($E$5:$E$750,MATCH(B13&"|"&WF_END_PERIOD,$AC$5:$AC$750,0)),"") | W13: =COUNTIFS($B$5:$B$750,B13,$D$5:$D$750,WF_START_PERIOD,$R$5:$R$750,TRUE())>0 -> TRUE | X13: =COUNTIFS($B$5:$B$750,B13,$D$5:$D$750,WF_END_PERIOD,$R$5:$R$750,TRUE())>0 -> FALSE | Y13: =IF(AND(D13=WF_END_PERIOD,COUNTIFS($B$5:$B$750,B13,$D$5:$D$750,WF_START_PERIOD)>0),INDEX($E$5:$E$750,MATCH(B13&"|"&WF_START_PERIOD,$AC$5:$AC$750,0)),"") | Z13: =IF(AND(D13=WF_END_PERIOD,R13),1+COUNTIFS($D$5:$D$750,WF_END_PERIOD,$E$5:$E$750,E13,$R$5:$R$750,TRUE(),$S$5:$S$750,">"&S13)+COUNTIFS($D$5:$D$750,WF_END_PERIOD,$E$5:$E$750,E13,$R$5:$R$750,TRUE(),$S$5:$S$750,S13,$B$5:$B$750,"<"&B13),"") | AA13: =IF(AND(D13=WF_END_PERIOD,R13,Z13<>1),1+COUNTIFS($D$5:$D$750,WF_END_PERIOD,$R$5:$R$750,TRUE(),$Z$5:$Z$750,"<>1",$S$5:$S$750,">"&S13)+COUNTIFS($D$5:$D$750,WF_END_PERIOD,$R$5:$R$750,TRUE(),$Z$5:$Z$750,"<>1",$S$5:$S$750,S13,$B$5:$B$750,"<"&B13),"") | AB13: =OR(D13=WF_START_PERIOD,D13=WF_END_PERIOD) -> FALSE | AC13: =B13&"|"&D13 -> 14240|20220331
A14: =RawFinancials!A14 -> 11 | B14: =RawFinancials!C14 -> 17115 | C14: =RawFinancials!P14 -> PARTNERS BANK OF NEW ENGLAND | D14: =RawFinancials!W14 -> 20220331 | E14: =RawFinancials!Z14 -> ME | F14: =RawFinancials!B14 -> 836644 | G14: =RawFinancials!U14 -> 0 | H14: =RawFinancials!O14 -> 164 | I14: =IF(AND(ISNUMBER(G14),ISNUMBER(H14)),G14+H14,"") -> 164 | J14: =RawFinancials!D14 -> 738943 | K14: =RawFinancials!F14 -> 83239 | L14: =RawFinancials!L14 -> 656481 | M14: =RawFinancials!N14 -> 608827 | N14: =RawFinancials!X14 -> 1.1149693 | O14: =RawFinancials!V14 -> 15.606469 | P14: =IF(AND(ISNUMBER(L14),L14<>0,ISNUMBER(M14)),100*M14/L14,"") -> 92.740993 | Q14: =IF(AND(ISNUMBER(F14),F14<>0,ISNUMBER(K14)),100*K14/F14,"") -> 9.949154 | R14: =AND(ISNUMBER(F14),F14>0,ISNUMBER(G14),G14>=0,ISNUMBER(H14),H14>=0) -> TRUE | S14: =IF(R14,100*I14/F14,"") -> 0.019602125 | T14: =NOT(AND(OR(AND(ISBLANK(RawFinancials!B14),ISBLANK(_RawBaseline!B11)),AND(ISNUMBER(RawFinancials!B14),ISNUMBER(_RawBaseline!B11),RawFinancials!B14=_RawBaseline!B11)),OR(AND(ISBLANK(RawFinancials!U14),ISBLANK(_RawBaseline!U11)),AND(ISNUMBER(RawFinancials!U14),ISNUMBER(_RawBaseline!U11),RawFinancials!U14=_RawBaseline!U11)),OR(AND(ISBLANK(RawFinancials!O14),ISBLANK(_RawBaseline!O11)),AND(ISNUMBER(RawFinancials!O14),ISNUMBER(_RawBaseline!O11),RawFinancials!O14=_RawBaseline!O11)))) -> FALSE | U14: =IF(AND(D14=WF_START_PERIOD,R14,COUNTIFS($B$5:$B$750,B14,$D$5:$D$750,WF_END_PERIOD,$R$5:$R$750,TRUE())>0),SUMIFS($S$5:$S$750,$B$5:$B$750,B14,$D$5:$D$750,WF_END_PERIOD,$R$5:$R$750,TRUE()),0) -> 0 | V14: =IF(AND(D14=WF_START_PERIOD,COUNTIFS($B$5:$B$750,B14,$D$5:$D$750,WF_END_PERIOD)>0),INDEX($E$5:$E$750,MATCH(B14&"|"&WF_END_PERIOD,$AC$5:$AC$750,0)),"") | W14: =COUNTIFS($B$5:$B$750,B14,$D$5:$D$750,WF_START_PERIOD,$R$5:$R$750,TRUE())>0 -> TRUE | X14: =COUNTIFS($B$5:$B$750,B14,$D$5:$D$750,WF_END_PERIOD,$R$5:$R$750,TRUE())>0 -> TRUE | Y14: =IF(AND(D14=WF_END_PERIOD,COUNTIFS($B$5:$B$750,B14,$D$5:$D$750,WF_START_PERIOD)>0),INDEX($E$5:$E$750,MATCH(B14&"|"&WF_START_PERIOD,$AC$5:$AC$750,0)),"") | Z14: =IF(AND(D14=WF_END_PERIOD,R14),1+COUNTIFS($D$5:$D$750,WF_END_PERIOD,$E$5:$E$750,E14,$R$5:$R$750,TRUE(),$S$5:$S$750,">"&S14)+COUNTIFS($D$5:$D$750,WF_END_PERIOD,$E$5:$E$750,E14,$R$5:$R$750,TRUE(),$S$5:$S$750,S14,$B$5:$B$750,"<"&B14),"") | AA14: =IF(AND(D14=WF_END_PERIOD,R14,Z14<>1),1+COUNTIFS($D$5:$D$750,WF_END_PERIOD,$R$5:$R$750,TRUE(),$Z$5:$Z$750,"<>1",$S$5:$S$750,">"&S14)+COUNTIFS($D$5:$D$750,WF_END_PERIOD,$R$5:$R$750,TRUE(),$Z$5:$Z$750,"<>1",$S$5:$S$750,S14,$B$5:$B$750,"<"&B14),"") | AB14: =OR(D14=WF_START_PERIOD,D14=WF_END_PERIOD) -> FALSE | AC14: =B14&"|"&D14 -> 17115|20220331
A15: =RawFinancials!A15 -> 12 | B15: =RawFinancials!C15 -> 17180 | C15: =RawFinancials!P15 -> MEREDITH VILLAGE SAVINGS BANK | D15: =RawFinancials!W15 -> 20220331 | E15: =RawFinancials!Z15 -> NH | F15: =RawFinancials!B15 -> 1291920 | G15: =RawFinancials!U15 -> 0 | H15: =RawFinancials!O15 -> 5753 | I15: =IF(AND(ISNUMBER(G15),ISNUMBER(H15)),G15+H15,"") -> 5753 | J15: =RawFinancials!D15 -> 1121172 | K15: =RawFinancials!F15 -> 126979 | L15: =RawFinancials!L15 -> 1143017 | M15: =RawFinancials!N15 -> 937482 | N15: =RawFinancials!X15 -> 0.80278929 | O15: =RawFinancials!V15 -> 16.056943 | P15: =IF(AND(ISNUMBER(L15),L15<>0,ISNUMBER(M15)),100*M15/L15,"") -> 82.018203 | Q15: =IF(AND(ISNUMBER(F15),F15<>0,ISNUMBER(K15)),100*K15/F15,"") -> 9.8287046 | R15: =AND(ISNUMBER(F15),F15>0,ISNUMBER(G15),G15>=0,ISNUMBER(H15),H15>=0) -> TRUE | S15: =IF(R15,100*I15/F15,"") -> 0.44530621 | T15: =NOT(AND(OR(AND(ISBLANK(RawFinancials!B15),ISBLANK(_RawBaseline!B12)),AND(ISNUMBER(RawFinancials!B15),ISNUMBER(_RawBaseline!B12),RawFinancials!B15=_RawBaseline!B12)),OR(AND(ISBLANK(RawFinancials!U15),ISBLANK(_RawBaseline!U12)),AND(ISNUMBER(RawFinancials!U15),ISNUMBER(_RawBaseline!U12),RawFinancials!U15=_RawBaseline!U12)),OR(AND(ISBLANK(RawFinancials!O15),ISBLANK(_RawBaseline!O12)),AND(ISNUMBER(RawFinancials!O15),ISNUMBER(_RawBaseline!O12),RawFinancials!O15=_RawBaseline!O12)))) -> FALSE | U15: =IF(AND(D15=WF_START_PERIOD,R15,COUNTIFS($B$5:$B$750,B15,$D$5:$D$750,WF_END_PERIOD,$R$5:$R$750,TRUE())>0),SUMIFS($S$5:$S$750,$B$5:$B$750,B15,$D$5:$D$750,WF_END_PERIOD,$R$5:$R$750,TRUE()),0) -> 0 | V15: =IF(AND(D15=WF_START_PERIOD,COUNTIFS($B$5:$B$750,B15,$D$5:$D$750,WF_END_PERIOD)>0),INDEX($E$5:$E$750,MATCH(B15&"|"&WF_END_PERIOD,$AC$5:$AC$750,0)),"") | W15: =COUNTIFS($B$5:$B$750,B15,$D$5:$D$750,WF_START_PERIOD,$R$5:$R$750,TRUE())>0 -> TRUE | X15: =COUNTIFS($B$5:$B$750,B15,$D$5:$D$750,WF_END_PERIOD,$R$5:$R$750,TRUE())>0 -> TRUE | Y15: =IF(AND(D15=WF_END_PERIOD,COUNTIFS($B$5:$B$750,B15,$D$5:$D$750,WF_START_PERIOD)>0),INDEX($E$5:$E$750,MATCH(B15&"|"&WF_START_PERIOD,$AC$5:$AC$750,0)),"") | Z15: =IF(AND(D15=WF_END_PERIOD,R15),1+COUNTIFS($D$5:$D$750,WF_END_PERIOD,$E$5:$E$750,E15,$R$5:$R$750,TRUE(),$S$5:$S$750,">"&S15)+COUNTIFS($D$5:$D$750,WF_END_PERIOD,$E$5:$E$750,E15,$R$5:$R$750,TRUE(),$S$5:$S$750,S15,$B$5:$B$750,"<"&B15),"") | AA15: =IF(AND(D15=WF_END_PERIOD,R15,Z15<>1),1+COUNTIFS($D$5:$D$750,WF_END_PERIOD,$R$5:$R$750,TRUE(),$Z$5:$Z$750,"<>1",$S$5:$S$750,">"&S15)+COUNTIFS($D$5:$D$750,WF_END_PERIOD,$R$5:$R$750,TRUE(),$Z$5:$Z$750,"<>1",$S$5:$S$750,S15,$B$5:$B$750,"<"&B15),"") | AB15: =OR(D15=WF_START_PERIOD,D15=WF_END_PERIOD) -> FALSE | AC15: =B15&"|"&D15 -> 17180|20220331
A16: =RawFinancials!A16 -> 13 | B16: =RawFinancials!C16 -> 17443 | C16: =RawFinancials!P16 -> PISCATAQUA SAVINGS BANK | D16: =RawFinancials!W16 -> 20220331 | E16: =RawFinancials!Z16 -> NH | F16: =RawFinancials!B16 -> 352255 | G16: =RawFinancials!U16 -> 0 | H16: =RawFinancials!O16 -> 842 | I16: =IF(AND(ISNUMBER(G16),ISNUMBER(H16)),G16+H16,"") -> 842 | J16: =RawFinancials!D16 -> 302135 | K16: =RawFinancials!F16 -> 42822 | L16: =RawFinancials!L16 -> 188952 | M16: =RawFinancials!N16 -> 186037 | N16: =RawFinancials!X16 -> 0.61925341 | O16: =RawFinancials!V16 -> 0 | P16: =IF(AND(ISNUMBER(L16),L16<>0,ISNUMBER(M16)),100*M16/L16,"") -> 98.45728 | Q16: =IF(AND(ISNUMBER(F16),F16<>0,ISNUMBER(K16)),100*K16/F16,"") -> 12.156534 | R16: =AND(ISNUMBER(F16),F16>0,ISNUMBER(G16),G16>=0,ISNUMBER(H16),H16>=0) -> TRUE | S16: =IF(R16,100*I16/F16,"") -> 0.23903138 | T16: =NOT(AND(OR(AND(ISBLANK(RawFinancials!B16),ISBLANK(_RawBaseline!B13)),AND(ISNUMBER(RawFinancials!B16),ISNUMBER(_RawBaseline!B13),RawFinancials!B16=_RawBaseline!B13)),OR(AND(ISBLANK(RawFinancials!U16),ISBLANK(_RawBaseline!U13)),AND(ISNUMBER(RawFinancials!U16),ISNUMBER(_RawBaseline!U13),RawFinancials!U16=_RawBaseline!U13)),OR(AND(ISBLANK(RawFinancials!O16),ISBLANK(_RawBaseline!O13)),AND(ISNUMBER(RawFinancials!O16),ISNUMBER(_RawBaseline!O13),RawFinancials!O16=_RawBaseline!O13)))) -> FALSE | U16: =IF(AND(D16=WF_START_PERIOD,R16,COUNTIFS($B$5:$B$750,B16,$D$5:$D$750,WF_END_PERIOD,$R$5:$R$750,TRUE())>0),SUMIFS($S$5:$S$750,$B$5:$B$750,B16,$D$5:$D$750,WF_END_PERIOD,$R$5:$R$750,TRUE()),0) -> 0 | V16: =IF(AND(D16=WF_START_PERIOD,COUNTIFS($B$5:$B$750,B16,$D$5:$D$750,WF_END_PERIOD)>0),INDEX($E$5:$E$750,MATCH(B16&"|"&WF_END_PERIOD,$AC$5:$AC$750,0)),"") | W16: =COUNTIFS($B$5:$B$750,B16,$D$5:$D$750,WF_START_PERIOD,$R$5:$R$750,TRUE())>0 -> TRUE | X16: =COUNTIFS($B$5:$B$750,B16,$D$5:$D$750,WF_END_PERIOD,$R$5:$R$750,TRUE())>0 -> TRUE | Y16: =IF(AND(D16=WF_END_PERIOD,COUNTIFS($B$5:$B$750,B16,$D$5:$D$750,WF_START_PERIOD)>0),INDEX($E$5:$E$750,MATCH(B16&"|"&WF_START_PERIOD,$AC$5:$AC$750,0)),"") | Z16: =IF(AND(D16=WF_END_PERIOD,R16),1+COUNTIFS($D$5:$D$750,WF_END_PERIOD,$E$5:$E$750,E16,$R$5:$R$750,TRUE(),$S$5:$S$750,">"&S16)+COUNTIFS($D$5:$D$750,WF_END_PERIOD,$E$5:$E$750,E16,$R$5:$R$750,TRUE(),$S$5:$S$750,S16,$B$5:$B$750,"<"&B16),"") | AA16: =IF(AND(D16=WF_END_PERIOD,R16,Z16<>1),1+COUNTIFS($D$5:$D$750,WF_END_PERIOD,$R$5:$R$750,TRUE(),$Z$5:$Z$750,"<>1",$S$5:$S$750,">"&S16)+COUNTIFS($D$5:$D$750,WF_END_PERIOD,$R$5:$R$750,TRUE(),$Z$5:$Z$750,"<>1",$S$5:$S$750,S16,$B$5:$B$750,"<"&B16),"") | AB16: =OR(D16=WF_START_PERIOD,D16=WF_END_PERIOD) -> FALSE | AC16: =B16&"|"&D16 -> 17443|20220331
... A750: =RawFinancials!A750 -> 747 | B750: =RawFinancials!C750 -> 6280 | C750: =RawFinancials!P750 -> THE FIRST NATIONAL BANK OF ORWELL | D750: =RawFinancials!W750 -> 20250630 | E750: =RawFinancials!Z750 -> VT | F750: =RawFinancials!B750 -> 87770 | G750: =RawFinancials!U750 -> 0 | H750: =RawFinancials!O750 -> 1455 | I750: =IF(AND(ISNUMBER(G750),ISNUMBER(H750)),G750+H750,"") -> 1455 | J750: =RawFinancials!D750 -> 77256 | K750: =RawFinancials!F750 -> 9949 | L750: =RawFinancials!L750 -> 73100 | M750: =RawFinancials!N750 -> 64947 | N750: =RawFinancials!X750 -> 1.3665403 | O750: =RawFinancials!V750 -> 0 | P750: =IF(AND(ISNUMBER(L750),L750<>0,ISNUMBER(M750)),100*M750/L750,"") -> 88.846785 | Q750: =IF(AND(ISNUMBER(F750),F750<>0,ISNUMBER(K750)),100*K750/F750,"") -> 11.335308 | R750: =AND(ISNUMBER(F750),F750>0,ISNUMBER(G750),G750>=0,ISNUMBER(H750),H750>=0) -> TRUE | S750: =IF(R750,100*I750/F750,"") -> 1.6577418 | T750: =NOT(AND(OR(AND(ISBLANK(RawFinancials!B750),ISBLANK(_RawBaseline!B747)),AND(ISNUMBER(RawFinancials!B750),ISNUMBER(_RawBaseline!B747),RawFinancials!B750=_RawBaseline!B747)),OR(AND(ISBLANK(RawFinancials!U750),ISBLANK(_RawBaseline!U747)),AND(ISNUMBER(RawFinancials!U750),ISNUMBER(_RawBaseline!U747),RawFinancials!U750=_RawBaseline!U747)),OR(AND(ISBLANK(RawFinancials!O750),ISBLANK(_RawBaseline!O747)),AND(ISNUMBER(RawFinancials!O750),ISNUMBER(_RawBaseline!O747),RawFinancials!O750=_RawBaseline!O747)))) -> FALSE | U750: =IF(AND(D750=WF_START_PERIOD,R750,COUNTIFS($B$5:$B$750,B750,$D$5:$D$750,WF_END_PERIOD,$R$5:$R$750,TRUE())>0),SUMIFS($S$5:$S$750,$B$5:$B$750,B750,$D$5:$D$750,WF_END_PERIOD,$R$5:$R$750,TRUE()),0) -> 0 | V750: =IF(AND(D750=WF_START_PERIOD,COUNTIFS($B$5:$B$750,B750,$D$5:$D$750,WF_END_PERIOD)>0),INDEX($E$5:$E$750,MATCH(B750&"|"&WF_END_PERIOD,$AC$5:$AC$750,0)),"") | W750: =COUNTIFS($B$5:$B$750,B750,$D$5:$D$750,WF_START_PERIOD,$R$5:$R$750,TRUE())>0 -> TRUE | X750: =COUNTIFS($B$5:$B$750,B750,$D$5:$D$750,WF_END_PERIOD,$R$5:$R$750,TRUE())>0 -> TRUE | Y750: =IF(AND(D750=WF_END_PERIOD,COUNTIFS($B$5:$B$750,B750,$D$5:$D$750,WF_START_PERIOD)>0),INDEX($E$5:$E$750,MATCH(B750&"|"&WF_START_PERIOD,$AC$5:$AC$750,0)),"") -> VT | Z750: =IF(AND(D750=WF_END_PERIOD,R750),1+COUNTIFS($D$5:$D$750,WF_END_PERIOD,$E$5:$E$750,E750,$R$5:$R$750,TRUE(),$S$5:$S$750,">"&S750)+COUNTIFS($D$5:$D$750,WF_END_PERIOD,$E$5:$E$750,E750,$R$5:$R$750,TRUE(),$S$5:$S$750,S750,$B$5:$B$750,"<"&B750),"") -> 1 | AA750: =IF(AND(D750=WF_END_PERIOD,R750,Z750<>1),1+COUNTIFS($D$5:$D$750,WF_END_PERIOD,$R$5:$R$750,TRUE(),$Z$5:$Z$750,"<>1",$S$5:$S$750,">"&S750)+COUNTIFS($D$5:$D$750,WF_END_PERIOD,$R$5:$R$750,TRUE(),$Z$5:$Z$750,"<>1",$S$5:$S$750,S750,$B$5:$B$750,"<"&B750),"") | AB750: =OR(D750=WF_START_PERIOD,D750=WF_END_PERIOD) -> TRUE | AC750: =B750&"|"&D750 -> 6280|20250630

Sheet DataAudit
A1: Data Audit
A2: Source shape, key integrity, quarter coverage, institution linkage, and formula-driven invalid-row reporting.
A4: Audit item | B4: Result | C4: Interpretation
A5: Financial source rows | B5: 746 | C5: Required complete local copy
A6: Financial columns | B6: 25 | C6: Original columns; source_row added at left
A7: Distinct CERT | B7: 54 | C7: Across all quarters
A8: Distinct quarters | B8: 14 | C8: 2022-03-31 through 2025-06-30
A9: Duplicate CERT + REPDTE | B9: 0 | C9: Expected 0
A10: Institution rows | B10: 355 | C10: Later snapshot
A11: Duplicate institution CERT | B11: 0 | C11: Expected 0 for one-to-one join
A12: Financial rows matched to institution CERT | B12: 746 | C12: 746 of 746
A13: Unmatched financial CERT | B13: 0 | C13: Expected 0
A14: Unused institution snapshot CERT | B14: 301 | C14: Historical/later universe; not joined into quarter population
A17: Quarter coverage and invalid proxy inputs
A18: REPDTE | B18: Rows | C18: Banks | D18: VT | E18: NH | F18: ME | G18: Missing vs 54-bank union | H18: ASSET blank/zero | I18: P9ASSET blank | J18: NAASSET blank | K18: Invalid proxy rows
A19: 20220331 | B19: =COUNTIF(BankQuarter!$D$5:$D$750,A19) -> 51 | C19: =COUNTIF(BankQuarter!$D$5:$D$750,A19) -> 51 | D19: =COUNTIFS(BankQuarter!$D$5:$D$750,$A19,BankQuarter!$E$5:$E$750,"VT") -> 11 | E19: =COUNTIFS(BankQuarter!$D$5:$D$750,$A19,BankQuarter!$E$5:$E$750,"NH") -> 17 | F19: =COUNTIFS(BankQuarter!$D$5:$D$750,$A19,BankQuarter!$E$5:$E$750,"ME") -> 23 | G19: =54-C19 -> 3 | H19: =COUNTIFS(BankQuarter!$D$5:$D$750,$A19,BankQuarter!$F$5:$F$750,"<=0")+COUNTIFS(BankQuarter!$D$5:$D$750,$A19,BankQuarter!$F$5:$F$750,"") -> 0 | I19: =COUNTIFS(BankQuarter!$D$5:$D$750,$A19,BankQuarter!$G$5:$G$750,"") -> 0 | J19: =COUNTIFS(BankQuarter!$D$5:$D$750,$A19,BankQuarter!$H$5:$H$750,"") -> 0 | K19: =COUNTIFS(BankQuarter!$D$5:$D$750,$A19,BankQuarter!$R$5:$R$750,FALSE()) -> 0
A20: 20220630 | B20: =COUNTIF(BankQuarter!$D$5:$D$750,A20) -> 52 | C20: =COUNTIF(BankQuarter!$D$5:$D$750,A20) -> 52 | D20: =COUNTIFS(BankQuarter!$D$5:$D$750,$A20,BankQuarter!$E$5:$E$750,"VT") -> 11 | E20: =COUNTIFS(BankQuarter!$D$5:$D$750,$A20,BankQuarter!$E$5:$E$750,"NH") -> 18 | F20: =COUNTIFS(BankQuarter!$D$5:$D$750,$A20,BankQuarter!$E$5:$E$750,"ME") -> 23 | G20: =54-C20 -> 2 | H20: =COUNTIFS(BankQuarter!$D$5:$D$750,$A20,BankQuarter!$F$5:$F$750,"<=0")+COUNTIFS(BankQuarter!$D$5:$D$750,$A20,BankQuarter!$F$5:$F$750,"") -> 0 | I20: =COUNTIFS(BankQuarter!$D$5:$D$750,$A20,BankQuarter!$G$5:$G$750,"") -> 0 | J20: =COUNTIFS(BankQuarter!$D$5:$D$750,$A20,BankQuarter!$H$5:$H$750,"") -> 0 | K20: =COUNTIFS(BankQuarter!$D$5:$D$750,$A20,BankQuarter!$R$5:$R$750,FALSE()) -> 0
A21: 20220930 | B21: =COUNTIF(BankQuarter!$D$5:$D$750,A21) -> 53 | C21: =COUNTIF(BankQuarter!$D$5:$D$750,A21) -> 53 | D21: =COUNTIFS(BankQuarter!$D$5:$D$750,$A21,BankQuarter!$E$5:$E$750,"VT") -> 12 | E21: =COUNTIFS(BankQuarter!$D$5:$D$750,$A21,BankQuarter!$E$5:$E$750,"NH") -> 18 | F21: =COUNTIFS(BankQuarter!$D$5:$D$750,$A21,BankQuarter!$E$5:$E$750,"ME") -> 23 | G21: =54-C21 -> 1 | H21: =COUNTIFS(BankQuarter!$D$5:$D$750,$A21,BankQuarter!$F$5:$F$750,"<=0")+COUNTIFS(BankQuarter!$D$5:$D$750,$A21,BankQuarter!$F$5:$F$750,"") -> 0 | I21: =COUNTIFS(BankQuarter!$D$5:$D$750,$A21,BankQuarter!$G$5:$G$750,"") -> 0 | J21: =COUNTIFS(BankQuarter!$D$5:$D$750,$A21,BankQuarter!$H$5:$H$750,"") -> 0 | K21: =COUNTIFS(BankQuarter!$D$5:$D$750,$A21,BankQuarter!$R$5:$R$750,FALSE()) -> 0
A22: 20221231 | B22: =COUNTIF(BankQuarter!$D$5:$D$750,A22) -> 54 | C22: =COUNTIF(BankQuarter!$D$5:$D$750,A22) -> 54 | D22: =COUNTIFS(BankQuarter!$D$5:$D$750,$A22,BankQuarter!$E$5:$E$750,"VT") -> 12 | E22: =COUNTIFS(BankQuarter!$D$5:$D$750,$A22,BankQuarter!$E$5:$E$750,"NH") -> 19 | F22: =COUNTIFS(BankQuarter!$D$5:$D$750,$A22,BankQuarter!$E$5:$E$750,"ME") -> 23 | G22: =54-C22 -> 0 | H22: =COUNTIFS(BankQuarter!$D$5:$D$750,$A22,BankQuarter!$F$5:$F$750,"<=0")+COUNTIFS(BankQuarter!$D$5:$D$750,$A22,BankQuarter!$F$5:$F$750,"") -> 0 | I22: =COUNTIFS(BankQuarter!$D$5:$D$750,$A22,BankQuarter!$G$5:$G$750,"") -> 0 | J22: =COUNTIFS(BankQuarter!$D$5:$D$750,$A22,BankQuarter!$H$5:$H$750,"") -> 0 | K22: =COUNTIFS(BankQuarter!$D$5:$D$750,$A22,BankQuarter!$R$5:$R$750,FALSE()) -> 0
A23: 20230331 | B23: =COUNTIF(BankQuarter!$D$5:$D$750,A23) -> 54 | C23: =COUNTIF(BankQuarter!$D$5:$D$750,A23) -> 54 | D23: =COUNTIFS(BankQuarter!$D$5:$D$750,$A23,BankQuarter!$E$5:$E$750,"VT") -> 12 | E23: =COUNTIFS(BankQuarter!$D$5:$D$750,$A23,BankQuarter!$E$5:$E$750,"NH") -> 19 | F23: =COUNTIFS(BankQuarter!$D$5:$D$750,$A23,BankQuarter!$E$5:$E$750,"ME") -> 23 | G23: =54-C23 -> 0 | H23: =COUNTIFS(BankQuarter!$D$5:$D$750,$A23,BankQuarter!$F$5:$F$750,"<=0")+COUNTIFS(BankQuarter!$D$5:$D$750,$A23,BankQuarter!$F$5:$F$750,"") -> 0 | I23: =COUNTIFS(BankQuarter!$D$5:$D$750,$A23,BankQuarter!$G$5:$G$750,"") -> 0 | J23: =COUNTIFS(BankQuarter!$D$5:$D$750,$A23,BankQuarter!$H$5:$H$750,"") -> 0 | K23: =COUNTIFS(BankQuarter!$D$5:$D$750,$A23,BankQuarter!$R$5:$R$750,FALSE()) -> 0
A24: 20230630 | B24: =COUNTIF(BankQuarter!$D$5:$D$750,A24) -> 54 | C24: =COUNTIF(BankQuarter!$D$5:$D$750,A24) -> 54 | D24: =COUNTIFS(BankQuarter!$D$5:$D$750,$A24,BankQuarter!$E$5:$E$750,"VT") -> 12 | E24: =COUNTIFS(BankQuarter!$D$5:$D$750,$A24,BankQuarter!$E$5:$E$750,"NH") -> 19 | F24: =COUNTIFS(BankQuarter!$D$5:$D$750,$A24,BankQuarter!$E$5:$E$750,"ME") -> 23 | G24: =54-C24 -> 0 | H24: =COUNTIFS(BankQuarter!$D$5:$D$750,$A24,BankQuarter!$F$5:$F$750,"<=0")+COUNTIFS(BankQuarter!$D$5:$D$750,$A24,BankQuarter!$F$5:$F$750,"") -> 0 | I24: =COUNTIFS(BankQuarter!$D$5:$D$750,$A24,BankQuarter!$G$5:$G$750,"") -> 0 | J24: =COUNTIFS(BankQuarter!$D$5:$D$750,$A24,BankQuarter!$H$5:$H$750,"") -> 0 | K24: =COUNTIFS(BankQuarter!$D$5:$D$750,$A24,BankQuarter!$R$5:$R$750,FALSE()) -> 0
