Workbook

Sheet Options
A1: 集中培训会务方案比较｜FY2027
A2: 修改黄色参数后，Options/Daily自动回算；Word/PPT/CSV为2026-10-23快照，参数变化后必须重新核对并导出。待询价项目未计入，任何“预算内”仅指已知费用。
A4: 可调整参数 | D4: 参数约束 | V4: 城市 | W4: 票价 | X4: 酒店报价 | Y4: MIE | Z4: 当地RT | AA4: 11/28上限 | AB4: 11/29上限 | AC4: 11/30上限 | AD4: 12/1上限
A5: 批准预算上限 | B5: 53000 | D5: $0–$100,000（含储备） | V5: Chicago | W5: 271 | X5: 126 | Y5: 92 | Z5: 10 | AA5: 232 | AB5: 232 | AC5: 232 | AD5: 148
A6: 票价调整系数 | B6: 1 | D6: 0.5–2；压力情景在调整后再×1.20 | V6: Denver | W6: 466 | X6: 75 | Y6: 92 | Z6: 20 | AA6: 170 | AB6: 170 | AC6: 170 | AD6: 170
A7: 应急储备比例 | B7: 0.05 | D7: 0–20%；基础费用小计 | V7: Phoenix | W7: 581 | X7: 93 | Y7: 86 | Z7: 4 | AA7: 165 | AB7: 165 | AC7: 165 | AD7: 165
A8: 11月29日政府提供早餐 | B8: 否 | D8: 是/否；“是”不新增采购费用但扣早餐M&IE | V8: Boston | W8: 330 | X8: 202 | Y8: 92 | Z8: 5 | AA8: 213 | AB8: 213 | AC8: 213 | AD8: 213
A9: 抵达日期 | B9: 46354 | D9: 不得晚于2026-11-29；预算按实际住宿夜数回算 | V9: Seattle | W9: 977 | X9: 170 | Y9: 92 | Z9: 6 | AA9: 188 | AB9: 188 | AC9: 188 | AD9: 188
A10: 返程日期 | B10: 46358 | D10: 不得早于2026-12-02；预算按实际住宿夜数回算
A13: 城市 | B13: 人数 | C13: 调整后机票 | D13: 住宿含12%税 | E13: M&IE净额 | F13: 注册费 | G13: 机构供餐 | H13: 总部↔DCA | I13: 当地交通 | J13: 场地/茶歇 | K13: 基础已知小计 | L13: 应急储备 | M13: 已知含储备 | N13: 场地等可用余额 | O13: 已知费用判定 | P13: 证据完整性 | Q13: 压力含储备 | R13: 压力判定 | S13: 排序 | T13: 临时结论
A14: Chicago | B14: 18 | C14: =$B14*$B$6*$W$5 | D14: =$B14*1.12*MAX(0,$B$10-$B$9)*$X$5 | E14: =$B14*(234.0-IF($B$8="是",23,0)+MAX(0,$B$10-$B$9-4)*92) | F14: =$B14*180 | G14: =$B14*102 | H14: =$B14*12 | I14: =$B14*$Z$5 | J14: 0 | K14: =SUM(C14:J14) | L14: =K14*$B$7 | M14: =K14+L14 | N14: =MAX(0,$B$5-M14) | O14: =IF(M14<=$B$5,"已知费用内","超预算") | P14: 待询价—阻断 | Q14: =(K14+C14*20%)*(1+$B$7) | R14: =IF(Q14<=$B$5,"压力已知费用内","压力超预算") | S14: =IF(O14="超预算",999999,(24-B14)*1000000+M14+COUNTIF($A$14:A14,A14)/1000) | T14: =IF(AND(B14=MAXIFS($B$14:$B$23,$O$14:$O$23,"已知费用内"),S14=MINIFS($S$14:$S$23,$B$14:$B$23,B14,$O$14:$O$23,"已知费用内")),"临时推荐*",IF(O14="已知费用内","备选*","排除"))
A15: Chicago | B15: 24 | C15: =$B15*$B$6*$W$5 | D15: =$B15*1.12*MAX(0,$B$10-$B$9)*$X$5 | E15: =$B15*(234.0-IF($B$8="是",23,0)+MAX(0,$B$10-$B$9-4)*92) | F15: =$B15*180 | G15: =$B15*102 | H15: =$B15*12 | I15: =$B15*$Z$5 | J15: 0 | K15: =SUM(C15:J15) | L15: =K15*$B$7 | M15: =K15+L15 | N15: =MAX(0,$B$5-M15) | O15: =IF(M15<=$B$5,"已知费用内","超预算") | P15: 待询价—阻断 | Q15: =(K15+C15*20%)*(1+$B$7) | R15: =IF(Q15<=$B$5,"压力已知费用内","压力超预算") | S15: =IF(O15="超预算",999999,(24-B15)*1000000+M15+COUNTIF($A$14:A15,A15)/1000) | T15: =IF(AND(B15=MAXIFS($B$14:$B$23,$O$14:$O$23,"已知费用内"),S15=MINIFS($S$14:$S$23,$B$14:$B$23,B15,$O$14:$O$23,"已知费用内")),"临时推荐*",IF(O15="已知费用内","备选*","排除"))
A16: Denver | B16: 18 | C16: =$B16*$B$6*$W$6 | D16: =$B16*1.12*MAX(0,$B$10-$B$9)*$X$6 | E16: =$B16*(234.0-IF($B$8="是",23,0)+MAX(0,$B$10-$B$9-4)*92) | F16: =$B16*180 | G16: =$B16*102 | H16: =$B16*12 | I16: =$B16*$Z$6 | J16: 0 | K16: =SUM(C16:J16) | L16: =K16*$B$7 | M16: =K16+L16 | N16: =MAX(0,$B$5-M16) | O16: =IF(M16<=$B$5,"已知费用内","超预算") | P16: 待询价—阻断 | Q16: =(K16+C16*20%)*(1+$B$7) | R16: =IF(Q16<=$B$5,"压力已知费用内","压力超预算") | S16: =IF(O16="超预算",999999,(24-B16)*1000000+M16+COUNTIF($A$14:A16,A16)/1000) | T16: =IF(AND(B16=MAXIFS($B$14:$B$23,$O$14:$O$23,"已知费用内"),S16=MINIFS($S$14:$S$23,$B$14:$B$23,B16,$O$14:$O$23,"已知费用内")),"临时推荐*",IF(O16="已知费用内","备选*","排除"))
A17: Denver | B17: 24 | C17: =$B17*$B$6*$W$6 | D17: =$B17*1.12*MAX(0,$B$10-$B$9)*$X$6 | E17: =$B17*(234.0-IF($B$8="是",23,0)+MAX(0,$B$10-$B$9-4)*92) | F17: =$B17*180 | G17: =$B17*102 | H17: =$B17*12 | I17: =$B17*$Z$6 | J17: 0 | K17: =SUM(C17:J17) | L17: =K17*$B$7 | M17: =K17+L17 | N17: =MAX(0,$B$5-M17) | O17: =IF(M17<=$B$5,"已知费用内","超预算") | P17: 待询价—阻断 | Q17: =(K17+C17*20%)*(1+$B$7) | R17: =IF(Q17<=$B$5,"压力已知费用内","压力超预算") | S17: =IF(O17="超预算",999999,(24-B17)*1000000+M17+COUNTIF($A$14:A17,A17)/1000) | T17: =IF(AND(B17=MAXIFS($B$14:$B$23,$O$14:$O$23,"已知费用内"),S17=MINIFS($S$14:$S$23,$B$14:$B$23,B17,$O$14:$O$23,"已知费用内")),"临时推荐*",IF(O17="已知费用内","备选*","排除"))
A18: Phoenix | B18: 18 | C18: =$B18*$B$6*$W$7 | D18: =$B18*1.12*MAX(0,$B$10-$B$9)*$X$7 | E18: =$B18*(223.0-IF($B$8="是",22,0)+MAX(0,$B$10-$B$9-4)*86) | F18: =$B18*180 | G18: =$B18*95 | H18: =$B18*12 | I18: =$B18*$Z$7 | J18: 0 | K18: =SUM(C18:J18) | L18: =K18*$B$7 | M18: =K18+L18 | N18: =MAX(0,$B$5-M18) | O18: =IF(M18<=$B$5,"已知费用内","超预算") | P18: 待询价—阻断 | Q18: =(K18+C18*20%)*(1+$B$7) | R18: =IF(Q18<=$B$5,"压力已知费用内","压力超预算") | S18: =IF(O18="超预算",999999,(24-B18)*1000000+M18+COUNTIF($A$14:A18,A18)/1000) | T18: =IF(AND(B18=MAXIFS($B$14:$B$23,$O$14:$O$23,"已知费用内"),S18=MINIFS($S$14:$S$23,$B$14:$B$23,B18,$O$14:$O$23,"已知费用内")),"临时推荐*",IF(O18="已知费用内","备选*","排除"))
A19: Phoenix | B19: 24 | C19: =$B19*$B$6*$W$7 | D19: =$B19*1.12*MAX(0,$B$10-$B$9)*$X$7 | E19: =$B19*(223.0-IF($B$8="是",22,0)+MAX(0,$B$10-$B$9-4)*86) | F19: =$B19*180 | G19: =$B19*95 | H19: =$B19*12 | I19: =$B19*$Z$7 | J19: 0 | K19: =SUM(C19:J19) | L19: =K19*$B$7 | M19: =K19+L19 | N19: =MAX(0,$B$5-M19) | O19: =IF(M19<=$B$5,"已知费用内","超预算") | P19: 待询价—阻断 | Q19: =(K19+C19*20%)*(1+$B$7) | R19: =IF(Q19<=$B$5,"压力已知费用内","压力超预算") | S19: =IF(O19="超预算",999999,(24-B19)*1000000+M19+COUNTIF($A$14:A19,A19)/1000) | T19: =IF(AND(B19=MAXIFS($B$14:$B$23,$O$14:$O$23,"已知费用内"),S19=MINIFS($S$14:$S$23,$B$14:$B$23,B19,$O$14:$O$23,"已知费用内")),"临时推荐*",IF(O19="已知费用内","备选*","排除"))
A20: Boston | B20: 18 | C20: =$B20*$B$6*$W$8 | D20: =$B20*1.12*MAX(0,$B$10-$B$9)*$X$8 | E20: =$B20*(234.0-IF($B$8="是",23,0)+MAX(0,$B$10-$B$9-4)*92) | F20: =$B20*180 | G20: =$B20*102 | H20: =$B20*12 | I20: =$B20*$Z$8 | J20: 0 | K20: =SUM(C20:J20) | L20: =K20*$B$7 | M20: =K20+L20 | N20: =MAX(0,$B$5-M20) | O20: =IF(M20<=$B$5,"已知费用内","超预算") | P20: 待询价—阻断 | Q20: =(K20+C20*20%)*(1+$B$7) | R20: =IF(Q20<=$B$5,"压力已知费用内","压力超预算") | S20: =IF(O20="超预算",999999,(24-B20)*1000000+M20+COUNTIF($A$14:A20,A20)/1000) | T20: =IF(AND(B20=MAXIFS($B$14:$B$23,$O$14:$O$23,"已知费用内"),S20=MINIFS($S$14:$S$23,$B$14:$B$23,B20,$O$14:$O$23,"已知费用内")),"临时推荐*",IF(O20="已知费用内","备选*","排除"))
A21: Boston | B21: 24 | C21: =$B21*$B$6*$W$8 | D21: =$B21*1.12*MAX(0,$B$10-$B$9)*$X$8 | E21: =$B21*(234.0-IF($B$8="是",23,0)+MAX(0,$B$10-$B$9-4)*92) | F21: =$B21*180 | G21: =$B21*102 | H21: =$B21*12 | I21: =$B21*$Z$8 | J21: 0 | K21: =SUM(C21:J21) | L21: =K21*$B$7 | M21: =K21+L21 | N21: =MAX(0,$B$5-M21) | O21: =IF(M21<=$B$5,"已知费用内","超预算") | P21: 待询价—阻断 | Q21: =(K21+C21*20%)*(1+$B$7) | R21: =IF(Q21<=$B$5,"压力已知费用内","压力超预算") | S21: =IF(O21="超预算",999999,(24-B21)*1000000+M21+COUNTIF($A$14:A21,A21)/1000) | T21: =IF(AND(B21=MAXIFS($B$14:$B$23,$O$14:$O$23,"已知费用内"),S21=MINIFS($S$14:$S$23,$B$14:$B$23,B21,$O$14:$O$23,"已知费用内")),"临时推荐*",IF(O21="已知费用内","备选*","排除"))
A22: Seattle | B22: 18 | C22: =$B22*$B$6*$W$9 | D22: =$B22*1.12*MAX(0,$B$10-$B$9)*$X$9 | E22: =$B22*(234.0-IF($B$8="是",23,0)+MAX(0,$B$10-$B$9-4)*92) | F22: =$B22*180 | G22: =$B22*102 | H22: =$B22*12 | I22: =$B22*$Z$9 | J22: 0 | K22: =SUM(C22:J22) | L22: =K22*$B$7 | M22: =K22+L22 | N22: =MAX(0,$B$5-M22) | O22: =IF(M22<=$B$5,"已知费用内","超预算") | P22: 待询价—阻断 | Q22: =(K22+C22*20%)*(1+$B$7) | R22: =IF(Q22<=$B$5,"压力已知费用内","压力超预算") | S22: =IF(O22="超预算",999999,(24-B22)*1000000+M22+COUNTIF($A$14:A22,A22)/1000) | T22: =IF(AND(B22=MAXIFS($B$14:$B$23,$O$14:$O$23,"已知费用内"),S22=MINIFS($S$14:$S$23,$B$14:$B$23,B22,$O$14:$O$23,"已知费用内")),"临时推荐*",IF(O22="已知费用内","备选*","排除"))
A23: Seattle | B23: 24 | C23: =$B23*$B$6*$W$9 | D23: =$B23*1.12*MAX(0,$B$10-$B$9)*$X$9 | E23: =$B23*(234.0-IF($B$8="是",23,0)+MAX(0,$B$10-$B$9-4)*92) | F23: =$B23*180 | G23: =$B23*102 | H23: =$B23*12 | I23: =$B23*$Z$9 | J23: 0 | K23: =SUM(C23:J23) | L23: =K23*$B$7 | M23: =K23+L23 | N23: =MAX(0,$B$5-M23) | O23: =IF(M23<=$B$5,"已知费用内","超预算") | P23: 待询价—阻断 | Q23: =(K23+C23*20%)*(1+$B$7) | R23: =IF(Q23<=$B$5,"压力已知费用内","压力超预算") | S23: =IF(O23="超预算",999999,(24-B23)*1000000+M23+COUNTIF($A$14:A23,A23)/1000) | T23: =IF(AND(B23=MAXIFS($B$14:$B$23,$O$14:$O$23,"已知费用内"),S23=MINIFS($S$14:$S$23,$B$14:$B$23,B23,$O$14:$O$23,"已知费用内")),"临时推荐*",IF(O23="已知费用内","备选*","排除"))
A25: * 临时推荐只按已知费用执行题面排序；场地、茶歇、机构供餐正式报价、团体房量/早餐、资质、采购与资金均未完成，最终批准被阻断。场地等报价必须不超过“可用余额”（并考虑储备）后方可维持预算内。

Sheet Daily
A1: 逐日预算明细
A2: 修改黄色参数后，Options/Daily自动回算；Word/PPT/CSV为2026-10-23快照，参数变化后必须重新核对并导出。待询价项目未计入，任何“预算内”仅指已知费用。
A4: 城市 | B4: 人数 | C4: 日期 | D4: 日程/餐食 | E4: 机票 | F4: 住宿 | G4: 住宿税12% | H4: M&IE净额 | I4: 注册 | J4: 机构供餐 | K4: 总部↔DCA | L4: 当地交通 | M4: 场地/茶歇 | N4: 当日已知小计
A5: =IF(AND(C5>=Options!$B$9,C5<=Options!$B$10),"Chicago","") | B5: =IF(A5="","",18) | C5: 46296 | D5: =IF(A5="","",IF(C5=DATE(2026,11,29),"培训；注册午餐；早餐参数",IF(C5=DATE(2026,11,30),"培训；注册午餐",IF(C5=DATE(2026,12,1),"培训；注册午餐；机构晚餐",IF(C5=Options!$B$9,"抵达；"&IF(C5=DATE(2026,11,28),"机构晚餐","无统一供餐"),IF(C5=Options!$B$10,"返程；"&IF(C5=DATE(2026,12,2),"机构午餐","无统一供餐"),"差旅状态；无统一日程")))))) | E5: =IF(C5=Options!$B$9,Options!$C$14,0) | F5: =IF(AND(A5<>"",C5<Options!$B$10),B5*Options!$X$5,0) | G5: =F5*12% | H5: =IF(A5="",0,B5*(92*IF(OR(C5=Options!$B$9,C5=Options!$B$10),75%,100%)-IF(C5=DATE(2026,11,29),26+IF(Options!$B$8="是",23,0),0)-IF(C5=DATE(2026,11,30),26,0)-IF(C5=DATE(2026,12,1),64,0)-IF(C5=DATE(2026,11,28),38,0)-IF(C5=DATE(2026,12,2),26,0))) | I5: =IF(AND(C5>=DATE(2026,11,29),C5<=DATE(2026,12,1)),B5*60,0) | J5: =IF(A5="",0,B5*(IF(C5=DATE(2026,11,28),38,0)+IF(C5=DATE(2026,12,1),38,0)+IF(C5=DATE(2026,12,2),26,0))) | K5: =IF(C5=Options!$B$9,B5*12,0) | L5: =IF(C5=Options!$B$9,B5*Options!$Z$5,0) | M5: 0 | N5: =SUM(E5:M5)
A6: =IF(AND(C6>=Options!$B$9,C6<=Options!$B$10),"Chicago","") | B6: =IF(A6="","",18) | C6: 46297 | D6: =IF(A6="","",IF(C6=DATE(2026,11,29),"培训；注册午餐；早餐参数",IF(C6=DATE(2026,11,30),"培训；注册午餐",IF(C6=DATE(2026,12,1),"培训；注册午餐；机构晚餐",IF(C6=Options!$B$9,"抵达；"&IF(C6=DATE(2026,11,28),"机构晚餐","无统一供餐"),IF(C6=Options!$B$10,"返程；"&IF(C6=DATE(2026,12,2),"机构午餐","无统一供餐"),"差旅状态；无统一日程")))))) | E6: =IF(C6=Options!$B$9,Options!$C$14,0) | F6: =IF(AND(A6<>"",C6<Options!$B$10),B6*Options!$X$5,0) | G6: =F6*12% | H6: =IF(A6="",0,B6*(92*IF(OR(C6=Options!$B$9,C6=Options!$B$10),75%,100%)-IF(C6=DATE(2026,11,29),26+IF(Options!$B$8="是",23,0),0)-IF(C6=DATE(2026,11,30),26,0)-IF(C6=DATE(2026,12,1),64,0)-IF(C6=DATE(2026,11,28),38,0)-IF(C6=DATE(2026,12,2),26,0))) | I6: =IF(AND(C6>=DATE(2026,11,29),C6<=DATE(2026,12,1)),B6*60,0) | J6: =IF(A6="",0,B6*(IF(C6=DATE(2026,11,28),38,0)+IF(C6=DATE(2026,12,1),38,0)+IF(C6=DATE(2026,12,2),26,0))) | K6: =IF(C6=Options!$B$9,B6*12,0) | L6: =IF(C6=Options!$B$9,B6*Options!$Z$5,0) | M6: 0 | N6: =SUM(E6:M6)
A7: =IF(AND(C7>=Options!$B$9,C7<=Options!$B$10),"Chicago","") | B7: =IF(A7="","",18) | C7: 46298 | D7: =IF(A7="","",IF(C7=DATE(2026,11,29),"培训；注册午餐；早餐参数",IF(C7=DATE(2026,11,30),"培训；注册午餐",IF(C7=DATE(2026,12,1),"培训；注册午餐；机构晚餐",IF(C7=Options!$B$9,"抵达；"&IF(C7=DATE(2026,11,28),"机构晚餐","无统一供餐"),IF(C7=Options!$B$10,"返程；"&IF(C7=DATE(2026,12,2),"机构午餐","无统一供餐"),"差旅状态；无统一日程")))))) | E7: =IF(C7=Options!$B$9,Options!$C$14,0) | F7: =IF(AND(A7<>"",C7<Options!$B$10),B7*Options!$X$5,0) | G7: =F7*12% | H7: =IF(A7="",0,B7*(92*IF(OR(C7=Options!$B$9,C7=Options!$B$10),75%,100%)-IF(C7=DATE(2026,11,29),26+IF(Options!$B$8="是",23,0),0)-IF(C7=DATE(2026,11,30),26,0)-IF(C7=DATE(2026,12,1),64,0)-IF(C7=DATE(2026,11,28),38,0)-IF(C7=DATE(2026,12,2),26,0))) | I7: =IF(AND(C7>=DATE(2026,11,29),C7<=DATE(2026,12,1)),B7*60,0) | J7: =IF(A7="",0,B7*(IF(C7=DATE(2026,11,28),38,0)+IF(C7=DATE(2026,12,1),38,0)+IF(C7=DATE(2026,12,2),26,0))) | K7: =IF(C7=Options!$B$9,B7*12,0) | L7: =IF(C7=Options!$B$9,B7*Options!$Z$5,0) | M7: 0 | N7: =SUM(E7:M7)
A8: =IF(AND(C8>=Options!$B$9,C8<=Options!$B$10),"Chicago","") | B8: =IF(A8="","",18) | C8: 46299 | D8: =IF(A8="","",IF(C8=DATE(2026,11,29),"培训；注册午餐；早餐参数",IF(C8=DATE(2026,11,30),"培训；注册午餐",IF(C8=DATE(2026,12,1),"培训；注册午餐；机构晚餐",IF(C8=Options!$B$9,"抵达；"&IF(C8=DATE(2026,11,28),"机构晚餐","无统一供餐"),IF(C8=Options!$B$10,"返程；"&IF(C8=DATE(2026,12,2),"机构午餐","无统一供餐"),"差旅状态；无统一日程")))))) | E8: =IF(C8=Options!$B$9,Options!$C$14,0) | F8: =IF(AND(A8<>"",C8<Options!$B$10),B8*Options!$X$5,0) | G8: =F8*12% | H8: =IF(A8="",0,B8*(92*IF(OR(C8=Options!$B$9,C8=Options!$B$10),75%,100%)-IF(C8=DATE(2026,11,29),26+IF(Options!$B$8="是",23,0),0)-IF(C8=DATE(2026,11,30),26,0)-IF(C8=DATE(2026,12,1),64,0)-IF(C8=DATE(2026,11,28),38,0)-IF(C8=DATE(2026,12,2),26,0))) | I8: =IF(AND(C8>=DATE(2026,11,29),C8<=DATE(2026,12,1)),B8*60,0) | J8: =IF(A8="",0,B8*(IF(C8=DATE(2026,11,28),38,0)+IF(C8=DATE(2026,12,1),38,0)+IF(C8=DATE(2026,12,2),26,0))) | K8: =IF(C8=Options!$B$9,B8*12,0) | L8: =IF(C8=Options!$B$9,B8*Options!$Z$5,0) | M8: 0 | N8: =SUM(E8:M8)
A9: =IF(AND(C9>=Options!$B$9,C9<=Options!$B$10),"Chicago","") | B9: =IF(A9="","",18) | C9: 46300 | D9: =IF(A9="","",IF(C9=DATE(2026,11,29),"培训；注册午餐；早餐参数",IF(C9=DATE(2026,11,30),"培训；注册午餐",IF(C9=DATE(2026,12,1),"培训；注册午餐；机构晚餐",IF(C9=Options!$B$9,"抵达；"&IF(C9=DATE(2026,11,28),"机构晚餐","无统一供餐"),IF(C9=Options!$B$10,"返程；"&IF(C9=DATE(2026,12,2),"机构午餐","无统一供餐"),"差旅状态；无统一日程")))))) | E9: =IF(C9=Options!$B$9,Options!$C$14,0) | F9: =IF(AND(A9<>"",C9<Options!$B$10),B9*Options!$X$5,0) | G9: =F9*12% | H9: =IF(A9="",0,B9*(92*IF(OR(C9=Options!$B$9,C9=Options!$B$10),75%,100%)-IF(C9=DATE(2026,11,29),26+IF(Options!$B$8="是",23,0),0)-IF(C9=DATE(2026,11,30),26,0)-IF(C9=DATE(2026,12,1),64,0)-IF(C9=DATE(2026,11,28),38,0)-IF(C9=DATE(2026,12,2),26,0))) | I9: =IF(AND(C9>=DATE(2026,11,29),C9<=DATE(2026,12,1)),B9*60,0) | J9: =IF(A9="",0,B9*(IF(C9=DATE(2026,11,28),38,0)+IF(C9=DATE(2026,12,1),38,0)+IF(C9=DATE(2026,12,2),26,0))) | K9: =IF(C9=Options!$B$9,B9*12,0) | L9: =IF(C9=Options!$B$9,B9*Options!$Z$5,0) | M9: 0 | N9: =SUM(E9:M9)
A10: =IF(AND(C10>=Options!$B$9,C10<=Options!$B$10),"Chicago","") | B10: =IF(A10="","",18) | C10: 46301 | D10: =IF(A10="","",IF(C10=DATE(2026,11,29),"培训；注册午餐；早餐参数",IF(C10=DATE(2026,11,30),"培训；注册午餐",IF(C10=DATE(2026,12,1),"培训；注册午餐；机构晚餐",IF(C10=Options!$B$9,"抵达；"&IF(C10=DATE(2026,11,28),"机构晚餐","无统一供餐"),IF(C10=Options!$B$10,"返程；"&IF(C10=DATE(2026,12,2),"机构午餐","无统一供餐"),"差旅状态；无统一日程")))))) | E10: =IF(C10=Options!$B$9,Options!$C$14,0) | F10: =IF(AND(A10<>"",C10<Options!$B$10),B10*Options!$X$5,0) | G10: =F10*12% | H10: =IF(A10="",0,B10*(92*IF(OR(C10=Options!$B$9,C10=Options!$B$10),75%,100%)-IF(C10=DATE(2026,11,29),26+IF(Options!$B$8="是",23,0),0)-IF(C10=DATE(2026,11,30),26,0)-IF(C10=DATE(2026,12,1),64,0)-IF(C10=DATE(2026,11,28),38,0)-IF(C10=DATE(2026,12,2),26,0))) | I10: =IF(AND(C10>=DATE(2026,11,29),C10<=DATE(2026,12,1)),B10*60,0) | J10: =IF(A10="",0,B10*(IF(C10=DATE(2026,11,28),38,0)+IF(C10=DATE(2026,12,1),38,0)+IF(C10=DATE(2026,12,2),26,0))) | K10: =IF(C10=Options!$B$9,B10*12,0) | L10: =IF(C10=Options!$B$9,B10*Options!$Z$5,0) | M10: 0 | N10: =SUM(E10:M10)
A11: =IF(AND(C11>=Options!$B$9,C11<=Options!$B$10),"Chicago","") | B11: =IF(A11="","",18) | C11: 46302 | D11: =IF(A11="","",IF(C11=DATE(2026,11,29),"培训；注册午餐；早餐参数",IF(C11=DATE(2026,11,30),"培训；注册午餐",IF(C11=DATE(2026,12,1),"培训；注册午餐；机构晚餐",IF(C11=Options!$B$9,"抵达；"&IF(C11=DATE(2026,11,28),"机构晚餐","无统一供餐"),IF(C11=Options!$B$10,"返程；"&IF(C11=DATE(2026,12,2),"机构午餐","无统一供餐"),"差旅状态；无统一日程")))))) | E11: =IF(C11=Options!$B$9,Options!$C$14,0) | F11: =IF(AND(A11<>"",C11<Options!$B$10),B11*Options!$X$5,0) | G11: =F11*12% | H11: =IF(A11="",0,B11*(92*IF(OR(C11=Options!$B$9,C11=Options!$B$10),75%,100%)-IF(C11=DATE(2026,11,29),26+IF(Options!$B$8="是",23,0),0)-IF(C11=DATE(2026,11,30),26,0)-IF(C11=DATE(2026,12,1),64,0)-IF(C11=DATE(2026,11,28),38,0)-IF(C11=DATE(2026,12,2),26,0))) | I11: =IF(AND(C11>=DATE(2026,11,29),C11<=DATE(2026,12,1)),B11*60,0) | J11: =IF(A11="",0,B11*(IF(C11=DATE(2026,11,28),38,0)+IF(C11=DATE(2026,12,1),38,0)+IF(C11=DATE(2026,12,2),26,0))) | K11: =IF(C11=Options!$B$9,B11*12,0) | L11: =IF(C11=Options!$B$9,B11*Options!$Z$5,0) | M11: 0 | N11: =SUM(E11:M11)
A12: =IF(AND(C12>=Options!$B$9,C12<=Options!$B$10),"Chicago","") | B12: =IF(A12="","",18) | C12: 46303 | D12: =IF(A12="","",IF(C12=DATE(2026,11,29),"培训；注册午餐；早餐参数",IF(C12=DATE(2026,11,30),"培训；注册午餐",IF(C12=DATE(2026,12,1),"培训；注册午餐；机构晚餐",IF(C12=Options!$B$9,"抵达；"&IF(C12=DATE(2026,11,28),"机构晚餐","无统一供餐"),IF(C12=Options!$B$10,"返程；"&IF(C12=DATE(2026,12,2),"机构午餐","无统一供餐"),"差旅状态；无统一日程")))))) | E12: =IF(C12=Options!$B$9,Options!$C$14,0) | F12: =IF(AND(A12<>"",C12<Options!$B$10),B12*Options!$X$5,0) | G12: =F12*12% | H12: =IF(A12="",0,B12*(92*IF(OR(C12=Options!$B$9,C12=Options!$B$10),75%,100%)-IF(C12=DATE(2026,11,29),26+IF(Options!$B$8="是",23,0),0)-IF(C12=DATE(2026,11,30),26,0)-IF(C12=DATE(2026,12,1),64,0)-IF(C12=DATE(2026,11,28),38,0)-IF(C12=DATE(2026,12,2),26,0))) | I12: =IF(AND(C12>=DATE(2026,11,29),C12<=DATE(2026,12,1)),B12*60,0) | J12: =IF(A12="",0,B12*(IF(C12=DATE(2026,11,28),38,0)+IF(C12=DATE(2026,12,1),38,0)+IF(C12=DATE(2026,12,2),26,0))) | K12: =IF(C12=Options!$B$9,B12*12,0) | L12: =IF(C12=Options!$B$9,B12*Options!$Z$5,0) | M12: 0 | N12: =SUM(E12:M12)
A13: =IF(AND(C13>=Options!$B$9,C13<=Options!$B$10),"Chicago","") | B13: =IF(A13="","",18) | C13: 46304 | D13: =IF(A13="","",IF(C13=DATE(2026,11,29),"培训；注册午餐；早餐参数",IF(C13=DATE(2026,11,30),"培训；注册午餐",IF(C13=DATE(2026,12,1),"培训；注册午餐；机构晚餐",IF(C13=Options!$B$9,"抵达；"&IF(C13=DATE(2026,11,28),"机构晚餐","无统一供餐"),IF(C13=Options!$B$10,"返程；"&IF(C13=DATE(2026,12,2),"机构午餐","无统一供餐"),"差旅状态；无统一日程")))))) | E13: =IF(C13=Options!$B$9,Options!$C$14,0) | F13: =IF(AND(A13<>"",C13<Options!$B$10),B13*Options!$X$5,0) | G13: =F13*12% | H13: =IF(A13="",0,B13*(92*IF(OR(C13=Options!$B$9,C13=Options!$B$10),75%,100%)-IF(C13=DATE(2026,11,29),26+IF(Options!$B$8="是",23,0),0)-IF(C13=DATE(2026,11,30),26,0)-IF(C13=DATE(2026,12,1),64,0)-IF(C13=DATE(2026,11,28),38,0)-IF(C13=DATE(2026,12,2),26,0))) | I13: =IF(AND(C13>=DATE(2026,11,29),C13<=DATE(2026,12,1)),B13*60,0) | J13: =IF(A13="",0,B13*(IF(C13=DATE(2026,11,28),38,0)+IF(C13=DATE(2026,12,1),38,0)+IF(C13=DATE(2026,12,2),26,0))) | K13: =IF(C13=Options!$B$9,B13*12,0) | L13: =IF(C13=Options!$B$9,B13*Options!$Z$5,0) | M13: 0 | N13: =SUM(E13:M13)
A14: =IF(AND(C14>=Options!$B$9,C14<=Options!$B$10),"Chicago","") | B14: =IF(A14="","",18) | C14: 46305 | D14: =IF(A14="","",IF(C14=DATE(2026,11,29),"培训；注册午餐；早餐参数",IF(C14=DATE(2026,11,30),"培训；注册午餐",IF(C14=DATE(2026,12,1),"培训；注册午餐；机构晚餐",IF(C14=Options!$B$9,"抵达；"&IF(C14=DATE(2026,11,28),"机构晚餐","无统一供餐"),IF(C14=Options!$B$10,"返程；"&IF(C14=DATE(2026,12,2),"机构午餐","无统一供餐"),"差旅状态；无统一日程")))))) | E14: =IF(C14=Options!$B$9,Options!$C$14,0) | F14: =IF(AND(A14<>"",C14<Options!$B$10),B14*Options!$X$5,0) | G14: =F14*12% | H14: =IF(A14="",0,B14*(92*IF(OR(C14=Options!$B$9,C14=Options!$B$10),75%,100%)-IF(C14=DATE(2026,11,29),26+IF(Options!$B$8="是",23,0),0)-IF(C14=DATE(2026,11,30),26,0)-IF(C14=DATE(2026,12,1),64,0)-IF(C14=DATE(2026,11,28),38,0)-IF(C14=DATE(2026,12,2),26,0))) | I14: =IF(AND(C14>=DATE(2026,11,29),C14<=DATE(2026,12,1)),B14*60,0) | J14: =IF(A14="",0,B14*(IF(C14=DATE(2026,11,28),38,0)+IF(C14=DATE(2026,12,1),38,0)+IF(C14=DATE(2026,12,2),26,0))) | K14: =IF(C14=Options!$B$9,B14*12,0) | L14: =IF(C14=Options!$B$9,B14*Options!$Z$5,0) | M14: 0 | N14: =SUM(E14:M14)
A15: =IF(AND(C15>=Options!$B$9,C15<=Options!$B$10),"Chicago","") | B15: =IF(A15="","",18) | C15: 46306 | D15: =IF(A15="","",IF(C15=DATE(2026,11,29),"培训；注册午餐；早餐参数",IF(C15=DATE(2026,11,30),"培训；注册午餐",IF(C15=DATE(2026,12,1),"培训；注册午餐；机构晚餐",IF(C15=Options!$B$9,"抵达；"&IF(C15=DATE(2026,11,28),"机构晚餐","无统一供餐"),IF(C15=Options!$B$10,"返程；"&IF(C15=DATE(2026,12,2),"机构午餐","无统一供餐"),"差旅状态；无统一日程")))))) | E15: =IF(C15=Options!$B$9,Options!$C$14,0) | F15: =IF(AND(A15<>"",C15<Options!$B$10),B15*Options!$X$5,0) | G15: =F15*12% | H15: =IF(A15="",0,B15*(92*IF(OR(C15=Options!$B$9,C15=Options!$B$10),75%,100%)-IF(C15=DATE(2026,11,29),26+IF(Options!$B$8="是",23,0),0)-IF(C15=DATE(2026,11,30),26,0)-IF(C15=DATE(2026,12,1),64,0)-IF(C15=DATE(2026,11,28),38,0)-IF(C15=DATE(2026,12,2),26,0))) | I15: =IF(AND(C15>=DATE(2026,11,29),C15<=DATE(2026,12,1)),B15*60,0) | J15: =IF(A15="",0,B15*(IF(C15=DATE(2026,11,28),38,0)+IF(C15=DATE(2026,12,1),38,0)+IF(C15=DATE(2026,12,2),26,0))) | K15: =IF(C15=Options!$B$9,B15*12,0) | L15: =IF(C15=Options!$B$9,B15*Options!$Z$5,0) | M15: 0 | N15: =SUM(E15:M15)
A16: =IF(AND(C16>=Options!$B$9,C16<=Options!$B$10),"Chicago","") | B16: =IF(A16="","",18) | C16: 46307 | D16: =IF(A16="","",IF(C16=DATE(2026,11,29),"培训；注册午餐；早餐参数",IF(C16=DATE(2026,11,30),"培训；注册午餐",IF(C16=DATE(2026,12,1),"培训；注册午餐；机构晚餐",IF(C16=Options!$B$9,"抵达；"&IF(C16=DATE(2026,11,28),"机构晚餐","无统一供餐"),IF(C16=Options!$B$10,"返程；"&IF(C16=DATE(2026,12,2),"机构午餐","无统一供餐"),"差旅状态；无统一日程")))))) | E16: =IF(C16=Options!$B$9,Options!$C$14,0) | F16: =IF(AND(A16<>"",C16<Options!$B$10),B16*Options!$X$5,0) | G16: =F16*12% | H16: =IF(A16="",0,B16*(92*IF(OR(C16=Options!$B$9,C16=Options!$B$10),75%,100%)-IF(C16=DATE(2026,11,29),26+IF(Options!$B$8="是",23,0),0)-IF(C16=DATE(2026,11,30),26,0)-IF(C16=DATE(2026,12,1),64,0)-IF(C16=DATE(2026,11,28),38,0)-IF(C16=DATE(2026,12,2),26,0))) | I16: =IF(AND(C16>=DATE(2026,11,29),C16<=DATE(2026,12,1)),B16*60,0) | J16: =IF(A16="",0,B16*(IF(C16=DATE(2026,11,28),38,0)+IF(C16=DATE(2026,12,1),38,0)+IF(C16=DATE(2026,12,2),26,0))) | K16: =IF(C16=Options!$B$9,B16*12,0) | L16: =IF(C16=Options!$B$9,B16*Options!$Z$5,0) | M16: 0 | N16: =SUM(E16:M16)
... A369: =IF(AND(C369>=Options!$B$9,C369<=Options!$B$10),"Chicago","") | B369: =IF(A369="","",18) | C369: 46660 | D369: =IF(A369="","",IF(C369=DATE(2026,11,29),"培训；注册午餐；早餐参数",IF(C369=DATE(2026,11,30),"培训；注册午餐",IF(C369=DATE(2026,12,1),"培训；注册午餐；机构晚餐",IF(C369=Options!$B$9,"抵达；"&IF(C369=DATE(2026,11,28),"机构晚餐","无统一供餐"),IF(C369=Options!$B$10,"返程；"&IF(C369=DATE(2026,12,2),"机构午餐","无统一供餐"),"差旅状态；无统一日程")))))) | E369: =IF(C369=Options!$B$9,Options!$C$14,0) | F369: =IF(AND(A369<>"",C369<Options!$B$10),B369*Options!$X$5,0) | G369: =F369*12% | H369: =IF(A369="",0,B369*(92*IF(OR(C369=Options!$B$9,C369=Options!$B$10),75%,100%)-IF(C369=DATE(2026,11,29),26+IF(Options!$B$8="是",23,0),0)-IF(C369=DATE(2026,11,30),26,0)-IF(C369=DATE(2026,12,1),64,0)-IF(C369=DATE(2026,11,28),38,0)-IF(C369=DATE(2026,12,2),26,0))) | I369: =IF(AND(C369>=DATE(2026,11,29),C369<=DATE(2026,12,1)),B369*60,0) | J369: =IF(A369="",0,B369*(IF(C369=DATE(2026,11,28),38,0)+IF(C369=DATE(2026,12,1),38,0)+IF(C369=DATE(2026,12,2),26,0))) | K369: =IF(C369=Options!$B$9,B369*12,0) | L369: =IF(C369=Options!$B$9,B369*Options!$Z$5,0) | M369: 0 | N369: =SUM(E369:M369)
A370: =IF(AND(C370>=Options!$B$9,C370<=Options!$B$10),"Chicago","") | B370: =IF(A370="","",24) | C370: 46296 | D370: =IF(A370="","",IF(C370=DATE(2026,11,29),"培训；注册午餐；早餐参数",IF(C370=DATE(2026,11,30),"培训；注册午餐",IF(C370=DATE(2026,12,1),"培训；注册午餐；机构晚餐",IF(C370=Options!$B$9,"抵达；"&IF(C370=DATE(2026,11,28),"机构晚餐","无统一供餐"),IF(C370=Options!$B$10,"返程；"&IF(C370=DATE(2026,12,2),"机构午餐","无统一供餐"),"差旅状态；无统一日程")))))) | E370: =IF(C370=Options!$B$9,Options!$C$15,0) | F370: =IF(AND(A370<>"",C370<Options!$B$10),B370*Options!$X$5,0) | G370: =F370*12% | H370: =IF(A370="",0,B370*(92*IF(OR(C370=Options!$B$9,C370=Options!$B$10),75%,100%)-IF(C370=DATE(2026,11,29),26+IF(Options!$B$8="是",23,0),0)-IF(C370=DATE(2026,11,30),26,0)-IF(C370=DATE(2026,12,1),64,0)-IF(C370=DATE(2026,11,28),38,0)-IF(C370=DATE(2026,12,2),26,0))) | I370: =IF(AND(C370>=DATE(2026,11,29),C370<=DATE(2026,12,1)),B370*60,0) | J370: =IF(A370="",0,B370*(IF(C370=DATE(2026,11,28),38,0)+IF(C370=DATE(2026,12,1),38,0)+IF(C370=DATE(2026,12,2),26,0))) | K370: =IF(C370=Options!$B$9,B370*12,0) | L370: =IF(C370=Options!$B$9,B370*Options!$Z$5,0) | M370: 0 | N370: =SUM(E370:M370)
A371: =IF(AND(C371>=Options!$B$9,C371<=Options!$B$10),"Chicago","") | B371: =IF(A371="","",24) | C371: 46297 | D371: =IF(A371="","",IF(C371=DATE(2026,11,29),"培训；注册午餐；早餐参数",IF(C371=DATE(2026,11,30),"培训；注册午餐",IF(C371=DATE(2026,12,1),"培训；注册午餐；机构晚餐",IF(C371=Options!$B$9,"抵达；"&IF(C371=DATE(2026,11,28),"机构晚餐","无统一供餐"),IF(C371=Options!$B$10,"返程；"&IF(C371=DATE(2026,12,2),"机构午餐","无统一供餐"),"差旅状态；无统一日程")))))) | E371: =IF(C371=Options!$B$9,Options!$C$15,0) | F371: =IF(AND(A371<>"",C371<Options!$B$10),B371*Options!$X$5,0) | G371: =F371*12% | H371: =IF(A371="",0,B371*(92*IF(OR(C371=Options!$B$9,C371=Options!$B$10),75%,100%)-IF(C371=DATE(2026,11,29),26+IF(Options!$B$8="是",23,0),0)-IF(C371=DATE(2026,11,30),26,0)-IF(C371=DATE(2026,12,1),64,0)-IF(C371=DATE(2026,11,28),38,0)-IF(C371=DATE(2026,12,2),26,0))) | I371: =IF(AND(C371>=DATE(2026,11,29),C371<=DATE(2026,12,1)),B371*60,0) | J371: =IF(A371="",0,B371*(IF(C371=DATE(2026,11,28),38,0)+IF(C371=DATE(2026,12,1),38,0)+IF(C371=DATE(2026,12,2),26,0))) | K371: =IF(C371=Options!$B$9,B371*12,0) | L371: =IF(C371=Options!$B$9,B371*Options!$Z$5,0) | M371: 0 | N371: =SUM(E371:M371)
A372: =IF(AND(C372>=Options!$B$9,C372<=Options!$B$10),"Chicago","") | B372: =IF(A372="","",24) | C372: 46298 | D372: =IF(A372="","",IF(C372=DATE(2026,11,29),"培训；注册午餐；早餐参数",IF(C372=DATE(2026,11,30),"培训；注册午餐",IF(C372=DATE(2026,12,1),"培训；注册午餐；机构晚餐",IF(C372=Options!$B$9,"抵达；"&IF(C372=DATE(2026,11,28),"机构晚餐","无统一供餐"),IF(C372=Options!$B$10,"返程；"&IF(C372=DATE(2026,12,2),"机构午餐","无统一供餐"),"差旅状态；无统一日程")))))) | E372: =IF(C372=Options!$B$9,Options!$C$15,0) | F372: =IF(AND(A372<>"",C372<Options!$B$10),B372*Options!$X$5,0) | G372: =F372*12% | H372: =IF(A372="",0,B372*(92*IF(OR(C372=Options!$B$9,C372=Options!$B$10),75%,100%)-IF(C372=DATE(2026,11,29),26+IF(Options!$B$8="是",23,0),0)-IF(C372=DATE(2026,11,30),26,0)-IF(C372=DATE(2026,12,1),64,0)-IF(C372=DATE(2026,11,28),38,0)-IF(C372=DATE(2026,12,2),26,0))) | I372: =IF(AND(C372>=DATE(2026,11,29),C372<=DATE(2026,12,1)),B372*60,0) | J372: =IF(A372="",0,B372*(IF(C372=DATE(2026,11,28),38,0)+IF(C372=DATE(2026,12,1),38,0)+IF(C372=DATE(2026,12,2),26,0))) | K372: =IF(C372=Options!$B$9,B372*12,0) | L372: =IF(C372=Options!$B$9,B372*Options!$Z$5,0) | M372: 0 | N372: =SUM(E372:M372)
A373: =IF(AND(C373>=Options!$B$9,C373<=Options!$B$10),"Chicago","") | B373: =IF(A373="","",24) | C373: 46299 | D373: =IF(A373="","",IF(C373=DATE(2026,11,29),"培训；注册午餐；早餐参数",IF(C373=DATE(2026,11,30),"培训；注册午餐",IF(C373=DATE(2026,12,1),"培训；注册午餐；机构晚餐",IF(C373=Options!$B$9,"抵达；"&IF(C373=DATE(2026,11,28),"机构晚餐","无统一供餐"),IF(C373=Options!$B$10,"返程；"&IF(C373=DATE(2026,12,2),"机构午餐","无统一供餐"),"差旅状态；无统一日程")))))) | E373: =IF(C373=Options!$B$9,Options!$C$15,0) | F373: =IF(AND(A373<>"",C373<Options!$B$10),B373*Options!$X$5,0) | G373: =F373*12% | H373: =IF(A373="",0,B373*(92*IF(OR(C373=Options!$B$9,C373=Options!$B$10),75%,100%)-IF(C373=DATE(2026,11,29),26+IF(Options!$B$8="是",23,0),0)-IF(C373=DATE(2026,11,30),26,0)-IF(C373=DATE(2026,12,1),64,0)-IF(C373=DATE(2026,11,28),38,0)-IF(C373=DATE(2026,12,2),26,0))) | I373: =IF(AND(C373>=DATE(2026,11,29),C373<=DATE(2026,12,1)),B373*60,0) | J373: =IF(A373="",0,B373*(IF(C373=DATE(2026,11,28),38,0)+IF(C373=DATE(2026,12,1),38,0)+IF(C373=DATE(2026,12,2),26,0))) | K373: =IF(C373=Options!$B$9,B373*12,0) | L373: =IF(C373=Options!$B$9,B373*Options!$Z$5,0) | M373: 0 | N373: =SUM(E373:M373)
A374: =IF(AND(C374>=Options!$B$9,C374<=Options!$B$10),"Chicago","") | B374: =IF(A374="","",24) | C374: 46300 | D374: =IF(A374="","",IF(C374=DATE(2026,11,29),"培训；注册午餐；早餐参数",IF(C374=DATE(2026,11,30),"培训；注册午餐",IF(C374=DATE(2026,12,1),"培训；注册午餐；机构晚餐",IF(C374=Options!$B$9,"抵达；"&IF(C374=DATE(2026,11,28),"机构晚餐","无统一供餐"),IF(C374=Options!$B$10,"返程；"&IF(C374=DATE(2026,12,2),"机构午餐","无统一供餐"),"差旅状态；无统一日程")))))) | E374: =IF(C374=Options!$B$9,Options!$C$15,0) | F374: =IF(AND(A374<>"",C374<Options!$B$10),B374*Options!$X$5,0) | G374: =F374*12% | H374: =IF(A374="",0,B374*(92*IF(OR(C374=Options!$B$9,C374=Options!$B$10),75%,100%)-IF(C374=DATE(2026,11,29),26+IF(Options!$B$8="是",23,0),0)-IF(C374=DATE(2026,11,30),26,0)-IF(C374=DATE(2026,12,1),64,0)-IF(C374=DATE(2026,11,28),38,0)-IF(C374=DATE(2026,12,2),26,0))) | I374: =IF(AND(C374>=DATE(2026,11,29),C374<=DATE(2026,12,1)),B374*60,0) | J374: =IF(A374="",0,B374*(IF(C374=DATE(2026,11,28),38,0)+IF(C374=DATE(2026,12,1),38,0)+IF(C374=DATE(2026,12,2),26,0))) | K374: =IF(C374=Options!$B$9,B374*12,0) | L374: =IF(C374=Options!$B$9,B374*Options!$Z$5,0) | M374: 0 | N374: =SUM(E374:M374)
A375: =IF(AND(C375>=Options!$B$9,C375<=Options!$B$10),"Chicago","") | B375: =IF(A375="","",24) | C375: 46301 | D375: =IF(A375="","",IF(C375=DATE(2026,11,29),"培训；注册午餐；早餐参数",IF(C375=DATE(2026,11,30),"培训；注册午餐",IF(C375=DATE(2026,12,1),"培训；注册午餐；机构晚餐",IF(C375=Options!$B$9,"抵达；"&IF(C375=DATE(2026,11,28),"机构晚餐","无统一供餐"),IF(C375=Options!$B$10,"返程；"&IF(C375=DATE(2026,12,2),"机构午餐","无统一供餐"),"差旅状态；无统一日程")))))) | E375: =IF(C375=Options!$B$9,Options!$C$15,0) | F375: =IF(AND(A375<>"",C375<Options!$B$10),B375*Options!$X$5,0) | G375: =F375*12% | H375: =IF(A375="",0,B375*(92*IF(OR(C375=Options!$B$9,C375=Options!$B$10),75%,100%)-IF(C375=DATE(2026,11,29),26+IF(Options!$B$8="是",23,0),0)-IF(C375=DATE(2026,11,30),26,0)-IF(C375=DATE(2026,12,1),64,0)-IF(C375=DATE(2026,11,28),38,0)-IF(C375=DATE(2026,12,2),26,0))) | I375: =IF(AND(C375>=DATE(2026,11,29),C375<=DATE(2026,12,1)),B375*60,0) | J375: =IF(A375="",0,B375*(IF(C375=DATE(2026,11,28),38,0)+IF(C375=DATE(2026,12,1),38,0)+IF(C375=DATE(2026,12,2),26,0))) | K375: =IF(C375=Options!$B$9,B375*12,0) | L375: =IF(C375=Options!$B$9,B375*Options!$Z$5,0) | M375: 0 | N375: =SUM(E375:M375)
A376: =IF(AND(C376>=Options!$B$9,C376<=Options!$B$10),"Chicago","") | B376: =IF(A376="","",24) | C376: 46302 | D376: =IF(A376="","",IF(C376=DATE(2026,11,29),"培训；注册午餐；早餐参数",IF(C376=DATE(2026,11,30),"培训；注册午餐",IF(C376=DATE(2026,12,1),"培训；注册午餐；机构晚餐",IF(C376=Options!$B$9,"抵达；"&IF(C376=DATE(2026,11,28),"机构晚餐","无统一供餐"),IF(C376=Options!$B$10,"返程；"&IF(C376=DATE(2026,12,2),"机构午餐","无统一供餐"),"差旅状态；无统一日程")))))) | E376: =IF(C376=Options!$B$9,Options!$C$15,0) | F376: =IF(AND(A376<>"",C376<Options!$B$10),B376*Options!$X$5,0) | G376: =F376*12% | H376: =IF(A376="",0,B376*(92*IF(OR(C376=Options!$B$9,C376=Options!$B$10),75%,100%)-IF(C376=DATE(2026,11,29),26+IF(Options!$B$8="是",23,0),0)-IF(C376=DATE(2026,11,30),26,0)-IF(C376=DATE(2026,12,1),64,0)-IF(C376=DATE(2026,11,28),38,0)-IF(C376=DATE(2026,12,2),26,0))) | I376: =IF(AND(C376>=DATE(2026,11,29),C376<=DATE(2026,12,1)),B376*60,0) | J376: =IF(A376="",0,B376*(IF(C376=DATE(2026,11,28),38,0)+IF(C376=DATE(2026,12,1),38,0)+IF(C376=DATE(2026,12,2),26,0))) | K376: =IF(C376=Options!$B$9,B376*12,0) | L376: =IF(C376=Options!$B$9,B376*Options!$Z$5,0) | M376: 0 | N376: =SUM(E376:M376)
A377: =IF(AND(C377>=Options!$B$9,C377<=Options!$B$10),"Chicago","") | B377: =IF(A377="","",24) | C377: 46303 | D377: =IF(A377="","",IF(C377=DATE(2026,11,29),"培训；注册午餐；早餐参数",IF(C377=DATE(2026,11,30),"培训；注册午餐",IF(C377=DATE(2026,12,1),"培训；注册午餐；机构晚餐",IF(C377=Options!$B$9,"抵达；"&IF(C377=DATE(2026,11,28),"机构晚餐","无统一供餐"),IF(C377=Options!$B$10,"返程；"&IF(C377=DATE(2026,12,2),"机构午餐","无统一供餐"),"差旅状态；无统一日程")))))) | E377: =IF(C377=Options!$B$9,Options!$C$15,0) | F377: =IF(AND(A377<>"",C377<Options!$B$10),B377*Options!$X$5,0) | G377: =F377*12% | H377: =IF(A377="",0,B377*(92*IF(OR(C377=Options!$B$9,C377=Options!$B$10),75%,100%)-IF(C377=DATE(2026,11,29),26+IF(Options!$B$8="是",23,0),0)-IF(C377=DATE(2026,11,30),26,0)-IF(C377=DATE(2026,12,1),64,0)-IF(C377=DATE(2026,11,28),38,0)-IF(C377=DATE(2026,12,2),26,0))) | I377: =IF(AND(C377>=DATE(2026,11,29),C377<=DATE(2026,12,1)),B377*60,0) | J377: =IF(A377="",0,B377*(IF(C377=DATE(2026,11,28),38,0)+IF(C377=DATE(2026,12,1),38,0)+IF(C377=DATE(2026,12,2),26,0))) | K377: =IF(C377=Options!$B$9,B377*12,0) | L377: =IF(C377=Options!$B$9,B377*Options!$Z$5,0) | M377: 0 | N377: =SUM(E377:M377)
A378: =IF(AND(C378>=Options!$B$9,C378<=Options!$B$10),"Chicago","") | B378: =IF(A378="","",24) | C378: 46304 | D378: =IF(A378="","",IF(C378=DATE(2026,11,29),"培训；注册午餐；早餐参数",IF(C378=DATE(2026,11,30),"培训；注册午餐",IF(C378=DATE(2026,12,1),"培训；注册午餐；机构晚餐",IF(C378=Options!$B$9,"抵达；"&IF(C378=DATE(2026,11,28),"机构晚餐","无统一供餐"),IF(C378=Options!$B$10,"返程；"&IF(C378=DATE(2026,12,2),"机构午餐","无统一供餐"),"差旅状态；无统一日程")))))) | E378: =IF(C378=Options!$B$9,Options!$C$15,0) | F378: =IF(AND(A378<>"",C378<Options!$B$10),B378*Options!$X$5,0) | G378: =F378*12% | H378: =IF(A378="",0,B378*(92*IF(OR(C378=Options!$B$9,C378=Options!$B$10),75%,100%)-IF(C378=DATE(2026,11,29),26+IF(Options!$B$8="是",23,0),0)-IF(C378=DATE(2026,11,30),26,0)-IF(C378=DATE(2026,12,1),64,0)-IF(C378=DATE(2026,11,28),38,0)-IF(C378=DATE(2026,12,2),26,0))) | I378: =IF(AND(C378>=DATE(2026,11,29),C378<=DATE(2026,12,1)),B378*60,0) | J378: =IF(A378="",0,B378*(IF(C378=DATE(2026,11,28),38,0)+IF(C378=DATE(2026,12,1),38,0)+IF(C378=DATE(2026,12,2),26,0))) | K378: =IF(C378=Options!$B$9,B378*12,0) | L378: =IF(C378=Options!$B$9,B378*Options!$Z$5,0) | M378: 0 | N378: =SUM(E378:M378)
A379: =IF(AND(C379>=Options!$B$9,C379<=Options!$B$10),"Chicago","") | B379: =IF(A379="","",24) | C379: 46305 | D379: =IF(A379="","",IF(C379=DATE(2026,11,29),"培训；注册午餐；早餐参数",IF(C379=DATE(2026,11,30),"培训；注册午餐",IF(C379=DATE(2026,12,1),"培训；注册午餐；机构晚餐",IF(C379=Options!$B$9,"抵达；"&IF(C379=DATE(2026,11,28),"机构晚餐","无统一供餐"),IF(C379=Options!$B$10,"返程；"&IF(C379=DATE(2026,12,2),"机构午餐","无统一供餐"),"差旅状态；无统一日程")))))) | E379: =IF(C379=Options!$B$9,Options!$C$15,0) | F379: =IF(AND(A379<>"",C379<Options!$B$10),B379*Options!$X$5,0) | G379: =F379*12% | H379: =IF(A379="",0,B379*(92*IF(OR(C379=Options!$B$9,C379=Options!$B$10),75%,100%)-IF(C379=DATE(2026,11,29),26+IF(Options!$B$8="是",23,0),0)-IF(C379=DATE(2026,11,30),26,0)-IF(C379=DATE(2026,12,1),64,0)-IF(C379=DATE(2026,11,28),38,0)-IF(C379=DATE(2026,12,2),26,0))) | I379: =IF(AND(C379>=DATE(2026,11,29),C379<=DATE(2026,12,1)),B379*60,0) | J379: =IF(A379="",0,B379*(IF(C379=DATE(2026,11,28),38,0)+IF(C379=DATE(2026,12,1),38,0)+IF(C379=DATE(2026,12,2),26,0))) | K379: =IF(C379=Options!$B$9,B379*12,0) | L379: =IF(C379=Options!$B$9,B379*Options!$Z$5,0) | M379: 0 | N379: =SUM(E379:M379)
A380: =IF(AND(C380>=Options!$B$9,C380<=Options!$B$10),"Chicago","") | B380: =IF(A380="","",24) | C380: 46306 | D380: =IF(A380="","",IF(C380=DATE(2026,11,29),"培训；注册午餐；早餐参数",IF(C380=DATE(2026,11,30),"培训；注册午餐",IF(C380=DATE(2026,12,1),"培训；注册午餐；机构晚餐",IF(C380=Options!$B$9,"抵达；"&IF(C380=DATE(2026,11,28),"机构晚餐","无统一供餐"),IF(C380=Options!$B$10,"返程；"&IF(C380=DATE(2026,12,2),"机构午餐","无统一供餐"),"差旅状态；无统一日程")))))) | E380: =IF(C380=Options!$B$9,Options!$C$15,0) | F380: =IF(AND(A380<>"",C380<Options!$B$10),B380*Options!$X$5,0) | G380: =F380*12% | H380: =IF(A380="",0,B380*(92*IF(OR(C380=Options!$B$9,C380=Options!$B$10),75%,100%)-IF(C380=DATE(2026,11,29),26+IF(Options!$B$8="是",23,0),0)-IF(C380=DATE(2026,11,30),26,0)-IF(C380=DATE(2026,12,1),64,0)-IF(C380=DATE(2026,11,28),38,0)-IF(C380=DATE(2026,12,2),26,0))) | I380: =IF(AND(C380>=DATE(2026,11,29),C380<=DATE(2026,12,1)),B380*60,0) | J380: =IF(A380="",0,B380*(IF(C380=DATE(2026,11,28),38,0)+IF(C380=DATE(2026,12,1),38,0)+IF(C380=DATE(2026,12,2),26,0))) | K380: =IF(C380=Options!$B$9,B380*12,0) | L380: =IF(C380=Options!$B$9,B380*Options!$Z$5,0) | M380: 0 | N380: =SUM(E380:M380)
A381: =IF(AND(C381>=Options!$B$9,C381<=Options!$B$10),"Chicago","") | B381: =IF(A381="","",24) | C381: 46307 | D381: =IF(A381="","",IF(C381=DATE(2026,11,29),"培训；注册午餐；早餐参数",IF(C381=DATE(2026,11,30),"培训；注册午餐",IF(C381=DATE(2026,12,1),"培训；注册午餐；机构晚餐",IF(C381=Options!$B$9,"抵达；"&IF(C381=DATE(2026,11,28),"机构晚餐","无统一供餐"),IF(C381=Options!$B$10,"返程；"&IF(C381=DATE(2026,12,2),"机构午餐","无统一供餐"),"差旅状态；无统一日程")))))) | E381: =IF(C381=Options!$B$9,Options!$C$15,0) | F381: =IF(AND(A381<>"",C381<Options!$B$10),B381*Options!$X$5,0) | G381: =F381*12% | H381: =IF(A381="",0,B381*(92*IF(OR(C381=Options!$B$9,C381=Options!$B$10),75%,100%)-IF(C381=DATE(2026,11,29),26+IF(Options!$B$8="是",23,0),0)-IF(C381=DATE(2026,11,30),26,0)-IF(C381=DATE(2026,12,1),64,0)-IF(C381=DATE(2026,11,28),38,0)-IF(C381=DATE(2026,12,2),26,0))) | I381: =IF(AND(C381>=DATE(2026,11,29),C381<=DATE(2026,12,1)),B381*60,0) | J381: =IF(A381="",0,B381*(IF(C381=DATE(2026,11,28),38,0)+IF(C381=DATE(2026,12,1),38,0)+IF(C381=DATE(2026,12,2),26,0))) | K381: =IF(C381=Options!$B$9,B381*12,0) | L381: =IF(C381=Options!$B$9,B381*Options!$Z$5,0) | M381: 0 | N381: =SUM(E381:M381)
... A734: =IF(AND(C734>=Options!$B$9,C734<=Options!$B$10),"Chicago","") | B734: =IF(A734="","",24) | C734: 46660 | D734: =IF(A734="","",IF(C734=DATE(2026,11,29),"培训；注册午餐；早餐参数",IF(C734=DATE(2026,11,30),"培训；注册午餐",IF(C734=DATE(2026,12,1),"培训；注册午餐；机构晚餐",IF(C734=Options!$B$9,"抵达；"&IF(C734=DATE(2026,11,28),"机构晚餐","无统一供餐"),IF(C734=Options!$B$10,"返程；"&IF(C734=DATE(2026,12,2),"机构午餐","无统一供餐"),"差旅状态；无统一日程")))))) | E734: =IF(C734=Options!$B$9,Options!$C$15,0) | F734: =IF(AND(A734<>"",C734<Options!$B$10),B734*Options!$X$5,0) | G734: =F734*12% | H734: =IF(A734="",0,B734*(92*IF(OR(C734=Options!$B$9,C734=Options!$B$10),75%,100%)-IF(C734=DATE(2026,11,29),26+IF(Options!$B$8="是",23,0),0)-IF(C734=DATE(2026,11,30),26,0)-IF(C734=DATE(2026,12,1),64,0)-IF(C734=DATE(2026,11,28),38,0)-IF(C734=DATE(2026,12,2),26,0))) | I734: =IF(AND(C734>=DATE(2026,11,29),C734<=DATE(2026,12,1)),B734*60,0) | J734: =IF(A734="",0,B734*(IF(C734=DATE(2026,11,28),38,0)+IF(C734=DATE(2026,12,1),38,0)+IF(C734=DATE(2026,12,2),26,0))) | K734: =IF(C734=Options!$B$9,B734*12,0) | L734: =IF(C734=Options!$B$9,B734*Options!$Z$5,0) | M734: 0 | N734: =SUM(E734:M734)
A735: =IF(AND(C735>=Options!$B$9,C735<=Options!$B$10),"Denver","") | B735: =IF(A735="","",18) | C735: 46296 | D735: =IF(A735="","",IF(C735=DATE(2026,11,29),"培训；注册午餐；早餐参数",IF(C735=DATE(2026,11,30),"培训；注册午餐",IF(C735=DATE(2026,12,1),"培训；注册午餐；机构晚餐",IF(C735=Options!$B$9,"抵达；"&IF(C735=DATE(2026,11,28),"机构晚餐","无统一供餐"),IF(C735=Options!$B$10,"返程；"&IF(C735=DATE(2026,12,2),"机构午餐","无统一供餐"),"差旅状态；无统一日程")))))) | E735: =IF(C735=Options!$B$9,Options!$C$16,0) | F735: =IF(AND(A735<>"",C735<Options!$B$10),B735*Options!$X$6,0) | G735: =F735*12% | H735: =IF(A735="",0,B735*(92*IF(OR(C735=Options!$B$9,C735=Options!$B$10),75%,100%)-IF(C735=DATE(2026,11,29),26+IF(Options!$B$8="是",23,0),0)-IF(C735=DATE(2026,11,30),26,0)-IF(C735=DATE(2026,12,1),64,0)-IF(C735=DATE(2026,11,28),38,0)-IF(C735=DATE(2026,12,2),26,0))) | I735: =IF(AND(C735>=DATE(2026,11,29),C735<=DATE(2026,12,1)),B735*60,0) | J735: =IF(A735="",0,B735*(IF(C735=DATE(2026,11,28),38,0)+IF(C735=DATE(2026,12,1),38,0)+IF(C735=DATE(2026,12,2),26,0))) | K735: =IF(C735=Options!$B$9,B735*12,0) | L735: =IF(C735=Options!$B$9,B735*Options!$Z$6,0) | M735: 0 | N735: =SUM(E735:M735)
A736: =IF(AND(C736>=Options!$B$9,C736<=Options!$B$10),"Denver","") | B736: =IF(A736="","",18) | C736: 46297 | D736: =IF(A736="","",IF(C736=DATE(2026,11,29),"培训；注册午餐；早餐参数",IF(C736=DATE(2026,11,30),"培训；注册午餐",IF(C736=DATE(2026,12,1),"培训；注册午餐；机构晚餐",IF(C736=Options!$B$9,"抵达；"&IF(C736=DATE(2026,11,28),"机构晚餐","无统一供餐"),IF(C736=Options!$B$10,"返程；"&IF(C736=DATE(2026,12,2),"机构午餐","无统一供餐"),"差旅状态；无统一日程")))))) | E736: =IF(C736=Options!$B$9,Options!$C$16,0) | F736: =IF(AND(A736<>"",C736<Options!$B$10),B736*Options!$X$6,0) | G736: =F736*12% | H736: =IF(A736="",0,B736*(92*IF(OR(C736=Options!$B$9,C736=Options!$B$10),75%,100%)-IF(C736=DATE(2026,11,29),26+IF(Options!$B$8="是",23,0),0)-IF(C736=DATE(2026,11,30),26,0)-IF(C736=DATE(2026,12,1),64,0)-IF(C736=DATE(2026,11,28),38,0)-IF(C736=DATE(2026,12,2),26,0))) | I736: =IF(AND(C736>=DATE(2026,11,29),C736<=DATE(2026,12,1)),B736*60,0) | J736: =IF(A736="",0,B736*(IF(C736=DATE(2026,11,28),38,0)+IF(C736=DATE(2026,12,1),38,0)+IF(C736=DATE(2026,12,2),26,0))) | K736: =IF(C736=Options!$B$9,B736*12,0) | L736: =IF(C736=Options!$B$9,B736*Options!$Z$6,0) | M736: 0 | N736: =SUM(E736:M736)
A737: =IF(AND(C737>=Options!$B$9,C737<=Options!$B$10),"Denver","") | B737: =IF(A737="","",18) | C737: 46298 | D737: =IF(A737="","",IF(C737=DATE(2026,11,29),"培训；注册午餐；早餐参数",IF(C737=DATE(2026,11,30),"培训；注册午餐",IF(C737=DATE(2026,12,1),"培训；注册午餐；机构晚餐",IF(C737=Options!$B$9,"抵达；"&IF(C737=DATE(2026,11,28),"机构晚餐","无统一供餐"),IF(C737=Options!$B$10,"返程；"&IF(C737=DATE(2026,12,2),"机构午餐","无统一供餐"),"差旅状态；无统一日程")))))) | E737: =IF(C737=Options!$B$9,Options!$C$16,0) | F737: =IF(AND(A737<>"",C737<Options!$B$10),B737*Options!$X$6,0) | G737: =F737*12% | H737: =IF(A737="",0,B737*(92*IF(OR(C737=Options!$B$9,C737=Options!$B$10),75%,100%)-IF(C737=DATE(2026,11,29),26+IF(Options!$B$8="是",23,0),0)-IF(C737=DATE(2026,11,30),26,0)-IF(C737=DATE(2026,12,1),64,0)-IF(C737=DATE(2026,11,28),38,0)-IF(C737=DATE(2026,12,2),26,0))) | I737: =IF(AND(C737>=DATE(2026,11,29),C737<=DATE(2026,12,1)),B737*60,0) | J737: =IF(A737="",0,B737*(IF(C737=DATE(2026,11,28),38,0)+IF(C737=DATE(2026,12,1),38,0)+IF(C737=DATE(2026,12,2),26,0))) | K737: =IF(C737=Options!$B$9,B737*12,0) | L737: =IF(C737=Options!$B$9,B737*Options!$Z$6,0) | M737: 0 | N737: =SUM(E737:M737)
A738: =IF(AND(C738>=Options!$B$9,C738<=Options!$B$10),"Denver","") | B738: =IF(A738="","",18) | C738: 46299 | D738: =IF(A738="","",IF(C738=DATE(2026,11,29),"培训；注册午餐；早餐参数",IF(C738=DATE(2026,11,30),"培训；注册午餐",IF(C738=DATE(2026,12,1),"培训；注册午餐；机构晚餐",IF(C738=Options!$B$9,"抵达；"&IF(C738=DATE(2026,11,28),"机构晚餐","无统一供餐"),IF(C738=Options!$B$10,"返程；"&IF(C738=DATE(2026,12,2),"机构午餐","无统一供餐"),"差旅状态；无统一日程")))))) | E738: =IF(C738=Options!$B$9,Options!$C$16,0) | F738: =IF(AND(A738<>"",C738<Options!$B$10),B738*Options!$X$6,0) | G738: =F738*12% | H738: =IF(A738="",0,B738*(92*IF(OR(C738=Options!$B$9,C738=Options!$B$10),75%,100%)-IF(C738=DATE(2026,11,29),26+IF(Options!$B$8="是",23,0),0)-IF(C738=DATE(2026,11,30),26,0)-IF(C738=DATE(2026,12,1),64,0)-IF(C738=DATE(2026,11,28),38,0)-IF(C738=DATE(2026,12,2),26,0))) | I738: =IF(AND(C738>=DATE(2026,11,29),C738<=DATE(2026,12,1)),B738*60,0) | J738: =IF(A738="",0,B738*(IF(C738=DATE(2026,11,28),38,0)+IF(C738=DATE(2026,12,1),38,0)+IF(C738=DATE(2026,12,2),26,0))) | K738: =IF(C738=Options!$B$9,B738*12,0) | L738: =IF(C738=Options!$B$9,B738*Options!$Z$6,0) | M738: 0 | N738: =SUM(E738:M738)
A739: =IF(AND(C739>=Options!$B$9,C739<=Options!$B$10),"Denver","") | B739: =IF(A739="","",18) | C739: 46300 | D739: =IF(A739="","",IF(C739=DATE(2026,11,29),"培训；注册午餐；早餐参数",IF(C739=DATE(2026,11,30),"培训；注册午餐",IF(C739=DATE(2026,12,1),"培训；注册午餐；机构晚餐",IF(C739=Options!$B$9,"抵达；"&IF(C739=DATE(2026,11,28),"机构晚餐","无统一供餐"),IF(C739=Options!$B$10,"返程；"&IF(C739=DATE(2026,12,2),"机构午餐","无统一供餐"),"差旅状态；无统一日程")))))) | E739: =IF(C739=Options!$B$9,Options!$C$16,0) | F739: =IF(AND(A739<>"",C739<Options!$B$10),B739*Options!$X$6,0) | G739: =F739*12% | H739: =IF(A739="",0,B739*(92*IF(OR(C739=Options!$B$9,C739=Options!$B$10),75%,100%)-IF(C739=DATE(2026,11,29),26+IF(Options!$B$8="是",23,0),0)-IF(C739=DATE(2026,11,30),26,0)-IF(C739=DATE(2026,12,1),64,0)-IF(C739=DATE(2026,11,28),38,0)-IF(C739=DATE(2026,12,2),26,0))) | I739: =IF(AND(C739>=DATE(2026,11,29),C739<=DATE(2026,12,1)),B739*60,0) | J739: =IF(A739="",0,B739*(IF(C739=DATE(2026,11,28),38,0)+IF(C739=DATE(2026,12,1),38,0)+IF(C739=DATE(2026,12,2),26,0))) | K739: =IF(C739=Options!$B$9,B739*12,0) | L739: =IF(C739=Options!$B$9,B739*Options!$Z$6,0) | M739: 0 | N739: =SUM(E739:M739)
A740: =IF(AND(C740>=Options!$B$9,C740<=Options!$B$10),"Denver","") | B740: =IF(A740="","",18) | C740: 46301 | D740: =IF(A740="","",IF(C740=DATE(2026,11,29),"培训；注册午餐；早餐参数",IF(C740=DATE(2026,11,30),"培训；注册午餐",IF(C740=DATE(2026,12,1),"培训；注册午餐；机构晚餐",IF(C740=Options!$B$9,"抵达；"&IF(C740=DATE(2026,11,28),"机构晚餐","无统一供餐"),IF(C740=Options!$B$10,"返程；"&IF(C740=DATE(2026,12,2),"机构午餐","无统一供餐"),"差旅状态；无统一日程")))))) | E740: =IF(C740=Options!$B$9,Options!$C$16,0) | F740: =IF(AND(A740<>"",C740<Options!$B$10),B740*Options!$X$6,0) | G740: =F740*12% | H740: =IF(A740="",0,B740*(92*IF(OR(C740=Options!$B$9,C740=Options!$B$10),75%,100%)-IF(C740=DATE(2026,11,29),26+IF(Options!$B$8="是",23,0),0)-IF(C740=DATE(2026,11,30),26,0)-IF(C740=DATE(2026,12,1),64,0)-IF(C740=DATE(2026,11,28),38,0)-IF(C740=DATE(2026,12,2),26,0))) | I740: =IF(AND(C740>=DATE(2026,11,29),C740<=DATE(2026,12,1)),B740*60,0) | J740: =IF(A740="",0,B740*(IF(C740=DATE(2026,11,28),38,0)+IF(C740=DATE(2026,12,1),38,0)+IF(C740=DATE(2026,12,2),26,0))) | K740: =IF(C740=Options!$B$9,B740*12,0) | L740: =IF(C740=Options!$B$9,B740*Options!$Z$6,0) | M740: 0 | N740: =SUM(E740:M740)
A741: =IF(AND(C741>=Options!$B$9,C741<=Options!$B$10),"Denver","") | B741: =IF(A741="","",18) | C741: 46302 | D741: =IF(A741="","",IF(C741=DATE(2026,11,29),"培训；注册午餐；早餐参数",IF(C741=DATE(2026,11,30),"培训；注册午餐",IF(C741=DATE(2026,12,1),"培训；注册午餐；机构晚餐",IF(C741=Options!$B$9,"抵达；"&IF(C741=DATE(2026,11,28),"机构晚餐","无统一供餐"),IF(C741=Options!$B$10,"返程；"&IF(C741=DATE(2026,12,2),"机构午餐","无统一供餐"),"差旅状态；无统一日程")))))) | E741: =IF(C741=Options!$B$9,Options!$C$16,0) | F741: =IF(AND(A741<>"",C741<Options!$B$10),B741*Options!$X$6,0) | G741: =F741*12% | H741: =IF(A741="",0,B741*(92*IF(OR(C741=Options!$B$9,C741=Options!$B$10),75%,100%)-IF(C741=DATE(2026,11,29),26+IF(Options!$B$8="是",23,0),0)-IF(C741=DATE(2026,11,30),26,0)-IF(C741=DATE(2026,12,1),64,0)-IF(C741=DATE(2026,11,28),38,0)-IF(C741=DATE(2026,12,2),26,0))) | I741: =IF(AND(C741>=DATE(2026,11,29),C741<=DATE(2026,12,1)),B741*60,0) | J741: =IF(A741="",0,B741*(IF(C741=DATE(2026,11,28),38,0)+IF(C741=DATE(2026,12,1),38,0)+IF(C741=DATE(2026,12,2),26,0))) | K741: =IF(C741=Options!$B$9,B741*12,0) | L741: =IF(C741=Options!$B$9,B741*Options!$Z$6,0) | M741: 0 | N741: =SUM(E741:M741)
A742: =IF(AND(C742>=Options!$B$9,C742<=Options!$B$10),"Denver","") | B742: =IF(A742="","",18) | C742: 46303 | D742: =IF(A742="","",IF(C742=DATE(2026,11,29),"培训；注册午餐；早餐参数",IF(C742=DATE(2026,11,30),"培训；注册午餐",IF(C742=DATE(2026,12,1),"培训；注册午餐；机构晚餐",IF(C742=Options!$B$9,"抵达；"&IF(C742=DATE(2026,11,28),"机构晚餐","无统一供餐"),IF(C742=Options!$B$10,"返程；"&IF(C742=DATE(2026,12,2),"机构午餐","无统一供餐"),"差旅状态；无统一日程")))))) | E742: =IF(C742=Options!$B$9,Options!$C$16,0) | F742: =IF(AND(A742<>"",C742<Options!$B$10),B742*Options!$X$6,0) | G742: =F742*12% | H742: =IF(A742="",0,B742*(92*IF(OR(C742=Options!$B$9,C742=Options!$B$10),75%,100%)-IF(C742=DATE(2026,11,29),26+IF(Options!$B$8="是",23,0),0)-IF(C742=DATE(2026,11,30),26,0)-IF(C742=DATE(2026,12,1),64,0)-IF(C742=DATE(2026,11,28),38,0)-IF(C742=DATE(2026,12,2),26,0))) | I742: =IF(AND(C742>=DATE(2026,11,29),C742<=DATE(2026,12,1)),B742*60,0) | J742: =IF(A742="",0,B742*(IF(C742=DATE(2026,11,28),38,0)+IF(C742=DATE(2026,12,1),38,0)+IF(C742=DATE(2026,12,2),26,0))) | K742: =IF(C742=Options!$B$9,B742*12,0) | L742: =IF(C742=Options!$B$9,B742*Options!$Z$6,0) | M742: 0 | N742: =SUM(E742:M742)
A743: =IF(AND(C743>=Options!$B$9,C743<=Options!$B$10),"Denver","") | B743: =IF(A743="","",18) | C743: 46304 | D743: =IF(A743="","",IF(C743=DATE(2026,11,29),"培训；注册午餐；早餐参数",IF(C743=DATE(2026,11,30),"培训；注册午餐",IF(C743=DATE(2026,12,1),"培训；注册午餐；机构晚餐",IF(C743=Options!$B$9,"抵达；"&IF(C743=DATE(2026,11,28),"机构晚餐","无统一供餐"),IF(C743=Options!$B$10,"返程；"&IF(C743=DATE(2026,12,2),"机构午餐","无统一供餐"),"差旅状态；无统一日程")))))) | E743: =IF(C743=Options!$B$9,Options!$C$16,0) | F743: =IF(AND(A743<>"",C743<Options!$B$10),B743*Options!$X$6,0) | G743: =F743*12% | H743: =IF(A743="",0,B743*(92*IF(OR(C743=Options!$B$9,C743=Options!$B$10),75%,100%)-IF(C743=DATE(2026,11,29),26+IF(Options!$B$8="是",23,0),0)-IF(C743=DATE(2026,11,30),26,0)-IF(C743=DATE(2026,12,1),64,0)-IF(C743=DATE(2026,11,28),38,0)-IF(C743=DATE(2026,12,2),26,0))) | I743: =IF(AND(C743>=DATE(2026,11,29),C743<=DATE(2026,12,1)),B743*60,0) | J743: =IF(A743="",0,B743*(IF(C743=DATE(2026,11,28),38,0)+IF(C743=DATE(2026,12,1),38,0)+IF(C743=DATE(2026,12,2),26,0))) | K743: =IF(C743=Options!$B$9,B743*12,0) | L743: =IF(C743=Options!$B$9,B743*Options!$Z$6,0) | M743: 0 | N743: =SUM(E743:M743)
A744: =IF(AND(C744>=Options!$B$9,C744<=Options!$B$10),"Denver","") | B744: =IF(A744="","",18) | C744: 46305 | D744: =IF(A744="","",IF(C744=DATE(2026,11,29),"培训；注册午餐；早餐参数",IF(C744=DATE(2026,11,30),"培训；注册午餐",IF(C744=DATE(2026,12,1),"培训；注册午餐；机构晚餐",IF(C744=Options!$B$9,"抵达；"&IF(C744=DATE(2026,11,28),"机构晚餐","无统一供餐"),IF(C744=Options!$B$10,"返程；"&IF(C744=DATE(2026,12,2),"机构午餐","无统一供餐"),"差旅状态；无统一日程")))))) | E744: =IF(C744=Options!$B$9,Options!$C$16,0) | F744: =IF(AND(A744<>"",C744<Options!$B$10),B744*Options!$X$6,0) | G744: =F744*12% | H744: =IF(A744="",0,B744*(92*IF(OR(C744=Options!$B$9,C744=Options!$B$10),75%,100%)-IF(C744=DATE(2026,11,29),26+IF(Options!$B$8="是",23,0),0)-IF(C744=DATE(2026,11,30),26,0)-IF(C744=DATE(2026,12,1),64,0)-IF(C744=DATE(2026,11,28),38,0)-IF(C744=DATE(2026,12,2),26,0))) | I744: =IF(AND(C744>=DATE(2026,11,29),C744<=DATE(2026,12,1)),B744*60,0) | J744: =IF(A744="",0,B744*(IF(C744=DATE(2026,11,28),38,0)+IF(C744=DATE(2026,12,1),38,0)+IF(C744=DATE(2026,12,2),26,0))) | K744: =IF(C744=Options!$B$9,B744*12,0) | L744: =IF(C744=Options!$B$9,B744*Options!$Z$6,0) | M744: 0 | N744: =SUM(E744:M744)
A745: =IF(AND(C745>=Options!$B$9,C745<=Options!$B$10),"Denver","") | B745: =IF(A745="","",18) | C745: 46306 | D745: =IF(A745="","",IF(C745=DATE(2026,11,29),"培训；注册午餐；早餐参数",IF(C745=DATE(2026,11,30),"培训；注册午餐",IF(C745=DATE(2026,12,1),"培训；注册午餐；机构晚餐",IF(C745=Options!$B$9,"抵达；"&IF(C745=DATE(2026,11,28),"机构晚餐","无统一供餐"),IF(C745=Options!$B$10,"返程；"&IF(C745=DATE(2026,12,2),"机构午餐","无统一供餐"),"差旅状态；无统一日程")))))) | E745: =IF(C745=Options!$B$9,Options!$C$16,0) | F745: =IF(AND(A745<>"",C745<Options!$B$10),B745*Options!$X$6,0) | G745: =F745*12% | H745: =IF(A745="",0,B745*(92*IF(OR(C745=Options!$B$9,C745=Options!$B$10),75%,100%)-IF(C745=DATE(2026,11,29),26+IF(Options!$B$8="是",23,0),0)-IF(C745=DATE(2026,11,30),26,0)-IF(C745=DATE(2026,12,1),64,0)-IF(C745=DATE(2026,11,28),38,0)-IF(C745=DATE(2026,12,2),26,0))) | I745: =IF(AND(C745>=DATE(2026,11,29),C745<=DATE(2026,12,1)),B745*60,0) | J745: =IF(A745="",0,B745*(IF(C745=DATE(2026,11,28),38,0)+IF(C745=DATE(2026,12,1),38,0)+IF(C745=DATE(2026,12,2),26,0))) | K745: =IF(C745=Options!$B$9,B745*12,0) | L745: =IF(C745=Options!$B$9,B745*Options!$Z$6,0) | M745: 0 | N745: =SUM(E745:M745)
...

Sheet Sources
A1: 资料依据与预算口径
A4: ID | B4: 主题 | C4: 来源/文件 | D4: 条款/页/条件 | E4: 查询时间 | F4: 金额/口径 | G4: 适用方案 | H4: 状态
A5: FL-ORD | B5: 机票 | C5: https://www.google.com/travel/flights?hl=en&curr=USD | D5: DCA–ORD; 2026-11-28/12-02; 1 adult economy; American 6:00–7:32, nonstop; American 15:00–18:04, nonstop. Google称必需税费已含，行李等可另收。 | E5: 2026-10-23 14:00 UTC | F5: USD 271.00/人往返 | G5: Chicago | H5: 动态估算；未预订
A6: HT-ORD | B6: 住宿 | C6: https://www.google.com/travel/search?hl=en&gl=us&curr=USD | D6: Embassy Suites by Hilton Chicago O'Hare Rosemont; 2026-11-28至12-02；页面默认2旅客/1房（作为每房起价代理，非单人已确认报价）；页面卡片标Free breakfast。税费、房型、单人入住价格、团体房量待酒店书面确认。 | E6: 2026-10-23 14:00 UTC | F6: USD 126.00/房夜起 | G6: Chicago | H6: 动态估算；未预订
A7: FL-DEN | B7: 机票 | C7: https://www.google.com/travel/flights?hl=en&curr=USD | D7: DCA–DEN; 2026-11-28/12-02; 1 adult economy; Frontier 7:00–9:16, nonstop; Frontier 7:30–12:48, nonstop. Google称必需税费已含，行李等可另收。 | E7: 2026-10-23 14:00 UTC | F7: USD 466.00/人往返 | G7: Denver | H7: 动态估算；未预订
A8: HT-DEN | B8: 住宿 | C8: https://www.google.com/travel/search?hl=en&gl=us&curr=USD | D8: Holiday Inn Express Denver Downtown by IHG; 2026-11-28至12-02；页面默认2旅客/1房（作为每房起价代理，非单人已确认报价）；页面卡片标Free breakfast。税费、房型、单人入住价格、团体房量待酒店书面确认。 | E8: 2026-10-23 14:00 UTC | F8: USD 75.00/房夜起 | G8: Denver | H8: 动态估算；未预订
A9: FL-PHX | B9: 机票 | C9: https://www.google.com/travel/flights?hl=en&curr=USD | D9: DCA–PHX; 2026-11-28/12-02; 1 adult economy; American 10:32–13:51, nonstop; American 12:49–19:00, nonstop. Google称必需税费已含，行李等可另收。 | E9: 2026-10-23 14:00 UTC | F9: USD 581.00/人往返 | G9: Phoenix | H9: 动态估算；未预订
A10: HT-PHX | B10: 住宿 | C10: https://www.google.com/travel/search?hl=en&gl=us&curr=USD | D10: SureStay InnSuites Phoenix Hotel & Suites by Best Western; 2026-11-28至12-02；页面默认2旅客/1房（作为每房起价代理，非单人已确认报价）；页面卡片标Free breakfast。税费、房型、单人入住价格、团体房量待酒店书面确认。 | E10: 2026-10-23 14:00 UTC | F10: USD 93.00/房夜起 | G10: Phoenix | H10: 动态估算；未预订
A11: FL-BOS | B11: 机票 | C11: https://www.google.com/travel/flights?hl=en&curr=USD | D11: DCA–BOS; 2026-11-28/12-02; 1 adult economy; Delta 6:00–7:38, nonstop; Delta 16:00–17:59, nonstop. Google称必需税费已含，行李等可另收。 | E11: 2026-10-23 14:00 UTC | F11: USD 330.00/人往返 | G11: Boston | H11: 动态估算；未预订
A12: HT-BOS | B12: 住宿 | C12: https://www.google.com/travel/search?hl=en&gl=us&curr=USD | D12: Hyatt Place Boston / Seaport District; 2026-11-28至12-02；页面默认2旅客/1房（作为每房起价代理，非单人已确认报价）；页面卡片标Free breakfast。税费、房型、单人入住价格、团体房量待酒店书面确认。 | E12: 2026-10-23 14:00 UTC | F12: USD 202.00/房夜起 | G12: Boston | H12: 动态估算；未预订
A13: FL-SEA | B13: 机票 | C13: https://www.google.com/travel/flights?hl=en&curr=USD | D13: DCA–SEA; 2026-11-28/12-02; 1 adult economy; Alaska 8:00–11:06, nonstop; Alaska 14:02–21:59, nonstop. Google称必需税费已含，行李等可另收。 | E13: 2026-10-23 14:00 UTC | F13: USD 977.00/人往返 | G13: Seattle | H13: 动态估算；未预订
A14: HT-SEA | B14: 住宿 | C14: https://www.google.com/travel/search?hl=en&gl=us&curr=USD | D14: Hyatt House Seattle/Downtown; 2026-11-28至12-02；页面默认2旅客/1房（作为每房起价代理，非单人已确认报价）；页面卡片标Free breakfast。税费、房型、单人入住价格、团体房量待酒店书面确认。 | E14: 2026-10-23 14:00 UTC | F14: USD 170.00/房夜起 | G14: Seattle | H14: 动态估算；未预订
A15: GSA27 | B15: 住宿/M&IE | C15: FY2027_PerDiemRates_Validated090126.xlsx | D15: FY2027，生效2026-10-01；按县和季节。Chicago 11/28-30 $232、12/1 $148；Denver $170；Phoenix $165；Boston $213；Seattle $188。M&IE：Phoenix $86，其余$92。 | E15: 附件版本 | F15: 住宿上限/房夜；M&IE/日 | G15: 全部 | H15: 适用
... A27: APP | B27: 审批字段 | C27: Conference-Attendance-fillable-Approval-Template.pdf | D27: 需事件目的、任务关联、人数理由、替代方式、议程、地点成本估算、参会者明细、财务/POC等；模板不替代批准。 | E27: 附件版本 | F27: 无金额 | G27: 全部 | H27: 需补证
