Workbook

Sheet Params
A1: 可调整参数（修改后 Daily / Options 各表自动更新；导出快照文件前请重新核对）
A2: 参数 | B2: 交付采用值 | C2: 允许范围/说明
A3: 批准预算上限（含储备，USD） | B3: 53000 | C3: 0-100000
A4: 票价调整系数 | B4: 1 | C4: 0.5-2；压力情景=调整后票价再×1.2
A5: 应急储备比例（适用于基础费用小计） | B5: 0.05 | C5: 0-20%
A6: 11月28日政府提供早餐 | B6: 否 | C6: 是/否；改为“是”时不新增采购费用，仅减少M&IE参考额
A7: 抵达日期 | B7: 2026-11-28 | C7: 须完整参加11/29-12/1培训
A8: 返程日期 | B8: 2026-12-02 | C8: 同上
A9: 参训人数（决策档） | B9: 24 | C9: 18或24
A11: 报价适用性检查
A12: 报价检索日期（Google Flights / Google Hotels） | B12: 2026-10-24
A13: 行程与报价日期一致性 | B13: =IF(AND(B7="2026-11-28",B8="2026-12-02"),"一致：报价适用（仍须出票前复核）","不一致：报价不适用，须重新询价（暂估）")
A14: 参数变动提示 | B14: =IF(AND(B3=53000,B4=1,B5=0.05,B6="否",B7="2026-11-28",B8="2026-12-02",B9=24),"与交付快照一致","参数已调整：请重新核对并重新导出 docx/csv/pptx/pdf 快照")
A16: 未询价参数（默认0，执行前须询价；不默认各方案相同）
A17: 芝加哥 场地+茶歇（USD，整团） | B17: 0
A18: 丹佛 场地+茶歇 | B18: 0
A19: 凤凰城 场地+茶歇 | B19: 0
A20: 波士顿 场地+茶歇 | B20: 0
A21: 西雅图 场地+茶歇 | B21: 0

Sheet Daily
A1: 逐日明细（推荐方案：Chicago，24人；M&IE为参考额，不计入预算）
A2: 依据：41 CFR 301-11.17（酒店免费早餐不扣M&IE）、301-11.18（政府/注册费提供餐食扣减）；FY2027费率文件；GSA FY2025 M&IE分项（92档：早23/午26/晚38/杂5，首末日69）
A4: 日期 | B4: 行程内容 | C4: 住宿夜数(间) | D4: 早餐来源 | E4: 机构/注册费供餐 | F4: M&IE参考额-每人(FY27,CHI) | G4: 机构供餐成本-每人(估) | H4: 说明
A5: 2026-11-28 | B5: DCA→ORD 航班+酒店入住；晚间机构晚餐 | C5: 1 | D5: 酒店含早(次日起) | E5: 晚餐(机构) | F5: =MAX(0,0.75*92-38-IF(Params!$B$6="是",23,0)) | G5: =38 | H5: 首末日75%扣机构晚餐38；参数=是再扣早餐23
A6: 2026-11-29 | B6: 培训日1；午餐含于注册费；酒店免费早餐不扣减 | C6: 1 | D6: 酒店含早(免费,301-11.17) | E6: 午餐(注册费) | F6: =92-26 | G6: 0 | H6: 仅扣注册费午餐26
A7: 2026-11-30 | B7: 培训日2；午餐含于注册费 | C7: 1 | D7: 酒店含早(免费,301-11.17) | E7: 午餐(注册费) | F7: =92-26 | G7: 0 | H7: 同前
A8: 2026-12-01 | B8: 培训日3；午餐含于注册费；晚间机构晚餐 | C8: 1 | D8: 酒店含早(免费,301-11.17) | E8: 午餐(注册费)+晚餐(机构) | F8: =92-26-38 | G8: =38 | H8: 扣午餐26与机构晚餐38
A9: 2026-12-02 | B9: 退房返程；午餐机构提供 | C9: 0 | D9: — | E9: 午餐(机构) | F9: =MAX(0,0.75*92-26) | G9: =26 | H9: 首末日75%扣机构午餐26
A10: 合计（每人） | F10: =SUM(F5:F9) | G10: =SUM(G5:G9)
A12: 注：M&IE参考额不计入本次预算（预算仅含题面列明费用）；机构供餐成本按FY27芝加哥餐值估算并计入预算“机构供餐”行。
A13: 注：11/29-12/1行公式中“酒店含早不扣”依301-11.17；参数B6=“是”时额外扣早餐值且不新增采购费用。

Sheet Options
A1: 候选方案比较（报价日2026-10-24；Google Flights/Google Hotels；USD；4夜=11/28入住-12/2退房）
A2: 酒店准入：Google评分≥4.0且评价数≥500，近期评论无系统性卫生/夜间噪声/维护缺陷；超FY27住宿上限者不得作为合规推荐（不截价比较）。
A4: 每城输入（单人/单间口径；整团按人数×单价，未确认团体价）
A5: 城市 | B5: 目的地机场/出发机场 | C5: 往返机票/人 | D5: 酒店(推荐) | E5: 房价/夜/间 | F5: 含早 | G5: 评分(评价数) | H5: 备选酒店 | I5: 备选房价/夜 | J5: M&IE餐值:早/午/晚 | K5: 地面交通/人(估) | L5: 注册费/人
A6: Chicago, IL | B6: ORD / DCA | C6: 270 | D6: Embassy Suites by Hilton Chicago O'Hare Rosemont | E6: 101 | F6: 含早 | G6: 4.1 (3.4K) | H6: DoubleTree by Hilton Chicago O'Hare Airport-Rosemont | I6: 133 | J6: 23/26/38 | K6: 5 | L6: 180
A7: Denver, CO | B7: DEN / IAD | C7: 578 | D7: Holiday Inn Express & Suites Denver Airport by IHG | E7: 113 | F7: 含早 | G7: 4.0 (1.4K) | H7: Tru by Hilton Denver Airport Tower Road | I7: 112 | J7: 23/26/38 | K7: 10 | L7: 180
A8: Phoenix, AZ | B8: PHX / IAD | C8: 499 | D8: Holiday Inn & Suites Phoenix Airport North by IHG | E8: 126 | F8: 早餐$计入 | G8: 4.0 (1.8K) | H8: Crowne Plaza Phoenix Airport - PHX | I8: 127 | J8: 22/23/36 | K8: 10 | L8: 180
A9: Boston, MA | B9: BOS / DCA | C9: 311 | D9: Residence Inn by Marriott Boston Logan Airport/Chelsea | E9: 154 | F9: 含早 | G9: 4.3 (855) | H9: Courtyard by Marriott Boston Logan Airport | I9: 165 | J9: 23/26/38 | K9: 5 | L9: 180
A10: Seattle, WA | B10: SEA / IAD | C10: 590 | D10: Country Inn & Suites by Radisson Sea-Tac | E10: 101 | F10: 含早 | G10: 4.3 (2.0K) | H10: Holiday Inn Express & Suites Seattle-Sea-Tac Airport by IHG | I10: 100 | J10: 23/26/38 | K10: 10 | L10: 180
A13: 整团测算（N=人数；住宿=房价×4夜×N；住宿税=12%×住宿；机构供餐=每人(38+38+午值)×N；PHX早餐$=15/夜/间计入住宿）
A14: 城市 | B14: N | C14: 机票小计 | D14: 住宿小计(含PHX早餐$) | E14: 住宿税12% | F14: 注册费 | G14: 机构供餐 | H14: 地面交通 | I14: 未询价(场地+茶歇) | J14: 基础小计 | K14: 储备 | L14: 含储备总额 | M14: 对上限余量 | N14: 可行 | O14: 人均(含储备) | P14: 24人可行总额 | Q14: 18人可行总额
A15: =A6 | B15: 18 | C15: =C6*Params!$B$4*B15 | D15: =(E6+IF(A15="Phoenix, AZ",15,0))*4*B15 | E15: =0.12*D15 | F15: =L6*B15 | G15: =(38+38+IF(A15="Phoenix, AZ",23,26))*B15 | H15: =K6*B15 | I15: =Params!B17 | J15: =SUM(C15:I15) | K15: =J15*Params!$B$5 | L15: =J15+K15 | M15: =Params!$B$3-L15 | N15: =IF(L15<=Params!$B$3,"是","否") | O15: =L15/B15 | P15: =IF(AND($B15=24,$N15="是"),$L15,"") | Q15: =IF(AND($B15=18,$N15="是"),$L15,"")
A16: =A6 | B16: 24 | C16: =C6*Params!$B$4*B16 | D16: =(E6+IF(A16="Phoenix, AZ",15,0))*4*B16 | E16: =0.12*D16 | F16: =L6*B16 | G16: =(38+38+IF(A16="Phoenix, AZ",23,26))*B16 | H16: =K6*B16 | I16: =Params!B17 | J16: =SUM(C16:I16) | K16: =J16*Params!$B$5 | L16: =J16+K16 | M16: =Params!$B$3-L16 | N16: =IF(L16<=Params!$B$3,"是","否") | O16: =L16/B16 | P16: =IF(AND($B16=24,$N16="是"),$L16,"") | Q16: =IF(AND($B16=18,$N16="是"),$L16,"")
A17: =A7 | B17: 18 | C17: =C7*Params!$B$4*B17 | D17: =(E7+IF(A17="Phoenix, AZ",15,0))*4*B17 | E17: =0.12*D17 | F17: =L7*B17 | G17: =(38+38+IF(A17="Phoenix, AZ",23,26))*B17 | H17: =K7*B17 | I17: =Params!B18 | J17: =SUM(C17:I17) | K17: =J17*Params!$B$5 | L17: =J17+K17 | M17: =Params!$B$3-L17 | N17: =IF(L17<=Params!$B$3,"是","否") | O17: =L17/B17 | P17: =IF(AND($B17=24,$N17="是"),$L17,"") | Q17: =IF(AND($B17=18,$N17="是"),$L17,"")
A18: =A7 | B18: 24 | C18: =C7*Params!$B$4*B18 | D18: =(E7+IF(A18="Phoenix, AZ",15,0))*4*B18 | E18: =0.12*D18 | F18: =L7*B18 | G18: =(38+38+IF(A18="Phoenix, AZ",23,26))*B18 | H18: =K7*B18 | I18: =Params!B18 | J18: =SUM(C18:I18) | K18: =J18*Params!$B$5 | L18: =J18+K18 | M18: =Params!$B$3-L18 | N18: =IF(L18<=Params!$B$3,"是","否") | O18: =L18/B18 | P18: =IF(AND($B18=24,$N18="是"),$L18,"") | Q18: =IF(AND($B18=18,$N18="是"),$L18,"")
A19: =A8 | B19: 18 | C19: =C8*Params!$B$4*B19 | D19: =(E8+IF(A19="Phoenix, AZ",15,0))*4*B19 | E19: =0.12*D19 | F19: =L8*B19 | G19: =(38+38+IF(A19="Phoenix, AZ",23,26))*B19 | H19: =K8*B19 | I19: =Params!B19 | J19: =SUM(C19:I19) | K19: =J19*Params!$B$5 | L19: =J19+K19 | M19: =Params!$B$3-L19 | N19: =IF(L19<=Params!$B$3,"是","否") | O19: =L19/B19 | P19: =IF(AND($B19=24,$N19="是"),$L19,"") | Q19: =IF(AND($B19=18,$N19="是"),$L19,"")
A20: =A8 | B20: 24 | C20: =C8*Params!$B$4*B20 | D20: =(E8+IF(A20="Phoenix, AZ",15,0))*4*B20 | E20: =0.12*D20 | F20: =L8*B20 | G20: =(38+38+IF(A20="Phoenix, AZ",23,26))*B20 | H20: =K8*B20 | I20: =Params!B19 | J20: =SUM(C20:I20) | K20: =J20*Params!$B$5 | L20: =J20+K20 | M20: =Params!$B$3-L20 | N20: =IF(L20<=Params!$B$3,"是","否") | O20: =L20/B20 | P20: =IF(AND($B20=24,$N20="是"),$L20,"") | Q20: =IF(AND($B20=18,$N20="是"),$L20,"")
A21: =A9 | B21: 18 | C21: =C9*Params!$B$4*B21 | D21: =(E9+IF(A21="Phoenix, AZ",15,0))*4*B21 | E21: =0.12*D21 | F21: =L9*B21 | G21: =(38+38+IF(A21="Phoenix, AZ",23,26))*B21 | H21: =K9*B21 | I21: =Params!B20 | J21: =SUM(C21:I21) | K21: =J21*Params!$B$5 | L21: =J21+K21 | M21: =Params!$B$3-L21 | N21: =IF(L21<=Params!$B$3,"是","否") | O21: =L21/B21 | P21: =IF(AND($B21=24,$N21="是"),$L21,"") | Q21: =IF(AND($B21=18,$N21="是"),$L21,"")
A22: =A9 | B22: 24 | C22: =C9*Params!$B$4*B22 | D22: =(E9+IF(A22="Phoenix, AZ",15,0))*4*B22 | E22: =0.12*D22 | F22: =L9*B22 | G22: =(38+38+IF(A22="Phoenix, AZ",23,26))*B22 | H22: =K9*B22 | I22: =Params!B20 | J22: =SUM(C22:I22) | K22: =J22*Params!$B$5 | L22: =J22+K22 | M22: =Params!$B$3-L22 | N22: =IF(L22<=Params!$B$3,"是","否") | O22: =L22/B22 | P22: =IF(AND($B22=24,$N22="是"),$L22,"") | Q22: =IF(AND($B22=18,$N22="是"),$L22,"")
A23: =A10 | B23: 18 | C23: =C10*Params!$B$4*B23 | D23: =(E10+IF(A23="Phoenix, AZ",15,0))*4*B23 | E23: =0.12*D23 | F23: =L10*B23 | G23: =(38+38+IF(A23="Phoenix, AZ",23,26))*B23 | H23: =K10*B23 | I23: =Params!B21 | J23: =SUM(C23:I23) | K23: =J23*Params!$B$5 | L23: =J23+K23 | M23: =Params!$B$3-L23 | N23: =IF(L23<=Params!$B$3,"是","否") | O23: =L23/B23 | P23: =IF(AND($B23=24,$N23="是"),$L23,"") | Q23: =IF(AND($B23=18,$N23="是"),$L23,"")
A24: =A10 | B24: 24 | C24: =C10*Params!$B$4*B24 | D24: =(E10+IF(A24="Phoenix, AZ",15,0))*4*B24 | E24: =0.12*D24 | F24: =L10*B24 | G24: =(38+38+IF(A24="Phoenix, AZ",23,26))*B24 | H24: =K10*B24 | I24: =Params!B21 | J24: =SUM(C24:I24) | K24: =J24*Params!$B$5 | L24: =J24+K24 | M24: =Params!$B$3-L24 | N24: =IF(L24<=Params!$B$3,"是","否") | O24: =L24/B24 | P24: =IF(AND($B24=24,$N24="是"),$L24,"") | Q24: =IF(AND($B24=18,$N24="是"),$L24,"")
A26: 推荐判定（人数优先→含储备总额低→城市英文名序）
A27: 24人档可行方案中含储备总额最低者 | B27: =INDEX($A$15:$A$24,MATCH(MIN(P15:P24),P15:P24,0))
A28: 备选（24人档含储备总额次低者） | B28: =INDEX($A$15:$A$24,MATCH(SMALL(P15:P24,2),P15:P24,0))
A29: 18人档最低者（24人全不可行时启用） | B29: =INDEX($A$15:$A$24,MATCH(MIN(Q15:Q24),Q15:Q24,0))
A30: 第三顺位（24人档第三低） | B30: =INDEX($A$15:$A$24,MATCH(SMALL(P15:P24,3),P15:P24,0))
A31: 压力情景：票价在调整系数基础上再+20%（仅机票×1.2）
A32: 城市 | B32: N | C32: 机票小计×1.2 | D32: 基础小计 | E32: 储备 | F32: 含储备总额 | G32: 余量 | H32: 可行
A33: =A15 | B33: =B15 | C33: =C15*1.2 | D33: =D15+E15+F15+G15+H15+I15+C33 | E33: =D33*Params!$B$5 | F33: =D33+E33 | G33: =Params!$B$3-F33 | H33: =IF(F33<=Params!$B$3,"是","否")
A34: =A16 | B34: =B16 | C34: =C16*1.2 | D34: =D16+E16+F16+G16+H16+I16+C34 | E34: =D34*Params!$B$5 | F34: =D34+E34 | G34: =Params!$B$3-F34 | H34: =IF(F34<=Params!$B$3,"是","否")
A35: =A17 | B35: =B17 | C35: =C17*1.2 | D35: =D17+E17+F17+G17+H17+I17+C35 | E35: =D35*Params!$B$5 | F35: =D35+E35 | G35: =Params!$B$3-F35 | H35: =IF(F35<=Params!$B$3,"是","否")
A36: =A18 | B36: =B18 | C36: =C18*1.2 | D36: =D18+E18+F18+G18+H18+I18+C36 | E36: =D36*Params!$B$5 | F36: =D36+E36 | G36: =Params!$B$3-F36 | H36: =IF(F36<=Params!$B$3,"是","否")
A37: =A19 | B37: =B19 | C37: =C19*1.2 | D37: =D19+E19+F19+G19+H19+I19+C37 | E37: =D37*Params!$B$5 | F37: =D37+E37 | G37: =Params!$B$3-F37 | H37: =IF(F37<=Params!$B$3,"是","否")
A38: =A20 | B38: =B20 | C38: =C20*1.2 | D38: =D20+E20+F20+G20+H20+I20+C38 | E38: =D38*Params!$B$5 | F38: =D38+E38 | G38: =Params!$B$3-F38 | H38: =IF(F38<=Params!$B$3,"是","否")
A39: =A21 | B39: =B21 | C39: =C21*1.2 | D39: =D21+E21+F21+G21+H21+I21+C39 | E39: =D39*Params!$B$5 | F39: =D39+E39 | G39: =Params!$B$3-F39 | H39: =IF(F39<=Params!$B$3,"是","否")
A40: =A22 | B40: =B22 | C40: =C22*1.2 | D40: =D22+E22+F22+G22+H22+I22+C40 | E40: =D40*Params!$B$5 | F40: =D40+E40 | G40: =Params!$B$3-F40 | H40: =IF(F40<=Params!$B$3,"是","否")
A41: =A23 | B41: =B23 | C41: =C23*1.2 | D41: =D23+E23+F23+G23+H23+I23+C41 | E41: =D41*Params!$B$5 | F41: =D41+E41 | G41: =Params!$B$3-F41 | H41: =IF(F41<=Params!$B$3,"是","否")
A42: =A24 | B42: =B24 | C42: =C24*1.2 | D42: =D24+E24+F24+G24+H24+I24+C42 | E42: =D42*Params!$B$5 | F42: =D42+E42 | G42: =Params!$B$3-F42 | H42: =IF(F42<=Params!$B$3,"是","否")
A44: 临界值与分段行动条件（f=机票涨幅0-20%；V=该城未询价费用）
A45: 推荐切换临界涨幅(Chicago 24 vs 备选Boston 24) | B45: =(J22-J16)/(C16-C22) | C45: 负值→0-20%区间内不切换；储备率对两侧同比例，临界涨幅以基础小计与机票小计解出 | D45: 未询价上限口径：储备同样覆盖未询价费用，故 V_max=上限/(1+储备率)-基础小计
...

Sheet History
A1: FY2025/FY2026/FY2027 住宿上限与M&IE对照（行程月份：2026年11月、12月；历史对照不代表过去真实报价，不适用本次报销）
A3: 城市 | B3: 县/区域 | C3: FY25住宿上限(11月) | D3: FY25(12月) | E3: FY26(11月) | F3: FY26(12月) | G3: FY27(11月) | H3: FY27(12月) | I3: M&IE(三版同) | J3: 推荐酒店房价/夜 | K3: FY27合规 | L3: FY26合规 | M3: FY25合规
A4: Chicago, IL | B4: Cook / Lake | C4: 223 | D4: 142 | E4: 223 | F4: 142 | G4: 232 | H4: 148 | I4: 92 | J4: 101 | K4: =IF(AND(J4<=G4,J4<=H4),"合规","超限") | L4: =IF(AND(J4<=E4,J4<=F4),"合规","超限") | M4: =IF(AND(J4<=C4,J4<=D4),"合规","超限")
A5: Denver, CO | B5: Denver / Adams / Arapahoe / Jefferson | C5: 165 | D5: 165 | E5: 165 | F5: 165 | G5: 170 | H5: 170 | I5: 92 | J5: 113 | K5: =IF(AND(J5<=G5,J5<=H5),"合规","超限") | L5: =IF(AND(J5<=E5,J5<=F5),"合规","超限") | M5: =IF(AND(J5<=C5,J5<=D5),"合规","超限")
A6: Phoenix, AZ | B6: Maricopa | C6: 160 | D6: 160 | E6: 160 | F6: 160 | G6: 165 | H6: 165 | I6: 86 | J6: 126 | K6: =IF(AND(J6<=G6,J6<=H6),"合规","超限") | L6: =IF(AND(J6<=E6,J6<=F6),"合规","超限") | M6: =IF(AND(J6<=C6,J6<=D6),"合规","超限")
A7: Boston, MA | B7: Suffolk, city of Cambridge | C7: 209 | D7: 209 | E7: 209 | F7: 209 | G7: 213 | H7: 213 | I7: 92 | J7: 154 | K7: =IF(AND(J7<=G7,J7<=H7),"合规","超限") | L7: =IF(AND(J7<=E7,J7<=F7),"合规","超限") | M7: =IF(AND(J7<=C7,J7<=D7),"合规","超限")
A8: Seattle, WA | B8: King | C8: 188 | D8: 188 | E8: 188 | F8: 188 | G8: 188 | H8: 188 | I8: 92 | J8: 101 | K8: =IF(AND(J8<=G8,J8<=H8),"合规","超限") | L8: =IF(AND(J8<=E8,J8<=F8),"合规","超限") | M8: =IF(AND(J8<=C8,J8<=D8),"合规","超限")
A9: 被排除酒店对照
A10: The Westin Denver International Airport | B10: 426 | C10: =IF(B10<=G5,"合规","超限：FY27 11月上限170") | D10: 三版均超限，不得作为合规推荐，不截价比较
A12: 结论
A13: 三版费率对预算金额无影响（预算采用市场报价）；对合规性：五城推荐酒店在三版下均合规，Westin在三版下均超限；选址判断不因年度版本改变。M&IE三版同值（92/86），餐食扣减参考额不变。

Sheet Itinerary
A1: 行程与酒店组合（衔接核对）
A3: 城市 | B3: 去程航班(11/28) | C3: 到达 | D3: 返程航班(12/2) | E3: 离开 | F3: 酒店 | G3: 入住 | H3: 退房 | I3: 机场-酒店交通 | J3: 场地日期/容量
A4: Chicago | B4: AA DCA-ORD 非经停 | C4: 07:32 | D4: AA ORD-DCA 非经停 | E4: 16:59 | F4: Embassy Suites Rosemont | G4: 11/28 | H4: 12/2 | I4: 酒店穿梭(待核实) | J4: 11/29-12/1, ≥24人(待核实)
A5: Denver | B5: UA IAD-DEN 非经停 | C5: 08:19 | D5: UA DEN-IAD 非经停 | E5: 14:10 | F5: HIE Denver Airport | G5: 11/28 | H5: 12/2 | I5: 酒店穿梭(待核实) | J5: 同上
A6: Phoenix | B6: UA IAD-PHX 非经停 | C6: 11:33 | D6: UA PHX-IAD 非经停 | E6: 14:54 | F6: HI & Suites Airport North | G6: 11/28 | H6: 12/2 | I6: 酒店穿梭(待核实) | J6: 同上
A7: Boston | B7: DL DCA-BOS 非经停 | C7: 07:38 | D7: DL BOS-DCA 非经停 | E7: 14:29 | F7: Residence Inn Chelsea | G7: 11/28 | H7: 12/2 | I7: 酒店穿梭(待核实) | J7: 同上
A8: Seattle | B8: UA IAD-SEA 非经停 | C8: 20:56 | D8: UA SEA-IAD 非经停 | E8: 08:09 | F8: Country Inn & Suites Sea-Tac | G8: 11/28 | H8: 12/2 | I8: 酒店穿梭(待核实) | J8: 同上
A10: 衔接说明：去程11/28抵达均早于酒店入住时间或可寄存；返程12/2起飞均晚于退房+培训结束次日；Seattle去程20:56抵达当晚入住、次日培训开始前无冲突。场地容量与团体库存未核实，列为执行条件。

Sheet Sources
A1: 来源登记（查询时间均为2026-10-24 UTC）
A3: 项目 | B3: 数值/结论 | C3: 来源 | D3: URL | E3: 查询时间 | F3: 适用日期/条件
A4: 机票 CHI | B4: DCA-ORD往返非经停 $270/人 | C4: Google Flights | D4: https://www.google.com/travel/flights | E4: 2026-10-24 | F4: 2026-11-28去/12-02返,1人,含税费, Economy incl. Basic
A5: 机票 DEN | B5: IAD-DEN往返非经停 $578/人 | C5: Google Flights | D5: https://www.google.com/travel/flights | E5: 2026-10-24 | F5: 同上
A6: 机票 PHX | B6: IAD-PHX往返非经停 $499/人 | C6: Google Flights | D6: https://www.google.com/travel/flights | E6: 2026-10-24 | F6: 同上
A7: 机票 BOS | B7: DCA-BOS往返非经停 $311/人 | C7: Google Flights | D7: https://www.google.com/travel/flights | E7: 2026-10-24 | F7: 同上
A8: 机票 SEA | B8: IAD-SEA往返非经停 $590/人 | C8: Google Flights | D8: https://www.google.com/travel/flights | E8: 2026-10-24 | F8: 同上
A9: 酒店 CHI 推荐 | B9: Embassy Suites Rosemont $101/夜 含早 4.1(3.4K) | C9: Google Hotels | D9: https://www.google.com/travel/hotels | E9: 2026-10-24 | F9: 11/28-12/2,1间1人,USD,列表价
A10: 酒店 CHI 备选 | B10: DoubleTree O'Hare-Rosemont $133/夜 早餐$ 4.2(3.1K) | C10: Google Hotels | D10: https://www.google.com/travel/hotels | E10: 2026-10-24 | F10: 同上
A11: 酒店 CHI 排除 | B11: ESA Allstate Arena 3.9分未达准入线且当前列表无报价，仅作历史对照不纳入测算 | C11: Google Hotels | D11: https://www.google.com/travel/hotels | E11: 2026-10-24 | F11: 未达质量准入
A12: 酒店 DEN 推荐 | B12: HIE Denver Airport $113/夜 含早 4.0(1.4K) | C12: Google Hotels | D12: https://www.google.com/travel/hotels | E12: 2026-10-24 | F12: 同上;ESA Aurora North当前列表无报价
A13: 酒店 DEN 备选 | B13: Tru by Hilton Denver Airport Tower Road $112/夜 含早 4.0(881) | C13: Google Hotels | D13: https://www.google.com/travel/hotels | E13: 2026-10-24 | F13: 同上;La Quinta 3.7未达准入线改列排除
A14: 酒店 DEN 排除 | B14: The Westin DEN $426/夜 > FY27上限170; La Quinta DIA 3.7(2.7K)未达准入线 | C14: Google Hotels | D14: https://www.google.com/travel/hotels | E14: 2026-10-24 | F14: 超限/未达准入不得推荐
... A28: 地面交通 | B28: 出发机场往返: DCA$5/IAD$10/目的地铁路或穿梭$0(酒店穿梭,待核实) | C28: 内部估算 | D28: — | E28: 2026-10-24 | F28: 估算,待询价
