Workbook

Sheet Parameters
A1: 可调整预算参数 / Adjustable Budget Parameters
A3: 参数 / Parameter | B3: 值 / Value | C3: 单位 | D3: 回算范围 / 说明
A4: 批准预算上限 Budget cap (incl. reserve) | B4: 53000 | C4: USD | D4: 0 – 100,000
A5: 票价调整系数 Fare adjustment factor | B5: 1 | C5: × | D5: 0.5 – 2.0
A6: 应急储备比例 Reserve ratio | B6: 0.05 | C6: % | D6: 0 – 20% of base subtotal
A7: 机票压力倍数 Airfare stress multiplier | B7: 1.2 | C7: × | D7: 题面固定: 调整后票价 ×1.2
A8: 住宿税率 Lodging tax rate (internal est.) | B8: 0.12 | C8: % | D8: 题面内部估算口径, 非当地实际税率
A9: 11/29 政府提供早餐 Nov-29 govt breakfast (1=是/0=否) | B9: 0 | C9: 1/0 | D9: 改为1=是: 不新增采购费, 触发M&IE早餐扣减
A10: 抵达日期 Arrival date | B10: 46354 | C10: date | D10: 可调, 须完整参训
A11: 返程日期 Return date | B11: 46358 | C11: date | D11: 可调, 须完整参训
A12: 注册费/人 Registration per person | B12: 180 | C12: USD | D12: 含11/29,11/30,12/1午餐
A13: 参训人数方案A Headcount option A | B13: 18 | C13: 人 | D13: 固定候选
A14: 参训人数方案B Headcount option B | B14: 24 | C14: 人 | D14: 固定候选
A16: M&IE 分项 (GSA FY2025 M&IE Breakdown, 适用 $92 档; FY2027分项待核对)
A17: M&IE 全日档 M&IE full-day tier | B17: 92 | C17: USD
A18: 早餐扣减 Breakfast deduction | B18: 23 | C18: USD
A19: 午餐扣减 Lunch deduction | B19: 26 | C19: USD
A20: 晚餐扣减 Dinner deduction | B20: 38 | C20: USD
A21: 杂费(下限) Incidental floor | B21: 5 | C21: USD
A22: 首末日比例 First/last-day factor | B22: 0.75 | C22: ×
A24: 提示 / Reminder: 修改上述参数后, Daily 与 Options 自动更新; 交付的 Word / CSV / PPT 为当前参数快照, 参数变更后须重新核对并重新导出相应文件, 避免误用旧结论。

Sheet Daily
A1: 各候选地逐日预算明细 (每人 / per person) — 住宿=GSA FY2027 per diem 上限; M&IE 按 FTR 301-11.18 扣减政府/注册供餐, 酒店免费早餐不扣减(301-11.17)
A2: 城市 City | B2: 日期 Date | C2: 住宿上限 Lodging cap | D2: 住宿夜? Night | E2: 住宿费 Lodging | F2: M&IE档 tier | G2: 行程日? Travel day | H2: 首末日? First/Last | I2: M&IE毛额 Gross | J2: 早餐供 Bk | K2: 午餐供 Ln | L2: 晚餐供 Dn | M2: 扣减 Deduct | N2: M&IE净 Net
A3: Chicago | B3: 46353 | C3: 232 | D3: =IF(AND(B3>=Parameters!$B$10,B3<Parameters!$B$11),1,0) -> 0 | E3: =C3*D3 -> 0 | F3: 92 | G3: =IF(AND(B3>=Parameters!$B$10,B3<=Parameters!$B$11),1,0) -> 0 | H3: =IF(OR(B3=Parameters!$B$10,B3=Parameters!$B$11),1,0) -> 0 | I3: =IF(G3=1,IF(H3=1,Parameters!$B$22*F3,F3),0) -> 0 | J3: 0 | K3: 0 | L3: 0 | M3: =G3*(J3*Parameters!$B$18+K3*Parameters!$B$19+L3*Parameters!$B$20) -> 0 | N3: =IF(G3=1,MAX(I3-M3,Parameters!$B$21),0) -> 0
A4: Chicago | B4: 46354 | C4: 232 | D4: =IF(AND(B4>=Parameters!$B$10,B4<Parameters!$B$11),1,0) -> 1 | E4: =C4*D4 -> 232 | F4: 92 | G4: =IF(AND(B4>=Parameters!$B$10,B4<=Parameters!$B$11),1,0) -> 1 | H4: =IF(OR(B4=Parameters!$B$10,B4=Parameters!$B$11),1,0) -> 1 | I4: =IF(G4=1,IF(H4=1,Parameters!$B$22*F4,F4),0) -> 69 | J4: 0 | K4: 0 | L4: 1 | M4: =G4*(J4*Parameters!$B$18+K4*Parameters!$B$19+L4*Parameters!$B$20) -> 38 | N4: =IF(G4=1,MAX(I4-M4,Parameters!$B$21),0) -> 31
A5: Chicago | B5: 46355 | C5: 232 | D5: =IF(AND(B5>=Parameters!$B$10,B5<Parameters!$B$11),1,0) -> 1 | E5: =C5*D5 -> 232 | F5: 92 | G5: =IF(AND(B5>=Parameters!$B$10,B5<=Parameters!$B$11),1,0) -> 1 | H5: =IF(OR(B5=Parameters!$B$10,B5=Parameters!$B$11),1,0) -> 0 | I5: =IF(G5=1,IF(H5=1,Parameters!$B$22*F5,F5),0) -> 92 | J5: =Parameters!$B$9 -> 0 | K5: 1 | L5: 0 | M5: =G5*(J5*Parameters!$B$18+K5*Parameters!$B$19+L5*Parameters!$B$20) -> 26 | N5: =IF(G5=1,MAX(I5-M5,Parameters!$B$21),0) -> 66
A6: Chicago | B6: 46356 | C6: 232 | D6: =IF(AND(B6>=Parameters!$B$10,B6<Parameters!$B$11),1,0) -> 1 | E6: =C6*D6 -> 232 | F6: 92 | G6: =IF(AND(B6>=Parameters!$B$10,B6<=Parameters!$B$11),1,0) -> 1 | H6: =IF(OR(B6=Parameters!$B$10,B6=Parameters!$B$11),1,0) -> 0 | I6: =IF(G6=1,IF(H6=1,Parameters!$B$22*F6,F6),0) -> 92 | J6: 0 | K6: 1 | L6: 0 | M6: =G6*(J6*Parameters!$B$18+K6*Parameters!$B$19+L6*Parameters!$B$20) -> 26 | N6: =IF(G6=1,MAX(I6-M6,Parameters!$B$21),0) -> 66
A7: Chicago | B7: 46357 | C7: 148 | D7: =IF(AND(B7>=Parameters!$B$10,B7<Parameters!$B$11),1,0) -> 1 | E7: =C7*D7 -> 148 | F7: 92 | G7: =IF(AND(B7>=Parameters!$B$10,B7<=Parameters!$B$11),1,0) -> 1 | H7: =IF(OR(B7=Parameters!$B$10,B7=Parameters!$B$11),1,0) -> 0 | I7: =IF(G7=1,IF(H7=1,Parameters!$B$22*F7,F7),0) -> 92 | J7: 0 | K7: 1 | L7: 1 | M7: =G7*(J7*Parameters!$B$18+K7*Parameters!$B$19+L7*Parameters!$B$20) -> 64 | N7: =IF(G7=1,MAX(I7-M7,Parameters!$B$21),0) -> 28
A8: Chicago | B8: 46358 | C8: 148 | D8: =IF(AND(B8>=Parameters!$B$10,B8<Parameters!$B$11),1,0) -> 0 | E8: =C8*D8 -> 0 | F8: 92 | G8: =IF(AND(B8>=Parameters!$B$10,B8<=Parameters!$B$11),1,0) -> 1 | H8: =IF(OR(B8=Parameters!$B$10,B8=Parameters!$B$11),1,0) -> 1 | I8: =IF(G8=1,IF(H8=1,Parameters!$B$22*F8,F8),0) -> 69 | J8: 0 | K8: 1 | L8: 0 | M8: =G8*(J8*Parameters!$B$18+K8*Parameters!$B$19+L8*Parameters!$B$20) -> 26 | N8: =IF(G8=1,MAX(I8-M8,Parameters!$B$21),0) -> 43
A9: Chicago | B9: 46359 | C9: 148 | D9: =IF(AND(B9>=Parameters!$B$10,B9<Parameters!$B$11),1,0) -> 0 | E9: =C9*D9 -> 0 | F9: 92 | G9: =IF(AND(B9>=Parameters!$B$10,B9<=Parameters!$B$11),1,0) -> 0 | H9: =IF(OR(B9=Parameters!$B$10,B9=Parameters!$B$11),1,0) -> 0 | I9: =IF(G9=1,IF(H9=1,Parameters!$B$22*F9,F9),0) -> 0 | J9: 0 | K9: 0 | L9: 0 | M9: =G9*(J9*Parameters!$B$18+K9*Parameters!$B$19+L9*Parameters!$B$20) -> 0 | N9: =IF(G9=1,MAX(I9-M9,Parameters!$B$21),0) -> 0
A10: Chicago 小计 / subtotal (每人 per person) | C10: 住宿/人 Lodging per person → | E10: =SUM(E3:E9) -> 844 | M10: M&IE/人 → | N10: =SUM(N3:N9) -> 234
A11: Denver | B11: 46353 | C11: 170 | D11: =IF(AND(B11>=Parameters!$B$10,B11<Parameters!$B$11),1,0) -> 0 | E11: =C11*D11 -> 0 | F11: 92 | G11: =IF(AND(B11>=Parameters!$B$10,B11<=Parameters!$B$11),1,0) -> 0 | H11: =IF(OR(B11=Parameters!$B$10,B11=Parameters!$B$11),1,0) -> 0 | I11: =IF(G11=1,IF(H11=1,Parameters!$B$22*F11,F11),0) -> 0 | J11: 0 | K11: 0 | L11: 0 | M11: =G11*(J11*Parameters!$B$18+K11*Parameters!$B$19+L11*Parameters!$B$20) -> 0 | N11: =IF(G11=1,MAX(I11-M11,Parameters!$B$21),0) -> 0
A12: Denver | B12: 46354 | C12: 170 | D12: =IF(AND(B12>=Parameters!$B$10,B12<Parameters!$B$11),1,0) -> 1 | E12: =C12*D12 -> 170 | F12: 92 | G12: =IF(AND(B12>=Parameters!$B$10,B12<=Parameters!$B$11),1,0) -> 1 | H12: =IF(OR(B12=Parameters!$B$10,B12=Parameters!$B$11),1,0) -> 1 | I12: =IF(G12=1,IF(H12=1,Parameters!$B$22*F12,F12),0) -> 69 | J12: 0 | K12: 0 | L12: 1 | M12: =G12*(J12*Parameters!$B$18+K12*Parameters!$B$19+L12*Parameters!$B$20) -> 38 | N12: =IF(G12=1,MAX(I12-M12,Parameters!$B$21),0) -> 31
A13: Denver | B13: 46355 | C13: 170 | D13: =IF(AND(B13>=Parameters!$B$10,B13<Parameters!$B$11),1,0) -> 1 | E13: =C13*D13 -> 170 | F13: 92 | G13: =IF(AND(B13>=Parameters!$B$10,B13<=Parameters!$B$11),1,0) -> 1 | H13: =IF(OR(B13=Parameters!$B$10,B13=Parameters!$B$11),1,0) -> 0 | I13: =IF(G13=1,IF(H13=1,Parameters!$B$22*F13,F13),0) -> 92 | J13: =Parameters!$B$9 -> 0 | K13: 1 | L13: 0 | M13: =G13*(J13*Parameters!$B$18+K13*Parameters!$B$19+L13*Parameters!$B$20) -> 26 | N13: =IF(G13=1,MAX(I13-M13,Parameters!$B$21),0) -> 66
A14: Denver | B14: 46356 | C14: 170 | D14: =IF(AND(B14>=Parameters!$B$10,B14<Parameters!$B$11),1,0) -> 1 | E14: =C14*D14 -> 170 | F14: 92 | G14: =IF(AND(B14>=Parameters!$B$10,B14<=Parameters!$B$11),1,0) -> 1 | H14: =IF(OR(B14=Parameters!$B$10,B14=Parameters!$B$11),1,0) -> 0 | I14: =IF(G14=1,IF(H14=1,Parameters!$B$22*F14,F14),0) -> 92 | J14: 0 | K14: 1 | L14: 0 | M14: =G14*(J14*Parameters!$B$18+K14*Parameters!$B$19+L14*Parameters!$B$20) -> 26 | N14: =IF(G14=1,MAX(I14-M14,Parameters!$B$21),0) -> 66
A15: Denver | B15: 46357 | C15: 170 | D15: =IF(AND(B15>=Parameters!$B$10,B15<Parameters!$B$11),1,0) -> 1 | E15: =C15*D15 -> 170 | F15: 92 | G15: =IF(AND(B15>=Parameters!$B$10,B15<=Parameters!$B$11),1,0) -> 1 | H15: =IF(OR(B15=Parameters!$B$10,B15=Parameters!$B$11),1,0) -> 0 | I15: =IF(G15=1,IF(H15=1,Parameters!$B$22*F15,F15),0) -> 92 | J15: 0 | K15: 1 | L15: 1 | M15: =G15*(J15*Parameters!$B$18+K15*Parameters!$B$19+L15*Parameters!$B$20) -> 64 | N15: =IF(G15=1,MAX(I15-M15,Parameters!$B$21),0) -> 28
A16: Denver | B16: 46358 | C16: 170 | D16: =IF(AND(B16>=Parameters!$B$10,B16<Parameters!$B$11),1,0) -> 0 | E16: =C16*D16 -> 0 | F16: 92 | G16: =IF(AND(B16>=Parameters!$B$10,B16<=Parameters!$B$11),1,0) -> 1 | H16: =IF(OR(B16=Parameters!$B$10,B16=Parameters!$B$11),1,0) -> 1 | I16: =IF(G16=1,IF(H16=1,Parameters!$B$22*F16,F16),0) -> 69 | J16: 0 | K16: 1 | L16: 0 | M16: =G16*(J16*Parameters!$B$18+K16*Parameters!$B$19+L16*Parameters!$B$20) -> 26 | N16: =IF(G16=1,MAX(I16-M16,Parameters!$B$21),0) -> 43
A17: Denver | B17: 46359 | C17: 170 | D17: =IF(AND(B17>=Parameters!$B$10,B17<Parameters!$B$11),1,0) -> 0 | E17: =C17*D17 -> 0 | F17: 92 | G17: =IF(AND(B17>=Parameters!$B$10,B17<=Parameters!$B$11),1,0) -> 0 | H17: =IF(OR(B17=Parameters!$B$10,B17=Parameters!$B$11),1,0) -> 0 | I17: =IF(G17=1,IF(H17=1,Parameters!$B$22*F17,F17),0) -> 0 | J17: 0 | K17: 0 | L17: 0 | M17: =G17*(J17*Parameters!$B$18+K17*Parameters!$B$19+L17*Parameters!$B$20) -> 0 | N17: =IF(G17=1,MAX(I17-M17,Parameters!$B$21),0) -> 0
A18: Denver 小计 / subtotal (每人 per person) | C18: 住宿/人 Lodging per person → | E18: =SUM(E11:E17) -> 680 | M18: M&IE/人 → | N18: =SUM(N11:N17) -> 234
A19: Phoenix | B19: 46353 | C19: 165 | D19: =IF(AND(B19>=Parameters!$B$10,B19<Parameters!$B$11),1,0) -> 0 | E19: =C19*D19 -> 0 | F19: 92 | G19: =IF(AND(B19>=Parameters!$B$10,B19<=Parameters!$B$11),1,0) -> 0 | H19: =IF(OR(B19=Parameters!$B$10,B19=Parameters!$B$11),1,0) -> 0 | I19: =IF(G19=1,IF(H19=1,Parameters!$B$22*F19,F19),0) -> 0 | J19: 0 | K19: 0 | L19: 0 | M19: =G19*(J19*Parameters!$B$18+K19*Parameters!$B$19+L19*Parameters!$B$20) -> 0 | N19: =IF(G19=1,MAX(I19-M19,Parameters!$B$21),0) -> 0
A20: Phoenix | B20: 46354 | C20: 165 | D20: =IF(AND(B20>=Parameters!$B$10,B20<Parameters!$B$11),1,0) -> 1 | E20: =C20*D20 -> 165 | F20: 92 | G20: =IF(AND(B20>=Parameters!$B$10,B20<=Parameters!$B$11),1,0) -> 1 | H20: =IF(OR(B20=Parameters!$B$10,B20=Parameters!$B$11),1,0) -> 1 | I20: =IF(G20=1,IF(H20=1,Parameters!$B$22*F20,F20),0) -> 69 | J20: 0 | K20: 0 | L20: 1 | M20: =G20*(J20*Parameters!$B$18+K20*Parameters!$B$19+L20*Parameters!$B$20) -> 38 | N20: =IF(G20=1,MAX(I20-M20,Parameters!$B$21),0) -> 31
A21: Phoenix | B21: 46355 | C21: 165 | D21: =IF(AND(B21>=Parameters!$B$10,B21<Parameters!$B$11),1,0) -> 1 | E21: =C21*D21 -> 165 | F21: 92 | G21: =IF(AND(B21>=Parameters!$B$10,B21<=Parameters!$B$11),1,0) -> 1 | H21: =IF(OR(B21=Parameters!$B$10,B21=Parameters!$B$11),1,0) -> 0 | I21: =IF(G21=1,IF(H21=1,Parameters!$B$22*F21,F21),0) -> 92 | J21: =Parameters!$B$9 -> 0 | K21: 1 | L21: 0 | M21: =G21*(J21*Parameters!$B$18+K21*Parameters!$B$19+L21*Parameters!$B$20) -> 26 | N21: =IF(G21=1,MAX(I21-M21,Parameters!$B$21),0) -> 66
A22: Phoenix | B22: 46356 | C22: 165 | D22: =IF(AND(B22>=Parameters!$B$10,B22<Parameters!$B$11),1,0) -> 1 | E22: =C22*D22 -> 165 | F22: 92 | G22: =IF(AND(B22>=Parameters!$B$10,B22<=Parameters!$B$11),1,0) -> 1 | H22: =IF(OR(B22=Parameters!$B$10,B22=Parameters!$B$11),1,0) -> 0 | I22: =IF(G22=1,IF(H22=1,Parameters!$B$22*F22,F22),0) -> 92 | J22: 0 | K22: 1 | L22: 0 | M22: =G22*(J22*Parameters!$B$18+K22*Parameters!$B$19+L22*Parameters!$B$20) -> 26 | N22: =IF(G22=1,MAX(I22-M22,Parameters!$B$21),0) -> 66
A23: Phoenix | B23: 46357 | C23: 165 | D23: =IF(AND(B23>=Parameters!$B$10,B23<Parameters!$B$11),1,0) -> 1 | E23: =C23*D23 -> 165 | F23: 92 | G23: =IF(AND(B23>=Parameters!$B$10,B23<=Parameters!$B$11),1,0) -> 1 | H23: =IF(OR(B23=Parameters!$B$10,B23=Parameters!$B$11),1,0) -> 0 | I23: =IF(G23=1,IF(H23=1,Parameters!$B$22*F23,F23),0) -> 92 | J23: 0 | K23: 1 | L23: 1 | M23: =G23*(J23*Parameters!$B$18+K23*Parameters!$B$19+L23*Parameters!$B$20) -> 64 | N23: =IF(G23=1,MAX(I23-M23,Parameters!$B$21),0) -> 28
A24: Phoenix | B24: 46358 | C24: 165 | D24: =IF(AND(B24>=Parameters!$B$10,B24<Parameters!$B$11),1,0) -> 0 | E24: =C24*D24 -> 0 | F24: 92 | G24: =IF(AND(B24>=Parameters!$B$10,B24<=Parameters!$B$11),1,0) -> 1 | H24: =IF(OR(B24=Parameters!$B$10,B24=Parameters!$B$11),1,0) -> 1 | I24: =IF(G24=1,IF(H24=1,Parameters!$B$22*F24,F24),0) -> 69 | J24: 0 | K24: 1 | L24: 0 | M24: =G24*(J24*Parameters!$B$18+K24*Parameters!$B$19+L24*Parameters!$B$20) -> 26 | N24: =IF(G24=1,MAX(I24-M24,Parameters!$B$21),0) -> 43
A25: Phoenix | B25: 46359 | C25: 165 | D25: =IF(AND(B25>=Parameters!$B$10,B25<Parameters!$B$11),1,0) -> 0 | E25: =C25*D25 -> 0 | F25: 92 | G25: =IF(AND(B25>=Parameters!$B$10,B25<=Parameters!$B$11),1,0) -> 0 | H25: =IF(OR(B25=Parameters!$B$10,B25=Parameters!$B$11),1,0) -> 0 | I25: =IF(G25=1,IF(H25=1,Parameters!$B$22*F25,F25),0) -> 0 | J25: 0 | K25: 0 | L25: 0 | M25: =G25*(J25*Parameters!$B$18+K25*Parameters!$B$19+L25*Parameters!$B$20) -> 0 | N25: =IF(G25=1,MAX(I25-M25,Parameters!$B$21),0) -> 0
A26: Phoenix 小计 / subtotal (每人 per person) | C26: 住宿/人 Lodging per person → | E26: =SUM(E19:E25) -> 660 | M26: M&IE/人 → | N26: =SUM(N19:N25) -> 234
A27: Boston | B27: 46353 | C27: 213 | D27: =IF(AND(B27>=Parameters!$B$10,B27<Parameters!$B$11),1,0) -> 0 | E27: =C27*D27 -> 0 | F27: 92 | G27: =IF(AND(B27>=Parameters!$B$10,B27<=Parameters!$B$11),1,0) -> 0 | H27: =IF(OR(B27=Parameters!$B$10,B27=Parameters!$B$11),1,0) -> 0 | I27: =IF(G27=1,IF(H27=1,Parameters!$B$22*F27,F27),0) -> 0 | J27: 0 | K27: 0 | L27: 0 | M27: =G27*(J27*Parameters!$B$18+K27*Parameters!$B$19+L27*Parameters!$B$20) -> 0 | N27: =IF(G27=1,MAX(I27-M27,Parameters!$B$21),0) -> 0
A28: Boston | B28: 46354 | C28: 213 | D28: =IF(AND(B28>=Parameters!$B$10,B28<Parameters!$B$11),1,0) -> 1 | E28: =C28*D28 -> 213 | F28: 92 | G28: =IF(AND(B28>=Parameters!$B$10,B28<=Parameters!$B$11),1,0) -> 1 | H28: =IF(OR(B28=Parameters!$B$10,B28=Parameters!$B$11),1,0) -> 1 | I28: =IF(G28=1,IF(H28=1,Parameters!$B$22*F28,F28),0) -> 69 | J28: 0 | K28: 0 | L28: 1 | M28: =G28*(J28*Parameters!$B$18+K28*Parameters!$B$19+L28*Parameters!$B$20) -> 38 | N28: =IF(G28=1,MAX(I28-M28,Parameters!$B$21),0) -> 31
A29: Boston | B29: 46355 | C29: 213 | D29: =IF(AND(B29>=Parameters!$B$10,B29<Parameters!$B$11),1,0) -> 1 | E29: =C29*D29 -> 213 | F29: 92 | G29: =IF(AND(B29>=Parameters!$B$10,B29<=Parameters!$B$11),1,0) -> 1 | H29: =IF(OR(B29=Parameters!$B$10,B29=Parameters!$B$11),1,0) -> 0 | I29: =IF(G29=1,IF(H29=1,Parameters!$B$22*F29,F29),0) -> 92 | J29: =Parameters!$B$9 -> 0 | K29: 1 | L29: 0 | M29: =G29*(J29*Parameters!$B$18+K29*Parameters!$B$19+L29*Parameters!$B$20) -> 26 | N29: =IF(G29=1,MAX(I29-M29,Parameters!$B$21),0) -> 66
A30: Boston | B30: 46356 | C30: 213 | D30: =IF(AND(B30>=Parameters!$B$10,B30<Parameters!$B$11),1,0) -> 1 | E30: =C30*D30 -> 213 | F30: 92 | G30: =IF(AND(B30>=Parameters!$B$10,B30<=Parameters!$B$11),1,0) -> 1 | H30: =IF(OR(B30=Parameters!$B$10,B30=Parameters!$B$11),1,0) -> 0 | I30: =IF(G30=1,IF(H30=1,Parameters!$B$22*F30,F30),0) -> 92 | J30: 0 | K30: 1 | L30: 0 | M30: =G30*(J30*Parameters!$B$18+K30*Parameters!$B$19+L30*Parameters!$B$20) -> 26 | N30: =IF(G30=1,MAX(I30-M30,Parameters!$B$21),0) -> 66
A31: Boston | B31: 46357 | C31: 213 | D31: =IF(AND(B31>=Parameters!$B$10,B31<Parameters!$B$11),1,0) -> 1 | E31: =C31*D31 -> 213 | F31: 92 | G31: =IF(AND(B31>=Parameters!$B$10,B31<=Parameters!$B$11),1,0) -> 1 | H31: =IF(OR(B31=Parameters!$B$10,B31=Parameters!$B$11),1,0) -> 0 | I31: =IF(G31=1,IF(H31=1,Parameters!$B$22*F31,F31),0) -> 92 | J31: 0 | K31: 1 | L31: 1 | M31: =G31*(J31*Parameters!$B$18+K31*Parameters!$B$19+L31*Parameters!$B$20) -> 64 | N31: =IF(G31=1,MAX(I31-M31,Parameters!$B$21),0) -> 28
A32: Boston | B32: 46358 | C32: 213 | D32: =IF(AND(B32>=Parameters!$B$10,B32<Parameters!$B$11),1,0) -> 0 | E32: =C32*D32 -> 0 | F32: 92 | G32: =IF(AND(B32>=Parameters!$B$10,B32<=Parameters!$B$11),1,0) -> 1 | H32: =IF(OR(B32=Parameters!$B$10,B32=Parameters!$B$11),1,0) -> 1 | I32: =IF(G32=1,IF(H32=1,Parameters!$B$22*F32,F32),0) -> 69 | J32: 0 | K32: 1 | L32: 0 | M32: =G32*(J32*Parameters!$B$18+K32*Parameters!$B$19+L32*Parameters!$B$20) -> 26 | N32: =IF(G32=1,MAX(I32-M32,Parameters!$B$21),0) -> 43
A33: Boston | B33: 46359 | C33: 213 | D33: =IF(AND(B33>=Parameters!$B$10,B33<Parameters!$B$11),1,0) -> 0 | E33: =C33*D33 -> 0 | F33: 92 | G33: =IF(AND(B33>=Parameters!$B$10,B33<=Parameters!$B$11),1,0) -> 0 | H33: =IF(OR(B33=Parameters!$B$10,B33=Parameters!$B$11),1,0) -> 0 | I33: =IF(G33=1,IF(H33=1,Parameters!$B$22*F33,F33),0) -> 0 | J33: 0 | K33: 0 | L33: 0 | M33: =G33*(J33*Parameters!$B$18+K33*Parameters!$B$19+L33*Parameters!$B$20) -> 0 | N33: =IF(G33=1,MAX(I33-M33,Parameters!$B$21),0) -> 0
A34: Boston 小计 / subtotal (每人 per person) | C34: 住宿/人 Lodging per person → | E34: =SUM(E27:E33) -> 852 | M34: M&IE/人 → | N34: =SUM(N27:N33) -> 234
A35: Seattle | B35: 46353 | C35: 188 | D35: =IF(AND(B35>=Parameters!$B$10,B35<Parameters!$B$11),1,0) -> 0 | E35: =C35*D35 -> 0 | F35: 92 | G35: =IF(AND(B35>=Parameters!$B$10,B35<=Parameters!$B$11),1,0) -> 0 | H35: =IF(OR(B35=Parameters!$B$10,B35=Parameters!$B$11),1,0) -> 0 | I35: =IF(G35=1,IF(H35=1,Parameters!$B$22*F35,F35),0) -> 0 | J35: 0 | K35: 0 | L35: 0 | M35: =G35*(J35*Parameters!$B$18+K35*Parameters!$B$19+L35*Parameters!$B$20) -> 0 | N35: =IF(G35=1,MAX(I35-M35,Parameters!$B$21),0) -> 0
A36: Seattle | B36: 46354 | C36: 188 | D36: =IF(AND(B36>=Parameters!$B$10,B36<Parameters!$B$11),1,0) -> 1 | E36: =C36*D36 -> 188 | F36: 92 | G36: =IF(AND(B36>=Parameters!$B$10,B36<=Parameters!$B$11),1,0) -> 1 | H36: =IF(OR(B36=Parameters!$B$10,B36=Parameters!$B$11),1,0) -> 1 | I36: =IF(G36=1,IF(H36=1,Parameters!$B$22*F36,F36),0) -> 69 | J36: 0 | K36: 0 | L36: 1 | M36: =G36*(J36*Parameters!$B$18+K36*Parameters!$B$19+L36*Parameters!$B$20) -> 38 | N36: =IF(G36=1,MAX(I36-M36,Parameters!$B$21),0) -> 31
A37: Seattle | B37: 46355 | C37: 188 | D37: =IF(AND(B37>=Parameters!$B$10,B37<Parameters!$B$11),1,0) -> 1 | E37: =C37*D37 -> 188 | F37: 92 | G37: =IF(AND(B37>=Parameters!$B$10,B37<=Parameters!$B$11),1,0) -> 1 | H37: =IF(OR(B37=Parameters!$B$10,B37=Parameters!$B$11),1,0) -> 0 | I37: =IF(G37=1,IF(H37=1,Parameters!$B$22*F37,F37),0) -> 92 | J37: =Parameters!$B$9 -> 0 | K37: 1 | L37: 0 | M37: =G37*(J37*Parameters!$B$18+K37*Parameters!$B$19+L37*Parameters!$B$20) -> 26 | N37: =IF(G37=1,MAX(I37-M37,Parameters!$B$21),0) -> 66
A38: Seattle | B38: 46356 | C38: 188 | D38: =IF(AND(B38>=Parameters!$B$10,B38<Parameters!$B$11),1,0) -> 1 | E38: =C38*D38 -> 188 | F38: 92 | G38: =IF(AND(B38>=Parameters!$B$10,B38<=Parameters!$B$11),1,0) -> 1 | H38: =IF(OR(B38=Parameters!$B$10,B38=Parameters!$B$11),1,0) -> 0 | I38: =IF(G38=1,IF(H38=1,Parameters!$B$22*F38,F38),0) -> 92 | J38: 0 | K38: 1 | L38: 0 | M38: =G38*(J38*Parameters!$B$18+K38*Parameters!$B$19+L38*Parameters!$B$20) -> 26 | N38: =IF(G38=1,MAX(I38-M38,Parameters!$B$21),0) -> 66
A39: Seattle | B39: 46357 | C39: 188 | D39: =IF(AND(B39>=Parameters!$B$10,B39<Parameters!$B$11),1,0) -> 1 | E39: =C39*D39 -> 188 | F39: 92 | G39: =IF(AND(B39>=Parameters!$B$10,B39<=Parameters!$B$11),1,0) -> 1 | H39: =IF(OR(B39=Parameters!$B$10,B39=Parameters!$B$11),1,0) -> 0 | I39: =IF(G39=1,IF(H39=1,Parameters!$B$22*F39,F39),0) -> 92 | J39: 0 | K39: 1 | L39: 1 | M39: =G39*(J39*Parameters!$B$18+K39*Parameters!$B$19+L39*Parameters!$B$20) -> 64 | N39: =IF(G39=1,MAX(I39-M39,Parameters!$B$21),0) -> 28
A40: Seattle | B40: 46358 | C40: 188 | D40: =IF(AND(B40>=Parameters!$B$10,B40<Parameters!$B$11),1,0) -> 0 | E40: =C40*D40 -> 0 | F40: 92 | G40: =IF(AND(B40>=Parameters!$B$10,B40<=Parameters!$B$11),1,0) -> 1 | H40: =IF(OR(B40=Parameters!$B$10,B40=Parameters!$B$11),1,0) -> 1 | I40: =IF(G40=1,IF(H40=1,Parameters!$B$22*F40,F40),0) -> 69 | J40: 0 | K40: 1 | L40: 0 | M40: =G40*(J40*Parameters!$B$18+K40*Parameters!$B$19+L40*Parameters!$B$20) -> 26 | N40: =IF(G40=1,MAX(I40-M40,Parameters!$B$21),0) -> 43
...

Sheet Options
A1: 候选方案比较与推荐 (每人金额 USD; 住宿按GSA per diem上限计, 为可报销上限的保守口径)
A3: 城市 City | B3: 基础票价 Airfare base | C3: 调整票价 Airfare×factor | D3: 住宿/人 Lodging | E3: 住宿税 Tax 12% | F3: M&IE/人 | G3: 注册费 Reg | H3: 本地交通 Local transit | I3: 每人小计 Per-person | J3: 每人(压力) Per-person+20%air | L3: 基础小计 Base | M3: 储备 Reserve | N3: 含储备总额 Total | O3: ≤上限? Within | P3: 压力总额 Stress total | Q3: 压力≤上限? | S3: 基础小计 Base | T3: 储备 Reserve | U3: 含储备总额 Total | V3: ≤上限? Within | W3: 压力总额 Stress total | X3: 压力≤上限? | AA3: elig24 | AB3: elig18
A4: Chicago | B4: 271 | C4: =B4*Parameters!$B$5 -> 271 | D4: =Daily!E10 -> 844 | E4: =D4*Parameters!$B$8 -> 101.28 | F4: =Daily!N10 -> 234 | G4: =Parameters!$B$12 -> 180 | H4: 70 | I4: =C4+D4+E4+F4+G4+H4 -> 1700.28 | J4: =I4+B4*Parameters!$B$5*(Parameters!$B$7-1) -> 1754.48 | L4: =I4*Parameters!$B$14 -> 40806.72 | M4: =ROUND(L4*Parameters!$B$6,2) -> 2040.34 | N4: =ROUND(L4+M4,2) -> 42847.06 | O4: =IF(N4<=Parameters!$B$4,"YES","NO") -> YES | P4: =ROUND(J4*Parameters!$B$14*(1+Parameters!$B$6),2) -> 44212.9 | Q4: =IF(P4<=Parameters!$B$4,"YES","NO") -> YES | S4: =I4*Parameters!$B$13 -> 30605.04 | T4: =ROUND(S4*Parameters!$B$6,2) -> 1530.25 | U4: =ROUND(S4+T4,2) -> 32135.29 | V4: =IF(U4<=Parameters!$B$4,"YES","NO") -> YES | W4: =ROUND(J4*Parameters!$B$13*(1+Parameters!$B$6),2) -> 33159.67 | X4: =IF(W4<=Parameters!$B$4,"YES","NO") -> YES | AA4: =IF(O4="YES",N4,"") -> 42847.06 | AB4: =IF(V4="YES",U4,"") -> 32135.29
A5: Denver | B5: 437 | C5: =B5*Parameters!$B$5 -> 437 | D5: =Daily!E18 -> 680 | E5: =D5*Parameters!$B$8 -> 81.6 | F5: =Daily!N18 -> 234 | G5: =Parameters!$B$12 -> 180 | H5: 80 | I5: =C5+D5+E5+F5+G5+H5 -> 1692.6 | J5: =I5+B5*Parameters!$B$5*(Parameters!$B$7-1) -> 1780 | L5: =I5*Parameters!$B$14 -> 40622.4 | M5: =ROUND(L5*Parameters!$B$6,2) -> 2031.12 | N5: =ROUND(L5+M5,2) -> 42653.52 | O5: =IF(N5<=Parameters!$B$4,"YES","NO") -> YES | P5: =ROUND(J5*Parameters!$B$14*(1+Parameters!$B$6),2) -> 44856 | Q5: =IF(P5<=Parameters!$B$4,"YES","NO") -> YES | S5: =I5*Parameters!$B$13 -> 30466.8 | T5: =ROUND(S5*Parameters!$B$6,2) -> 1523.34 | U5: =ROUND(S5+T5,2) -> 31990.14 | V5: =IF(U5<=Parameters!$B$4,"YES","NO") -> YES | W5: =ROUND(J5*Parameters!$B$13*(1+Parameters!$B$6),2) -> 33642 | X5: =IF(W5<=Parameters!$B$4,"YES","NO") -> YES | AA5: =IF(O5="YES",N5,"") -> 42653.52 | AB5: =IF(V5="YES",U5,"") -> 31990.14
A6: Phoenix | B6: 473 | C6: =B6*Parameters!$B$5 -> 473 | D6: =Daily!E26 -> 660 | E6: =D6*Parameters!$B$8 -> 79.2 | F6: =Daily!N26 -> 234 | G6: =Parameters!$B$12 -> 180 | H6: 50 | I6: =C6+D6+E6+F6+G6+H6 -> 1676.2 | J6: =I6+B6*Parameters!$B$5*(Parameters!$B$7-1) -> 1770.8 | L6: =I6*Parameters!$B$14 -> 40228.8 | M6: =ROUND(L6*Parameters!$B$6,2) -> 2011.44 | N6: =ROUND(L6+M6,2) -> 42240.24 | O6: =IF(N6<=Parameters!$B$4,"YES","NO") -> YES | P6: =ROUND(J6*Parameters!$B$14*(1+Parameters!$B$6),2) -> 44624.16 | Q6: =IF(P6<=Parameters!$B$4,"YES","NO") -> YES | S6: =I6*Parameters!$B$13 -> 30171.6 | T6: =ROUND(S6*Parameters!$B$6,2) -> 1508.58 | U6: =ROUND(S6+T6,2) -> 31680.18 | V6: =IF(U6<=Parameters!$B$4,"YES","NO") -> YES | W6: =ROUND(J6*Parameters!$B$13*(1+Parameters!$B$6),2) -> 33468.12 | X6: =IF(W6<=Parameters!$B$4,"YES","NO") -> YES | AA6: =IF(O6="YES",N6,"") -> 42240.24 | AB6: =IF(V6="YES",U6,"") -> 31680.18
A7: Boston | B7: 322 | C7: =B7*Parameters!$B$5 -> 322 | D7: =Daily!E34 -> 852 | E7: =D7*Parameters!$B$8 -> 102.24 | F7: =Daily!N34 -> 234 | G7: =Parameters!$B$12 -> 180 | H7: 50 | I7: =C7+D7+E7+F7+G7+H7 -> 1740.24 | J7: =I7+B7*Parameters!$B$5*(Parameters!$B$7-1) -> 1804.64 | L7: =I7*Parameters!$B$14 -> 41765.76 | M7: =ROUND(L7*Parameters!$B$6,2) -> 2088.29 | N7: =ROUND(L7+M7,2) -> 43854.05 | O7: =IF(N7<=Parameters!$B$4,"YES","NO") -> YES | P7: =ROUND(J7*Parameters!$B$14*(1+Parameters!$B$6),2) -> 45476.93 | Q7: =IF(P7<=Parameters!$B$4,"YES","NO") -> YES | S7: =I7*Parameters!$B$13 -> 31324.32 | T7: =ROUND(S7*Parameters!$B$6,2) -> 1566.22 | U7: =ROUND(S7+T7,2) -> 32890.54 | V7: =IF(U7<=Parameters!$B$4,"YES","NO") -> YES | W7: =ROUND(J7*Parameters!$B$13*(1+Parameters!$B$6),2) -> 34107.7 | X7: =IF(W7<=Parameters!$B$4,"YES","NO") -> YES | AA7: =IF(O7="YES",N7,"") -> 43854.05 | AB7: =IF(V7="YES",U7,"") -> 32890.54
A8: Seattle | B8: 643 | C8: =B8*Parameters!$B$5 -> 643 | D8: =Daily!E42 -> 752 | E8: =D8*Parameters!$B$8 -> 90.24 | F8: =Daily!N42 -> 234 | G8: =Parameters!$B$12 -> 180 | H8: 65 | I8: =C8+D8+E8+F8+G8+H8 -> 1964.24 | J8: =I8+B8*Parameters!$B$5*(Parameters!$B$7-1) -> 2092.84 | L8: =I8*Parameters!$B$14 -> 47141.76 | M8: =ROUND(L8*Parameters!$B$6,2) -> 2357.09 | N8: =ROUND(L8+M8,2) -> 49498.85 | O8: =IF(N8<=Parameters!$B$4,"YES","NO") -> YES | P8: =ROUND(J8*Parameters!$B$14*(1+Parameters!$B$6),2) -> 52739.57 | Q8: =IF(P8<=Parameters!$B$4,"YES","NO") -> YES | S8: =I8*Parameters!$B$13 -> 35356.32 | T8: =ROUND(S8*Parameters!$B$6,2) -> 1767.82 | U8: =ROUND(S8+T8,2) -> 37124.14 | V8: =IF(U8<=Parameters!$B$4,"YES","NO") -> YES | W8: =ROUND(J8*Parameters!$B$13*(1+Parameters!$B$6),2) -> 39554.68 | X8: =IF(W8<=Parameters!$B$4,"YES","NO") -> YES | AA8: =IF(O8="YES",N8,"") -> 49498.85 | AB8: =IF(V8="YES",U8,"") -> 37124.14
A11: — 自动推荐结果 Auto recommendation (优先24人; 同人数取含储备总额最低; 完全并列按城市英文名) —
A12: 24人方案中符合预算数 Count within (24) | E12: =COUNTIF($O$4:$O$8,"YES") -> 5
A13: 18人方案中符合预算数 Count within (18) | E13: =COUNTIF($V$4:$V$8,"YES") -> 5
A14: 推荐人数 Recommended headcount | E14: =IF(E12>0,Parameters!$B$14,IF(E13>0,Parameters!$B$13,"无可行方案")) -> 24
A15: 推荐方案含储备总额 Recommended total | E15: =IF(E12>0,MIN($AA$4:$AA$8),IF(E13>0,MIN($AB$4:$AB$8),"")) -> 42240.24
A16: 推荐城市 Recommended city | E16: =IFERROR(IF(E12>0,INDEX($A$4:$A$8,MATCH(E15,$N$4:$N$8,0)),IF(E13>0,INDEX($A$4:$A$8,MATCH(E15,$U$4:$U$8,0)),"—")),"—") -> Phoenix
A17: 预算余量(推荐) Headroom vs cap | E17: =IF(ISNUMBER(E15),Parameters!$B$4-E15,"") -> 10759.76
A19: 待询价 / 未纳入计算 (不得虚构): 培训场地/会议室租金; 机构供餐(11/28晚餐,12/1晚餐,12/2午餐)餐饮费。 二者须在批准前取得报价并计入, 届时重算储备与总额、复核是否≤上限。详见 Sources 与审批登记。

Sheet Sources
A1: 资料依据、查询日期与预算口径 / Sources, query dates, pricing basis
A2: 项目 Item | B2: 数值/口径 Value | C2: 来源 Source | D2: 查询/版本日期 Date | E2: 适用条件/备注 Conditions & notes
A3: 行程 Itinerary | B3: 抵达 2026-11-28, 返程 2026-12-02 | C3: 题面(培训11/29–12/1)+提前一天抵/次日返 | D3: 2026-10-23 | E3: 住宿4夜(11/28–12/1); 行程日5天(11/28–12/2); 首末日M&IE 75%
A4: 出发机场 Origin airport | B4: DCA(里根机场)为主 | C4: USDA HQ 1400 Independence Ave SW 距DCA约4.8英里(~15min); IAD约26mi, BWI约32mi(45–60min) | D4: 2026-10-23 | E4: DCA接驳成本/时间最低; 若无合适直达再比IAD/BWI
A5: 机票 Chicago ORD | B5: RT $271.00 (DCA↔ORD, American 直飞) | C5: Google Flights (google.com/travel/flights) | D5: 2026-10-23 | E5: 往返 11/28–12/2 最低经济舱总价含税费; 非GSA city-pair合同价, 实订以ETS合同价为准
A6: 机票 Denver DEN | B6: RT $437.00 (DCA↔DEN, Frontier 直飞) | C6: Google Flights | D6: 2026-10-23 | E6: 同上; Frontier基础经济, 行李/选座另计
A7: 机票 Phoenix PHX | B7: RT $473.00 (DCA↔PHX, 1中转JFK; 直飞American约$546) | C7: Google Flights | D7: 2026-10-23 | E7: 同上; 取最低价, 直飞略高
A8: 机票 Boston BOS | B8: RT $322.00 (DCA↔BOS, Delta 直飞) | C8: Google Flights | D8: 2026-10-23 | E8: 同上
A9: 机票 Seattle SEA | B9: RT $643.00 (DCA↔SEA, Frontier 1中转DEN; 直飞Alaska约$977) | C9: Google Flights | D9: 2026-10-23 | E9: 同上; 当前票价偏高(页面提示 Prices high)
A10: 住宿上限 Lodging cap | B10: Chi 232/232/232/148; Den 170; Phx 165; Bos 213; Sea 188 (每夜) | C10: GSA FY2027 Per Diem (FY2027_PerDiemRates_Validated090126.xlsx) | D10: Validated 2026-09-01 | E10: 按入住日所属季节; 芝加哥12/1起降至148; 为可报销上限, 实订须≤上限且含早餐
A11: M&IE 率 | B11: 全部候选地 $92/日; 首末日 $69 | C11: GSA FY2027 Per Diem file | D11: Validated 2026-09-01 | E11: 首末日75% (FTR 301-11.101)
A12: M&IE 分项 | B12: 早$23/午$26/晚$38/杂$5 | C12: GSA FY2025 M&IE Breakdown (GSA_FY2025_MIE_Breakdown.docx), $92档 | D12: FY2025 | E12: 适用于$92档; FY2027分项官方表待核对(待核实)
A13: 供餐扣减 Meal deductions | B13: 11/28晚;11/29午;11/30午;12/1午+晚;12/2午 | C13: 题面(注册含3午餐; 机构供11/28晚/12/1晚/12/2午) + FTR 301-11.18 / RD 2036-A §2036.11(d) | D13: 2026-10-23 | E13: 酒店免费早餐不扣减(FTR 301-11.17); 茶歇(咖啡/水果)为light refreshments不扣减(301-74.7/.21)
... A21: 机构供餐费 Catered meals | B21: 待询价 TBD | C21: 尚无餐饮报价 | D21: pending | E21: 11/28晚/12/1晚/12/2午; 须竞争性采购(RD 2036-A §2036.74(b)(7))
A23: 合规依据 / Compliance references (区分法规要求与内部建议):
A24: FTR 41 CFR 301-11.17: 酒店免费早餐与承运人供餐不减per diem。
A25: FTR 41 CFR 301-11.18: 政府供餐/注册含餐须按GSA分项扣减M&IE; 首末日从降后(75%)额扣全额; 不低于杂费额。
A26: FTR 41 CFR 301-11.100 / .101: 住宿实报不超当地上限; 首末日M&IE为75%。
A27: FTR 41 CFR 301-74.2/.4/.5: 会议成本须含差旅/per diem/会议室/地面交通等; 比较须用既定per diem率; 选址以最小成本为原则。
A28: FTR 41 CFR 301-74.7/.21: 可提供茶歇(light refreshments), 不扣M&IE。
A29: RD Instruction 2036-A (生效 2024-07-19) §2036.74(a): 须对≥3个地理上分散地点做成本比较; 禁止拆分事件/采购。
A30: RD Instruction 2036-A §2036.74(b): 机构总成本>$20,000的会议/培训须经 OCFO 事前批准(本预算约$42k, 适用) — 阻断性审批。
A31: RD Instruction 2036-A §2036.11(d): 政府供餐按301-11.18扣减; 会议供餐者不得另报同餐。
A32: RD Instruction 2036-A 交通: 须经 e-Gov(ETS)提前≥14天订票, 优先 contract city-pair 合同价(本工作簿票价为市场最低价估算, 实订以合同价为准 — 待核实)。
A33: RD Instruction 2036-A 住宿: 优先GSA合同/FEMA消防合规酒店(Hotel-Motel Fire Safety Act)。
A34: 内部建议(非法规): 本地交通、场地与供餐为估算/待询价, 须在批准前以实际报价替换并重算。
