Workbook
Name WF_BUDGET: ControlPanel!$B$5
Name WF_AIR_MULTIPLIER: ControlPanel!$B$6
Name WF_RESERVE_RATE: ControlPanel!$B$7
Name WF_GOV_BREAKFAST_0929: ControlPanel!$B$8
Name WF_ARRIVAL: ControlPanel!$B$9
Name WF_SNAPSHOT_CURRENT: ControlPanel!$B$11
Name WF_TOTAL_CHICAGO_18: Options!T2
Name WF_STRESS_CHICAGO_18: Options!Z2
Name WF_TOTAL_CHICAGO_24: Options!T3
Name WF_STRESS_CHICAGO_24: Options!Z3
Name WF_TOTAL_DENVER_18: Options!T4
Name WF_STRESS_DENVER_18: Options!Z4
Name WF_TOTAL_DENVER_24: Options!T5
Name WF_STRESS_DENVER_24: Options!Z5
Name WF_TOTAL_PHOENIX_18: Options!T6
Name WF_STRESS_PHOENIX_18: Options!Z6
Name WF_TOTAL_PHOENIX_24: Options!T7
Name WF_STRESS_PHOENIX_24: Options!Z7
Name WF_MIE_CHICAGO_0929: Daily!U5
Name WF_MIE_DENVER_0929: Daily!U13
Name WF_MIE_PHOENIX_0929: Daily!U21
Name WF_SELECTED_CITY: ControlPanel!$B$15
Name WF_SELECTED_N: ControlPanel!$B$16
Name WF_STRESS_SELECTED_CITY: ControlPanel!$B$17
Name WF_STRESS_SELECTED_N: ControlPanel!$B$18

Sheet ControlPanel
A1: Conference Budget Control Panel
A2: Edit the yellow cells. Daily and Options recalculate automatically.
A4: Input | B4: Value | C4: Unit / Range | D4: Default | E4: Notes
A5: WF_BUDGET | B5: 53000 | C5: USD, 0-100000 | D5: 53000 | E5: Approved total including reserve. Do not exceed.
A6: WF_AIR_MULTIPLIER | B6: 1 | C6: factor, 0.5-2.0 | D6: 1 | E6: Applied uniformly to all three cities' base airfare. Stress scenario = +20% on top.
A7: WF_RESERVE_RATE | B7: 0.05 | C7: rate, 0-0.20 | D7: 0.05 | E7: Contingency applied to each plan base subtotal.
A8: WF_GOV_BREAKFAST_0929 | B8: 0 | C8: 0 or 1 | D8: 0 | E8: 1 = government also provides 09-29 breakfast (deduct Breakfast, no procurement cost).
A9: WF_ARRIVAL | B9: 20250928 | C9: YYYYMMDD | D9: 20250928 | E9: Allowed: 20250927, 20250928, 20250929. Return 10-02 and training/gov-meal calendar unchanged.
A11: WF_SNAPSHOT_CURRENT | B11: =AND($B$5=53000,$B$6=1,$B$7=0.05,$B$8=0,$B$9=20250928) | C11: boolean | E11: TRUE only when all 5 inputs equal defaults.
A12: Snapshot note: | B12: The Word brief and CSV delivered herewith are static snapshots at the default parameters. If any ControlPanel input is changed, those documents MUST be regenerated; they do not auto-update.
A14: Selected plan (max people, then lowest total)
A15: WF_SELECTED_CITY | B15: =IF(MAX(Options!G12:G17)<1000000000000,"NONE",INDEX(Options!A12:A17,MATCH(MAX(Options!G12:G17),Options!G12:G17,0)))
A16: WF_SELECTED_N | B16: =IF(MAX(Options!G12:G17)<1000000000000,0,INDEX(Options!B12:B17,MATCH(MAX(Options!G12:G17),Options!G12:G17,0)))
A17: WF_STRESS_OK | B17: =IF(MAX(Options!H12:H17)<1000000000000,"NONE",INDEX(Options!A12:A17,MATCH(MAX(Options!H12:H17),Options!H12:H17,0)))
A18: WF_STRESS_SELECTED_N | B18: =IF(MAX(Options!H12:H17)<1000000000000,0,INDEX(Options!B12:B17,MATCH(MAX(Options!H12:H17),Options!H12:H17,0)))

Sheet Daily
A1: City | B1: Date | C1: DOW | D1: Kind | E1: FY | F1: Lodging Cap (GSA) | G1: Quote (untaxed) | H1: Quote<=Cap | I1: Nightly Lodging Used | J1: Nightly Tax (12%) | K1: Nightly Lodging+Tax | L1: Full M&IE (GSA) | M1: First/Last M&IE | N1: Is First Day | O1: Is Last Day | P1: Hotel BF free (no deduct per 301-11.17) | Q1: Gov Breakfast deduct | R1: Gov Lunch deduct | S1: Gov Dinner deduct | T1: Total Meal Deduction | U1: Final M&IE per person | V1: Notes
A2: CHICAGO
A3: CHICAGO | B3: 45927 | C3: Sat | D3: Pre-arrival | E3: FY2025 | F3: 223 | G3: 218 | H3: =(218<=223) | I3: =MIN(218,223) | J3: =MIN(218,223)*0.12 | K3: =MIN(218,223)*1.12 | L3: 92 | M3: 69 | N3: =(ControlPanel!$B$9=20250927)*1 | O3: =(20250927=20251002)*1 | P3: Yes - 301-11.17 | Q3: 0 | R3: 0 | S3: 0 | T3: =(0)+(0)+(0) | U3: =IF(ControlPanel!$B$9>20250927,0,IF(OR(ControlPanel!$B$9=20250927,20250927=20251002),MAX(69.0-((0)+(0)+(0)),5),MAX(92-((0)+(0)+(0)),5))) | V3: Cap from FY2025 Master row 258; M&IE from FY2025 row 258; Pre-arrival per WF_ARRIVAL; no lodging/tax/M&IE incurred this day; Hotel breakfast is complimentary (301-11.17) → no deduction in any case; First/last day applies 75% M&IE per 301-11.101; floor is $5 incidental (301-11.18)
A4: CHICAGO | B4: 45928 | C4: Sun | D4: Arrival / first travel day | E4: FY2025 | F4: 223 | G4: 218 | H4: =(218<=223) | I4: =MIN(218,223) | J4: =MIN(218,223)*0.12 | K4: =MIN(218,223)*1.12 | L4: 92 | M4: 69 | N4: =(ControlPanel!$B$9=20250928)*1 | O4: =(20250928=20251002)*1 | P4: Yes - 301-11.17 | Q4: 0 | R4: 0 | S4: 38 | T4: =(0)+(0)+(38) | U4: =IF(ControlPanel!$B$9>20250928,0,IF(OR(ControlPanel!$B$9=20250928,20250928=20251002),MAX(69.0-((0)+(0)+(38)),5),MAX(92-((0)+(0)+(38)),5))) | V4: Cap from FY2025 Master row 258; M&IE from FY2025 row 258; Government welcome dinner (included in fixed venue fee) → deduct Dinner; Hotel breakfast is complimentary (301-11.17) → no deduction in any case; First/last day applies 75% M&IE per 301-11.101; floor is $5 incidental (301-11.18)
A5: CHICAGO | B5: 45929 | C5: Mon | D5: Training day | E5: FY2025 | F5: 223 | G5: 218 | H5: =(218<=223) | I5: =MIN(218,223) | J5: =MIN(218,223)*0.12 | K5: =MIN(218,223)*1.12 | L5: 92 | M5: 69 | N5: =(ControlPanel!$B$9=20250929)*1 | O5: =(20250929=20251002)*1 | P5: Yes - 301-11.17 | Q5: IF(ControlPanel!$B$8=1,23,0) | R5: 26 | S5: 0 | T5: =(IF(ControlPanel!$B$8=1,23,0))+(26)+(0) | U5: =IF(ControlPanel!$B$9>20250929,0,IF(OR(ControlPanel!$B$9=20250929,20250929=20251002),MAX(69.0-((IF(ControlPanel!$B$8=1,23,0))+(26)+(0)),5),MAX(92-((IF(ControlPanel!$B$8=1,23,0))+(26)+(0)),5))) | V5: Cap from FY2025 Master row 258; M&IE from FY2025 row 258; Registration-fee lunch → deduct Lunch; Hotel breakfast is complimentary (301-11.17) → no deduction in any case; First/last day applies 75% M&IE per 301-11.101; floor is $5 incidental (301-11.18)
A6: CHICAGO | B6: 45930 | C6: Tue | D6: Training day | E6: FY2025 | F6: 223 | G6: 218 | H6: =(218<=223) | I6: =MIN(218,223) | J6: =MIN(218,223)*0.12 | K6: =MIN(218,223)*1.12 | L6: 92 | M6: 69 | N6: =(ControlPanel!$B$9=20250930)*1 | O6: =(20250930=20251002)*1 | P6: Yes - 301-11.17 | Q6: 0 | R6: 26 | S6: 0 | T6: =(0)+(26)+(0) | U6: =IF(ControlPanel!$B$9>20250930,0,IF(OR(ControlPanel!$B$9=20250930,20250930=20251002),MAX(69.0-((0)+(26)+(0)),5),MAX(92-((0)+(26)+(0)),5))) | V6: Cap from FY2025 Master row 258; M&IE from FY2025 row 258; Registration-fee lunch → deduct Lunch; Hotel breakfast is complimentary (301-11.17) → no deduction in any case; First/last day applies 75% M&IE per 301-11.101; floor is $5 incidental (301-11.18)
A7: CHICAGO | B7: 45931 | C7: Wed | D7: Training day | E7: FY2026 | F7: 223 | G7: 218 | H7: =(218<=223) | I7: =MIN(218,223) | J7: =MIN(218,223)*0.12 | K7: =MIN(218,223)*1.12 | L7: 92 | M7: 69 | N7: =(ControlPanel!$B$9=20251001)*1 | O7: =(20251001=20251002)*1 | P7: Yes - 301-11.17 | Q7: 0 | R7: 26 | S7: 38 | T7: =(0)+(26)+(38) | U7: =IF(ControlPanel!$B$9>20251001,0,IF(OR(ControlPanel!$B$9=20251001,20251001=20251002),MAX(69.0-((0)+(26)+(38)),5),MAX(92-((0)+(26)+(38)),5))) | V7: Cap from FY2026 Master row 254; M&IE from FY2026 row 254; Registration-fee lunch + government dinner → deduct both; Hotel breakfast is complimentary (301-11.17) → no deduction in any case; First/last day applies 75% M&IE per 301-11.101; floor is $5 incidental (301-11.18)
A8: CHICAGO | B8: 45932 | C8: Thu | D8: Return / last travel day | E8: FY2026 | F8: 223 | G8: 218 | H8: =(218<=223) | I8: =MIN(218,223) | J8: =MIN(218,223)*0.12 | K8: =MIN(218,223)*1.12 | L8: 92 | M8: 69 | N8: =(ControlPanel!$B$9=20251002)*1 | O8: =(20251002=20251002)*1 | P8: Yes - 301-11.17 | Q8: 0 | R8: 26 | S8: 0 | T8: =(0)+(26)+(0) | U8: =IF(ControlPanel!$B$9>20251002,0,IF(OR(ControlPanel!$B$9=20251002,20251002=20251002),MAX(69.0-((0)+(26)+(0)),5),MAX(92-((0)+(26)+(0)),5))) | V8: Cap from FY2026 Master row 254; M&IE from FY2026 row 254; Government departure lunch → deduct Lunch; Hotel breakfast is complimentary (301-11.17) → no deduction in any case; First/last day applies 75% M&IE per 301-11.101; floor is $5 incidental (301-11.18)
A10: DENVER
A11: DENVER | B11: 45927 | C11: Sat | D11: Pre-arrival | E11: FY2025 | F11: 215 | G11: 209 | H11: =(209<=215) | I11: =MIN(209,215) | J11: =MIN(209,215)*0.12 | K11: =MIN(209,215)*1.12 | L11: 92 | M11: 69 | N11: =(ControlPanel!$B$9=20250927)*1 | O11: =(20250927=20251002)*1 | P11: Yes - 301-11.17 | Q11: 0 | R11: 0 | S11: 0 | T11: =(0)+(0)+(0) | U11: =IF(ControlPanel!$B$9>20250927,0,IF(OR(ControlPanel!$B$9=20250927,20250927=20251002),MAX(69.0-((0)+(0)+(0)),5),MAX(92-((0)+(0)+(0)),5))) | V11: Cap from FY2025 Master row 109; M&IE from FY2025 row 109; Pre-arrival per WF_ARRIVAL; no lodging/tax/M&IE incurred this day; Hotel breakfast is complimentary (301-11.17) → no deduction in any case; First/last day applies 75% M&IE per 301-11.101; floor is $5 incidental (301-11.18)
A12: DENVER | B12: 45928 | C12: Sun | D12: Arrival / first travel day | E12: FY2025 | F12: 215 | G12: 209 | H12: =(209<=215) | I12: =MIN(209,215) | J12: =MIN(209,215)*0.12 | K12: =MIN(209,215)*1.12 | L12: 92 | M12: 69 | N12: =(ControlPanel!$B$9=20250928)*1 | O12: =(20250928=20251002)*1 | P12: Yes - 301-11.17 | Q12: 0 | R12: 0 | S12: 38 | T12: =(0)+(0)+(38) | U12: =IF(ControlPanel!$B$9>20250928,0,IF(OR(ControlPanel!$B$9=20250928,20250928=20251002),MAX(69.0-((0)+(0)+(38)),5),MAX(92-((0)+(0)+(38)),5))) | V12: Cap from FY2025 Master row 109; M&IE from FY2025 row 109; Government welcome dinner (included in fixed venue fee) → deduct Dinner; Hotel breakfast is complimentary (301-11.17) → no deduction in any case; First/last day applies 75% M&IE per 301-11.101; floor is $5 incidental (301-11.18)
A13: DENVER | B13: 45929 | C13: Mon | D13: Training day | E13: FY2025 | F13: 215 | G13: 209 | H13: =(209<=215) | I13: =MIN(209,215) | J13: =MIN(209,215)*0.12 | K13: =MIN(209,215)*1.12 | L13: 92 | M13: 69 | N13: =(ControlPanel!$B$9=20250929)*1 | O13: =(20250929=20251002)*1 | P13: Yes - 301-11.17 | Q13: IF(ControlPanel!$B$8=1,23,0) | R13: 26 | S13: 0 | T13: =(IF(ControlPanel!$B$8=1,23,0))+(26)+(0) | U13: =IF(ControlPanel!$B$9>20250929,0,IF(OR(ControlPanel!$B$9=20250929,20250929=20251002),MAX(69.0-((IF(ControlPanel!$B$8=1,23,0))+(26)+(0)),5),MAX(92-((IF(ControlPanel!$B$8=1,23,0))+(26)+(0)),5))) | V13: Cap from FY2025 Master row 109; M&IE from FY2025 row 109; Registration-fee lunch → deduct Lunch; Hotel breakfast is complimentary (301-11.17) → no deduction in any case; First/last day applies 75% M&IE per 301-11.101; floor is $5 incidental (301-11.18)
A14: DENVER | B14: 45930 | C14: Tue | D14: Training day | E14: FY2025 | F14: 215 | G14: 209 | H14: =(209<=215) | I14: =MIN(209,215) | J14: =MIN(209,215)*0.12 | K14: =MIN(209,215)*1.12 | L14: 92 | M14: 69 | N14: =(ControlPanel!$B$9=20250930)*1 | O14: =(20250930=20251002)*1 | P14: Yes - 301-11.17 | Q14: 0 | R14: 26 | S14: 0 | T14: =(0)+(26)+(0) | U14: =IF(ControlPanel!$B$9>20250930,0,IF(OR(ControlPanel!$B$9=20250930,20250930=20251002),MAX(69.0-((0)+(26)+(0)),5),MAX(92-((0)+(26)+(0)),5))) | V14: Cap from FY2025 Master row 109; M&IE from FY2025 row 109; Registration-fee lunch → deduct Lunch; Hotel breakfast is complimentary (301-11.17) → no deduction in any case; First/last day applies 75% M&IE per 301-11.101; floor is $5 incidental (301-11.18)
A15: DENVER | B15: 45931 | C15: Wed | D15: Training day | E15: FY2026 | F15: 215 | G15: 209 | H15: =(209<=215) | I15: =MIN(209,215) | J15: =MIN(209,215)*0.12 | K15: =MIN(209,215)*1.12 | L15: 92 | M15: 69 | N15: =(ControlPanel!$B$9=20251001)*1 | O15: =(20251001=20251002)*1 | P15: Yes - 301-11.17 | Q15: 0 | R15: 26 | S15: 38 | T15: =(0)+(26)+(38) | U15: =IF(ControlPanel!$B$9>20251001,0,IF(OR(ControlPanel!$B$9=20251001,20251001=20251002),MAX(69.0-((0)+(26)+(38)),5),MAX(92-((0)+(26)+(38)),5))) | V15: Cap from FY2026 Master row 107; M&IE from FY2026 row 107; Registration-fee lunch + government dinner → deduct both; Hotel breakfast is complimentary (301-11.17) → no deduction in any case; First/last day applies 75% M&IE per 301-11.101; floor is $5 incidental (301-11.18)
A16: DENVER | B16: 45932 | C16: Thu | D16: Return / last travel day | E16: FY2026 | F16: 215 | G16: 209 | H16: =(209<=215) | I16: =MIN(209,215) | J16: =MIN(209,215)*0.12 | K16: =MIN(209,215)*1.12 | L16: 92 | M16: 69 | N16: =(ControlPanel!$B$9=20251002)*1 | O16: =(20251002=20251002)*1 | P16: Yes - 301-11.17 | Q16: 0 | R16: 26 | S16: 0 | T16: =(0)+(26)+(0) | U16: =IF(ControlPanel!$B$9>20251002,0,IF(OR(ControlPanel!$B$9=20251002,20251002=20251002),MAX(69.0-((0)+(26)+(0)),5),MAX(92-((0)+(26)+(0)),5))) | V16: Cap from FY2026 Master row 107; M&IE from FY2026 row 107; Government departure lunch → deduct Lunch; Hotel breakfast is complimentary (301-11.17) → no deduction in any case; First/last day applies 75% M&IE per 301-11.101; floor is $5 incidental (301-11.18)
A18: PHOENIX
A19: PHOENIX | B19: 45927 | C19: Sat | D19: Pre-arrival | E19: FY2025 | F19: 160 | G19: 155 | H19: =(155<=160) | I19: =MIN(155,160) | J19: =MIN(155,160)*0.12 | K19: =MIN(155,160)*1.12 | L19: 86 | M19: 64.5 | N19: =(ControlPanel!$B$9=20250927)*1 | O19: =(20250927=20251002)*1 | P19: Yes - 301-11.17 | Q19: 0 | R19: 0 | S19: 0 | T19: =(0)+(0)+(0) | U19: =IF(ControlPanel!$B$9>20250927,0,IF(OR(ControlPanel!$B$9=20250927,20250927=20251002),MAX(64.5-((0)+(0)+(0)),5),MAX(86-((0)+(0)+(0)),5))) | V19: Cap from FY2025 Master row 22; M&IE from FY2025 row 22; Pre-arrival per WF_ARRIVAL; no lodging/tax/M&IE incurred this day; Hotel breakfast is complimentary (301-11.17) → no deduction in any case; First/last day applies 75% M&IE per 301-11.101; floor is $5 incidental (301-11.18)
A20: PHOENIX | B20: 45928 | C20: Sun | D20: Arrival / first travel day | E20: FY2025 | F20: 160 | G20: 155 | H20: =(155<=160) | I20: =MIN(155,160) | J20: =MIN(155,160)*0.12 | K20: =MIN(155,160)*1.12 | L20: 86 | M20: 64.5 | N20: =(ControlPanel!$B$9=20250928)*1 | O20: =(20250928=20251002)*1 | P20: Yes - 301-11.17 | Q20: 0 | R20: 0 | S20: 36 | T20: =(0)+(0)+(36) | U20: =IF(ControlPanel!$B$9>20250928,0,IF(OR(ControlPanel!$B$9=20250928,20250928=20251002),MAX(64.5-((0)+(0)+(36)),5),MAX(86-((0)+(0)+(36)),5))) | V20: Cap from FY2025 Master row 22; M&IE from FY2025 row 22; Government welcome dinner (included in fixed venue fee) → deduct Dinner; Hotel breakfast is complimentary (301-11.17) → no deduction in any case; First/last day applies 75% M&IE per 301-11.101; floor is $5 incidental (301-11.18)
A21: PHOENIX | B21: 45929 | C21: Mon | D21: Training day | E21: FY2025 | F21: 160 | G21: 155 | H21: =(155<=160) | I21: =MIN(155,160) | J21: =MIN(155,160)*0.12 | K21: =MIN(155,160)*1.12 | L21: 86 | M21: 64.5 | N21: =(ControlPanel!$B$9=20250929)*1 | O21: =(20250929=20251002)*1 | P21: Yes - 301-11.17 | Q21: IF(ControlPanel!$B$8=1,22,0) | R21: 23 | S21: 0 | T21: =(IF(ControlPanel!$B$8=1,22,0))+(23)+(0) | U21: =IF(ControlPanel!$B$9>20250929,0,IF(OR(ControlPanel!$B$9=20250929,20250929=20251002),MAX(64.5-((IF(ControlPanel!$B$8=1,22,0))+(23)+(0)),5),MAX(86-((IF(ControlPanel!$B$8=1,22,0))+(23)+(0)),5))) | V21: Cap from FY2025 Master row 22; M&IE from FY2025 row 22; Registration-fee lunch → deduct Lunch; Hotel breakfast is complimentary (301-11.17) → no deduction in any case; First/last day applies 75% M&IE per 301-11.101; floor is $5 incidental (301-11.18)
A22: PHOENIX | B22: 45930 | C22: Tue | D22: Training day | E22: FY2025 | F22: 160 | G22: 155 | H22: =(155<=160) | I22: =MIN(155,160) | J22: =MIN(155,160)*0.12 | K22: =MIN(155,160)*1.12 | L22: 86 | M22: 64.5 | N22: =(ControlPanel!$B$9=20250930)*1 | O22: =(20250930=20251002)*1 | P22: Yes - 301-11.17 | Q22: 0 | R22: 23 | S22: 0 | T22: =(0)+(23)+(0) | U22: =IF(ControlPanel!$B$9>20250930,0,IF(OR(ControlPanel!$B$9=20250930,20250930=20251002),MAX(64.5-((0)+(23)+(0)),5),MAX(86-((0)+(23)+(0)),5))) | V22: Cap from FY2025 Master row 22; M&IE from FY2025 row 22; Registration-fee lunch → deduct Lunch; Hotel breakfast is complimentary (301-11.17) → no deduction in any case; First/last day applies 75% M&IE per 301-11.101; floor is $5 incidental (301-11.18)
A23: PHOENIX | B23: 45931 | C23: Wed | D23: Training day | E23: FY2026 | F23: 160 | G23: 155 | H23: =(155<=160) | I23: =MIN(155,160) | J23: =MIN(155,160)*0.12 | K23: =MIN(155,160)*1.12 | L23: 86 | M23: 64.5 | N23: =(ControlPanel!$B$9=20251001)*1 | O23: =(20251001=20251002)*1 | P23: Yes - 301-11.17 | Q23: 0 | R23: 23 | S23: 36 | T23: =(0)+(23)+(36) | U23: =IF(ControlPanel!$B$9>20251001,0,IF(OR(ControlPanel!$B$9=20251001,20251001=20251002),MAX(64.5-((0)+(23)+(36)),5),MAX(86-((0)+(23)+(36)),5))) | V23: Cap from FY2026 Master row 18; M&IE from FY2026 row 18; Registration-fee lunch + government dinner → deduct both; Hotel breakfast is complimentary (301-11.17) → no deduction in any case; First/last day applies 75% M&IE per 301-11.101; floor is $5 incidental (301-11.18)
A24: PHOENIX | B24: 45932 | C24: Thu | D24: Return / last travel day | E24: FY2026 | F24: 160 | G24: 155 | H24: =(155<=160) | I24: =MIN(155,160) | J24: =MIN(155,160)*0.12 | K24: =MIN(155,160)*1.12 | L24: 86 | M24: 64.5 | N24: =(ControlPanel!$B$9=20251002)*1 | O24: =(20251002=20251002)*1 | P24: Yes - 301-11.17 | Q24: 0 | R24: 23 | S24: 0 | T24: =(0)+(23)+(0) | U24: =IF(ControlPanel!$B$9>20251002,0,IF(OR(ControlPanel!$B$9=20251002,20251002=20251002),MAX(64.5-((0)+(23)+(0)),5),MAX(86-((0)+(23)+(0)),5))) | V24: Cap from FY2026 Master row 18; M&IE from FY2026 row 18; Government departure lunch → deduct Lunch; Hotel breakfast is complimentary (301-11.17) → no deduction in any case; First/last day applies 75% M&IE per 301-11.101; floor is $5 incidental (301-11.18)

Sheet Options
A1: City | B1: Headcount | C1: FY split (Sep/Oct) | D1: Airfare/person (base × WF_AIR_MULTIPLIER) | E1: Local transport/person | F1: Registration/person | G1: M&IE/person (Daily sum over travel dates) | H1: Nights per person | I1: Nightly lodging (quote) | J1: Nightly lodging tax (12%) | K1: Lodging+tax/person (4 nights) | L1: Fixed venue fee | M1: Airfare subtotal | N1: Local subtotal | O1: Registration subtotal | P1: M&IE subtotal | Q1: Lodging+tax subtotal | R1: Base subtotal | S1: Reserve (WF_RESERVE_RATE) | T1: Total with reserve | U1: WF_BUDGET | V1: Under budget? | W1: Stress: Airfare ×1.20 subtotal | X1: Stress: Base subtotal | Y1: Stress: Reserve | Z1: Stress: Total with reserve | AA1: Stress under budget? | AB1: Lodging compliance (quote <= GSA cap all nights) | AC1: Notes
A2: CHICAGO | B2: 18 | C2: 09-28..09-30 FY2025; 10-01..10-02 FY2026 (cap/MIE identical across FY here) | D2: =ControlPanel!$B$6*410 | E2: =80 | F2: =180 | G2: =Daily!U3+Daily!U4+Daily!U5+Daily!U6+Daily!U7+Daily!U8 | H2: =IF((ControlPanel!$B$9<=20250927)*(20250927<=20251001),1,0)+IF((ControlPanel!$B$9<=20250928)*(20250928<=20251001),1,0)+IF((ControlPanel!$B$9<=20250929)*(20250929<=20251001),1,0)+IF((ControlPanel!$B$9<=20250930)*(20250930<=20251001),1,0)+IF((ControlPanel!$B$9<=20251001)*(20251001<=20251001),1,0)+IF((ControlPanel!$B$9<=20251002)*(20251002<=20251001),1,0) | I2: =MIN(218,223) | J2: =MIN(218,223)*0.12 | K2: =(MIN(218,223)+MIN(218,223)*0.12)*(IF((ControlPanel!$B$9<=20250927)*(20250927<=20251001),1,0)+IF((ControlPanel!$B$9<=20250928)*(20250928<=20251001),1,0)+IF((ControlPanel!$B$9<=20250929)*(20250929<=20251001),1,0)+IF((ControlPanel!$B$9<=20250930)*(20250930<=20251001),1,0)+IF((ControlPanel!$B$9<=20251001)*(20251001<=20251001),1,0)+IF((ControlPanel!$B$9<=20251002)*(20251002<=20251001),1,0)) | L2: =9500 | M2: =(ControlPanel!$B$6*410)*18 | N2: =(80)*18 | O2: =(180)*18 | P2: =(Daily!U3+Daily!U4+Daily!U5+Daily!U6+Daily!U7+Daily!U8)*18 | Q2: =((MIN(218,223)+MIN(218,223)*0.12)*(IF((ControlPanel!$B$9<=20250927)*(20250927<=20251001),1,0)+IF((ControlPanel!$B$9<=20250928)*(20250928<=20251001),1,0)+IF((ControlPanel!$B$9<=20250929)*(20250929<=20251001),1,0)+IF((ControlPanel!$B$9<=20250930)*(20250930<=20251001),1,0)+IF((ControlPanel!$B$9<=20251001)*(20251001<=20251001),1,0)+IF((ControlPanel!$B$9<=20251002)*(20251002<=20251001),1,0)))*18 | R2: =((ControlPanel!$B$6*410)*18)+((80)*18)+((180)*18)+((Daily!U3+Daily!U4+Daily!U5+Daily!U6+Daily!U7+Daily!U8)*18)+(((MIN(218,223)+MIN(218,223)*0.12)*(IF((ControlPanel!$B$9<=20250927)*(20250927<=20251001),1,0)+IF((ControlPanel!$B$9<=20250928)*(20250928<=20251001),1,0)+IF((ControlPanel!$B$9<=20250929)*(20250929<=20251001),1,0)+IF((ControlPanel!$B$9<=20250930)*(20250930<=20251001),1,0)+IF((ControlPanel!$B$9<=20251001)*(20251001<=20251001),1,0)+IF((ControlPanel!$B$9<=20251002)*(20251002<=20251001),1,0)))*18)+(9500) | S2: =(((ControlPanel!$B$6*410)*18)+((80)*18)+((180)*18)+((Daily!U3+Daily!U4+Daily!U5+Daily!U6+Daily!U7+Daily!U8)*18)+(((MIN(218,223)+MIN(218,223)*0.12)*(IF((ControlPanel!$B$9<=20250927)*(20250927<=20251001),1,0)+IF((ControlPanel!$B$9<=20250928)*(20250928<=20251001),1,0)+IF((ControlPanel!$B$9<=20250929)*(20250929<=20251001),1,0)+IF((ControlPanel!$B$9<=20250930)*(20250930<=20251001),1,0)+IF((ControlPanel!$B$9<=20251001)*(20251001<=20251001),1,0)+IF((ControlPanel!$B$9<=20251002)*(20251002<=20251001),1,0)))*18)+(9500))*ControlPanel!$B$7 | T2: =(((ControlPanel!$B$6*410)*18)+((80)*18)+((180)*18)+((Daily!U3+Daily!U4+Daily!U5+Daily!U6+Daily!U7+Daily!U8)*18)+(((MIN(218,223)+MIN(218,223)*0.12)*(IF((ControlPanel!$B$9<=20250927)*(20250927<=20251001),1,0)+IF((ControlPanel!$B$9<=20250928)*(20250928<=20251001),1,0)+IF((ControlPanel!$B$9<=20250929)*(20250929<=20251001),1,0)+IF((ControlPanel!$B$9<=20250930)*(20250930<=20251001),1,0)+IF((ControlPanel!$B$9<=20251001)*(20251001<=20251001),1,0)+IF((ControlPanel!$B$9<=20251002)*(20251002<=20251001),1,0)))*18)+(9500))+((((ControlPanel!$B$6*410)*18)+((80)*18)+((180)*18)+((Daily!U3+Daily!U4+Daily!U5+Daily!U6+Daily!U7+Daily!U8)*18)+(((MIN(218,223)+MIN(218,223)*0.12)*(IF((ControlPanel!$B$9<=20250927)*(20250927<=20251001),1,0)+IF((ControlPanel!$B$9<=20250928)*(20250928<=20251001),1,0)+IF((ControlPanel!$B$9<=20250929)*(20250929<=20251001),1,0)+IF((ControlPanel!$B$9<=20250930)*(20250930<=20251001),1,0)+IF((ControlPanel!$B$9<=20251001)*(20251001<=20251001),1,0)+IF((ControlPanel!$B$9<=20251002)*(20251002<=20251001),1,0)))*18)+(9500))*ControlPanel!$B$7) | U2: =ControlPanel!$B$5 | V2: =((((ControlPanel!$B$6*410)*18)+((80)*18)+((180)*18)+((Daily!U3+Daily!U4+Daily!U5+Daily!U6+Daily!U7+Daily!U8)*18)+(((MIN(218,223)+MIN(218,223)*0.12)*(IF((ControlPanel!$B$9<=20250927)*(20250927<=20251001),1,0)+IF((ControlPanel!$B$9<=20250928)*(20250928<=20251001),1,0)+IF((ControlPanel!$B$9<=20250929)*(20250929<=20251001),1,0)+IF((ControlPanel!$B$9<=20250930)*(20250930<=20251001),1,0)+IF((ControlPanel!$B$9<=20251001)*(20251001<=20251001),1,0)+IF((ControlPanel!$B$9<=20251002)*(20251002<=20251001),1,0)))*18)+(9500))+((((ControlPanel!$B$6*410)*18)+((80)*18)+((180)*18)+((Daily!U3+Daily!U4+Daily!U5+Daily!U6+Daily!U7+Daily!U8)*18)+(((MIN(218,223)+MIN(218,223)*0.12)*(IF((ControlPanel!$B$9<=20250927)*(20250927<=20251001),1,0)+IF((ControlPanel!$B$9<=20250928)*(20250928<=20251001),1,0)+IF((ControlPanel!$B$9<=20250929)*(20250929<=20251001),1,0)+IF((ControlPanel!$B$9<=20250930)*(20250930<=20251001),1,0)+IF((ControlPanel!$B$9<=20251001)*(20251001<=20251001),1,0)+IF((ControlPanel!$B$9<=20251002)*(20251002<=20251001),1,0)))*18)+(9500))*ControlPanel!$B$7))<=ControlPanel!$B$5 | W2: =(ControlPanel!$B$6*410)*18*1.2 | X2: =(((ControlPanel!$B$6*410)*18)+((80)*18)+((180)*18)+((Daily!U3+Daily!U4+Daily!U5+Daily!U6+Daily!U7+Daily!U8)*18)+(((MIN(218,223)+MIN(218,223)*0.12)*(IF((ControlPanel!$B$9<=20250927)*(20250927<=20251001),1,0)+IF((ControlPanel!$B$9<=20250928)*(20250928<=20251001),1,0)+IF((ControlPanel!$B$9<=20250929)*(20250929<=20251001),1,0)+IF((ControlPanel!$B$9<=20250930)*(20250930<=20251001),1,0)+IF((ControlPanel!$B$9<=20251001)*(20251001<=20251001),1,0)+IF((ControlPanel!$B$9<=20251002)*(20251002<=20251001),1,0)))*18)+(9500))-((ControlPanel!$B$6*410)*18)+((ControlPanel!$B$6*410)*18*1.2) | Y2: =((((ControlPanel!$B$6*410)*18)+((80)*18)+((180)*18)+((Daily!U3+Daily!U4+Daily!U5+Daily!U6+Daily!U7+Daily!U8)*18)+(((MIN(218,223)+MIN(218,223)*0.12)*(IF((ControlPanel!$B$9<=20250927)*(20250927<=20251001),1,0)+IF((ControlPanel!$B$9<=20250928)*(20250928<=20251001),1,0)+IF((ControlPanel!$B$9<=20250929)*(20250929<=20251001),1,0)+IF((ControlPanel!$B$9<=20250930)*(20250930<=20251001),1,0)+IF((ControlPanel!$B$9<=20251001)*(20251001<=20251001),1,0)+IF((ControlPanel!$B$9<=20251002)*(20251002<=20251001),1,0)))*18)+(9500))-((ControlPanel!$B$6*410)*18)+((ControlPanel!$B$6*410)*18*1.2))*ControlPanel!$B$7 | Z2: =((((ControlPanel!$B$6*410)*18)+((80)*18)+((180)*18)+((Daily!U3+Daily!U4+Daily!U5+Daily!U6+Daily!U7+Daily!U8)*18)+(((MIN(218,223)+MIN(218,223)*0.12)*(IF((ControlPanel!$B$9<=20250927)*(20250927<=20251001),1,0)+IF((ControlPanel!$B$9<=20250928)*(20250928<=20251001),1,0)+IF((ControlPanel!$B$9<=20250929)*(20250929<=20251001),1,0)+IF((ControlPanel!$B$9<=20250930)*(20250930<=20251001),1,0)+IF((ControlPanel!$B$9<=20251001)*(20251001<=20251001),1,0)+IF((ControlPanel!$B$9<=20251002)*(20251002<=20251001),1,0)))*18)+(9500))-((ControlPanel!$B$6*410)*18)+((ControlPanel!$B$6*410)*18*1.2))+(((((ControlPanel!$B$6*410)*18)+((80)*18)+((180)*18)+((Daily!U3+Daily!U4+Daily!U5+Daily!U6+Daily!U7+Daily!U8)*18)+(((MIN(218,223)+MIN(218,223)*0.12)*(IF((ControlPanel!$B$9<=20250927)*(20250927<=20251001),1,0)+IF((ControlPanel!$B$9<=20250928)*(20250928<=20251001),1,0)+IF((ControlPanel!$B$9<=20250929)*(20250929<=20251001),1,0)+IF((ControlPanel!$B$9<=20250930)*(20250930<=20251001),1,0)+IF((ControlPanel!$B$9<=20251001)*(20251001<=20251001),1,0)+IF((ControlPanel!$B$9<=20251002)*(20251002<=20251001),1,0)))*18)+(9500))-((ControlPanel!$B$6*410)*18)+((ControlPanel!$B$6*410)*18*1.2))*ControlPanel!$B$7) | AA2: =(((((ControlPanel!$B$6*410)*18)+((80)*18)+((180)*18)+((Daily!U3+Daily!U4+Daily!U5+Daily!U6+Daily!U7+Daily!U8)*18)+(((MIN(218,223)+MIN(218,223)*0.12)*(IF((ControlPanel!$B$9<=20250927)*(20250927<=20251001),1,0)+IF((ControlPanel!$B$9<=20250928)*(20250928<=20251001),1,0)+IF((ControlPanel!$B$9<=20250929)*(20250929<=20251001),1,0)+IF((ControlPanel!$B$9<=20250930)*(20250930<=20251001),1,0)+IF((ControlPanel!$B$9<=20251001)*(20251001<=20251001),1,0)+IF((ControlPanel!$B$9<=20251002)*(20251002<=20251001),1,0)))*18)+(9500))-((ControlPanel!$B$6*410)*18)+((ControlPanel!$B$6*410)*18*1.2))+(((((ControlPanel!$B$6*410)*18)+((80)*18)+((180)*18)+((Daily!U3+Daily!U4+Daily!U5+Daily!U6+Daily!U7+Daily!U8)*18)+(((MIN(218,223)+MIN(218,223)*0.12)*(IF((ControlPanel!$B$9<=20250927)*(20250927<=20251001),1,0)+IF((ControlPanel!$B$9<=20250928)*(20250928<=20251001),1,0)+IF((ControlPanel!$B$9<=20250929)*(20250929<=20251001),1,0)+IF((ControlPanel!$B$9<=20250930)*(20250930<=20251001),1,0)+IF((ControlPanel!$B$9<=20251001)*(20251001<=20251001),1,0)+IF((ControlPanel!$B$9<=20251002)*(20251002<=20251001),1,0)))*18)+(9500))-((ControlPanel!$B$6*410)*18)+((ControlPanel!$B$6*410)*18*1.2))*ControlPanel!$B$7))<=ControlPanel!$B$5 | AB2: =AND(Daily!H3,Daily!H4,Daily!H5,Daily!H6,Daily!H7,Daily!H8) | AC2: Cap per 09-28..09-30 FY2025; 10-01..10-02 FY2026 (cap/MIE identical across FY here); M&IE per 09-28..09-30 FY2025; 10-01..10-02 FY2026 (cap/MIE identical across FY here). FY2025 Master rows: lodging 258, M&IE 258. FY2026 Master rows: lodging 254, M&IE 254. Tax is internal 12% assumption on reimbursable lodging (301-11.27). Hotel BF free = no M&IE deduction (301-11.17). Gov meals deducted per 301-11.18 with $5 incidental floor. Stress adds 20% airfare on top of current WF_AIR_MULTIPLIER.
A3: CHICAGO | B3: 24 | C3: 09-28..09-30 FY2025; 10-01..10-02 FY2026 (cap/MIE identical across FY here) | D3: =ControlPanel!$B$6*410 | E3: =80 | F3: =180 | G3: =Daily!U3+Daily!U4+Daily!U5+Daily!U6+Daily!U7+Daily!U8 | H3: =IF((ControlPanel!$B$9<=20250927)*(20250927<=20251001),1,0)+IF((ControlPanel!$B$9<=20250928)*(20250928<=20251001),1,0)+IF((ControlPanel!$B$9<=20250929)*(20250929<=20251001),1,0)+IF((ControlPanel!$B$9<=20250930)*(20250930<=20251001),1,0)+IF((ControlPanel!$B$9<=20251001)*(20251001<=20251001),1,0)+IF((ControlPanel!$B$9<=20251002)*(20251002<=20251001),1,0) | I3: =MIN(218,223) | J3: =MIN(218,223)*0.12 | K3: =(MIN(218,223)+MIN(218,223)*0.12)*(IF((ControlPanel!$B$9<=20250927)*(20250927<=20251001),1,0)+IF((ControlPanel!$B$9<=20250928)*(20250928<=20251001),1,0)+IF((ControlPanel!$B$9<=20250929)*(20250929<=20251001),1,0)+IF((ControlPanel!$B$9<=20250930)*(20250930<=20251001),1,0)+IF((ControlPanel!$B$9<=20251001)*(20251001<=20251001),1,0)+IF((ControlPanel!$B$9<=20251002)*(20251002<=20251001),1,0)) | L3: =9500 | M3: =(ControlPanel!$B$6*410)*24 | N3: =(80)*24 | O3: =(180)*24 | P3: =(Daily!U3+Daily!U4+Daily!U5+Daily!U6+Daily!U7+Daily!U8)*24 | Q3: =((MIN(218,223)+MIN(218,223)*0.12)*(IF((ControlPanel!$B$9<=20250927)*(20250927<=20251001),1,0)+IF((ControlPanel!$B$9<=20250928)*(20250928<=20251001),1,0)+IF((ControlPanel!$B$9<=20250929)*(20250929<=20251001),1,0)+IF((ControlPanel!$B$9<=20250930)*(20250930<=20251001),1,0)+IF((ControlPanel!$B$9<=20251001)*(20251001<=20251001),1,0)+IF((ControlPanel!$B$9<=20251002)*(20251002<=20251001),1,0)))*24 | R3: =((ControlPanel!$B$6*410)*24)+((80)*24)+((180)*24)+((Daily!U3+Daily!U4+Daily!U5+Daily!U6+Daily!U7+Daily!U8)*24)+(((MIN(218,223)+MIN(218,223)*0.12)*(IF((ControlPanel!$B$9<=20250927)*(20250927<=20251001),1,0)+IF((ControlPanel!$B$9<=20250928)*(20250928<=20251001),1,0)+IF((ControlPanel!$B$9<=20250929)*(20250929<=20251001),1,0)+IF((ControlPanel!$B$9<=20250930)*(20250930<=20251001),1,0)+IF((ControlPanel!$B$9<=20251001)*(20251001<=20251001),1,0)+IF((ControlPanel!$B$9<=20251002)*(20251002<=20251001),1,0)))*24)+(9500) | S3: =(((ControlPanel!$B$6*410)*24)+((80)*24)+((180)*24)+((Daily!U3+Daily!U4+Daily!U5+Daily!U6+Daily!U7+Daily!U8)*24)+(((MIN(218,223)+MIN(218,223)*0.12)*(IF((ControlPanel!$B$9<=20250927)*(20250927<=20251001),1,0)+IF((ControlPanel!$B$9<=20250928)*(20250928<=20251001),1,0)+IF((ControlPanel!$B$9<=20250929)*(20250929<=20251001),1,0)+IF((ControlPanel!$B$9<=20250930)*(20250930<=20251001),1,0)+IF((ControlPanel!$B$9<=20251001)*(20251001<=20251001),1,0)+IF((ControlPanel!$B$9<=20251002)*(20251002<=20251001),1,0)))*24)+(9500))*ControlPanel!$B$7 | T3: =(((ControlPanel!$B$6*410)*24)+((80)*24)+((180)*24)+((Daily!U3+Daily!U4+Daily!U5+Daily!U6+Daily!U7+Daily!U8)*24)+(((MIN(218,223)+MIN(218,223)*0.12)*(IF((ControlPanel!$B$9<=20250927)*(20250927<=20251001),1,0)+IF((ControlPanel!$B$9<=20250928)*(20250928<=20251001),1,0)+IF((ControlPanel!$B$9<=20250929)*(20250929<=20251001),1,0)+IF((ControlPanel!$B$9<=20250930)*(20250930<=20251001),1,0)+IF((ControlPanel!$B$9<=20251001)*(20251001<=20251001),1,0)+IF((ControlPanel!$B$9<=20251002)*(20251002<=20251001),1,0)))*24)+(9500))+((((ControlPanel!$B$6*410)*24)+((80)*24)+((180)*24)+((Daily!U3+Daily!U4+Daily!U5+Daily!U6+Daily!U7+Daily!U8)*24)+(((MIN(218,223)+MIN(218,223)*0.12)*(IF((ControlPanel!$B$9<=20250927)*(20250927<=20251001),1,0)+IF((ControlPanel!$B$9<=20250928)*(20250928<=20251001),1,0)+IF((ControlPanel!$B$9<=20250929)*(20250929<=20251001),1,0)+IF((ControlPanel!$B$9<=20250930)*(20250930<=20251001),1,0)+IF((ControlPanel!$B$9<=20251001)*(20251001<=20251001),1,0)+IF((ControlPanel!$B$9<=20251002)*(20251002<=20251001),1,0)))*24)+(9500))*ControlPanel!$B$7) | U3: =ControlPanel!$B$5 | V3: =((((ControlPanel!$B$6*410)*24)+((80)*24)+((180)*24)+((Daily!U3+Daily!U4+Daily!U5+Daily!U6+Daily!U7+Daily!U8)*24)+(((MIN(218,223)+MIN(218,223)*0.12)*(IF((ControlPanel!$B$9<=20250927)*(20250927<=20251001),1,0)+IF((ControlPanel!$B$9<=20250928)*(20250928<=20251001),1,0)+IF((ControlPanel!$B$9<=20250929)*(20250929<=20251001),1,0)+IF((ControlPanel!$B$9<=20250930)*(20250930<=20251001),1,0)+IF((ControlPanel!$B$9<=20251001)*(20251001<=20251001),1,0)+IF((ControlPanel!$B$9<=20251002)*(20251002<=20251001),1,0)))*24)+(9500))+((((ControlPanel!$B$6*410)*24)+((80)*24)+((180)*24)+((Daily!U3+Daily!U4+Daily!U5+Daily!U6+Daily!U7+Daily!U8)*24)+(((MIN(218,223)+MIN(218,223)*0.12)*(IF((ControlPanel!$B$9<=20250927)*(20250927<=20251001),1,0)+IF((ControlPanel!$B$9<=20250928)*(20250928<=20251001),1,0)+IF((ControlPanel!$B$9<=20250929)*(20250929<=20251001),1,0)+IF((ControlPanel!$B$9<=20250930)*(20250930<=20251001),1,0)+IF((ControlPanel!$B$9<=20251001)*(20251001<=20251001),1,0)+IF((ControlPanel!$B$9<=20251002)*(20251002<=20251001),1,0)))*24)+(9500))*ControlPanel!$B$7))<=ControlPanel!$B$5 | W3: =(ControlPanel!$B$6*410)*24*1.2 | X3: =(((ControlPanel!$B$6*410)*24)+((80)*24)+((180)*24)+((Daily!U3+Daily!U4+Daily!U5+Daily!U6+Daily!U7+Daily!U8)*24)+(((MIN(218,223)+MIN(218,223)*0.12)*(IF((ControlPanel!$B$9<=20250927)*(20250927<=20251001),1,0)+IF((ControlPanel!$B$9<=20250928)*(20250928<=20251001),1,0)+IF((ControlPanel!$B$9<=20250929)*(20250929<=20251001),1,0)+IF((ControlPanel!$B$9<=20250930)*(20250930<=20251001),1,0)+IF((ControlPanel!$B$9<=20251001)*(20251001<=20251001),1,0)+IF((ControlPanel!$B$9<=20251002)*(20251002<=20251001),1,0)))*24)+(9500))-((ControlPanel!$B$6*410)*24)+((ControlPanel!$B$6*410)*24*1.2) | Y3: =((((ControlPanel!$B$6*410)*24)+((80)*24)+((180)*24)+((Daily!U3+Daily!U4+Daily!U5+Daily!U6+Daily!U7+Daily!U8)*24)+(((MIN(218,223)+MIN(218,223)*0.12)*(IF((ControlPanel!$B$9<=20250927)*(20250927<=20251001),1,0)+IF((ControlPanel!$B$9<=20250928)*(20250928<=20251001),1,0)+IF((ControlPanel!$B$9<=20250929)*(20250929<=20251001),1,0)+IF((ControlPanel!$B$9<=20250930)*(20250930<=20251001),1,0)+IF((ControlPanel!$B$9<=20251001)*(20251001<=20251001),1,0)+IF((ControlPanel!$B$9<=20251002)*(20251002<=20251001),1,0)))*24)+(9500))-((ControlPanel!$B$6*410)*24)+((ControlPanel!$B$6*410)*24*1.2))*ControlPanel!$B$7 | Z3: =((((ControlPanel!$B$6*410)*24)+((80)*24)+((180)*24)+((Daily!U3+Daily!U4+Daily!U5+Daily!U6+Daily!U7+Daily!U8)*24)+(((MIN(218,223)+MIN(218,223)*0.12)*(IF((ControlPanel!$B$9<=20250927)*(20250927<=20251001),1,0)+IF((ControlPanel!$B$9<=20250928)*(20250928<=20251001),1,0)+IF((ControlPanel!$B$9<=20250929)*(20250929<=20251001),1,0)+IF((ControlPanel!$B$9<=20250930)*(20250930<=20251001),1,0)+IF((ControlPanel!$B$9<=20251001)*(20251001<=20251001),1,0)+IF((ControlPanel!$B$9<=20251002)*(20251002<=20251001),1,0)))*24)+(9500))-((ControlPanel!$B$6*410)*24)+((ControlPanel!$B$6*410)*24*1.2))+(((((ControlPanel!$B$6*410)*24)+((80)*24)+((180)*24)+((Daily!U3+Daily!U4+Daily!U5+Daily!U6+Daily!U7+Daily!U8)*24)+(((MIN(218,223)+MIN(218,223)*0.12)*(IF((ControlPanel!$B$9<=20250927)*(20250927<=20251001),1,0)+IF((ControlPanel!$B$9<=20250928)*(20250928<=20251001),1,0)+IF((ControlPanel!$B$9<=20250929)*(20250929<=20251001),1,0)+IF((ControlPanel!$B$9<=20250930)*(20250930<=20251001),1,0)+IF((ControlPanel!$B$9<=20251001)*(20251001<=20251001),1,0)+IF((ControlPanel!$B$9<=20251002)*(20251002<=20251001),1,0)))*24)+(9500))-((ControlPanel!$B$6*410)*24)+((ControlPanel!$B$6*410)*24*1.2))*ControlPanel!$B$7) | AA3: =(((((ControlPanel!$B$6*410)*24)+((80)*24)+((180)*24)+((Daily!U3+Daily!U4+Daily!U5+Daily!U6+Daily!U7+Daily!U8)*24)+(((MIN(218,223)+MIN(218,223)*0.12)*(IF((ControlPanel!$B$9<=20250927)*(20250927<=20251001),1,0)+IF((ControlPanel!$B$9<=20250928)*(20250928<=20251001),1,0)+IF((ControlPanel!$B$9<=20250929)*(20250929<=20251001),1,0)+IF((ControlPanel!$B$9<=20250930)*(20250930<=20251001),1,0)+IF((ControlPanel!$B$9<=20251001)*(20251001<=20251001),1,0)+IF((ControlPanel!$B$9<=20251002)*(20251002<=20251001),1,0)))*24)+(9500))-((ControlPanel!$B$6*410)*24)+((ControlPanel!$B$6*410)*24*1.2))+(((((ControlPanel!$B$6*410)*24)+((80)*24)+((180)*24)+((Daily!U3+Daily!U4+Daily!U5+Daily!U6+Daily!U7+Daily!U8)*24)+(((MIN(218,223)+MIN(218,223)*0.12)*(IF((ControlPanel!$B$9<=20250927)*(20250927<=20251001),1,0)+IF((ControlPanel!$B$9<=20250928)*(20250928<=20251001),1,0)+IF((ControlPanel!$B$9<=20250929)*(20250929<=20251001),1,0)+IF((ControlPanel!$B$9<=20250930)*(20250930<=20251001),1,0)+IF((ControlPanel!$B$9<=20251001)*(20251001<=20251001),1,0)+IF((ControlPanel!$B$9<=20251002)*(20251002<=20251001),1,0)))*24)+(9500))-((ControlPanel!$B$6*410)*24)+((ControlPanel!$B$6*410)*24*1.2))*ControlPanel!$B$7))<=ControlPanel!$B$5 | AB3: =AND(Daily!H3,Daily!H4,Daily!H5,Daily!H6,Daily!H7,Daily!H8) | AC3: Cap per 09-28..09-30 FY2025; 10-01..10-02 FY2026 (cap/MIE identical across FY here); M&IE per 09-28..09-30 FY2025; 10-01..10-02 FY2026 (cap/MIE identical across FY here). FY2025 Master rows: lodging 258, M&IE 258. FY2026 Master rows: lodging 254, M&IE 254. Tax is internal 12% assumption on reimbursable lodging (301-11.27). Hotel BF free = no M&IE deduction (301-11.17). Gov meals deducted per 301-11.18 with $5 incidental floor. Stress adds 20% airfare on top of current WF_AIR_MULTIPLIER.
A4: DENVER | B4: 18 | C4: 09-28..09-30 FY2025; 10-01..10-02 FY2026 (cap/MIE identical across FY here) | D4: =ControlPanel!$B$6*340 | E4: =70 | F4: =180 | G4: =Daily!U11+Daily!U12+Daily!U13+Daily!U14+Daily!U15+Daily!U16 | H4: =IF((ControlPanel!$B$9<=20250927)*(20250927<=20251001),1,0)+IF((ControlPanel!$B$9<=20250928)*(20250928<=20251001),1,0)+IF((ControlPanel!$B$9<=20250929)*(20250929<=20251001),1,0)+IF((ControlPanel!$B$9<=20250930)*(20250930<=20251001),1,0)+IF((ControlPanel!$B$9<=20251001)*(20251001<=20251001),1,0)+IF((ControlPanel!$B$9<=20251002)*(20251002<=20251001),1,0) | I4: =MIN(209,215) | J4: =MIN(209,215)*0.12 | K4: =(MIN(209,215)+MIN(209,215)*0.12)*(IF((ControlPanel!$B$9<=20250927)*(20250927<=20251001),1,0)+IF((ControlPanel!$B$9<=20250928)*(20250928<=20251001),1,0)+IF((ControlPanel!$B$9<=20250929)*(20250929<=20251001),1,0)+IF((ControlPanel!$B$9<=20250930)*(20250930<=20251001),1,0)+IF((ControlPanel!$B$9<=20251001)*(20251001<=20251001),1,0)+IF((ControlPanel!$B$9<=20251002)*(20251002<=20251001),1,0)) | L4: =10500 | M4: =(ControlPanel!$B$6*340)*18 | N4: =(70)*18 | O4: =(180)*18 | P4: =(Daily!U11+Daily!U12+Daily!U13+Daily!U14+Daily!U15+Daily!U16)*18 | Q4: =((MIN(209,215)+MIN(209,215)*0.12)*(IF((ControlPanel!$B$9<=20250927)*(20250927<=20251001),1,0)+IF((ControlPanel!$B$9<=20250928)*(20250928<=20251001),1,0)+IF((ControlPanel!$B$9<=20250929)*(20250929<=20251001),1,0)+IF((ControlPanel!$B$9<=20250930)*(20250930<=20251001),1,0)+IF((ControlPanel!$B$9<=20251001)*(20251001<=20251001),1,0)+IF((ControlPanel!$B$9<=20251002)*(20251002<=20251001),1,0)))*18 | R4: =((ControlPanel!$B$6*340)*18)+((70)*18)+((180)*18)+((Daily!U11+Daily!U12+Daily!U13+Daily!U14+Daily!U15+Daily!U16)*18)+(((MIN(209,215)+MIN(209,215)*0.12)*(IF((ControlPanel!$B$9<=20250927)*(20250927<=20251001),1,0)+IF((ControlPanel!$B$9<=20250928)*(20250928<=20251001),1,0)+IF((ControlPanel!$B$9<=20250929)*(20250929<=20251001),1,0)+IF((ControlPanel!$B$9<=20250930)*(20250930<=20251001),1,0)+IF((ControlPanel!$B$9<=20251001)*(20251001<=20251001),1,0)+IF((ControlPanel!$B$9<=20251002)*(20251002<=20251001),1,0)))*18)+(10500) | S4: =(((ControlPanel!$B$6*340)*18)+((70)*18)+((180)*18)+((Daily!U11+Daily!U12+Daily!U13+Daily!U14+Daily!U15+Daily!U16)*18)+(((MIN(209,215)+MIN(209,215)*0.12)*(IF((ControlPanel!$B$9<=20250927)*(20250927<=20251001),1,0)+IF((ControlPanel!$B$9<=20250928)*(20250928<=20251001),1,0)+IF((ControlPanel!$B$9<=20250929)*(20250929<=20251001),1,0)+IF((ControlPanel!$B$9<=20250930)*(20250930<=20251001),1,0)+IF((ControlPanel!$B$9<=20251001)*(20251001<=20251001),1,0)+IF((ControlPanel!$B$9<=20251002)*(20251002<=20251001),1,0)))*18)+(10500))*ControlPanel!$B$7 | T4: =(((ControlPanel!$B$6*340)*18)+((70)*18)+((180)*18)+((Daily!U11+Daily!U12+Daily!U13+Daily!U14+Daily!U15+Daily!U16)*18)+(((MIN(209,215)+MIN(209,215)*0.12)*(IF((ControlPanel!$B$9<=20250927)*(20250927<=20251001),1,0)+IF((ControlPanel!$B$9<=20250928)*(20250928<=20251001),1,0)+IF((ControlPanel!$B$9<=20250929)*(20250929<=20251001),1,0)+IF((ControlPanel!$B$9<=20250930)*(20250930<=20251001),1,0)+IF((ControlPanel!$B$9<=20251001)*(20251001<=20251001),1,0)+IF((ControlPanel!$B$9<=20251002)*(20251002<=20251001),1,0)))*18)+(10500))+((((ControlPanel!$B$6*340)*18)+((70)*18)+((180)*18)+((Daily!U11+Daily!U12+Daily!U13+Daily!U14+Daily!U15+Daily!U16)*18)+(((MIN(209,215)+MIN(209,215)*0.12)*(IF((ControlPanel!$B$9<=20250927)*(20250927<=20251001),1,0)+IF((ControlPanel!$B$9<=20250928)*(20250928<=20251001),1,0)+IF((ControlPanel!$B$9<=20250929)*(20250929<=20251001),1,0)+IF((ControlPanel!$B$9<=20250930)*(20250930<=20251001),1,0)+IF((ControlPanel!$B$9<=20251001)*(20251001<=20251001),1,0)+IF((ControlPanel!$B$9<=20251002)*(20251002<=20251001),1,0)))*18)+(10500))*ControlPanel!$B$7) | U4: =ControlPanel!$B$5 | V4: =((((ControlPanel!$B$6*340)*18)+((70)*18)+((180)*18)+((Daily!U11+Daily!U12+Daily!U13+Daily!U14+Daily!U15+Daily!U16)*18)+(((MIN(209,215)+MIN(209,215)*0.12)*(IF((ControlPanel!$B$9<=20250927)*(20250927<=20251001),1,0)+IF((ControlPanel!$B$9<=20250928)*(20250928<=20251001),1,0)+IF((ControlPanel!$B$9<=20250929)*(20250929<=20251001),1,0)+IF((ControlPanel!$B$9<=20250930)*(20250930<=20251001),1,0)+IF((ControlPanel!$B$9<=20251001)*(20251001<=20251001),1,0)+IF((ControlPanel!$B$9<=20251002)*(20251002<=20251001),1,0)))*18)+(10500))+((((ControlPanel!$B$6*340)*18)+((70)*18)+((180)*18)+((Daily!U11+Daily!U12+Daily!U13+Daily!U14+Daily!U15+Daily!U16)*18)+(((MIN(209,215)+MIN(209,215)*0.12)*(IF((ControlPanel!$B$9<=20250927)*(20250927<=20251001),1,0)+IF((ControlPanel!$B$9<=20250928)*(20250928<=20251001),1,0)+IF((ControlPanel!$B$9<=20250929)*(20250929<=20251001),1,0)+IF((ControlPanel!$B$9<=20250930)*(20250930<=20251001),1,0)+IF((ControlPanel!$B$9<=20251001)*(20251001<=20251001),1,0)+IF((ControlPanel!$B$9<=20251002)*(20251002<=20251001),1,0)))*18)+(10500))*ControlPanel!$B$7))<=ControlPanel!$B$5 | W4: =(ControlPanel!$B$6*340)*18*1.2 | X4: =(((ControlPanel!$B$6*340)*18)+((70)*18)+((180)*18)+((Daily!U11+Daily!U12+Daily!U13+Daily!U14+Daily!U15+Daily!U16)*18)+(((MIN(209,215)+MIN(209,215)*0.12)*(IF((ControlPanel!$B$9<=20250927)*(20250927<=20251001),1,0)+IF((ControlPanel!$B$9<=20250928)*(20250928<=20251001),1,0)+IF((ControlPanel!$B$9<=20250929)*(20250929<=20251001),1,0)+IF((ControlPanel!$B$9<=20250930)*(20250930<=20251001),1,0)+IF((ControlPanel!$B$9<=20251001)*(20251001<=20251001),1,0)+IF((ControlPanel!$B$9<=20251002)*(20251002<=20251001),1,0)))*18)+(10500))-((ControlPanel!$B$6*340)*18)+((ControlPanel!$B$6*340)*18*1.2) | Y4: =((((ControlPanel!$B$6*340)*18)+((70)*18)+((180)*18)+((Daily!U11+Daily!U12+Daily!U13+Daily!U14+Daily!U15+Daily!U16)*18)+(((MIN(209,215)+MIN(209,215)*0.12)*(IF((ControlPanel!$B$9<=20250927)*(20250927<=20251001),1,0)+IF((ControlPanel!$B$9<=20250928)*(20250928<=20251001),1,0)+IF((ControlPanel!$B$9<=20250929)*(20250929<=20251001),1,0)+IF((ControlPanel!$B$9<=20250930)*(20250930<=20251001),1,0)+IF((ControlPanel!$B$9<=20251001)*(20251001<=20251001),1,0)+IF((ControlPanel!$B$9<=20251002)*(20251002<=20251001),1,0)))*18)+(10500))-((ControlPanel!$B$6*340)*18)+((ControlPanel!$B$6*340)*18*1.2))*ControlPanel!$B$7 | Z4: =((((ControlPanel!$B$6*340)*18)+((70)*18)+((180)*18)+((Daily!U11+Daily!U12+Daily!U13+Daily!U14+Daily!U15+Daily!U16)*18)+(((MIN(209,215)+MIN(209,215)*0.12)*(IF((ControlPanel!$B$9<=20250927)*(20250927<=20251001),1,0)+IF((ControlPanel!$B$9<=20250928)*(20250928<=20251001),1,0)+IF((ControlPanel!$B$9<=20250929)*(20250929<=20251001),1,0)+IF((ControlPanel!$B$9<=20250930)*(20250930<=20251001),1,0)+IF((ControlPanel!$B$9<=20251001)*(20251001<=20251001),1,0)+IF((ControlPanel!$B$9<=20251002)*(20251002<=20251001),1,0)))*18)+(10500))-((ControlPanel!$B$6*340)*18)+((ControlPanel!$B$6*340)*18*1.2))+(((((ControlPanel!$B$6*340)*18)+((70)*18)+((180)*18)+((Daily!U11+Daily!U12+Daily!U13+Daily!U14+Daily!U15+Daily!U16)*18)+(((MIN(209,215)+MIN(209,215)*0.12)*(IF((ControlPanel!$B$9<=20250927)*(20250927<=20251001),1,0)+IF((ControlPanel!$B$9<=20250928)*(20250928<=20251001),1,0)+IF((ControlPanel!$B$9<=20250929)*(20250929<=20251001),1,0)+IF((ControlPanel!$B$9<=20250930)*(20250930<=20251001),1,0)+IF((ControlPanel!$B$9<=20251001)*(20251001<=20251001),1,0)+IF((ControlPanel!$B$9<=20251002)*(20251002<=20251001),1,0)))*18)+(10500))-((ControlPanel!$B$6*340)*18)+((ControlPanel!$B$6*340)*18*1.2))*ControlPanel!$B$7) | AA4: =(((((ControlPanel!$B$6*340)*18)+((70)*18)+((180)*18)+((Daily!U11+Daily!U12+Daily!U13+Daily!U14+Daily!U15+Daily!U16)*18)+(((MIN(209,215)+MIN(209,215)*0.12)*(IF((ControlPanel!$B$9<=20250927)*(20250927<=20251001),1,0)+IF((ControlPanel!$B$9<=20250928)*(20250928<=20251001),1,0)+IF((ControlPanel!$B$9<=20250929)*(20250929<=20251001),1,0)+IF((ControlPanel!$B$9<=20250930)*(20250930<=20251001),1,0)+IF((ControlPanel!$B$9<=20251001)*(20251001<=20251001),1,0)+IF((ControlPanel!$B$9<=20251002)*(20251002<=20251001),1,0)))*18)+(10500))-((ControlPanel!$B$6*340)*18)+((ControlPanel!$B$6*340)*18*1.2))+(((((ControlPanel!$B$6*340)*18)+((70)*18)+((180)*18)+((Daily!U11+Daily!U12+Daily!U13+Daily!U14+Daily!U15+Daily!U16)*18)+(((MIN(209,215)+MIN(209,215)*0.12)*(IF((ControlPanel!$B$9<=20250927)*(20250927<=20251001),1,0)+IF((ControlPanel!$B$9<=20250928)*(20250928<=20251001),1,0)+IF((ControlPanel!$B$9<=20250929)*(20250929<=20251001),1,0)+IF((ControlPanel!$B$9<=20250930)*(20250930<=20251001),1,0)+IF((ControlPanel!$B$9<=20251001)*(20251001<=20251001),1,0)+IF((ControlPanel!$B$9<=20251002)*(20251002<=20251001),1,0)))*18)+(10500))-((ControlPanel!$B$6*340)*18)+((ControlPanel!$B$6*340)*18*1.2))*ControlPanel!$B$7))<=ControlPanel!$B$5 | AB4: =AND(Daily!H11,Daily!H12,Daily!H13,Daily!H14,Daily!H15,Daily!H16) | AC4: Cap per 09-28..09-30 FY2025; 10-01..10-02 FY2026 (cap/MIE identical across FY here); M&IE per 09-28..09-30 FY2025; 10-01..10-02 FY2026 (cap/MIE identical across FY here). FY2025 Master rows: lodging 109, M&IE 109. FY2026 Master rows: lodging 107, M&IE 107. Tax is internal 12% assumption on reimbursable lodging (301-11.27). Hotel BF free = no M&IE deduction (301-11.17). Gov meals deducted per 301-11.18 with $5 incidental floor. Stress adds 20% airfare on top of current WF_AIR_MULTIPLIER.
A5: DENVER | B5: 24 | C5: 09-28..09-30 FY2025; 10-01..10-02 FY2026 (cap/MIE identical across FY here) | D5: =ControlPanel!$B$6*340 | E5: =70 | F5: =180 | G5: =Daily!U11+Daily!U12+Daily!U13+Daily!U14+Daily!U15+Daily!U16 | H5: =IF((ControlPanel!$B$9<=20250927)*(20250927<=20251001),1,0)+IF((ControlPanel!$B$9<=20250928)*(20250928<=20251001),1,0)+IF((ControlPanel!$B$9<=20250929)*(20250929<=20251001),1,0)+IF((ControlPanel!$B$9<=20250930)*(20250930<=20251001),1,0)+IF((ControlPanel!$B$9<=20251001)*(20251001<=20251001),1,0)+IF((ControlPanel!$B$9<=20251002)*(20251002<=20251001),1,0) | I5: =MIN(209,215) | J5: =MIN(209,215)*0.12 | K5: =(MIN(209,215)+MIN(209,215)*0.12)*(IF((ControlPanel!$B$9<=20250927)*(20250927<=20251001),1,0)+IF((ControlPanel!$B$9<=20250928)*(20250928<=20251001),1,0)+IF((ControlPanel!$B$9<=20250929)*(20250929<=20251001),1,0)+IF((ControlPanel!$B$9<=20250930)*(20250930<=20251001),1,0)+IF((ControlPanel!$B$9<=20251001)*(20251001<=20251001),1,0)+IF((ControlPanel!$B$9<=20251002)*(20251002<=20251001),1,0)) | L5: =10500 | M5: =(ControlPanel!$B$6*340)*24 | N5: =(70)*24 | O5: =(180)*24 | P5: =(Daily!U11+Daily!U12+Daily!U13+Daily!U14+Daily!U15+Daily!U16)*24 | Q5: =((MIN(209,215)+MIN(209,215)*0.12)*(IF((ControlPanel!$B$9<=20250927)*(20250927<=20251001),1,0)+IF((ControlPanel!$B$9<=20250928)*(20250928<=20251001),1,0)+IF((ControlPanel!$B$9<=20250929)*(20250929<=20251001),1,0)+IF((ControlPanel!$B$9<=20250930)*(20250930<=20251001),1,0)+IF((ControlPanel!$B$9<=20251001)*(20251001<=20251001),1,0)+IF((ControlPanel!$B$9<=20251002)*(20251002<=20251001),1,0)))*24 | R5: =((ControlPanel!$B$6*340)*24)+((70)*24)+((180)*24)+((Daily!U11+Daily!U12+Daily!U13+Daily!U14+Daily!U15+Daily!U16)*24)+(((MIN(209,215)+MIN(209,215)*0.12)*(IF((ControlPanel!$B$9<=20250927)*(20250927<=20251001),1,0)+IF((ControlPanel!$B$9<=20250928)*(20250928<=20251001),1,0)+IF((ControlPanel!$B$9<=20250929)*(20250929<=20251001),1,0)+IF((ControlPanel!$B$9<=20250930)*(20250930<=20251001),1,0)+IF((ControlPanel!$B$9<=20251001)*(20251001<=20251001),1,0)+IF((ControlPanel!$B$9<=20251002)*(20251002<=20251001),1,0)))*24)+(10500) | S5: =(((ControlPanel!$B$6*340)*24)+((70)*24)+((180)*24)+((Daily!U11+Daily!U12+Daily!U13+Daily!U14+Daily!U15+Daily!U16)*24)+(((MIN(209,215)+MIN(209,215)*0.12)*(IF((ControlPanel!$B$9<=20250927)*(20250927<=20251001),1,0)+IF((ControlPanel!$B$9<=20250928)*(20250928<=20251001),1,0)+IF((ControlPanel!$B$9<=20250929)*(20250929<=20251001),1,0)+IF((ControlPanel!$B$9<=20250930)*(20250930<=20251001),1,0)+IF((ControlPanel!$B$9<=20251001)*(20251001<=20251001),1,0)+IF((ControlPanel!$B$9<=20251002)*(20251002<=20251001),1,0)))*24)+(10500))*ControlPanel!$B$7 | T5: =(((ControlPanel!$B$6*340)*24)+((70)*24)+((180)*24)+((Daily!U11+Daily!U12+Daily!U13+Daily!U14+Daily!U15+Daily!U16)*24)+(((MIN(209,215)+MIN(209,215)*0.12)*(IF((ControlPanel!$B$9<=20250927)*(20250927<=20251001),1,0)+IF((ControlPanel!$B$9<=20250928)*(20250928<=20251001),1,0)+IF((ControlPanel!$B$9<=20250929)*(20250929<=20251001),1,0)+IF((ControlPanel!$B$9<=20250930)*(20250930<=20251001),1,0)+IF((ControlPanel!$B$9<=20251001)*(20251001<=20251001),1,0)+IF((ControlPanel!$B$9<=20251002)*(20251002<=20251001),1,0)))*24)+(10500))+((((ControlPanel!$B$6*340)*24)+((70)*24)+((180)*24)+((Daily!U11+Daily!U12+Daily!U13+Daily!U14+Daily!U15+Daily!U16)*24)+(((MIN(209,215)+MIN(209,215)*0.12)*(IF((ControlPanel!$B$9<=20250927)*(20250927<=20251001),1,0)+IF((ControlPanel!$B$9<=20250928)*(20250928<=20251001),1,0)+IF((ControlPanel!$B$9<=20250929)*(20250929<=20251001),1,0)+IF((ControlPanel!$B$9<=20250930)*(20250930<=20251001),1,0)+IF((ControlPanel!$B$9<=20251001)*(20251001<=20251001),1,0)+IF((ControlPanel!$B$9<=20251002)*(20251002<=20251001),1,0)))*24)+(10500))*ControlPanel!$B$7) | U5: =ControlPanel!$B$5 | V5: =((((ControlPanel!$B$6*340)*24)+((70)*24)+((180)*24)+((Daily!U11+Daily!U12+Daily!U13+Daily!U14+Daily!U15+Daily!U16)*24)+(((MIN(209,215)+MIN(209,215)*0.12)*(IF((ControlPanel!$B$9<=20250927)*(20250927<=20251001),1,0)+IF((ControlPanel!$B$9<=20250928)*(20250928<=20251001),1,0)+IF((ControlPanel!$B$9<=20250929)*(20250929<=20251001),1,0)+IF((ControlPanel!$B$9<=20250930)*(20250930<=20251001),1,0)+IF((ControlPanel!$B$9<=20251001)*(20251001<=20251001),1,0)+IF((ControlPanel!$B$9<=20251002)*(20251002<=20251001),1,0)))*24)+(10500))+((((ControlPanel!$B$6*340)*24)+((70)*24)+((180)*24)+((Daily!U11+Daily!U12+Daily!U13+Daily!U14+Daily!U15+Daily!U16)*24)+(((MIN(209,215)+MIN(209,215)*0.12)*(IF((ControlPanel!$B$9<=20250927)*(20250927<=20251001),1,0)+IF((ControlPanel!$B$9<=20250928)*(20250928<=20251001),1,0)+IF((ControlPanel!$B$9<=20250929)*(20250929<=20251001),1,0)+IF((ControlPanel!$B$9<=20250930)*(20250930<=20251001),1,0)+IF((ControlPanel!$B$9<=20251001)*(20251001<=20251001),1,0)+IF((ControlPanel!$B$9<=20251002)*(20251002<=20251001),1,0)))*24)+(10500))*ControlPanel!$B$7))<=ControlPanel!$B$5 | W5: =(ControlPanel!$B$6*340)*24*1.2 | X5: =(((ControlPanel!$B$6*340)*24)+((70)*24)+((180)*24)+((Daily!U11+Daily!U12+Daily!U13+Daily!U14+Daily!U15+Daily!U16)*24)+(((MIN(209,215)+MIN(209,215)*0.12)*(IF((ControlPanel!$B$9<=20250927)*(20250927<=20251001),1,0)+IF((ControlPanel!$B$9<=20250928)*(20250928<=20251001),1,0)+IF((ControlPanel!$B$9<=20250929)*(20250929<=20251001),1,0)+IF((ControlPanel!$B$9<=20250930)*(20250930<=20251001),1,0)+IF((ControlPanel!$B$9<=20251001)*(20251001<=20251001),1,0)+IF((ControlPanel!$B$9<=20251002)*(20251002<=20251001),1,0)))*24)+(10500))-((ControlPanel!$B$6*340)*24)+((ControlPanel!$B$6*340)*24*1.2) | Y5: =((((ControlPanel!$B$6*340)*24)+((70)*24)+((180)*24)+((Daily!U11+Daily!U12+Daily!U13+Daily!U14+Daily!U15+Daily!U16)*24)+(((MIN(209,215)+MIN(209,215)*0.12)*(IF((ControlPanel!$B$9<=20250927)*(20250927<=20251001),1,0)+IF((ControlPanel!$B$9<=20250928)*(20250928<=20251001),1,0)+IF((ControlPanel!$B$9<=20250929)*(20250929<=20251001),1,0)+IF((ControlPanel!$B$9<=20250930)*(20250930<=20251001),1,0)+IF((ControlPanel!$B$9<=20251001)*(20251001<=20251001),1,0)+IF((ControlPanel!$B$9<=20251002)*(20251002<=20251001),1,0)))*24)+(10500))-((ControlPanel!$B$6*340)*24)+((ControlPanel!$B$6*340)*24*1.2))*ControlPanel!$B$7 | Z5: =((((ControlPanel!$B$6*340)*24)+((70)*24)+((180)*24)+((Daily!U11+Daily!U12+Daily!U13+Daily!U14+Daily!U15+Daily!U16)*24)+(((MIN(209,215)+MIN(209,215)*0.12)*(IF((ControlPanel!$B$9<=20250927)*(20250927<=20251001),1,0)+IF((ControlPanel!$B$9<=20250928)*(20250928<=20251001),1,0)+IF((ControlPanel!$B$9<=20250929)*(20250929<=20251001),1,0)+IF((ControlPanel!$B$9<=20250930)*(20250930<=20251001),1,0)+IF((ControlPanel!$B$9<=20251001)*(20251001<=20251001),1,0)+IF((ControlPanel!$B$9<=20251002)*(20251002<=20251001),1,0)))*24)+(10500))-((ControlPanel!$B$6*340)*24)+((ControlPanel!$B$6*340)*24*1.2))+(((((ControlPanel!$B$6*340)*24)+((70)*24)+((180)*24)+((Daily!U11+Daily!U12+Daily!U13+Daily!U14+Daily!U15+Daily!U16)*24)+(((MIN(209,215)+MIN(209,215)*0.12)*(IF((ControlPanel!$B$9<=20250927)*(20250927<=20251001),1,0)+IF((ControlPanel!$B$9<=20250928)*(20250928<=20251001),1,0)+IF((ControlPanel!$B$9<=20250929)*(20250929<=20251001),1,0)+IF((ControlPanel!$B$9<=20250930)*(20250930<=20251001),1,0)+IF((ControlPanel!$B$9<=20251001)*(20251001<=20251001),1,0)+IF((ControlPanel!$B$9<=20251002)*(20251002<=20251001),1,0)))*24)+(10500))-((ControlPanel!$B$6*340)*24)+((ControlPanel!$B$6*340)*24*1.2))*ControlPanel!$B$7) | AA5: =(((((ControlPanel!$B$6*340)*24)+((70)*24)+((180)*24)+((Daily!U11+Daily!U12+Daily!U13+Daily!U14+Daily!U15+Daily!U16)*24)+(((MIN(209,215)+MIN(209,215)*0.12)*(IF((ControlPanel!$B$9<=20250927)*(20250927<=20251001),1,0)+IF((ControlPanel!$B$9<=20250928)*(20250928<=20251001),1,0)+IF((ControlPanel!$B$9<=20250929)*(20250929<=20251001),1,0)+IF((ControlPanel!$B$9<=20250930)*(20250930<=20251001),1,0)+IF((ControlPanel!$B$9<=20251001)*(20251001<=20251001),1,0)+IF((ControlPanel!$B$9<=20251002)*(20251002<=20251001),1,0)))*24)+(10500))-((ControlPanel!$B$6*340)*24)+((ControlPanel!$B$6*340)*24*1.2))+(((((ControlPanel!$B$6*340)*24)+((70)*24)+((180)*24)+((Daily!U11+Daily!U12+Daily!U13+Daily!U14+Daily!U15+Daily!U16)*24)+(((MIN(209,215)+MIN(209,215)*0.12)*(IF((ControlPanel!$B$9<=20250927)*(20250927<=20251001),1,0)+IF((ControlPanel!$B$9<=20250928)*(20250928<=20251001),1,0)+IF((ControlPanel!$B$9<=20250929)*(20250929<=20251001),1,0)+IF((ControlPanel!$B$9<=20250930)*(20250930<=20251001),1,0)+IF((ControlPanel!$B$9<=20251001)*(20251001<=20251001),1,0)+IF((ControlPanel!$B$9<=20251002)*(20251002<=20251001),1,0)))*24)+(10500))-((ControlPanel!$B$6*340)*24)+((ControlPanel!$B$6*340)*24*1.2))*ControlPanel!$B$7))<=ControlPanel!$B$5 | AB5: =AND(Daily!H11,Daily!H12,Daily!H13,Daily!H14,Daily!H15,Daily!H16) | AC5: Cap per 09-28..09-30 FY2025; 10-01..10-02 FY2026 (cap/MIE identical across FY here); M&IE per 09-28..09-30 FY2025; 10-01..10-02 FY2026 (cap/MIE identical across FY here). FY2025 Master rows: lodging 109, M&IE 109. FY2026 Master rows: lodging 107, M&IE 107. Tax is internal 12% assumption on reimbursable lodging (301-11.27). Hotel BF free = no M&IE deduction (301-11.17). Gov meals deducted per 301-11.18 with $5 incidental floor. Stress adds 20% airfare on top of current WF_AIR_MULTIPLIER.
